Workbook
Name AP: #REF!
Name AR: #REF!
Name capex: #REF!
Name cash: #REF!
Name CFF: #REF!
Name CFI: #REF!
Name CFO: #REF!
Name cogs: #REF!
Name cpi_rus_cumul: #REF!
Name cpi_rus_month: #REF!
Name cpi_us_month: #REF!
Name days_month: #REF!
Name depr: #REF!
Name first_month: #REF!
Name fixed_asset: #REF!
Name inventory: #REF!
Name ltgr: #REF!
Name min_cash: #REF!
Name min_cash_div: #REF!
Name month_year: #REF!
Name ndfl: #REF!
Name ndfl_rate: #REF!
Name nds: #REF!
Name opex: #REF!
Name prof_tax: #REF!
Name prof_tax_rate: #REF!
Name re: #REF!
Name revenue: #REF!
Name social_tax_rate: #REF!
Name TV: #REF!
Name work_cap_ch: #REF!
Name AP: #REF!
Name AR: #REF!
Name capex: #REF!

Sheet Дашборд
A1: ФИНАНСОВЫЙ ДАШБОРД 2025
A2: =TODAY()
A5: КЛЮЧЕВЫЕ ПОКАЗАТЕЛИ
A7: Показатель | C7: Значение
A8: Годовая выручка (продажи) | C8: ='PL общ'!O15 | E8: Выручка от реализации товаров
A9: Чистая прибыль | C9: ='PL общ'!O57 | E9: Прибыль после налогов
A10: Маржинальность | C10: ='PL общ'!O59 | E10: Отношение прибыли к выручке
A11: Валовая прибыль | C11: ='PL общ'!O36 | E11: Прибыль до расходов
A12: Рентабельность | C12: ='PL общ'!O58 | E12: ROI вложений
A14: СРАВНЕНИЕ ПЛАТФОРМ
A16: Метрика | C16: Wildberries | F16: OZON
A17: Продажи (шт) | C17: ='PL WB'!O7 | D17: =C17/(C17+F17) | F17: ='PL OZON'!O7 | G17: =100%-D17
A18: Выручка (руб) | C18: ='PL WB'!O15 | D18: =C18/(C18+F18) | F18: ='PL OZON'!O14 | G18: =100%-D18
A19: Чистая прибыль | C19: ='PL WB'!O57 | D19: =C19/(C19+F19) | F19: ='PL OZON'!O57 | G19: =100%-D19
A20: Средний чек | C20: =C18/C17 | F20: =F18/F17
A21: Маржа (%) | C21: ='PL WB'!O59 | F21: ='PL OZON'!O59
A23: СТРУКТУРА РАСХОДОВ
A25: Статья расходов | C25: Сумма (руб) | E25: Доля (%)
A26: Комиссии площадок | C26: ='PL общ'!O17 | E26: =C26/'PL общ'!O14
A27: Логистика | C27: ='PL общ'!O40 | E27: =C27/'PL общ'!O14
A28: Продвижение | C28: ='PL общ'!O41 | E28: =C28/'PL общ'!O14
A29: Себестоимость | C29: ='PL общ'!O33 | E29: =C29/'PL общ'!O14
A30: Хранение | C30: ='PL общ'!O43 | E30: =C30/'PL общ'!O14
A31: Прочие расходы | C31: ='PL общ'!O38-'PL общ'!O40-'PL общ'!O41-'PL общ'!O43 | E31: =C31/'PL общ'!O14
A32: ИТОГО расходов | C32: ='PL общ'!O38+'PL общ'!O17+'PL общ'!O33 | E32: =C32/'PL общ'!O14
A34: ПОМЕСЯЧНАЯ ДИНАМИКА
A36: Месяц | B36: Янв | C36: Фев | D36: Мар | E36: Апр | F36: Май | G36: Июн | H36: Июл | I36: Авг | J36: Сен | K36: Окт | L36: Ноя | M36: Дек
A37: Выручка | B37: ='PL общ'!C15 | C37: ='PL общ'!D15 | D37: ='PL общ'!E15 | E37: ='PL общ'!F15 | F37: ='PL общ'!G15 | G37: ='PL общ'!H15 | H37: ='PL общ'!I15 | I37: ='PL общ'!J15 | ... M37: ='PL общ'!N15
A38: Прибыль | B38: ='PL общ'!C57 | C38: ='PL общ'!D57 | D38: ='PL общ'!E57 | E38: ='PL общ'!F57 | F38: ='PL общ'!G57 | G38: ='PL общ'!H57 | H38: ='PL общ'!I57 | I38: ='PL общ'!J57 | ... M38: ='PL общ'!N57

Sheet PL общ
A1: Заполняем PL и CF еженедельный!
A2: Прибыли и убытки | C2: 2025
C3: Январь | D3: Февраль | E3: Март | F3: Апрель | G3: Май | H3: Июнь | I3: Июль | J3: Август | K3: Сентябрь | L3: Октябрь | M3: Ноябрь | N3: Декабрь
A4: Товарооборот
A5: Остаток товара по цене закупки | C5: ='PL WB'!C5+'PL OZON'!C5 | D5: ='PL WB'!D5+'PL OZON'!D5 | E5: ='PL WB'!E5+'PL OZON'!E5 | F5: ='PL WB'!F5+'PL OZON'!F5 | G5: ='PL WB'!G5+'PL OZON'!G5 | H5: ='PL WB'!H5+'PL OZON'!H5 | I5: ='PL WB'!I5+'PL OZON'!I5 | J5: ='PL WB'!J5+'PL OZON'!J5 | ... N5: ='PL WB'!N5+'PL OZON'!N5
B7: Продажи шт | C7: ='PL WB'!C7+'PL OZON'!C7 | D7: ='PL WB'!D7+'PL OZON'!D7 | E7: ='PL WB'!E7+'PL OZON'!E7 | F7: ='PL WB'!F7+'PL OZON'!F7 | G7: ='PL WB'!G7+'PL OZON'!G7 | H7: ='PL WB'!H7+'PL OZON'!H7 | I7: ='PL WB'!I7+'PL OZON'!I7 | J7: ='PL WB'!J7+'PL OZON'!J7 | ... N7: ='PL WB'!N7+'PL OZON'!N7 | O7: =SUM(C7:N7)
B8: Отгрузки по себестоимости | C8: =C33 | D8: =D33 | E8: =E33 | F8: =F33 | G8: =G33 | H8: =H33 | I8: =I33 | J8: =J33 | ... N8: =N33 | O8: =SUM(C8:N8)
A10: Поступление товара, р | C10: ='PL WB'!C10+'PL OZON'!C10 | D10: ='PL WB'!D10+'PL OZON'!D10 | E10: ='PL WB'!E10+'PL OZON'!E10 | F10: ='PL WB'!F10+'PL OZON'!F10 | G10: ='PL WB'!G10+'PL OZON'!G10 | H10: ='PL WB'!H10+'PL OZON'!H10 | I10: ='PL WB'!I10+'PL OZON'!I10 | J10: ='PL WB'!J10+'PL OZON'!J10 | ... N10: ='PL WB'!N10+'PL OZON'!N10 | O10: =SUM(C10:N10)
A11: Поступление товара, шт | C11: ='PL WB'!C11+'PL OZON'!C11 | D11: ='PL WB'!D11+'PL OZON'!D11 | E11: ='PL WB'!E11+'PL OZON'!E11 | F11: ='PL WB'!F11+'PL OZON'!F11 | G11: ='PL WB'!G11+'PL OZON'!G11 | H11: ='PL WB'!H11+'PL OZON'!H11 | I11: ='PL WB'!I11+'PL OZON'!I11 | J11: ='PL WB'!J11+'PL OZON'!J11 | ... N11: ='PL WB'!N11+'PL OZON'!N11 | O11: =SUM(C11:N11)
A12: Доступно на складе по цене закупки | C12: ='PL WB'!C12+'PL OZON'!C12 | D12: ='PL WB'!D12+'PL OZON'!D12 | E12: ='PL WB'!E12+'PL OZON'!E12 | F12: ='PL WB'!F12+'PL OZON'!F12 | G12: ='PL WB'!G12+'PL OZON'!G12 | H12: ='PL WB'!H12+'PL OZON'!H12 | I12: ='PL WB'!I12+'PL OZON'!I12 | J12: ='PL WB'!J12+'PL OZON'!J12 | ... N12: ='PL WB'!N12+'PL OZON'!N12
A13: Доступно на складе, шт | C13: ='PL WB'!C13+'PL OZON'!C13 | D13: ='PL WB'!D13+'PL OZON'!D13 | E13: ='PL WB'!E13+'PL OZON'!E13 | F13: ='PL WB'!F13+'PL OZON'!F13 | G13: ='PL WB'!G13+'PL OZON'!G13 | H13: ='PL WB'!H13+'PL OZON'!H13 | I13: ='PL WB'!I13+'PL OZON'!I13 | J13: ='PL WB'!J13+'PL OZON'!J13 | ... N13: ='PL WB'!N13+'PL OZON'!N13
A14: Продано товаров по цене в карточке | C14: ='PL WB'!C14+'PL OZON'!C14 | D14: ='PL WB'!D14+'PL OZON'!D14 | E14: ='PL WB'!E14+'PL OZON'!E14 | F14: ='PL WB'!F14+'PL OZON'!F14 | G14: ='PL WB'!G14+'PL OZON'!G14 | H14: ='PL WB'!H14+'PL OZON'!H14 | I14: ='PL WB'!I14+'PL OZON'!I14 | J14: ='PL WB'!J14+'PL OZON'!J14 | ... N14: ='PL WB'!N14+'PL OZON'!N14 | O14: =SUM(C14:N14)
A15: Продано товаров -ПРОДАЖИ | C15: ='PL WB'!C15+'PL OZON'!C14 | D15: ='PL WB'!D15+'PL OZON'!D14 | E15: ='PL WB'!E15+'PL OZON'!E14 | F15: ='PL WB'!F15+'PL OZON'!F14 | G15: ='PL WB'!G15+'PL OZON'!G14 | H15: ='PL WB'!H15+'PL OZON'!H14 | I15: ='PL WB'!I15+'PL OZON'!I14 | J15: ='PL WB'!J15+'PL OZON'!J14 | ... N15: ='PL WB'!N15+'PL OZON'!N14 | O15: =SUM(C15:N15)
O16: =SUM(C16:N16)
A17: Комиссия | C17: =C14-C20 | D17: =D14-D20 | E17: =E14-E20 | F17: =F14-F20 | G17: =G14-G20 | H17: =H14-H20 | I17: =I14-I20 | J17: =J14-J20 | ... M17: =M14-M20 | N17: =N15-N20 | O17: =SUM(C17:N17)
A18: % комиссии | C18: =C17/C14 | D18: =D17/D15 | E18: =E17/E15 | F18: =F17/F15 | G18: =G17/G15 | H18: =H17/H15 | I18: =I17/I15 | J18: =J17/J15 | K18: =K17/K15 | ... O18: =O17/O15
A20: Выручка от реализации (к перечислению за товар), руб | C20: ='PL WB'!C20+'PL OZON'!C20 | D20: ='PL WB'!D20+'PL OZON'!D20 | E20: ='PL WB'!E20+'PL OZON'!E20 | F20: ='PL WB'!F20+'PL OZON'!F20 | G20: ='PL WB'!G20+'PL OZON'!G20 | H20: ='PL WB'!H20+'PL OZON'!H20 | I20: ='PL WB'!I20+'PL OZON'!I20 | J20: ='PL WB'!J20+'PL OZON'!J20 | ... N20: ='PL WB'!N20+'PL OZON'!N20 | O20: =SUM(C20:N20)
O21: =SUM(C21:N21)
A22: Возвраты, руб | C22: ='PL WB'!C22+'PL OZON'!C22 | D22: ='PL WB'!D22+'PL OZON'!D22 | E22: ='PL WB'!E22+'PL OZON'!E22 | F22: ='PL WB'!F22+'PL OZON'!F22 | G22: ='PL WB'!G22+'PL OZON'!G22 | H22: ='PL WB'!H22+'PL OZON'!H22 | I22: ='PL WB'!I22+'PL OZON'!I22 | J22: ='PL WB'!J22+'PL OZON'!J22 | ... N22: ='PL WB'!N22+'PL OZON'!N22 | O22: =SUM(C22:N22)
A23: Возвраты, шт | C23: ='PL WB'!C23+'PL OZON'!C23 | D23: ='PL WB'!D23+'PL OZON'!D23 | E23: ='PL WB'!E23+'PL OZON'!E23 | F23: ='PL WB'!F23+'PL OZON'!F23 | G23: ='PL WB'!G23+'PL OZON'!G23 | H23: ='PL WB'!H23+'PL OZON'!H23 | I23: ='PL WB'!I23+'PL OZON'!I23 | J23: ='PL WB'!J23+'PL OZON'!J23 | ... N23: ='PL WB'!N23+'PL OZON'!N23 | O23: =SUM(C23:N23)
A24: % возвратов | C24: ='PL WB'!C24+'PL OZON'!C24 | D24: =D22/D20 | E24: =E22/E20 | F24: =F22/F20 | G24: =G22/G20 | H24: =H22/H20 | I24: =I22/I20 | J24: =J22/J20 | K24: =K22/K20 | ... O24: =O22/O20
C25: ='PL WB'!C25+'PL OZON'!C25
A26: Брак, руб | C26: ='PL WB'!C26+'PL OZON'!C26
A27: Брак, шт | C27: ='PL WB'!C27+'PL OZON'!C27 | D27: =SUM('PL WB (нед)'!H27:K27) | E27: =SUM('PL WB (нед)'!L27:O27) | F27: =SUM('PL WB (нед)'!P27:S27) | G27: =SUM('PL WB (нед)'!T27:X27) | H27: =SUM('PL WB (нед)'!Y27:AB27) | I27: =SUM('PL WB (нед)'!AC27:AF27) | J27: =SUM('PL WB (нед)'!AG27:AK27) | K27: =SUM('PL WB (нед)'!AL27:AO27) | L27: =SUM('PL WB (нед)'!AP27:AT27) | M27: =SUM('PL WB (нед)'!AU27:AX27) | N27: =SUM('PL WB (нед)'!AY27:BB27)
A28: % брака | C28: ='PL WB'!C28+'PL OZON'!C28 | D28: =D27/D7 | E28: =E27/E7 | F28: =F27/F7 | G28: =G27/G7 | H28: =H27/H7 | I28: =I27/I7 | J28: =J27/J7 | K28: =K27/K7 | ... N28: =N27/N7
A30: Поступление на счет | C30: ='PL WB'!C30+'PL OZON'!C30 | D30: ='PL WB'!D30+'PL OZON'!D30 | E30: ='PL WB'!E30+'PL OZON'!E30 | F30: ='PL WB'!F30+'PL OZON'!F30 | G30: ='PL WB'!G30+'PL OZON'!G30 | H30: ='PL WB'!H30+'PL OZON'!H30 | I30: ='PL WB'!I30+'PL OZON'!I30 | J30: ='PL WB'!J30+'PL OZON'!J30 | ... N30: ='PL WB'!N30+'PL OZON'!N30 | O30: =SUM(C30:N30)
A31: в т.ч. Прочие доходы | C31: =SUM('PL WB (нед)'!C31:G31) | D31: =SUM('PL WB (нед)'!H31:K31) | E31: =SUM('PL WB (нед)'!L31:O31) | F31: =SUM('PL WB (нед)'!P31:S31) | G31: =SUM('PL WB (нед)'!T31:X31) | H31: =SUM('PL WB (нед)'!Y31:AB31) | I31: =SUM('PL WB (нед)'!AC31:AF31) | J31: =SUM('PL WB (нед)'!AG31:AK31) | K31: =SUM('PL WB (нед)'!AL31:AO31) | L31: =SUM('PL WB (нед)'!AP31:AT31) | M31: =SUM('PL WB (нед)'!AU31:AX31) | N31: =SUM('PL WB (нед)'!AY31:BB31) | O31: =SUM(C31:N31)
O32: =SUM(C32:N32)
A33: Себестоимость | C33: ='PL WB'!C33+'PL OZON'!C33 | D33: ='PL WB'!D33+'PL OZON'!D33 | E33: ='PL WB'!E33+'PL OZON'!E33 | F33: ='PL WB'!F33+'PL OZON'!F33 | G33: ='PL WB'!G33+'PL OZON'!G33 | H33: ='PL WB'!H33+'PL OZON'!H33 | I33: ='PL WB'!I33+'PL OZON'!I33 | J33: ='PL WB'!J33+'PL OZON'!J33 | ... N33: ='PL WB'!N33+'PL OZON'!N33 | O33: =SUM(C33:N33)
A34: % себестоимости | C34: =C33/C14 | D34: =D33/D15 | E34: =E33/E15 | F34: =F33/F15 | G34: =G33/G15 | H34: =H33/H15 | I34: =I33/I15 | J34: =J33/J15 | K34: =K33/K15 | ... O34: =O33/O15
A36: Валовая прибыль | C36: ='PL WB'!C36+'PL OZON'!C36 | D36: ='PL WB'!D36+'PL OZON'!D36 | E36: ='PL WB'!E36+'PL OZON'!E36 | F36: ='PL WB'!F36+'PL OZON'!F36 | G36: ='PL WB'!G36+'PL OZON'!G36 | H36: ='PL WB'!H36+'PL OZON'!H36 | I36: ='PL WB'!I36+'PL OZON'!I36 | J36: ='PL WB'!J36+'PL OZON'!J36 | K36: ='PL WB'!K36+'PL OZON'!K36 | L36: =L20-L33 | M36: =M20-M33 | N36: =N20-N33 | O36: =SUM(C36:N36)
O37: =SUM(C37:N37)
A38: Расходы | C38: ='PL WB'!C38+'PL OZON'!C38 | D38: ='PL WB'!D38+'PL OZON'!D38 | E38: ='PL WB'!E38+'PL OZON'!E38 | F38: ='PL WB'!F38+'PL OZON'!F38 | G38: ='PL WB'!G38+'PL OZON'!G38 | H38: ='PL WB'!H38+'PL OZON'!H38 | I38: ='PL WB'!I38+'PL OZON'!I38 | J38: ='PL WB'!J38+'PL OZON'!J38 | ... N38: ='PL WB'!N38+'PL OZON'!N38 | O38: =SUM(C38:N38)
A39: % расходы | C39: =C38/C14 | D39: =D38/D14 | E39: =E38/E14 | F39: =F38/F14 | G39: =G38/G14 | H39: =H38/H14 | I39: =I38/I14 | J39: =J38/J14 | ... N39: =N38/N14
A40: Логистика | C40: ='PL WB'!C40+'PL OZON'!C40 | D40: ='PL WB'!D40+'PL OZON'!D40 | E40: ='PL WB'!E40+'PL OZON'!E40 | F40: ='PL WB'!F40+'PL OZON'!F40 | G40: ='PL WB'!G40+'PL OZON'!G40 | H40: ='PL WB'!H40+'PL OZON'!H40 | I40: ='PL WB'!I40+'PL OZON'!I40 | J40: ='PL WB'!J40+'PL OZON'!J40 | ... N40: ='PL WB'!N40+'PL OZON'!N40 | O40: =SUM(C40:N40)
A41: Продвижение | C41: ='PL WB'!C41+'PL OZON'!C41 | D41: ='PL WB'!D41+'PL OZON'!D41 | E41: ='PL WB'!E41+'PL OZON'!E41 | F41: ='PL WB'!F41+'PL OZON'!F41 | G41: ='PL WB'!G41+'PL OZON'!G41 | H41: ='PL WB'!H41+'PL OZON'!H41 | I41: ='PL WB'!I41+'PL OZON'!I41 | J41: ='PL WB'!J41+'PL OZON'!J41 | ... N41: ='PL WB'!N41+'PL OZON'!N41 | O41: =SUM(C41:N41)
A42: Эквайринг | C42: ='PL WB'!C42+'PL OZON'!C42 | D42: ='PL WB'!D42+'PL OZON'!D42 | E42: ='PL WB'!E42+'PL OZON'!E42 | F42: ='PL WB'!F42+'PL OZON'!F42 | G42: ='PL WB'!G42+'PL OZON'!G42 | H42: ='PL WB'!H42+'PL OZON'!H42 | I42: ='PL WB'!I42+'PL OZON'!I42 | J42: ='PL WB'!J42+'PL OZON'!J42 | ... N42: ='PL WB'!N42+'PL OZON'!N42 | O42: =SUM(C42:N42)
A43: Хранение | C43: ='PL WB'!C43+'PL OZON'!C43 | D43: ='PL WB'!D43+'PL OZON'!D43 | E43: ='PL WB'!E43+'PL OZON'!E43 | F43: ='PL WB'!F43+'PL OZON'!F43 | G43: ='PL WB'!G43+'PL OZON'!G43 | H43: ='PL WB'!H43+'PL OZON'!H43 | I43: ='PL WB'!I43+'PL OZON'!I43 | J43: ='PL WB'!J43+'PL OZON'!J43 | ... N43: ='PL WB'!N43+'PL OZON'!N43 | O43: =SUM(C43:N43)
A44: Штрафы | C44: ='PL WB'!C44+'PL OZON'!C44 | D44: ='PL WB'!D44+'PL OZON'!D44 | E44: ='PL WB'!E44+'PL OZON'!E44 | F44: ='PL WB'!F44+'PL OZON'!F44 | G44: ='PL WB'!G44+'PL OZON'!G44 | H44: ='PL WB'!H44+'PL OZON'!H44 | I44: ='PL WB'!I44+'PL OZON'!I44 | J44: ='PL WB'!J44+'PL OZON'!J44 | ... N44: ='PL WB'!N44+'PL OZON'!N44 | O44: =SUM(C44:N44)
A45: Платная приемка | C45: ='PL WB'!C45+'PL OZON'!C45 | D45: ='PL WB'!D45+'PL OZON'!D45 | E45: ='PL WB'!E45+'PL OZON'!E45 | F45: ='PL WB'!F45+'PL OZON'!F45 | G45: ='PL WB'!G45+'PL OZON'!G45 | H45: ='PL WB'!H45+'PL OZON'!H45 | I45: ='PL WB'!I45+'PL OZON'!I45 | J45: ='PL WB'!J45+'PL OZON'!J45 | ... N45: ='PL WB'!N45+'PL OZON'!N45 | O45: =SUM(C45:N45)
...

Sheet PL WB (нед)
A1: Голубым выделены строки, которые заполняем! Заполняем эту вкладку, формулы не трогаем! Если добавляете строки - добавляете на всех листах PL и СF | C1: 1 | D1: 2 | E1: 3 | F1: 4 | G1: 5 | H1: 6 | I1: 7 | J1: 8 | K1: 9 | L1: 10 | M1: 11 | N1: 12 | O1: 13 | P1: 14 | Q1: 15 | R1: 16 | S1: 17 | T1: 18 | U1: 19 | V1: 20 | W1: 21 | X1: 22 | Y1: 23 | Z1: 24 | AA1: 25 | AB1: 26 | AC1: 27 | AD1: 28 | AE1: 29 | AF1: 30 | AG1: 31 | AH1: 32 | AI1: 33 | AJ1: 34 | AK1: 35 | AL1: 36 | AM1: 37 | AN1: 38 | AO1: 39 | AP1: 40 | AQ1: 41 | AR1: 42 | AS1: 43 | AT1: 44 | AU1: 45 | AV1: 46 | AW1: 47 | AX1: 48 | AY1: 49 | AZ1: 50 | BA1: 51 | BB1: 52 | BC1: Остаток года
A2: Прибыли и убытки, еженедельно | C2: Январь | H2: Февраль | L2: Март | P2: Апрель | T2: Май | Y2: Июнь | AC2: Июль | AG2: Август | AL2: Сентябрь | AP2: Октябрь | AU2: Ноябрь | AY2: Декабрь
C3: 30.12-05.01 | D3: 06.01-12.01 | E3: 13.01-19.01 | F3: 20.01-26.01 | G3: 27.01-02.02 | H3: 03.02-09.02 | I3: 10.02-16.02 | J3: 17.02-23.02 | K3: 24.02-02.03 | L3: 03.03-09.03 | M3: 10.03-16.03 | N3: 17.03-23.03 | O3: 24.03-30.03 | P3: 31.03-06.04 | Q3: 07.04-13.04 | R3: 14.04-20.04 | S3: 21.04-27.04 | T3: 28.04-04.05 | U3: 05.05-11.05 | V3: 12.05-18.05 | W3: 19.05-25.05 | X3: 26.05-01.06 | Y3: 02.06-08.06 | Z3: 09.06-15.06 | AA3: 16.06-22.06 | AB3: 23.06-29.06 | AC3: 30.06-06.07 | AD3: 07.07-13.07 | AE3: 14.07-20.07 | AF3: 21.07-27.07 | AG3: 28.07-03.08 | AH3: 04.08-10.08 | AI3: 11.08-17.08 | AJ3: 18.08-24.08 | AK3: 25.08-31.08 | AL3: 1-7.09 | AM3: 8-14.09 | AN3: 15-21.09 | AO3: 22.09-28.09 | AP3: 29.09-05.10 | AQ3: 06.10-12.10 | AR3: 13.10-20.10 | AS3: 21.10-26.10 | AT3: 27.10-02.11 | AU3: 03.11-09.11 | AV3: 10.11-16.11 | AW3: 17.11-23.11 | AX3: 24.11-30.11 | AY3: 01.12-07.12 | AZ3: 08.12-14.12 | BA3: 15.12-21.12 | BB3: 22.12-28.12 | BC3: 29.12-31.12
A4: Товарооборот
A5: Остаток товара по цене закупки | D5: =C12 | E5: =D12 | F5: =E12 | G5: =F12 | H5: =G12 | I5: =H12 | J5: =I12 | K5: =J12 | ... BC5: =BB12
A7: Продажи шт | BD7: =SUM(C7:BC7)
A8: Отгрузки по себестоимости | C8: =C33 | D8: =D33 | E8: =E33 | F8: =F33 | G8: =G33 | H8: =H33 | I8: =I33 | J8: =J33 | ... BC8: =BC33 | BD8: =SUM(C8:BC8)
BD9: =SUM(C9:BC9)
A10: Поступление товара, р | BD10: =SUM(C10:BC10)
A11: Поступление товара, шт | BD11: =SUM(C11:BC11)
A12: Доступно на складе по цене закупки | C12: =C10-C8+C5 | D12: =D10-D8+D5 | E12: =E10-E8+E5 | F12: =F10-F8+F5 | G12: =G10-G8+G5 | H12: =H10-H8+H5 | I12: =I10-I8+I5 | J12: =J10-J8+J5 | ... BC12: =BC10-BC8+BC5 | BD12: =SUM(C12:BC12)/52.5
A13: Доступно на складе, шт | C13: =5904-C7-C27+C11+C23 | D13: =C13-D7-D27+D11+D23 | E13: =D13-E7-E27+E11+E23 | F13: =E13-F7-F27+F11+F23 | G13: =F13-G7-G27+G11+G23 | H13: =G13-H7-H27+H11+H23 | I13: =H13-I7-I27+I11+I23 | J13: =I13-J7-J27+J11+J23 | K13: =J13-K7-K27+K11+K23 | ... BC13: =BB13-BC7-BC27+BC11+BC23 | BD13: =SUM(C13:BC13)/53.5
A14: Продано товаров WB по цене в карточке | BD14: =SUM(C14:BC14)
A15: Продано товаров WB ВБ реализовал-ПРОДАЖИ | BD15: =SUM(C15:BC15)
BD16: =SUM(C16:BC16)
A17: Комиссия ВБ | C17: =C14-C20 | D17: =D14-D20 | E17: =E14-E20 | F17: =F14-F20 | G17: =G14-G20 | H17: =H14-H20 | I17: =I14-I20 | J17: =J14-J20 | ... BC17: =BC14-BC20 | BD17: =SUM(C17:BC17)
A18: % комиссии | C18: =C17/C14 | D18: =D17/D14 | E18: =E17/E14 | F18: =F17/F14 | G18: =G17/G14 | H18: =H17/H14 | I18: =I17/I14 | J18: =J17/J14 | ... BC18: =BC17/BC14 | BD18: =SUM(C18:BC18)
BD19: =SUM(C19:BC19)
A20: Выручка от реализации (к перечислению за товар), руб | BD20: =SUM(C20:BC20)
BD21: =SUM(C21:BC21)
A22: Возвраты, руб | BD22: =SUM(C22:BC22)
A23: Возвраты, шт | BD23: =SUM(C23:BC23)
A24: % возвратов | C24: =C22/(C14-C22) | D24: =D22/(D14-D22) | E24: =E22/(E14-E22) | F24: =F22/(F14-F22) | G24: =G22/(G14-G22) | H24: =H22/(H14-H22) | I24: =I22/(I14-I22) | J24: =J22/(J14-J22) | ... BD24: =BD22/(BD14-BD22)
A26: Брак, руб | BD26: =SUM(C26:BB26)
A27: Брак, шт | BD27: =SUM(C27:BC27)
A28: % брака | C28: =C27/C7 | D28: =D27/D7 | E28: =E27/E7 | F28: =F27/F7 | G28: =G27/G7 | H28: =H27/H7 | I28: =I27/I7 | J28: =J27/J7 | ... BC28: =BC27/BC7
BD29: =SUM(C29:BC29)
A30: Поступление на счет от ВБ | C30: =C20+C31-SUM(C40:C45)-C42 | D30: =D20+D31-SUM(D40:D45)-D42 | E30: =E20+E31-SUM(E40:E45)-E42 | F30: =F20+F31-SUM(F40:F45)-F41 | G30: =G20+G31-SUM(G40:G45)-G41 | H30: =H20+H31-SUM(H40:H45)-H41 | I30: =I20+I31-SUM(I40:I45)-I41 | J30: =J20+J31-SUM(J40:J45)-J41 | K30: =K20+K31-SUM(K40:K45)-K42 | L30: =L20+L31-SUM(L40:L45)-L42 | M30: =M20+M31-SUM(M40:M45)-M42 | N30: =N20+N31-SUM(N40:N45)-N42 | O30: =O20+O31-SUM(O40:O45)-O42 | P30: =P20+P31-SUM(P40:P45)-P42 | Q30: =Q20+Q31-SUM(Q40:Q45)-Q42 | R30: =R20+R31-SUM(R40:R45)-R42 | ... BC30: =BC20+BC31-SUM(BC40:BC45)-BC42 | BD30: =SUM(C30:BC30)
A31: в т.ч. Прочие доходы | BD31: =SUM(C31:BC31)
BD32: =SUM(C32:BC32)
A33: Себестоимость | BD33: =SUM(C33:BC33)
A34: % себестоимости в цене | C34: =C33/C14 | D34: =D33/D14 | E34: =E33/E14 | F34: =F33/F14 | G34: =G33/G14 | H34: =H33/H14 | I34: =I33/I14 | J34: =J33/J14 | ... BD34: =BD33/BD14
BD35: =SUM(C35:BC35)
A36: Валовая прибыль | C36: =C20-C33 | D36: =D20-D33 | E36: =E20-E33 | F36: =F20-F33 | G36: =G20-G33 | H36: =H20-H33 | I36: =I20-I33 | J36: =J20-J33 | ... BC36: =BC20-BC33 | BD36: =SUM(C36:BC36)
BD37: =SUM(C37:BC37)
A38: Расходы | C38: =SUM(C40:C51) | D38: =SUM(D40:D51) | E38: =SUM(E40:E51) | F38: =SUM(F40:F51) | G38: =SUM(G40:G51) | H38: =SUM(H40:H51) | I38: =SUM(I40:I51) | J38: =SUM(J40:J51) | ... BC38: =SUM(BC40:BC51) | BD38: =SUM(C38:BC38)
A39: % расходы | C39: =C38/C14 | D39: =D38/D14 | E39: =E38/E14 | F39: =F38/F14 | G39: =G38/G14 | H39: =H38/H14 | I39: =I38/I14 | J39: =J38/J14 | ... BC39: =BC38/BC14
A40: Логистика ВБ | BD40: =SUM(C40:BC40)
A41: Продвижение ВБ (взаимозачет) | BD41: =SUM(C41:BC41)
A42: Эквайринг ВБ | BD42: =SUM(C42:BC42)
...

Sheet PL WB
A1: Заполняем PL и CF еженедельный!
A2: Прибыли и убытки | C2: 2025
C3: Январь | D3: Февраль | E3: Март | F3: Апрель | G3: Май | H3: Июнь | I3: Июль | J3: Август | K3: Сентябрь | L3: Октябрь | M3: Ноябрь | N3: Декабрь
A4: Товарооборот | O4: =SUM(C4:N4)
A5: Остаток товара по цене закупки | C5: ='PL WB (нед)'!C5 | D5: =C12 | E5: =D12 | F5: =E12 | G5: =F12 | H5: =G12 | I5: =H12 | J5: =I12 | K5: =J12 | ... N5: =M12 | O5: =SUM(C5:N5)/12
O6: =SUM(C6:N6)
B7: Продажи шт | C7: =SUM('PL WB (нед)'!C7:G7) | D7: =SUM('PL WB (нед)'!H7:K7) | E7: =SUM('PL WB (нед)'!L7:O7) | F7: =SUM('PL WB (нед)'!P7:S7) | G7: =SUM('PL WB (нед)'!T7:X7) | H7: =SUM('PL WB (нед)'!Y7:AB7) | I7: =SUM('PL WB (нед)'!AC7:AF7) | J7: =SUM('PL WB (нед)'!AG7:AK7) | K7: =SUM('PL WB (нед)'!AL7:AO7) | L7: =SUM('PL WB (нед)'!AP7:AT7) | M7: =SUM('PL WB (нед)'!AU7:AX7) | N7: =SUM('PL WB (нед)'!AY7:BC7) | O7: =SUM(C7:N7)
B8: Отгрузки по себестоимости | C8: =C33 | D8: =D33 | E8: =E33 | F8: =F33 | G8: =G33 | H8: =H33 | I8: =I33 | J8: =J33 | ... N8: =N33 | O8: =SUM(C8:N8)
O9: =SUM(C9:N9)
A10: Поступление товара, р | C10: =SUM('PL WB (нед)'!C10:G10) | D10: =SUM('PL WB (нед)'!H10:K10) | E10: =SUM('PL WB (нед)'!L10:O10) | F10: =SUM('PL WB (нед)'!P10:S10) | G10: =SUM('PL WB (нед)'!T10:X10) | H10: =SUM('PL WB (нед)'!Y10:AB10) | I10: =SUM('PL WB (нед)'!AC10:AF10) | J10: =SUM('PL WB (нед)'!AG10:AK10) | K10: =SUM('PL WB (нед)'!AL10:AO10) | L10: =SUM('PL WB (нед)'!AP10:AT10) | M10: =SUM('PL WB (нед)'!AU10:AX10) | N10: =SUM('PL WB (нед)'!AY10:BC10) | O10: =SUM(C10:N10)
A11: Поступление товара, шт | C11: =SUM('PL WB (нед)'!C11:G11) | D11: =SUM('PL WB (нед)'!H11:K11) | E11: =SUM('PL WB (нед)'!L11:O11) | F11: =SUM('PL WB (нед)'!P11:S11) | G11: =SUM('PL WB (нед)'!T11:X11) | H11: =SUM('PL WB (нед)'!Y11:AB11) | I11: =SUM('PL WB (нед)'!AC11:AF11) | J11: =SUM('PL WB (нед)'!AG11:AK11) | K11: =SUM('PL WB (нед)'!AL11:AO11) | L11: =SUM('PL WB (нед)'!AP11:AT11) | M11: =SUM('PL WB (нед)'!AU11:AX11) | N11: =SUM('PL WB (нед)'!AY11:BC11) | O11: =SUM(C11:N11)
A12: Доступно на складе по цене закупки | C12: =C10-C8+C5 | D12: =D10-D8+D5 | E12: =E10-E8+E5 | F12: =F10-F8+F5 | G12: =G10-G8+G5 | H12: =H10-H8+H5 | I12: =I10-I8+I5 | J12: =J10-J8+J5 | ... N12: =N10-N8+N5 | O12: =SUM(C12:N12)
A13: Доступно на складе, шт | C13: ='PL WB (нед)'!G13 | D13: =C13-D7-D27+D11+D23 | E13: =D13-E7-E27+E11+E23 | F13: =E13-F7-F27+F11+F23 | G13: =F13-G7-G27+G11+G23 | H13: =G13-H7-H27+H11+H23 | I13: =H13-I7-I27+I11+I23 | J13: =I13-J7-J27+J11+J23 | K13: =J13-K7-K27+K11+K23 | ... N13: =M13-N7-N27+N11+N23 | O13: =SUM(C13:N13)
A14: Продано товаров WB по цене в карточке | C14: =SUM('PL WB (нед)'!C14:G14) | D14: =SUM('PL WB (нед)'!H14:K14) | E14: =SUM('PL WB (нед)'!L14:O14) | F14: =SUM('PL WB (нед)'!P14:S14) | G14: =SUM('PL WB (нед)'!T14:X14) | H14: =SUM('PL WB (нед)'!Y14:AB14) | I14: =SUM('PL WB (нед)'!AC14:AF14) | J14: =SUM('PL WB (нед)'!AG14:AK14) | K14: =SUM('PL WB (нед)'!AL14:AO14) | L14: =SUM('PL WB (нед)'!AP14:AT14) | M14: =SUM('PL WB (нед)'!AU14:AX14) | N14: =SUM('PL WB (нед)'!AY14:BC14) | O14: =SUM(C14:N14)
A15: Продано товаров WB ВБ реализовал-ПРОДАЖИ | C15: =SUM('PL WB (нед)'!C15:G15) | D15: =SUM('PL WB (нед)'!H15:K15) | E15: =SUM('PL WB (нед)'!L15:O15) | F15: =SUM('PL WB (нед)'!P15:S15) | G15: =SUM('PL WB (нед)'!T15:X15) | H15: =SUM('PL WB (нед)'!Y15:AB15) | I15: =SUM('PL WB (нед)'!AC15:AF15) | J15: =SUM('PL WB (нед)'!AG15:AK15) | K15: =SUM('PL WB (нед)'!AL15:AO15) | L15: =SUM('PL WB (нед)'!AP15:AT15) | M15: =SUM('PL WB (нед)'!AU15:AX15) | N15: =SUM('PL WB (нед)'!AY15:BC15) | O15: =SUM(C15:N15)
O16: =SUM(C16:N16)
A17: Комиссия ВБ | C17: =C14-C20 | D17: =D14-D20 | E17: =E14-E20 | F17: =F14-F20 | G17: =G14-G20 | H17: =H14-H20 | I17: =I14-I20 | J17: =J14-J20 | ... M17: =M14-M20 | N17: =N15-N20 | O17: =SUM(C17:N17)
A18: % комиссии | C18: =C17/C14 | D18: =D17/D15 | E18: =E17/E15 | F18: =F17/F15 | G18: =G17/G15 | H18: =H17/H15 | I18: =I17/I15 | J18: =J17/J15 | K18: =K17/K15 | ... N18: =N17/N15 | O18: =SUM(C18:N18)
O19: =SUM(C19:N19)
A20: Выручка от реализации (к перечислению за товар), руб | C20: =SUM('PL WB (нед)'!C20:G20) | D20: =SUM('PL WB (нед)'!H20:K20) | E20: =SUM('PL WB (нед)'!L20:O20) | F20: =SUM('PL WB (нед)'!P20:S20) | G20: =SUM('PL WB (нед)'!T20:X20) | H20: =SUM('PL WB (нед)'!Y20:AB20) | I20: =SUM('PL WB (нед)'!AC20:AF20) | J20: =SUM('PL WB (нед)'!AG20:AK20) | K20: =SUM('PL WB (нед)'!AL20:AO20) | L20: =SUM('PL WB (нед)'!AP20:AT20) | M20: =SUM('PL WB (нед)'!AU20:AX20) | N20: =SUM('PL WB (нед)'!AY20:BC20) | O20: =SUM(C20:N20)
O21: =SUM(C21:N21)
A22: Возвраты, руб | C22: =SUM('PL WB (нед)'!C22:G22) | D22: =SUM('PL WB (нед)'!H22:K22) | E22: =SUM('PL WB (нед)'!L22:O22) | F22: =SUM('PL WB (нед)'!P22:S22) | G22: =SUM('PL WB (нед)'!T22:X22) | H22: =SUM('PL WB (нед)'!Y22:AB22) | I22: =SUM('PL WB (нед)'!AC22:AF22) | J22: =SUM('PL WB (нед)'!AG22:AK22) | K22: =SUM('PL WB (нед)'!AL22:AO22) | L22: =SUM('PL WB (нед)'!AP22:AT22) | M22: =SUM('PL WB (нед)'!AU22:AX22) | N22: =SUM('PL WB (нед)'!AY22:BC22) | O22: =SUM(C22:N22)
A23: Возвраты, шт | C23: =SUM('PL WB (нед)'!C23:G23) | D23: =SUM('PL WB (нед)'!H23:K23) | E23: =SUM('PL WB (нед)'!L23:O23) | F23: =SUM('PL WB (нед)'!P23:S23) | G23: =SUM('PL WB (нед)'!T23:X23) | H23: =SUM('PL WB (нед)'!Y23:AB23) | I23: =SUM('PL WB (нед)'!AC23:AF23) | J23: =SUM('PL WB (нед)'!AG23:AK23) | K23: =SUM('PL WB (нед)'!AL23:AO23) | L23: =SUM('PL WB (нед)'!AP23:AT23) | M23: =SUM('PL WB (нед)'!AU23:AX23) | N23: =SUM('PL WB (нед)'!AY23:BC23) | O23: =SUM(C23:N23)
A24: % возвратов | C24: =C22/C14 | D24: =D22/D20 | E24: =E22/E20 | F24: =F22/F20 | G24: =G22/G20 | H24: =H22/H20 | I24: =I22/I20 | J24: =J22/J20 | K24: =K22/K20 | ... O24: =O22/O20
A26: Брак, руб
A27: Брак, шт | C27: =SUM('PL WB (нед)'!C27:G27) | D27: =SUM('PL WB (нед)'!H27:K27) | E27: =SUM('PL WB (нед)'!L27:O27) | F27: =SUM('PL WB (нед)'!P27:S27) | G27: =SUM('PL WB (нед)'!T27:X27) | H27: =SUM('PL WB (нед)'!Y27:AB27) | I27: =SUM('PL WB (нед)'!AC27:AF27) | J27: =SUM('PL WB (нед)'!AG27:AK27) | K27: =SUM('PL WB (нед)'!AL27:AO27) | L27: =SUM('PL WB (нед)'!AP27:AT27) | M27: =SUM('PL WB (нед)'!AU27:AX27) | N27: =SUM('PL WB (нед)'!AY27:BB27)
A28: % брака | C28: =C27/C7 | D28: =D27/D7 | E28: =E27/E7 | F28: =F27/F7 | G28: =G27/G7 | H28: =H27/H7 | I28: =I27/I7 | J28: =J27/J7 | ... N28: =N27/N7
A30: Поступление на счет от ВБ | C30: =C20+C31-SUM(C40:C45)-C42 | D30: =D20+D31-SUM(D40:D45)-D42 | E30: =E20+E31-SUM(E40:E45)-E42 | F30: =F20+F31-SUM(F40:F45)-F42 | G30: =G20+G31-SUM(G40:G45)-G42 | H30: =H20+H31-SUM(H40:H45)-H42 | I30: =I20+I31-SUM(I40:I45)-I42 | J30: =J20+J31-SUM(J40:J45)-J42 | ... N30: =N20+N31-SUM(N40:N45)-N42 | O30: =SUM(C30:N30)
A31: в т.ч. Прочие доходы | C31: =SUM('PL WB (нед)'!C31:G31) | D31: =SUM('PL WB (нед)'!H31:K31) | E31: =SUM('PL WB (нед)'!L31:O31) | F31: =SUM('PL WB (нед)'!P31:S31) | G31: =SUM('PL WB (нед)'!T31:X31) | H31: =SUM('PL WB (нед)'!Y31:AB31) | I31: =SUM('PL WB (нед)'!AC31:AF31) | J31: =SUM('PL WB (нед)'!AG31:AK31) | K31: =SUM('PL WB (нед)'!AL31:AO31) | L31: =SUM('PL WB (нед)'!AP31:AT31) | M31: =SUM('PL WB (нед)'!AU31:AX31) | N31: =SUM('PL WB (нед)'!AY31:BB31)
A33: Себестоимость | C33: =SUM('PL WB (нед)'!C33:G33) | D33: =SUM('PL WB (нед)'!H33:K33) | E33: =SUM('PL WB (нед)'!L33:O33) | F33: =SUM('PL WB (нед)'!P33:S33) | G33: =SUM('PL WB (нед)'!T33:X33) | H33: =SUM('PL WB (нед)'!Y33:AB33) | I33: =SUM('PL WB (нед)'!AC33:AF33) | J33: =SUM('PL WB (нед)'!AG33:AK33) | K33: =SUM('PL WB (нед)'!AL33:AO33) | L33: =SUM('PL WB (нед)'!AP33:AT33) | M33: =SUM('PL WB (нед)'!AU33:AX33) | N33: =SUM('PL WB (нед)'!AY33:BC33) | O33: =SUM('PL WB (нед)'!AZ33:BD33)
A34: % себестоимости | C34: =C33/C14 | D34: =D33/D15 | E34: =E33/E15 | F34: =F33/F15 | G34: =G33/G15 | H34: =H33/H15 | I34: =I33/I15 | J34: =J33/J15 | K34: =K33/K15 | ... O34: =O33/O15
A36: Валовая прибыль | C36: =C20-C33 | D36: =D20-D33 | E36: =E20-E33 | F36: =F20-F33 | G36: =G20-G33 | H36: =H20-H33 | I36: =I20-I33 | J36: =J20-J33 | ... O36: =O20-O33
A38: Расходы | C38: =SUM(C40:C51) | D38: =SUM(D40:D51) | E38: =SUM(E40:E51) | F38: =SUM(F40:F51) | G38: =SUM(G40:G51) | H38: =SUM(H40:H51) | I38: =SUM(I40:I51) | J38: =SUM(J40:J51) | ... N38: =SUM(N40:N51) | O38: =SUM(C38:N38)
A39: % расходы | C39: =C38/C14 | D39: =D38/D14 | E39: =E38/E14 | F39: =F38/F14 | G39: =G38/G14 | H39: =H38/H14 | I39: =I38/I14 | J39: =J38/J14 | ... O39: =O38/O14
A40: Логистика ВБ | C40: =SUM('PL WB (нед)'!C40:G40) | D40: =SUM('PL WB (нед)'!H40:K40) | E40: =SUM('PL WB (нед)'!L40:O40) | F40: =SUM('PL WB (нед)'!P40:S40) | G40: =SUM('PL WB (нед)'!T40:X40) | H40: =SUM('PL WB (нед)'!Y40:AB40) | I40: =SUM('PL WB (нед)'!AC40:AF40) | J40: =SUM('PL WB (нед)'!AG40:AK40) | K40: =SUM('PL WB (нед)'!AL40:AO40) | L40: =SUM('PL WB (нед)'!AP40:AT40) | M40: =SUM('PL WB (нед)'!AU40:AX40) | N40: =SUM('PL WB (нед)'!AY40:BC40) | O40: =SUM(C40:N40)
A41: Продвижение ВБ (взаимозачет) | C41: =SUM('PL WB (нед)'!C41:G41) | D41: =SUM('PL WB (нед)'!H41:K41) | E41: =SUM('PL WB (нед)'!L41:O41) | F41: =SUM('PL WB (нед)'!P41:S41) | G41: =SUM('PL WB (нед)'!T41:X41) | H41: =SUM('PL WB (нед)'!Y41:AB41) | I41: =SUM('PL WB (нед)'!AC41:AF41) | J41: =SUM('PL WB (нед)'!AG41:AK41) | K41: =SUM('PL WB (нед)'!AL41:AO41) | L41: =SUM('PL WB (нед)'!AP41:AT41) | M41: =SUM('PL WB (нед)'!AU41:AX41) | N41: =SUM('PL WB (нед)'!AY41:BC41) | O41: =SUM(C41:N41)
A42: Эквайринг ВБ | C42: =SUM('PL WB (нед)'!C42:G42) | D42: =SUM('PL WB (нед)'!H42:K42) | E42: =SUM('PL WB (нед)'!L42:O42) | F42: =SUM('PL WB (нед)'!P42:S42) | G42: =SUM('PL WB (нед)'!T42:X42) | H42: =SUM('PL WB (нед)'!Y42:AB42) | I42: =SUM('PL WB (нед)'!AC42:AF42) | J42: =SUM('PL WB (нед)'!AG42:AK42) | K42: =SUM('PL WB (нед)'!AL42:AO42) | L42: =SUM('PL WB (нед)'!AP42:AT42) | M42: =SUM('PL WB (нед)'!AU42:AX42) | N42: =SUM('PL WB (нед)'!AY42:BC42) | O42: =SUM(C42:N42)
A43: Хранение ВБ | C43: =SUM('PL WB (нед)'!C43:G43) | D43: =SUM('PL WB (нед)'!H43:K43) | E43: =SUM('PL WB (нед)'!L43:O43) | F43: =SUM('PL WB (нед)'!P43:S43) | G43: =SUM('PL WB (нед)'!T43:X43) | H43: =SUM('PL WB (нед)'!Y43:AB43) | I43: =SUM('PL WB (нед)'!AC43:AF43) | J43: =SUM('PL WB (нед)'!AG43:AK43) | K43: =SUM('PL WB (нед)'!AL43:AO43) | L43: =SUM('PL WB (нед)'!AP43:AT43) | M43: =SUM('PL WB (нед)'!AU43:AX43) | N43: =SUM('PL WB (нед)'!AY43:BC43) | O43: =SUM(C43:N43)
A44: Штрафы ВБ | C44: =SUM('PL WB (нед)'!C44:G44) | D44: =SUM('PL WB (нед)'!H44:K44) | E44: =SUM('PL WB (нед)'!L44:O44) | F44: =SUM('PL WB (нед)'!P44:S44) | G44: =SUM('PL WB (нед)'!T44:X44) | H44: =SUM('PL WB (нед)'!Y44:AB44) | I44: =SUM('PL WB (нед)'!AC44:AF44) | J44: =SUM('PL WB (нед)'!AG44:AK44) | K44: =SUM('PL WB (нед)'!AL44:AO44) | L44: =SUM('PL WB (нед)'!AP44:AT44) | M44: =SUM('PL WB (нед)'!AU44:AX44) | N44: =SUM('PL WB (нед)'!AY44:BC44) | O44: =SUM(C44:N44)
A45: Платная приемка ВБ | C45: =SUM('PL WB (нед)'!C45:G45) | D45: =SUM('PL WB (нед)'!H45:K45) | E45: =SUM('PL WB (нед)'!L45:O45) | F45: =SUM('PL WB (нед)'!P45:S45) | G45: =SUM('PL WB (нед)'!T45:X45) | H45: =SUM('PL WB (нед)'!Y45:AB45) | I45: =SUM('PL WB (нед)'!AC45:AF45) | J45: =SUM('PL WB (нед)'!AG45:AK45) | K45: =SUM('PL WB (нед)'!AL45:AO45) | L45: =SUM('PL WB (нед)'!AP45:AT45) | M45: =SUM('PL WB (нед)'!AU45:AX45) | N45: =SUM('PL WB (нед)'!AY45:BC45) | O45: =SUM(C45:N45)
...

Sheet CF (нед)
A1: Заполняем Вложения инвестора, Закупки и выплаты дивидендов. Формулы не трогаем! | C1: ='PL WB (нед)'!C1 | D1: ='PL WB (нед)'!D1 | E1: ='PL WB (нед)'!E1 | F1: ='PL WB (нед)'!F1 | G1: ='PL WB (нед)'!G1 | H1: ='PL WB (нед)'!H1 | I1: ='PL WB (нед)'!I1 | J1: ='PL WB (нед)'!J1 | ... BC1: ='PL WB (нед)'!BC1
A2: Движение денежных средств, еженедельно | C2: Январь | H2: Февраль | L2: Март | P2: Апрель | T2: Май | Y2: Июнь | AC2: Июль | AG2: Август | AL2: Сентябрь | AP2: Октябрь | AU2: Ноябрь | AY2: Декабрь
C3: ='PL WB (нед)'!C3 | D3: ='PL WB (нед)'!D3 | E3: ='PL WB (нед)'!E3 | F3: ='PL WB (нед)'!F3 | G3: ='PL WB (нед)'!G3 | H3: ='PL WB (нед)'!H3 | I3: ='PL WB (нед)'!I3 | J3: ='PL WB (нед)'!J3 | ... BB3: ='PL WB (нед)'!BB3 | BC3: 29.12-31.12
A4: Поступление товара по цене закупки | C4: ='PL WB (нед)'!C10+'PL OZON (нед)'!C10 | D4: ='PL WB (нед)'!D10+'PL OZON (нед)'!D10 | E4: ='PL WB (нед)'!E10+'PL OZON (нед)'!E10 | F4: ='PL WB (нед)'!F10+'PL OZON (нед)'!F10 | G4: ='PL WB (нед)'!G10+'PL OZON (нед)'!G10 | H4: ='PL WB (нед)'!H10+'PL OZON (нед)'!H10 | I4: ='PL WB (нед)'!I10+'PL OZON (нед)'!I10 | J4: ='PL WB (нед)'!J10+'PL OZON (нед)'!J10 | ... BC4: ='PL WB (нед)'!BC10+'PL OZON (нед)'!BC10
A5: Доступно на складе по цене закупки | C5: ='PL WB (нед)'!C12+'PL OZON (нед)'!C12 | D5: ='PL WB (нед)'!D12+'PL OZON (нед)'!D12 | E5: ='PL WB (нед)'!E12+'PL OZON (нед)'!E12 | F5: ='PL WB (нед)'!F12+'PL OZON (нед)'!F12 | G5: ='PL WB (нед)'!G12+'PL OZON (нед)'!G12 | H5: ='PL WB (нед)'!H12+'PL OZON (нед)'!H12 | I5: ='PL WB (нед)'!I12+'PL OZON (нед)'!I12 | J5: ='PL WB (нед)'!J12+'PL OZON (нед)'!J12 | ... BC5: ='PL WB (нед)'!BC12+'PL OZON (нед)'!BC12
A7: Остаток денежных средств на начало периода | C7: ='[1]CF факт (нед)'!$BB$33 | D7: =C42 | E7: =D42 | F7: =E42 | G7: =F42 | H7: =G42 | I7: =H42 | J7: =I42 | K7: =J42 | ... BC7: =BB42
A9: Поступление на счет от WB и OZON | C9: ='PL WB (нед)'!C30+'PL OZON (нед)'!C30 | D9: ='PL WB (нед)'!D30+'PL OZON (нед)'!D30 | E9: ='PL WB (нед)'!E30+'PL OZON (нед)'!E30 | F9: ='PL WB (нед)'!F30+'PL OZON (нед)'!F30 | G9: ='PL WB (нед)'!G30+'PL OZON (нед)'!G30 | H9: ='PL WB (нед)'!H30+'PL OZON (нед)'!H30 | I9: ='PL WB (нед)'!I30+'PL OZON (нед)'!I30 | J9: ='PL WB (нед)'!J30+'PL OZON (нед)'!J30 | ... BC9: ='PL WB (нед)'!BC30+'PL OZON (нед)'!BC30
A11: Итого остаток + поступление | C11: =C7+C9 | D11: =D7+D9 | E11: =E7+E9 | F11: =F7+F9 | G11: =G7+G9 | H11: =H7+H9 | I11: =I7+I9 | J11: =J7+J9 | ... BC11: =BC7+BC9
A13: Расходы - факт списания | C13: =SUM(C14:C19) | D13: =SUM(D14:D19) | E13: =SUM(E14:E19) | F13: =SUM(F14:F19) | G13: =SUM(G14:G19) | H13: =SUM(H14:H19) | I13: =SUM(I14:I19) | J13: =SUM(J14:J19) | ... BC13: =SUM(BC14:BC19)
A14: Контент | C14: ='PL WB (нед)'!C47+'PL OZON (нед)'!C47 | D14: ='PL WB (нед)'!D47+'PL OZON (нед)'!D47 | E14: ='PL WB (нед)'!E47+'PL OZON (нед)'!E47 | F14: ='PL WB (нед)'!F47+'PL OZON (нед)'!F47 | G14: ='PL WB (нед)'!G47+'PL OZON (нед)'!G47 | H14: ='PL WB (нед)'!H47+'PL OZON (нед)'!H47 | I14: ='PL WB (нед)'!I47+'PL OZON (нед)'!I47 | J14: ='PL WB (нед)'!J47+'PL OZON (нед)'!J47 | ... BC14: ='PL WB (нед)'!BC47+'PL OZON (нед)'!BC47
A15: Аренда офиса | C15: ='PL WB (нед)'!C48+'PL OZON (нед)'!C48 | D15: ='PL WB (нед)'!D48+'PL OZON (нед)'!D48 | E15: ='PL WB (нед)'!E48+'PL OZON (нед)'!E48 | F15: ='PL WB (нед)'!F48+'PL OZON (нед)'!F48 | G15: ='PL WB (нед)'!G48+'PL OZON (нед)'!G48 | H15: ='PL WB (нед)'!H48+'PL OZON (нед)'!H48 | I15: ='PL WB (нед)'!I48+'PL OZON (нед)'!I48 | J15: ='PL WB (нед)'!J48+'PL OZON (нед)'!J48 | ... BC15: ='PL WB (нед)'!BC48+'PL OZON (нед)'!BC48
A16: Реклама внешняя | C16: ='PL WB (нед)'!C49+'PL OZON (нед)'!C49 | D16: ='PL WB (нед)'!D49+'PL OZON (нед)'!D49 | E16: ='PL WB (нед)'!E49+'PL OZON (нед)'!E49 | F16: ='PL WB (нед)'!F49+'PL OZON (нед)'!F49 | G16: ='PL WB (нед)'!G49+'PL OZON (нед)'!G49 | H16: ='PL WB (нед)'!H49+'PL OZON (нед)'!H49 | I16: ='PL WB (нед)'!I49+'PL OZON (нед)'!I49 | J16: ='PL WB (нед)'!J49+'PL OZON (нед)'!J49 | ... BC16: ='PL WB (нед)'!BC49+'PL OZON (нед)'!BC49
A17: Продвижение | C17: ='PL WB (нед)'!C41+'PL OZON (нед)'!C41 | D17: ='PL WB (нед)'!D41+'PL OZON (нед)'!D41 | E17: ='PL WB (нед)'!E41+'PL OZON (нед)'!E41 | F17: ='PL WB (нед)'!F41+'PL OZON (нед)'!F41 | G17: ='PL WB (нед)'!G41+'PL OZON (нед)'!G41 | H17: ='PL WB (нед)'!H41+'PL OZON (нед)'!H41 | I17: ='PL WB (нед)'!I41+'PL OZON (нед)'!I41 | J17: ='PL WB (нед)'!J41+'PL OZON (нед)'!J41 | ... BC17: ='PL WB (нед)'!BC41+'PL OZON (нед)'!BC41
A18: Подписка Аналитика | C18: ='PL WB (нед)'!C51+'PL OZON (нед)'!C51 | D18: ='PL WB (нед)'!D51+'PL OZON (нед)'!D51 | E18: ='PL WB (нед)'!E51+'PL OZON (нед)'!E51 | F18: ='PL WB (нед)'!F51+'PL OZON (нед)'!F51 | G18: ='PL WB (нед)'!G51+'PL OZON (нед)'!G51 | H18: ='PL WB (нед)'!H51+'PL OZON (нед)'!H51 | I18: ='PL WB (нед)'!I50+'PL OZON (нед)'!I50 | J18: ='PL WB (нед)'!J50+'PL OZON (нед)'!J50 | K18: ='PL WB (нед)'!K50+'PL OZON (нед)'!K50 | L18: ='PL WB (нед)'!L50+'PL OZON (нед)'!L50 | M18: ='PL WB (нед)'!M50+'PL OZON (нед)'!M50 | N18: ='PL WB (нед)'!N50+'PL OZON (нед)'!N50 | O18: ='PL WB (нед)'!O50+'PL OZON (нед)'!O50 | P18: ='PL WB (нед)'!P50+'PL OZON (нед)'!P50 | ... BC18: ='PL WB (нед)'!BC50+'PL OZON (нед)'!BC50
A19: Прочее | C19: ='PL WB (нед)'!C51+'PL OZON (нед)'!C51 | D19: ='PL WB (нед)'!D51+'PL OZON (нед)'!D51 | E19: ='PL WB (нед)'!E51+'PL OZON (нед)'!E51 | F19: ='PL WB (нед)'!F51+'PL OZON (нед)'!F51 | G19: ='PL WB (нед)'!G51+'PL OZON (нед)'!G51 | H19: ='PL WB (нед)'!H51+'PL OZON (нед)'!H51 | I19: ='PL WB (нед)'!I51+'PL OZON (нед)'!I51 | J19: ='PL WB (нед)'!J51+'PL OZON (нед)'!J51 | ... BC19: ='PL WB (нед)'!BC51+'PL OZON (нед)'!BC51
A21: Налоги уплаченные | C21: ='PL WB (нед)'!C55+'PL OZON (нед)'!C55 | D21: ='PL WB (нед)'!D55+'PL OZON (нед)'!D55 | E21: ='PL WB (нед)'!E55+'PL OZON (нед)'!E55 | F21: ='PL WB (нед)'!F55+'PL OZON (нед)'!F55 | G21: ='PL WB (нед)'!G55+'PL OZON (нед)'!G55 | H21: ='PL WB (нед)'!H55+'PL OZON (нед)'!H55 | I21: ='PL WB (нед)'!I55+'PL OZON (нед)'!I55 | J21: ='PL WB (нед)'!J55+'PL OZON (нед)'!J55 | ... BC21: ='PL WB (нед)'!BC55+'PL OZON (нед)'!BC55
A23: Закупка Китай
A24: Закупка нал
A25: Закупка р/с
A26: Доставка Китай
A27: Доставка РФ
A29: Вложения инвестора
A31: Самовыкупы (покупка товара)
A33: Остаток денежных средств на конец периода | C33: =C11-C13-C21-SUM(C23:C27)+C29-C31 | D33: =D11-D13-D21-SUM(D23:D27)+D29-D31 | E33: =E11-E13-E21-SUM(E23:E27)+E29-E31 | F33: =F11-F13-F21-SUM(F23:F27)+F29-F31 | G33: =G11-G13-G21-SUM(G23:G27)+G29-G31 | H33: =H11-H13-H21-SUM(H23:H27)+H29-H31 | I33: =I11-I13-I21-SUM(I23:I27)+I29-I31 | J33: =J11-J13-J21-SUM(J23:J27)+J29-J31 | ... BC33: =BC11-BC13-BC21-SUM(BC23:BC27)+BC29-BC31
B35: Авансы уплаченные | C35: =283707+SUM(C23:C27)-C4 | D35: =C35+SUM(D23:D27)-D4 | E35: =D35+SUM(E23:E27)-E4 | F35: =E35+SUM(F23:F27)-F4 | G35: =F35+SUM(G23:G27)-G4 | H35: =G35+SUM(H23:H27)-H4 | I35: =H35+SUM(I23:I27)-I4 | J35: =I35+SUM(J23:J27)-J4 | K35: =J35+SUM(K23:K27)-K4 | ... BC35: =BB35+SUM(BC23:BC27)-BC4
B36: Денег в обороте | C36: =C5+C42+C35 | D36: =D5+D42+D35 | E36: =E5+E42+E35 | F36: =F5+F42+F35 | G36: =G5+G42+G35 | H36: =H5+H42+H35 | I36: =I5+I42+I35 | J36: =J5+J42+J35 | ... BC36: =BC5+BC42+BC35
G37: =G36-CF!C36 | K37: =K36-CF!D36
A38: Выплата диведентов: | C38: =C39+C40 | D38: =D39+D40 | E38: =E39+E40 | F38: =F39+F40 | G38: =G39+G40 | H38: =H39+H40 | I38: =I39+I40 | J38: =J39+J40 | ... BC38: =BC39+BC40
A39: Инвестор | B39: Остаток после вывода должен быть больше суммы закупки и доставки следующего месяца
A40: Управляющий
G41: =G42-CF!C42 | K41: =K42-CF!D42 | O41: =O42-CF!E42 | S41: =S42-CF!F42 | X41: =X42-CF!G42 | AB41: =AB42-CF!H42 | AF41: =AF42-CF!I42 | AK41: =AK42-CF!J42 | AO41: =AO42-CF!K42 | AT41: =AT42-CF!L42 | AX41: =AX42-CF!M42 | BB41: =BB42-CF!N42 | BC41: =BC42-CF!O42
A42: Остаток денежных средств на конец периода | C42: =C33-C38 | D42: =D33-D38 | E42: =E33-E38 | F42: =F33-F38 | G42: =G33-G38 | H42: =H33-H38 | I42: =I33-I38 | J42: =J33-J38 | ... BC42: =BC33-BC38
B43: Накопленный финансовый результат | C43: ='PL WB (нед)'!C64+'PL OZON (нед)'!C64 | D43: ='PL WB (нед)'!D64+'PL OZON (нед)'!D64 | E43: ='PL WB (нед)'!E64+'PL OZON (нед)'!E64 | F43: ='PL WB (нед)'!F64+'PL OZON (нед)'!F64 | G43: ='PL WB (нед)'!G64+'PL OZON (нед)'!G64 | H43: ='PL WB (нед)'!H64+'PL OZON (нед)'!H64 | I43: ='PL WB (нед)'!I64+'PL OZON (нед)'!I64 | J43: ='PL WB (нед)'!J64+'PL OZON (нед)'!J64 | ... BC43: ='PL WB (нед)'!BC64+'PL OZON (нед)'!BC64
G44: =G43-'PL OZON'!C64 | K44: =K43-CF!D43 | O44: =O43-CF!E43 | S44: =S43-CF!F43 | X44: =X43-CF!G43 | AB44: =AB43-CF!H43 | AF44: =AF43-CF!I43 | AK44: =AK43-CF!J43 | AO44: =AO43-CF!K43 | AT44: =AT43-CF!L43 | AX44: =AX43-CF!M43 | BB44: =BB43-CF!N43
A45: Серые нули (стр 34, 38, 41) - это проверки между листами! Если не ноль - ищем ошибку

Sheet CF
A1: Заполняем PL и CF еженедельный!
A2: Движение денежных средств | C2: 2023
C3: Январь | D3: Февраль | E3: Март | F3: Апрель | G3: Май | H3: Июнь | I3: Июль | J3: Август | K3: Сентябрь | L3: Октябрь | M3: Ноябрь | N3: Декабрь
A4: Поступление товара по цене закупки | C4: ='PL WB'!C10+'PL OZON'!C10 | D4: ='PL WB'!D10+'PL OZON'!D10 | E4: ='PL WB'!E10+'PL OZON'!E10 | F4: ='PL WB'!F10+'PL OZON'!F10 | G4: ='PL WB'!G10+'PL OZON'!G10 | H4: ='PL WB'!H10+'PL OZON'!H10 | I4: ='PL WB'!I10+'PL OZON'!I10 | J4: ='PL WB'!J10+'PL OZON'!J10 | ... N4: ='PL WB'!N10+'PL OZON'!N10 | O4: =SUM(C4:N4)
A5: Доступно на складе по цене закупки | C5: ='PL WB'!C12+'PL OZON'!C12 | D5: ='PL WB'!D12+'PL OZON'!D12 | E5: ='PL WB'!E12+'PL OZON'!E12 | F5: ='PL WB'!F12+'PL OZON'!F12 | G5: ='PL WB'!G12+'PL OZON'!G12 | H5: ='PL WB'!H12+'PL OZON'!H12 | I5: ='PL WB'!I12+'PL OZON'!I12 | J5: ='PL WB'!J12+'PL OZON'!J12 | ... N5: ='PL WB'!N12+'PL OZON'!N12
A7: Остаток денежных средств на начало периода | C7: ='CF (нед)'!C7 | D7: =C42 | E7: =D42 | F7: =E42 | G7: =F42 | H7: =G42 | I7: =H42 | J7: =I42 | K7: =J42 | ... N7: =M42
A9: Поступление на счет | C9: ='PL WB'!C30+'PL OZON'!C30 | D9: ='PL WB'!D30+'PL OZON'!D30 | E9: ='PL WB'!E30+'PL OZON'!E30 | F9: ='PL WB'!F30+'PL OZON'!F30 | G9: ='PL WB'!G30+'PL OZON'!G30 | H9: ='PL WB'!H30+'PL OZON'!H30 | I9: ='PL WB'!I30+'PL OZON'!I30 | J9: ='PL WB'!J30+'PL OZON'!J30 | ... N9: ='PL WB'!N30+'PL OZON'!N30 | O9: =SUM(C9:N9)
A11: Итого остаток + поступление | C11: =C7+C9 | D11: =D7+D9 | E11: =E7+E9 | F11: =F7+F9 | G11: =G7+G9 | H11: =H7+H9 | I11: =I7+I9 | J11: =J7+J9 | ... N11: =N7+N9
A13: Расходы - факт списания | C13: =SUM(C14:C19) | D13: =SUM(D14:D19) | E13: =SUM(E14:E19) | F13: =SUM(F14:F19) | G13: =SUM(G14:G19) | H13: =SUM(H14:H19) | I13: =SUM(I14:I19) | J13: =SUM(J14:J19) | ... N13: =SUM(N14:N19) | O13: =SUM(C13:N13)
A14: Контент | C14: ='PL WB'!C47+'PL OZON'!C47 | D14: ='PL WB'!D47+'PL OZON'!D47 | E14: ='PL WB'!E47+'PL OZON'!E47 | F14: ='PL WB'!F47+'PL OZON'!F47 | G14: ='PL WB'!G47+'PL OZON'!G47 | H14: ='PL WB'!H47+'PL OZON'!H47 | I14: ='PL WB'!I47+'PL OZON'!I47 | J14: ='PL WB'!J47+'PL OZON'!J47 | ... N14: ='PL WB'!N47+'PL OZON'!N47 | O14: =SUM(C14:N14)
A15: Аренда офиса | C15: ='PL WB'!C48+'PL OZON'!C48 | D15: ='PL WB'!D48+'PL OZON'!D48 | E15: ='PL WB'!E48+'PL OZON'!E48 | F15: ='PL WB'!F48+'PL OZON'!F48 | G15: ='PL WB'!G48+'PL OZON'!G48 | H15: ='PL WB'!H48+'PL OZON'!H48 | I15: ='PL WB'!I48+'PL OZON'!I48 | J15: ='PL WB'!J48+'PL OZON'!J48 | ... N15: ='PL WB'!N48+'PL OZON'!N48 | O15: =SUM(C15:N15)
A16: Реклама внешняя | C16: ='PL WB'!C49+'PL OZON'!C49 | D16: ='PL WB'!D49+'PL OZON'!D49 | E16: ='PL WB'!E49+'PL OZON'!E49 | F16: ='PL WB'!F49+'PL OZON'!F49 | G16: ='PL WB'!G49+'PL OZON'!G49 | H16: ='PL WB'!H49+'PL OZON'!H49 | I16: ='PL WB'!I49+'PL OZON'!I49 | J16: ='PL WB'!J49+'PL OZON'!J49 | ... N16: ='PL WB'!N49+'PL OZON'!N49 | O16: =SUM(C16:N16)
A17: Продвижение | C17: ='PL WB'!C41+'PL OZON'!C41 | D17: ='PL WB'!D41+'PL OZON'!D41 | E17: ='PL WB'!E41+'PL OZON'!E41 | F17: ='PL WB'!F41+'PL OZON'!F41 | G17: ='PL WB'!G41+'PL OZON'!G41 | H17: ='PL WB'!H41+'PL OZON'!H41 | I17: ='PL WB'!I41+'PL OZON'!I41 | J17: ='PL WB'!J41+'PL OZON'!J41 | ... N17: ='PL WB'!N41+'PL OZON'!N41 | O17: =SUM(C17:N17)
A18: Подписка Аналитика | C18: ='PL WB'!C50+'PL OZON'!C50 | D18: ='PL WB'!D50+'PL OZON'!D50 | E18: ='PL WB'!E50+'PL OZON'!E50 | F18: ='PL WB'!F50+'PL OZON'!F50 | G18: ='PL WB'!G50+'PL OZON'!G50 | H18: ='PL WB'!H50+'PL OZON'!H50 | I18: ='PL WB'!I50+'PL OZON'!I50 | J18: ='PL WB'!J50+'PL OZON'!J50 | ... N18: ='PL WB'!N50+'PL OZON'!N50 | O18: =SUM(C18:N18)
C19: ='PL WB'!C51+'PL OZON'!C51 | D19: ='PL WB'!D51+'PL OZON'!D51 | E19: ='PL WB'!E51+'PL OZON'!E51 | F19: ='PL WB'!F51+'PL OZON'!F51 | G19: ='PL WB'!G51+'PL OZON'!G51 | H19: ='PL WB'!H51+'PL OZON'!H51 | I19: ='PL WB'!I51+'PL OZON'!I51 | J19: ='PL WB'!J51+'PL OZON'!J51 | ... N19: ='PL WB'!N51+'PL OZON'!N51 | O19: =SUM(C19:N19)
A21: Налоги уплаченные | C21: ='PL WB'!C55+'PL OZON'!C55 | D21: ='PL WB'!D55+'PL OZON'!D55 | E21: ='PL WB'!E55+'PL OZON'!E55 | F21: ='PL WB'!F55+'PL OZON'!F55 | G21: ='PL WB'!G55+'PL OZON'!G55 | H21: ='PL WB'!H55+'PL OZON'!H55 | I21: ='PL WB'!I55+'PL OZON'!I55 | J21: ='PL WB'!J55+'PL OZON'!J55 | ... N21: ='PL WB'!N55+'PL OZON'!N55 | O21: =SUM(C21:N21)
A23: Закупка Китай | C23: =SUM('CF (нед)'!C23:G23) | D23: =SUM('CF (нед)'!H23:K23) | E23: =SUM('CF (нед)'!L23:O23) | F23: =SUM('CF (нед)'!P23:S23) | G23: =SUM('CF (нед)'!T23:X23) | H23: =SUM('CF (нед)'!Y23:AB23) | I23: =SUM('CF (нед)'!AC23:AF23) | J23: =SUM('CF (нед)'!AG23:AK23) | K23: =SUM('CF (нед)'!AL23:AO23) | L23: =SUM('CF (нед)'!AP23:AT23) | M23: =SUM('CF (нед)'!AU23:AX23) | N23: =SUM('CF (нед)'!AY23:BB23) | O23: =SUM(C23:N23)
A24: Закупка нал | C24: =SUM('CF (нед)'!C24:G24) | D24: =SUM('CF (нед)'!H24:K24) | E24: =SUM('CF (нед)'!L24:O24) | F24: =SUM('CF (нед)'!P24:S24) | G24: =SUM('CF (нед)'!T24:X24) | H24: =SUM('CF (нед)'!Y24:AB24) | I24: =SUM('CF (нед)'!AC24:AF24) | J24: =SUM('CF (нед)'!AG24:AK24) | K24: =SUM('CF (нед)'!AL24:AO24) | L24: =SUM('CF (нед)'!AP24:AT24) | M24: =SUM('CF (нед)'!AU24:AX24) | N24: =SUM('CF (нед)'!AY24:BB24) | O24: =SUM(C24:N24)
A25: Закупка р/с | C25: =SUM('CF (нед)'!C25:G25) | D25: =SUM('CF (нед)'!H25:K25) | E25: =SUM('CF (нед)'!L25:O25) | F25: =SUM('CF (нед)'!P25:S25) | G25: =SUM('CF (нед)'!T25:X25) | H25: =SUM('CF (нед)'!Y25:AB25) | I25: =SUM('CF (нед)'!AC25:AF25) | J25: =SUM('CF (нед)'!AG25:AK25) | K25: =SUM('CF (нед)'!AL25:AO25) | L25: =SUM('CF (нед)'!AP25:AT25) | M25: =SUM('CF (нед)'!AU25:AX25) | N25: =SUM('CF (нед)'!AY25:BB25) | O25: =SUM(C25:N25)
A26: Доставка Китай | C26: =SUM('CF (нед)'!C26:G26) | D26: =SUM('CF (нед)'!H26:K26) | E26: =SUM('CF (нед)'!L26:O26) | F26: =SUM('CF (нед)'!P26:S26) | G26: =SUM('CF (нед)'!T26:X26) | H26: =SUM('CF (нед)'!Y26:AB26) | I26: =SUM('CF (нед)'!AC26:AF26) | J26: =SUM('CF (нед)'!AG26:AK26) | K26: =SUM('CF (нед)'!AM26:AO26) | L26: =SUM('CF (нед)'!AP26:AT26) | M26: =SUM('CF (нед)'!AU26:AX26) | N26: =SUM('CF (нед)'!AY26:BB26) | O26: =SUM(C26:N26)
A27: Доставка РФ | C27: =SUM('CF (нед)'!C27:G27) | D27: =SUM('CF (нед)'!H27:K27) | E27: =SUM('CF (нед)'!L27:O27) | F27: =SUM('CF (нед)'!P27:S27) | G27: =SUM('CF (нед)'!T27:X27) | H27: =SUM('CF (нед)'!Y27:AB27) | I27: =SUM('CF (нед)'!AC27:AF27) | J27: =SUM('CF (нед)'!AG27:AK27) | K27: =SUM('CF (нед)'!AL27:AO27) | L27: =SUM('CF (нед)'!AP27:AT27) | M27: =SUM('CF (нед)'!AU27:AX27) | N27: =SUM('CF (нед)'!AY27:BB27) | O27: =SUM(C27:N27)
A29: Вложения инвестора | C29: =SUM('CF (нед)'!C29:G29) | D29: =SUM('CF (нед)'!H29:K29) | E29: =SUM('CF (нед)'!L29:O29) | F29: =SUM('CF (нед)'!P29:S29) | G29: =SUM('CF (нед)'!T29:X29) | H29: =SUM('CF (нед)'!Y29:AB29) | I29: =SUM('CF (нед)'!AC29:AF29) | J29: =SUM('CF (нед)'!AG29:AK29) | K29: =SUM('CF (нед)'!AL29:AO29) | L29: =SUM('CF (нед)'!AP29:AT29) | M29: =SUM('CF (нед)'!AU29:AX29) | N29: =SUM('CF (нед)'!AY29:BB29) | O29: =SUM(C29:N29)
A31: Самовыкупы (покупка товара) | C31: =SUM('CF (нед)'!C31:G31) | D31: =SUM('CF (нед)'!H31:K31) | E31: =SUM('CF (нед)'!L31:O31) | F31: =SUM('CF (нед)'!P31:S31) | G31: =SUM('CF (нед)'!T31:X31) | H31: =SUM('CF (нед)'!Y31:AB31) | I31: =SUM('CF (нед)'!AC31:AF31) | J31: =SUM('CF (нед)'!AG31:AK31) | K31: =SUM('CF (нед)'!AL31:AO31) | L31: =SUM('CF (нед)'!AP31:AT31) | M31: =SUM('CF (нед)'!AU31:AX31) | N31: =SUM('CF (нед)'!AY31:BB31) | O31: =SUM(C31:N31)
A33: Остаток денежных средств на конец периода | C33: =C11-C13-C21-SUM(C23:C27)+C29-C31 | D33: =D11-D13-D21-SUM(D23:D27)+D29-D31 | E33: =E11-E13-E21-SUM(E23:E27)+E29-E31 | F33: =F11-F13-F21-SUM(F23:F27)+F29-F31 | G33: =G11-G13-G21-SUM(G23:G27)+G29-G31 | H33: =H11-H13-H21-SUM(H23:H27)+H29-H31 | I33: =I11-I13-I21-SUM(I23:I27)+I29-I31 | J33: =J11-J13-J21-SUM(J23:J27)+J29-J31 | ... N33: =N11-N13-N21-SUM(N23:N27)+N29-N31
B35: Авансы уплаченные | C35: =283707+SUM(C23:C27)-C4 | D35: =C35+SUM(D23:D27)-D4 | E35: =D35+SUM(E23:E27)-E4 | F35: =E35+SUM(F23:F27)-F4 | G35: =F35+SUM(G23:G27)-G4 | H35: =G35+SUM(H23:H27)-H4 | I35: =H35+SUM(I23:I27)-I4 | J35: =I35+SUM(J23:J27)-J4 | K35: =J35+SUM(K23:K27)-K4 | ... N35: =M35+SUM(N23:N27)-N4
B36: Денег в обороте | C36: =C5+C35+C42 | D36: =D5+D35+D42 | E36: =E5+E35+E42 | F36: =F5+F35+F42 | G36: =G5+G35+G42 | H36: =H5+H35+H42 | I36: =I5+I35+I42 | J36: =J5+J35+J42 | ... N36: =N5+N35+N42
A38: Выплата дивидентов: | C38: =SUM('CF (нед)'!C38:G38) | D38: =SUM('CF (нед)'!H38:K38) | E38: =SUM('CF (нед)'!L38:O38) | F38: =SUM('CF (нед)'!P38:S38) | G38: =SUM('CF (нед)'!T38:X38) | H38: =SUM('CF (нед)'!Y38:AB38) | I38: =SUM('CF (нед)'!AC38:AF38) | J38: =SUM('CF (нед)'!AG38:AK38) | K38: =SUM('CF (нед)'!AL38:AO38) | L38: =SUM('CF (нед)'!AP38:AT38) | M38: =SUM('CF (нед)'!AU38:AX38) | N38: =SUM('CF (нед)'!AY38:BB38) | O38: =SUM(C38:N38)
A39: Инвестор | B39: Остаток после вывода должен быть больше суммы закупки и доставки следующего месяца | C39: =SUM('CF (нед)'!C39:G39) | D39: =SUM('CF (нед)'!H39:K39) | E39: =SUM('CF (нед)'!L39:O39) | F39: =SUM('CF (нед)'!P39:S39) | G39: =SUM('CF (нед)'!T39:X39) | H39: =SUM('CF (нед)'!Y39:AB39) | I39: =SUM('CF (нед)'!AC39:AF39) | J39: =SUM('CF (нед)'!AG39:AK39) | K39: =SUM('CF (нед)'!AL39:AO39) | L39: =SUM('CF (нед)'!AP39:AT39) | M39: =SUM('CF (нед)'!AU39:AX39) | N39: =SUM('CF (нед)'!AY39:BB39) | O39: =SUM(C39:N39)
A40: Управляющий | C40: =SUM('CF (нед)'!C40:G40) | D40: =SUM('CF (нед)'!H40:K40) | E40: =SUM('CF (нед)'!L40:O40) | F40: =SUM('CF (нед)'!P40:S40) | G40: =SUM('CF (нед)'!T40:X40) | H40: =SUM('CF (нед)'!Y40:AB40) | I40: =SUM('CF (нед)'!AC40:AF40) | J40: =SUM('CF (нед)'!AG40:AK40) | K40: =SUM('CF (нед)'!AL40:AO40) | L40: =SUM('CF (нед)'!AP40:AT40) | M40: =SUM('CF (нед)'!AU40:AX40) | N40: =SUM('CF (нед)'!AY40:BB40) | O40: =SUM(C40:N40)
A42: Остаток денежных средств на конец периода | C42: =C33-C38 | D42: =D33-D38 | E42: =E33-E38 | F42: =F33-F38 | G42: =G33-G38 | H42: =H33-H38 | I42: =I33-I38 | J42: =J33-J38 | ... N42: =N33-N38
B43: Накопленный финансовый результат | C43: ='PL WB'!C64+'PL OZON'!C64 | D43: ='PL WB'!D64+'PL OZON'!D64 | E43: ='PL WB'!E64+'PL OZON'!E64 | F43: ='PL WB'!F64+'PL OZON'!F64 | G43: ='PL WB'!G64+'PL OZON'!G64 | H43: ='PL WB'!H64+'PL OZON'!H64 | I43: ='PL WB'!I64+'PL OZON'!I64 | J43: ='PL WB'!J64+'PL OZON'!J64 | ... N43: ='PL WB'!N64+'PL OZON'!N64
A45: Доступный остаток средств | C45: =C42-SUM(D23:D27) | D45: =D42-SUM(E23:E27) | E45: =E42-SUM(F23:F27) | F45: =F42-SUM(G23:G27) | G45: =G42-SUM(H23:H27) | H45: =H42-SUM(I23:I27) | I45: =I42-SUM(J23:J27) | J45: =J42-SUM(K23:K27) | ... N45: =N42-SUM(O23:O27)
