Workbook
Name _12_18__15_3__утолщенный_шелк_7_100шт: #REF!
Name _14_20__17_3___утолщенный_шелк_7_100шт: #REF!
Name _169112569_2038161736993_ACRF1BN101PN_Маска_бандаж_для_лица_розовая: #REF!
Name _169153168_2038162681926_ACRF1BN101BC_Маска_бандаж_для_лица_черная: #REF!
Name _169395410_2038172050200_ACRF1BN201GR_Маска_бандаж_для_лица_серая: #REF!
Name _170899505_2038224716238_AHMA6BW101BG_Набор_мешков_для_стирки_6_шт.: #REF!
Name _172832355_2038337652454_AHMA7BW101BG_Набор_мешков_для_стирки_7_шт.: #REF!
Name _173605843_2038430289250_ACRH1MS101RJ_Массажер_для_пальцев_суставов: #REF!
Name _176170511_2038586639107_ACRF1SK101WH_Скребок_Гуаша_белый_короб: #REF!
Name _176500218_2038597850744_AHMA1BW101BG_Мешок_для_стирки_бюстгалтеров: #REF!
Name _176709293_2038605982115_ACRF2RS201NF_Комплект_Гуаша_роллер_и_скребок_бол_нефрит_прем: #REF!
Name _176721350_2038606201642_AHMA3BW201WH_Комплект_мешков_сетка_мелкая_на_шнурке_3_шт.: #REF!
Name _176723275_2038606256161_AHMA3BW202WH_Комплект_мешков_сетка_крупная_на_шнурке_3_шт.: #REF!
Name _177404837_2038627692689_AHMA3BW101BG_Комплект_мешков_для_стирки_3_шт.: #REF!
Name _177405495_2038627713902_AHMA3BW102BG_Комплект_мешков_для_деликатной_стирки_3_шт.: #REF!
Name _18_27__23_4___утолщенный_шелк_7_100шт: #REF!
Name _186800214_2038890789598_ACRA7TB101BC_Таблетница_круглая_7_2: #REF!
Name _186826338_2038891723249_ACRA7TB201BC_Таблетница_прямоугольная_7_2_черная: #REF!
Name _188194883_2038931439581_AHMA3BW211WH_Комплект_мешков_сетка_мелкая_на_шнурке_3_шт._с_шаром: #REF!
Name _199452263_2039291528267_AHMA3BW212WH_Комплект_мешков_сетка_крупная_на_шнурке_3_шт._с_шаром: #REF!
Name _20_30__26_4___утолщенный_шелк_7_100шт: #REF!
Name _20_34__30_4___утолщенный_шелк_7_100шт: #REF!
Name _200946531_2039323172727_AHMA3BW221WH_Комплект_мешков_сетка_крупная_на_шнурке_3_шт._с_цилиндром: #REF!
Name _200953158_2039323305576_ACRA7TB301BC_Таблетница_прямоугольная_7_3: #REF!
Name _204260887_2039399347548_AHMA3BW222WH_Комплект_мешков_мелкая_сетка_на_шнурке_3_шт._с_цилиндром: #REF!
Name _204615141_2039404446068_AHMA2BW201WH_Комплект_мешков_2_шт._серый: #REF!
Name _205841460_2039422231875_ACRF1SK202NF_Скребок_Гуаша_нефрит: #REF!
Name _22_34__30_4___утолщенный_шелк_7_100шт: #REF!
Name _220252787_2039735724354_ACRL1MS101RJ_Массажер_для_ног: #REF!
Name _223420736_2039813223373_ACRB1MS101RJ_Массажер_для_тела: #REF!
Name _223671295_2039818580389_ACRB1MS102RJ_Массажер_мяч_оранжевый: #REF!
Name _236072834_2040278804649_ACRB1MS102BL_Массажер_мяч_голубой: #REF!
Name _236072835_2040278804496_ACRB1MS102WH_Массажер_мяч_белый: #REF!
Name _236072836_2040278810534_ACRB1MS102PN_Массажер_мяч_розовый: #REF!
Name _236074677_2040278862540_AHMA2BW202WH_Комплект_мешков_2_шт._розовый: #REF!
Name _236929187_2040335626849_AHMA1BW112WH_Мешок_большой_крупная_сетка_60_80: #REF!
Name _236929188_2040335648124_AHMA1BW111WH_Мешок_большой_мелкая_сетка_60_80: #REF!
Name _239233529_2040478696884_AHMA1BW302WH_Мешок_для_стирки_обуви_XL___35_см: #REF!
Name _239235150_2040478720961_AHMA1BW301WH_Мешок_для_стирки_обуви_L___30_см: #REF!
Name _24_34__30_4___утолщенный_шелк_7_100шт: #REF!
Name _248267432_2040797652776_AAND1ST201BL_Палочка_для_жевания: #REF!
Name _251407392_2040900511679_AAND1BL102BL_Мяч_шина_синий: #REF!
Name _251516159_2040902555480_AAND1BL102RD_Мяч_шина_красный: #REF!
Name _251537223_2040903539366_AAND1BL101RD_Мяч_регби_красный: #REF!
Name _251537413_2040903547941_AAND1BL101BL_Мяч_регби_синий: #REF!
Name _253681275_2040957863936_ACRA7TB401CL_Таблетница_прямоугольная_7_2_цветная: #REF!
Name A1016__мелкое_отверстие_30_40: #REF!
Name A1016__толстое_отверстие_30_40: #REF!
Name A1016__толстое_отверстие_40_50: #REF!
Name A1016__толстое_отверстие_60_80: #REF!
Name A1016__тонкое_отверстие_40_50: #REF!
Name A1016__тонкое_отверстие_50_60: #REF!
Name A1016__тонкое_отверстие_60_80: #REF!
Name A1016_толстое_отверстие_50_60: #REF!
Name Бандаж_лайкра_розовый: #REF!
Name Бандаж_лайкра_черный: #REF!
Name Бандаж_силикон_серый: #REF!
Name Бежевые_трусики_20_20: #REF!
Name Бежевый_Бюстгальтер_Раковина_18_16: #REF!
Name Белый__скребок_Гуаша_в_коробке: #REF!

Sheet Акция 1
A1: Товар уже участвует в акции | B1: Бренд | C1: Предмет | D1: Наименование | E1: Артикул поставщика | F1: Артикул WB | G1: Последний баркод | H1: Количество дней на сайте | I1: Оборачиваемость | J1: Остаток товара на складах Wb (шт.) | K1: Остаток товара на складе продавца Wb (шт.) | L1: Плановая цена для акции | M1: Текущая розничная цена | N1: Валюта | O1: Текущая скидка на сайте, % | P1: Загружаемая скидка для участия в акции | Q1: Статус
A2: Да | B2: AROLS | C2: Бандажи косметические | D2: Маска-бандаж для лица подбородка косметический | E2: ACRF1BN101PN | F2: 169112569 | G2: 2038161736993 | H2: 1070.8294 | I2: 984 | J2: 128 | K2: 0 | L2: 746 | M2: 1258 | N2: RUB | O2: 41 | P2: 41 | Q2: Участвует: добавлен, цена равна или ниже плановой
A3: Да | B3: AROLS | C3: Бандажи косметические | D3: Бандаж для лица и подбородка многоразовый | E3: ACRF1BN101BC | F3: 169153168 | G3: 2038162681926 | H3: 1070.5835 | I3: 999 | J3: 216 | K3: 0 | L3: 746 | M3: 1258 | N3: RUB | O3: 41 | P3: 41 | Q3: Участвует: добавлен, цена равна или ниже плановой
A4: Да | B4: AROLS | C4: Бандажи косметические | D4: Бандаж для лица и подбородка многоразовый силиконовый | E4: ACRF1BN201GR | F4: 169395410 | G4: 2038172050200 | H4: 1067.6335 | I4: 999 | J4: 202 | K4: 0 | L4: 1045 | M4: 1656 | N4: RUB | O4: 37 | P4: 37 | Q4: Участвует: добавлен, цена равна или ниже плановой
A5: Да | B5: AROLS HOME | C5: Мешки для стирки | D5: Мешок для стирки белья -7 штук | E5: AHMA7BW101BG | F5: 172832355 | G5: 2038337652454 | H5: 1041.668 | I5: 269 | J5: 139 | K5: 0 | L5: 2097 | M5: 3027 | N5: RUB | O5: 31 | P5: 31 | Q5: Участвует: добавлен, цена равна или ниже плановой
A6: Да | B6: AROLS | C6: Массажеры механические | D6: Массажер для пальцев рук роликовый механический | E6: ACRH1MS101RJ | F6: 173605843 | G6: 2038430289250 | H6: 1035.8927 | I6: 999 | J6: 535 | K6: 0 | L6: 337 | M6: 585 | N6: RUB | O6: 43 | P6: 43 | Q6: Участвует: добавлен, цена равна или ниже плановой
A7: Да | B7: AROLS HOME | C7: Мешки для стирки | D7: Мешок для стирки бюстгальтера | E7: AHMA1BW101BG | F7: 176500218 | G7: 2038597850744 | H7: 1013.689 | I7: 726 | J7: 320 | K7: 0 | L7: 539 | M7: 792 | N7: RUB | O7: 40 | P7: 40 | Q7: Участвует: добавлен, цена равна или ниже плановой
A8: Да | B8: AROLS HOME | C8: Мешки для стирки | D8: Мешки для стирки одежды - сетка мелкая - 3 штуки | E8: AHMA3BW201WH | F8: 176721350 | G8: 2038606201642 | H8: 1011.7208 | I8: 334 | J8: 258 | K8: 0 | L8: 757 | M8: 1199 | N8: RUB | O8: 37 | P8: 37 | Q8: Участвует: добавлен, цена равна или ниже плановой
A9: Да | B9: AROLS HOME | C9: Мешки для стирки | D9: Мешок для стирки одежды - 3 штуки | E9: AHMA3BW101BG | F9: 177404837 | G9: 2038627692689 | H9: 1007.677 | I9: 502 | J9: 146 | K9: 0 | L9: 1246 | M9: 1799 | N9: RUB | O9: 31 | P9: 31 | Q9: Участвует: добавлен, цена равна или ниже плановой
A10: Да | B10: AROLS HOME | C10: Мешки для стирки | D10: Мешки для стирки белья - 3 штуки | E10: AHMA3BW102BG | F10: 177405495 | G10: 2038627713902 | H10: 1007.6705 | I10: 999 | J10: 264 | K10: 0 | L10: 1108 | M10: 1599 | N10: RUB | O10: 31 | P10: 31 | Q10: Участвует: добавлен, цена равна или ниже плановой
A11: Да | B11: AROLS | C11: Таблетницы | D11: Таблетница на неделю 2 приема круглая черная | E11: ACRA7TB101BC | F11: 186800214 | G11: 2038890789598 | H11: 960.62615 | I11: 168 | J11: 180 | K11: 0 | L11: 827 | M11: 1273 | N11: RUB | O11: 40 | P11: 40 | Q11: Участвует: добавлен, цена равна или ниже плановой
A12: Да | B12: AROLS HOME | C12: Мешки для стирки | D12: Мешки для стирки бюстгальтера - набор 2 штуки | E12: AHMA2BW201WH | F12: 204615141 | G12: 2039404446068 | H12: 876.64918 | I12: 602 | J12: 222 | K12: 0 | L12: 598 | M12: 941 | N12: RUB | O12: 37 | P12: 37 | Q12: Участвует: добавлен, цена равна или ниже плановой
A13: Да | B13: AROLS | C13: Массажеры механические | D13: Массажер для шеи спины тела ручной роликовый | E13: ACRB1MS101RJ | F13: 223420736 | G13: 2039813223373 | H13: 799.77998 | I13: 368 | J13: 56 | K13: 0 | L13: 901 | M13: 1313 | N13: RUB | O13: 32 | P13: 32 | Q13: Участвует: добавлен, цена равна или ниже плановой
... A55: Да | B55: AROLS | C55: Эспандеры | D55: Набор тканевых фитнес резинок 3 шт для ягодиц и ног | E55: ACRB3FR101CL | F55: 820643010 | G55: 2048933027488 | H55: 127.77703 | I55: 520 | J55: 89 | K55: 0 | L55: 1483 | M55: 2141 | N55: RUB | O55: 41 | P55: 41 | Q55: Участвует: добавлен, цена равна или ниже плановой

Sheet Акция 2
A1: Товар уже участвует в акции | B1: Бренд | C1: Предмет | D1: Наименование | E1: Артикул поставщика | F1: Артикул WB | G1: Последний баркод | H1: Количество дней на сайте | I1: Оборачиваемость | J1: Остаток товара на складах Wb (шт.) | K1: Остаток товара на складе продавца Wb (шт.) | L1: Плановая цена для акции | M1: Текущая розничная цена | N1: Валюта | O1: Текущая скидка на сайте, % | P1: Загружаемая скидка для участия в акции | Q1: Статус
A2: Да | B2: AROLS HOME | C2: Мешки для стирки | D2: Мешок для стирки белья - сетка крупная - 3 штуки | E2: AHMA3BW202WH | F2: 176723275 | G2: 2038606256161 | H2: 1011.7111 | I2: 87 | J2: 92 | K2: 0 | L2: 839 | M2: 1199 | N2: RUB | O2: 30 | P2: 30 | Q2: Участвует: добавлен, цена равна или ниже плановой
A3: Да | B3: AROLS | C3: Таблетницы | D3: Таблетница органайзер на неделю 7 дней 14 приемов | E3: ACRA7TB201BC | F3: 186826338 | G3: 2038891723249 | H3: 960.48538 | I3: 273 | J3: 457 | K3: 0 | L3: 868 | M3: 1241 | N3: RUB | O3: 30 | P3: 30 | Q3: Участвует: добавлен, цена равна или ниже плановой
A4: Да | B4: AROLS | C4: Массажеры механические | D4: Массажный мяч мфр 6 см для йоги фитнеса пилатеса | E4: ACRB1MS106WH | F4: 236072835 | G4: 2040278804496 | H4: 743.62222 | I4: 256 | J4: 427 | K4: 0 | L4: 597 | M4: 856 | N4: RUB | O4: 31 | P4: 31 | Q4: Участвует: добавлен, цена равна или ниже плановой
A5: Да | B5: AROLS HOME | C5: Мешки для стирки | D5: Большой мешок для стирки - 60*80 сетка крупная | E5: AHMA1BW112WH | F5: 236929187 | G5: 2040335626849 | H5: 739.71473 | I5: 72 | J5: 94 | K5: 0 | L5: 669 | M5: 956 | N5: RUB | O5: 30 | P5: 30 | Q5: Участвует: добавлен, цена равна или ниже плановой
A6: Да | B6: DOG JOY | C6: Игрушки для животных | D6: Прочная игрушка-мяч для собак средних-крупных пород | E6: AAND1BL102BL | F6: 251407392 | G6: 2040900511679 | H6: 678.51668 | I6: 643 | J6: 192 | K6: 0 | L6: 741 | M6: 913 | N6: RUB | O6: 30 | P6: 30 | Q6: Участвует: добавлен, цена равна или ниже плановой

Sheet Акция 3
A1: Товар уже участвует в акции | B1: Бренд | C1: Предмет | D1: Наименование | E1: Артикул поставщика | F1: Артикул WB | G1: Последний баркод | H1: Количество дней на сайте | I1: Оборачиваемость | J1: Остаток товара на складах Wb (шт.) | K1: Остаток товара на складе продавца Wb (шт.) | L1: Плановая цена для акции | M1: Текущая розничная цена | N1: Валюта | O1: Текущая скидка на сайте, % | P1: Загружаемая скидка для участия в акции | Q1: Статус
A2: Нет | B2: AROLS | C2: Бандажи косметические | D2: Маска-бандаж для лица подбородка косметический | E2: ACRF1BN101PN | F2: 169112569 | G2: 2038161736993 | H2: 1070.8311 | I2: 984 | J2: 128 | K2: 0 | L2: 594 | M2: 1258 | N2: RUB | O2: 41 | P2: 53 | Q2: Не участвует: не добавлен или цена выше плановой
A3: Нет | B3: AROLS | C3: Бандажи косметические | D3: Бандаж для лица и подбородка многоразовый | E3: ACRF1BN101BC | F3: 169153168 | G3: 2038162681926 | H3: 1070.5852 | I3: 999 | J3: 216 | K3: 0 | L3: 562 | M3: 1258 | N3: RUB | O3: 41 | P3: 56 | Q3: Не участвует: не добавлен или цена выше плановой
A4: Нет | B4: AROLS | C4: Бандажи косметические | D4: Бандаж для лица и подбородка многоразовый силиконовый | E4: ACRF1BN201GR | F4: 169395410 | G4: 2038172050200 | H4: 1067.6352 | I4: 999 | J4: 202 | K4: 0 | L4: 1011 | M4: 1656 | N4: RUB | O4: 37 | P4: 39 | Q4: Не участвует: не добавлен или цена выше плановой
A5: Нет | B5: AROLS HOME | C5: Мешки для стирки | D5: Мешок для стирки белья -7 штук | E5: AHMA7BW101BG | F5: 172832355 | G5: 2038337652454 | H5: 1041.6697 | I5: 269 | J5: 139 | K5: 0 | L5: 1101 | M5: 3027 | N5: RUB | O5: 31 | P5: 64 | Q5: Не участвует: не добавлен или цена выше плановой
A6: Да | B6: AROLS | C6: Массажеры механические | D6: Массажер для пальцев рук роликовый механический | E6: ACRH1MS101RJ | F6: 173605843 | G6: 2038430289250 | H6: 1035.8944 | I6: 999 | J6: 535 | K6: 0 | L6: 343 | M6: 585 | N6: RUB | O6: 43 | P6: 43 | Q6: Участвует: добавлен, цена равна или ниже плановой
A7: Да | B7: AROLS HOME | C7: Мешки для стирки | D7: Мешок для стирки бюстгальтера | E7: AHMA1BW101BG | F7: 176500218 | G7: 2038597850744 | H7: 1013.6907 | I7: 726 | J7: 320 | K7: 0 | L7: 475 | M7: 792 | N7: RUB | O7: 40 | P7: 40 | Q7: Участвует: добавлен, цена равна или ниже плановой
A8: Нет | B8: AROLS HOME | C8: Мешки для стирки | D8: Мешки для стирки одежды - сетка мелкая - 3 штуки | E8: AHMA3BW201WH | F8: 176721350 | G8: 2038606201642 | H8: 1011.7225 | I8: 334 | J8: 258 | K8: 0 | L8: 577 | M8: 1199 | N8: RUB | O8: 37 | P8: 52 | Q8: Не участвует: не добавлен или цена выше плановой
A9: Нет | B9: AROLS HOME | C9: Мешки для стирки | D9: Мешок для стирки белья - сетка крупная - 3 штуки | E9: AHMA3BW202WH | F9: 176723275 | G9: 2038606256161 | H9: 1011.712 | I9: 87 | J9: 92 | K9: 0 | L9: 752 | M9: 1199 | N9: RUB | O9: 30 | P9: 38 | Q9: Не участвует: не добавлен или цена выше плановой
A10: Нет | B10: AROLS HOME | C10: Мешки для стирки | D10: Мешок для стирки одежды - 3 штуки | E10: AHMA3BW101BG | F10: 177404837 | G10: 2038627692689 | H10: 1007.6787 | I10: 502 | J10: 146 | K10: 0 | L10: 696 | M10: 1799 | N10: RUB | O10: 31 | P10: 62 | Q10: Не участвует: не добавлен или цена выше плановой
A11: Нет | B11: AROLS HOME | C11: Мешки для стирки | D11: Мешки для стирки белья - 3 штуки | E11: AHMA3BW102BG | F11: 177405495 | G11: 2038627713902 | H11: 1007.6722 | I11: 999 | J11: 264 | K11: 0 | L11: 842 | M11: 1599 | N11: RUB | O11: 31 | P11: 48 | Q11: Не участвует: не добавлен или цена выше плановой
A12: Нет | B12: AROLS | C12: Таблетницы | D12: Таблетница на неделю 2 приема круглая черная | E12: ACRA7TB101BC | F12: 186800214 | G12: 2038890789598 | H12: 960.62784 | I12: 168 | J12: 180 | K12: 0 | L12: 696 | M12: 1273 | N12: RUB | O12: 40 | P12: 46 | Q12: Не участвует: не добавлен или цена выше плановой
A13: Нет | B13: AROLS | C13: Таблетницы | D13: Таблетница органайзер на неделю 7 дней 14 приемов | E13: ACRA7TB201BC | F13: 186826338 | G13: 2038891723249 | H13: 960.48628 | I13: 273 | J13: 457 | K13: 0 | L13: 638 | M13: 1241 | N13: RUB | O13: 30 | P13: 49 | Q13: Не участвует: не добавлен или цена выше плановой
... A60: Нет | B60: AROLS | C60: Эспандеры | D60: Набор тканевых фитнес резинок 3 шт для ягодиц и ног | E60: ACRB3FR101CL | F60: 820643010 | G60: 2048933027488 | H60: 127.77873 | I60: 520 | J60: 89 | K60: 0 | L60: 1043 | M60: 2141 | N60: RUB | O60: 41 | P60: 52 | Q60: Не участвует: не добавлен или цена выше плановой

Sheet Акция 4
A1: Товар уже участвует в акции | B1: Бренд | C1: Предмет | D1: Наименование | E1: Артикул поставщика | F1: Артикул WB | G1: Последний баркод | H1: Количество дней на сайте | I1: Оборачиваемость | J1: Остаток товара на складах Wb (шт.) | K1: Остаток товара на складе продавца Wb (шт.) | L1: Плановая цена для акции | M1: Текущая розничная цена | N1: Валюта | O1: Текущая скидка на сайте, % | P1: Загружаемая скидка для участия в акции | Q1: Статус
A2: Да | B2: AROLS | C2: Скакалки | D2: Скакалка спортивная взрослая скоростная | E2: ACRB1SK101BC | F2: 271440668 | G2: 2041473034138 | H2: 609.74101 | I2: 983 | J2: 130 | K2: 0 | L2: 1146 | M2: 1741 | N2: RUB | O2: 35 | P2: 35 | Q2: Участвует: добавлен, цена равна или ниже плановой
A3: Да | B3: AROLS | C3: Скакалки | D3: Скакалка спортивная скоростная | E3: ACRB1SK101RD | F3: 271440669 | G3: 2041473034145 | H3: 609.74101 | I3: 440 | J3: 128 | K3: 0 | L3: 813 | M3: 1575 | N3: RUB | O3: 49 | P3: 49 | Q3: Участвует: добавлен, цена равна или ниже плановой
A4: Да | B4: AROLS | C4: Скакалки | D4: Скакалка спортивная скоростная | E4: ACRB1SK101BL | F4: 271440670 | G4: 2041473034169 | H4: 609.74101 | I4: 999 | J4: 100 | K4: 0 | L4: 813 | M4: 1467 | N4: RUB | O4: 45 | P4: 45 | Q4: Участвует: добавлен, цена равна или ниже плановой
A5: Да | B5: AROLS | C5: Эспандеры | D5: Фитнес резинки тканевые 5 шт эспандер для ног ягодиц | E5: ACRB5FR200CL | F5: 550539998 | G5: 2046392546618 | H5: 260.69337 | I5: 999 | J5: 59 | K5: 0 | L5: 1387 | M5: 2542 | N5: RUB | O5: 46 | P5: 46 | Q5: Участвует: добавлен, цена равна или ниже плановой
A6: Да | B6: AROLS | C6: Эспандеры | D6: Набор фитнес резинок латексных 4 шт эспандер для йоги | E6: ACRB4FR300CL | F6: 550539999 | G6: 2046392546632 | H6: 260.69337 | I6: 999 | J6: 40 | K6: 0 | L6: 910 | M6: 1456 | N6: RUB | O6: 38 | P6: 38 | Q6: Участвует: добавлен, цена равна или ниже плановой
A7: Да | B7: AROLS | C7: Эспандеры | D7: Набор тканевых фитнес резинок 3 шт для ягодиц и ног | E7: ACRB3FR101CL | F7: 820643010 | G7: 2048933027488 | H7: 127.77951 | I7: 520 | J7: 89 | K7: 0 | L7: 1265 | M7: 2141 | N7: RUB | O7: 41 | P7: 41 | Q7: Участвует: добавлен, цена равна или ниже плановой

Sheet Акция 5

Sheet Акция 6

Sheet Акция 7

Sheet Акция 8
A1: Товар уже участвует в акции | B1: Бренд | C1: Предмет | D1: Наименование
A2: Да | B2: AROLS | C2: Массажеры механические | D2: Массажный мяч мфр для йоги - фитнеса пилатеса гимнастики
A3: Да | B3: AROLS | C3: Массажеры механические | D3: Массажный мяч мфр для йоги - фитнеса пилатеса гимнастики
A4: Да | B4: AROLS HOME | C4: Прессы для чеснока | D4: Чеснокодавка металлическая – пресс для чеснока измельчитель
A5: Да | B5: AROLS | C5: Массажеры механические | D5: Массажный мяч для мфр йоги пилатеса с шипами жесткий 7 см
A6: Да | B6: AROLS | C6: Массажеры механические | D6: Массажный мяч для мфр йоги пилатеса с шипами жесткий 7 см
A7: Нет | B7: AROLS | C7: Массажеры механические | D7: Массажный мяч для мфр йоги пилатеса с шипами жесткий 7 см
A8: Да | B8: AROLS | C8: Массажеры механические | D8: Массажный мяч с шипами для мфр йоги пилатеса жесткий 9 см

Sheet Акция 9

Sheet Акция 10

Sheet Акция 11

Sheet Рассчет акции
C1: Данные с листа Юнит ВБ (подтягиваются автоматически) | E1: Вставляем из | I1: ЖЕЛАЕМАЯ ЦЕНА | Q1: 1 | R1: АКЦИЯ | T1: 2 | U1: АКЦИЯ | W1: 3 | X1: АКЦИЯ | Z1: 4 | AA1: АКЦИЯ | AC1: 5 | AD1: АКЦИЯ | AF1: 6 | AG1: АКЦИЯ | AJ1: АКЦИЯ | AM1: АКЦИЯ | AP1: АКЦИЯ | AS1: АКЦИЯ | AV1: АКЦИЯ | AY1: АКЦИЯ | BF1: МАРЖА акции | BG1: МАРЖА текущая | BH1: БУДУТ УЧАСТВОВАТЬ (ПОСТАВИТЬ ЗНАК *) | BI1: ВНЕСТИ ИЗМЕНЕНИЯ В ШАБЛОН ЦЕН! | BJ1: ВНЕСТИ ИЗМЕНЕНИЯ В ШАБЛОН ЦЕН! | BM1: Остатки | BN1: Оборачиваемость
E2: "Цена текущая на ВБ" | N2: ЦЕНА ТЕКУЩАЯ НА ВБ | Q2: дата | R2: 17.06-19.07 | T2: дата | U2: 17.06-19.07 | W2: дата | X2: 10.06-.25.06 | Z2: дата | AA2: 16.06-29.06 | AC2: дата | AF2: дата | AI2: дата | AL2: дата | AO2: дата | AR2: дата | AU2: дата | AX2: дата | BA2: Выбор Акции | BD2: Для установки в акции
E3: перед сохранением листа | M3: подтягивается с листа текущая цена | Q3: Жаркие скидки (автоматические скидки) | T3: Жаркие скидки-2 (автоматические скидки) | W3: Повышаем заказы (автоматические скидки) | Z3: Спортивные скидки (автоматические скидки) | BD3: 0.4
A4: Арт. WB | B4: Арт. Поставщика | C4: Номенклатура | D4: Штрихкод | E4: Цена продажи | F4: Скидка | G4: Цена в карточке | H4: Маржа | I4: Цена продажи плановая | J4: 0.3 | K4: Цена в карточке | L4: Маржа | M4: Цена продажи плановая | N4: Скидка | O4: Цена в карточке | P4: Маржа | Q4: Цена плановая акции | R4: Скидка акции | S4: Цена в карточке | T4: Цена плановая акции | U4: Скидка акции | V4: Цена в карточке | W4: Цена плановая акции | X4: Скидка акции | Y4: Цена в карточке | Z4: Цена плановая акции | AA4: Скидка акции | AB4: Цена в карточке | AC4: Цена плановая акции | AD4: Скидка акции | AE4: Цена в карточке | AF4: Цена плановая акции | AG4: Скидка акции | AH4: Цена в карточке | AI4: Цена плановая акции | AJ4: Скидка акции | AK4: Цена в карточке | AL4: Цена плановая акции | AM4: Скидка акции | AN4: Цена в карточке | AO4: Цена плановая акции | AP4: Скидка акции | AQ4: Цена в карточке | AR4: Цена плановая акции | AS4: Скидка акции | AT4: Цена в карточке | AU4: Цена плановая акции | AV4: Скидка акции | AW4: Цена в карточке | AX4: Цена плановая акции | AY4: Скидка акции | AZ4: Цена в карточке | BA4: Цена продажи Акции МАКС | BB4: Номер акции | BC4: Цена продажи в Акции | BD4: Скидка Акции (вручную) | BE4: Цена в карточке в Акции | BI4: Цена новая | BJ4: Скидка Новая | BK4: Цена Видит покупатель
A5: 1 | B5: 2 | C5: 3 | D5: 4 | E5: 5 | F5: 6 | G5: 7 | H5: 8 | I5: 9 | J5: 10 | K5: 11 | L5: 12 | M5: 13 | N5: 14 | O5: 15 | Q5: 17 | R5: 18 | S5: 19 | T5: 20 | U5: 21 | V5: 22 | W5: 23 | X5: 24 | Y5: 25 | Z5: 26 | AA5: 27 | AB5: 28 | AC5: 29 | AD5: 30 | AE5: 31 | AI5: 15 | AJ5: 16 | AK5: 17 | BA5: 24 | BB5: 25 | BC5: 26 | BD5: 27 | BE5: 28 | BG5: 29 | BH5: 30
A6: =[1]Юнит!A5 -> 169112569 | B6: =[1]Юнит!C5 -> ACRF1BN101PN | C6: =[1]Юнит!D5 -> Бандаж для лица розовый | D6: =[1]Юнит!E5 -> 2038161736993 | E6: 746 | F6: 0.4 | G6: 1243 | H6: 0.21980974 | I6: =_xlfn.XLOOKUP(D6,[1]Юнит!$E:$E,[1]Юнит!$AN:$AN) -> 829 | J6: =$J$4 -> 0.3 | K6: =I6/(100%-$J$4) -> 1184.2857 | L6: =_xlfn.XLOOKUP(D6,[1]Юнит!$E:$E,[1]Юнит!$AR:$AR) -> 0.29258596 | M6: =MROUND(O6-O6*N6,1) -> 746 | N6: =_xlfn.XLOOKUP($A6,'Текущая цена на ВБ'!$C:$C,'Текущая цена на ВБ'!$K:$K,0,0)% -> 0.4 | O6: =_xlfn.XLOOKUP($A6,'Текущая цена на ВБ'!$C:$C,'Текущая цена на ВБ'!$I:$I,0) -> 1243 | P6: =_xlfn.XLOOKUP($A6,[1]Юнит!$A:$A,[1]Юнит!$AJ:$AJ,0) -> 0.22147729 | Q6: =_xlfn.XLOOKUP($A6,'Акция 1'!$F:$F,'Акция 1'!$L:$L,0,0) -> 746 | R6: =(_xlfn.XLOOKUP($A6,'Акция 1'!$F:$F,'Акция 1'!$P:$P,0,0))% -> 0.41 | S6: =Q6/(100%-R6) -> 1264.4068 | T6: =_xlfn.XLOOKUP($A6,'Акция 2'!$F:$F,'Акция 2'!$L:$L,0,0) -> 0 | U6: =(_xlfn.XLOOKUP($A6,'Акция 2'!$F:$F,'Акция 2'!$O:$O,0,0))% -> 0 | V6: =T6/(100%-U6) -> 0 | W6: =_xlfn.XLOOKUP($A6,'Акция 3'!$F:$F,'Акция 3'!$L:$L,0,0) -> 594 | X6: =(_xlfn.XLOOKUP($A6,'Акция 3'!$F:$F,'Акция 3'!$P:$P,0,0))% -> 0.53 | Y6: =W6/(100%-X6) -> 1263.8298 | Z6: =_xlfn.XLOOKUP($A6,'Акция 4'!$F:$F,'Акция 4'!$L:$L,0,0) -> 0 | AA6: =(_xlfn.XLOOKUP($A6,'Акция 4'!$F:$F,'Акция 4'!$P:$P,0,0))% -> 0 | AB6: =Z6/(100%-AA6) -> 0 | AC6: =_xlfn.XLOOKUP($A6,'Акция 5'!$F:$F,'Акция 5'!$L:$L,0,0) -> 0 | AD6: =(_xlfn.XLOOKUP($A6,'Акция 5'!$F:$F,'Акция 5'!O:O,0,0))% -> 0 | AE6: =AC6/(100%-AD6) -> 0 | AF6: =_xlfn.XLOOKUP($A6,'Акция 6'!$F:$F,'Акция 6'!$L:$L,0,0) -> 0 | AG6: =(_xlfn.XLOOKUP($A6,'Акция 6'!$F:$F,'Акция 6'!$O:$O,0,0))% -> 0 | AH6: =AF6/(100%-AG6) -> 0 | AI6: =_xlfn.XLOOKUP($A6,'Акция 7'!$F:$F,'Акция 7'!$L:$L,0,0) -> 0 | AJ6: =(_xlfn.XLOOKUP($A6,'Акция 7'!$F:$F,'Акция 7'!$O:$O,0,0))% -> 0 | AK6: =AI6/(100%-AJ6) -> 0 | AL6: =_xlfn.XLOOKUP($A6,'Акция 8'!$F:$F,'Акция 8'!$L:$L,0,0) -> 0 | AM6: =(_xlfn.XLOOKUP($A6,'Акция 8'!$F:$F,'Акция 8'!$S:$S,0,0))% -> 0 | AN6: =AL6/(100%-AM6) -> 0 | AO6: =_xlfn.XLOOKUP($A6,'Акция 9'!$F:$F,'Акция 9'!$L:$L,0,0) -> 0 | AP6: =(_xlfn.XLOOKUP($A6,'Акция 9'!$F:$F,'Акция 9'!$O:$O,0,0))% -> 0 | AQ6: =AO6/(100%-AP6) -> 0 | AR6: =_xlfn.XLOOKUP($A6,'Акция 10'!$F:$F,'Акция 10'!$L:$L,0,0) -> 0 | AS6: =(_xlfn.XLOOKUP($A6,'Акция 10'!$F:$F,'Акция 10'!$O:$O,0,0))% -> 0 | AT6: =AR6/(100%-AS6) -> 0 | AU6: =_xlfn.XLOOKUP($A6,'Акция 11'!$F:$F,'Акция 11'!$L:$L,0,0) -> 0 | AV6: =(_xlfn.XLOOKUP($A6,'Акция 11'!$F:$F,'Акция 11'!$O:$O,0,0))% -> 0 | AW6: =AU6/(100%-AV6) -> 0 | BA6: =MAX($Q6,$T6,W6,Z6,AC6,AF6,AL6,AO6,AR6,AU6,AX6,AI6) -> 746 | BB6: =IF(BA6=0,0,_xlfn.XLOOKUP($BA6,$Q6:$AZ6,$Q$1:$AZ$1,0,0)) -> 1 | BC6: =_xlfn.XLOOKUP($BB6,$Q$1:$AZ$1,$Q6:$AZ6,0,0) -> 746 | BD6: =IF(BA6=0,0,$BD$3) -> 0.4 | BE6: =BC6/(100%-BD6) -> 1243.3333 | BF6: =_xlfn.XLOOKUP(A6,[1]Юнит!$A:$A,[1]Юнит!$AU:$AU,0) -> 0.22166724 | BG6: =P6 -> 0.22147729 | BH6: * | BI6: =MROUND(IF($BH6="*",$BE6,K6),1) -> 1243 | BJ6: =IF($BH6="*",$BD6,J6) -> 0.4 | BK6: =MROUND(BI6-BI6*BJ6,1) -> 746 | BL6: =IF(BH6="*",1,0) -> 1 | BM6: =_xlfn.XLOOKUP(A6,'Текущая цена на ВБ'!C:C,'Текущая цена на ВБ'!F:F) -> 128 | BN6: =_xlfn.XLOOKUP(A6,'Текущая цена на ВБ'!C:C,'Текущая цена на ВБ'!H:H) -> 984
A7: =[1]Юнит!A6 -> 169153168 | B7: =[1]Юнит!C6 -> ACRF1BN101BC | C7: =[1]Юнит!D6 -> Бандаж для лица черный | D7: =[1]Юнит!E6 -> 2038162681926 | E7: 746 | F7: 0.4 | G7: 1243 | H7: 0.24774963 | I7: =_xlfn.XLOOKUP(D7,[1]Юнит!$E:$E,[1]Юнит!$AN:$AN) -> 829 | J7: =$J$4 -> 0.3 | K7: =I7/(100%-$J$4) -> 1184.2857 | L7: =_xlfn.XLOOKUP(D7,[1]Юнит!$E:$E,[1]Юнит!$AR:$AR) -> 0.3176011 | M7: =MROUND(O7-O7*N7,1) -> 746 | N7: =_xlfn.XLOOKUP($A7,'Текущая цена на ВБ'!$C:$C,'Текущая цена на ВБ'!$K:$K,0,0)% -> 0.4 | O7: =_xlfn.XLOOKUP($A7,'Текущая цена на ВБ'!$C:$C,'Текущая цена на ВБ'!$I:$I,0) -> 1243 | P7: =_xlfn.XLOOKUP($A7,[1]Юнит!$A:$A,[1]Юнит!$AJ:$AJ,0) -> 0.24928306 | Q7: =_xlfn.XLOOKUP($A7,'Акция 1'!$F:$F,'Акция 1'!$L:$L,0,0) -> 746 | R7: =(_xlfn.XLOOKUP($A7,'Акция 1'!$F:$F,'Акция 1'!$P:$P,0,0))% -> 0.41 | S7: =Q7/(100%-R7) -> 1264.4068 | T7: =_xlfn.XLOOKUP($A7,'Акция 2'!$F:$F,'Акция 2'!$L:$L,0,0) -> 0 | U7: =(_xlfn.XLOOKUP($A7,'Акция 2'!$F:$F,'Акция 2'!$O:$O,0,0))% -> 0 | V7: =T7/(100%-U7) -> 0 | W7: =_xlfn.XLOOKUP($A7,'Акция 3'!$F:$F,'Акция 3'!$L:$L,0,0) -> 562 | X7: =(_xlfn.XLOOKUP($A7,'Акция 3'!$F:$F,'Акция 3'!$P:$P,0,0))% -> 0.56 | Y7: =W7/(100%-X7) -> 1277.2727 | Z7: =_xlfn.XLOOKUP($A7,'Акция 4'!$F:$F,'Акция 4'!$L:$L,0,0) -> 0 | AA7: =(_xlfn.XLOOKUP($A7,'Акция 4'!$F:$F,'Акция 4'!$P:$P,0,0))% -> 0 | AB7: =Z7/(100%-AA7) -> 0 | AC7: =_xlfn.XLOOKUP($A7,'Акция 5'!$F:$F,'Акция 5'!$L:$L,0,0) -> 0 | AD7: =(_xlfn.XLOOKUP($A7,'Акция 5'!$F:$F,'Акция 5'!O:O,0,0))% -> 0 | AE7: =AC7/(100%-AD7) -> 0 | AF7: =_xlfn.XLOOKUP($A7,'Акция 6'!$F:$F,'Акция 6'!$L:$L,0,0) -> 0 | AG7: =(_xlfn.XLOOKUP($A7,'Акция 6'!$F:$F,'Акция 6'!$O:$O,0,0))% -> 0 | AH7: =AF7/(100%-AG7) -> 0 | AI7: =_xlfn.XLOOKUP($A7,'Акция 7'!$F:$F,'Акция 7'!$L:$L,0,0) -> 0 | AJ7: =(_xlfn.XLOOKUP($A7,'Акция 7'!$F:$F,'Акция 7'!$O:$O,0,0))% -> 0 | AK7: =AI7/(100%-AJ7) -> 0 | AL7: =_xlfn.XLOOKUP($A7,'Акция 8'!$F:$F,'Акция 8'!$L:$L,0,0) -> 0 | AM7: =(_xlfn.XLOOKUP($A7,'Акция 8'!$F:$F,'Акция 8'!$S:$S,0,0))% -> 0 | AN7: =AL7/(100%-AM7) -> 0 | AO7: =_xlfn.XLOOKUP($A7,'Акция 9'!$F:$F,'Акция 9'!$L:$L,0,0) -> 0 | AP7: =(_xlfn.XLOOKUP($A7,'Акция 9'!$F:$F,'Акция 9'!$O:$O,0,0))% -> 0 | AQ7: =AO7/(100%-AP7) -> 0 | AR7: =_xlfn.XLOOKUP($A7,'Акция 10'!$F:$F,'Акция 10'!$L:$L,0,0) -> 0 | AS7: =(_xlfn.XLOOKUP($A7,'Акция 10'!$F:$F,'Акция 10'!$O:$O,0,0))% -> 0 | AT7: =AR7/(100%-AS7) -> 0 | AU7: =_xlfn.XLOOKUP($A7,'Акция 11'!$F:$F,'Акция 11'!$L:$L,0,0) -> 0 | AV7: =(_xlfn.XLOOKUP($A7,'Акция 11'!$F:$F,'Акция 11'!$O:$O,0,0))% -> 0 | AW7: =AU7/(100%-AV7) -> 0 | BA7: =MAX($Q7,$T7,W7,Z7,AC7,AF7,AL7,AO7,AR7,AU7,AX7,AI7) -> 746 | BB7: =IF(BA7=0,0,_xlfn.XLOOKUP($BA7,$Q7:$AZ7,$Q$1:$AZ$1,0,0)) -> 1 | BC7: =_xlfn.XLOOKUP($BB7,$Q$1:$AZ$1,$Q7:$AZ7,0,0) -> 746 | BD7: =IF(BA7=0,0,$BD$3) -> 0.4 | BE7: =BC7/(100%-BD7) -> 1243.3333 | BF7: =_xlfn.XLOOKUP(A7,[1]Юнит!$A:$A,[1]Юнит!$AU:$AU,0) -> 0.24946556 | BG7: =P7 -> 0.24928306 | BH7: * | BI7: =MROUND(IF($BH7="*",$BE7,K7),1) -> 1243 | BJ7: =IF($BH7="*",$BD7,J7) -> 0.4 | BK7: =MROUND(BI7-BI7*BJ7,1) -> 746 | BL7: =IF(BH7="*",1,0) -> 1 | BM7: =_xlfn.XLOOKUP(A7,'Текущая цена на ВБ'!C:C,'Текущая цена на ВБ'!F:F) -> 216 | BN7: =_xlfn.XLOOKUP(A7,'Текущая цена на ВБ'!C:C,'Текущая цена на ВБ'!H:H) -> 999
A8: =[1]Юнит!A7 -> 169395410 | B8: =[1]Юнит!C7 -> ACRF1BN201GR | C8: =[1]Юнит!D7 -> Бандаж для лица серый | D8: =[1]Юнит!E7 -> 2038172050200 | E8: 1045 | F8: 0.4 | G8: 1742 | H8: 0.22712541 | I8: =_xlfn.XLOOKUP(D8,[1]Юнит!$E:$E,[1]Юнит!$AN:$AN) -> 1159 | J8: =$J$4 -> 0.3 | K8: =I8/(100%-$J$4) -> 1655.7143 | L8: =_xlfn.XLOOKUP(D8,[1]Юнит!$E:$E,[1]Юнит!$AR:$AR) -> 0.2967027 | M8: =MROUND(O8-O8*N8,1) -> 1045 | N8: =_xlfn.XLOOKUP($A8,'Текущая цена на ВБ'!$C:$C,'Текущая цена на ВБ'!$K:$K,0,0)% -> 0.4 | O8: =_xlfn.XLOOKUP($A8,'Текущая цена на ВБ'!$C:$C,'Текущая цена на ВБ'!$I:$I,0) -> 1742 | P8: =_xlfn.XLOOKUP($A8,[1]Юнит!$A:$A,[1]Юнит!$AJ:$AJ,0) -> 0.22775012 | Q8: =_xlfn.XLOOKUP($A8,'Акция 1'!$F:$F,'Акция 1'!$L:$L,0,0) -> 1045 | R8: =(_xlfn.XLOOKUP($A8,'Акция 1'!$F:$F,'Акция 1'!$P:$P,0,0))% -> 0.37 | S8: =Q8/(100%-R8) -> 1658.7302 | T8: =_xlfn.XLOOKUP($A8,'Акция 2'!$F:$F,'Акция 2'!$L:$L,0,0) -> 0 | U8: =(_xlfn.XLOOKUP($A8,'Акция 2'!$F:$F,'Акция 2'!$O:$O,0,0))% -> 0 | V8: =T8/(100%-U8) -> 0 | W8: =_xlfn.XLOOKUP($A8,'Акция 3'!$F:$F,'Акция 3'!$L:$L,0,0) -> 1011 | X8: =(_xlfn.XLOOKUP($A8,'Акция 3'!$F:$F,'Акция 3'!$P:$P,0,0))% -> 0.39 | Y8: =W8/(100%-X8) -> 1657.377 | Z8: =_xlfn.XLOOKUP($A8,'Акция 4'!$F:$F,'Акция 4'!$L:$L,0,0) -> 0 | AA8: =(_xlfn.XLOOKUP($A8,'Акция 4'!$F:$F,'Акция 4'!$P:$P,0,0))% -> 0 | AB8: =Z8/(100%-AA8) -> 0 | AC8: =_xlfn.XLOOKUP($A8,'Акция 5'!$F:$F,'Акция 5'!$L:$L,0,0) -> 0 | AD8: =(_xlfn.XLOOKUP($A8,'Акция 5'!$F:$F,'Акция 5'!O:O,0,0))% -> 0 | AE8: =AC8/(100%-AD8) -> 0 | AF8: =_xlfn.XLOOKUP($A8,'Акция 6'!$F:$F,'Акция 6'!$L:$L,0,0) -> 0 | AG8: =(_xlfn.XLOOKUP($A8,'Акция 6'!$F:$F,'Акция 6'!$O:$O,0,0))% -> 0 | AH8: =AF8/(100%-AG8) -> 0 | AI8: =_xlfn.XLOOKUP($A8,'Акция 7'!$F:$F,'Акция 7'!$L:$L,0,0) -> 0 | AJ8: =(_xlfn.XLOOKUP($A8,'Акция 7'!$F:$F,'Акция 7'!$O:$O,0,0))% -> 0 | AK8: =AI8/(100%-AJ8) -> 0 | AL8: =_xlfn.XLOOKUP($A8,'Акция 8'!$F:$F,'Акция 8'!$L:$L,0,0) -> 0 | AM8: =(_xlfn.XLOOKUP($A8,'Акция 8'!$F:$F,'Акция 8'!$S:$S,0,0))% -> 0 | AN8: =AL8/(100%-AM8) -> 0 | AO8: =_xlfn.XLOOKUP($A8,'Акция 9'!$F:$F,'Акция 9'!$L:$L,0,0) -> 0 | AP8: =(_xlfn.XLOOKUP($A8,'Акция 9'!$F:$F,'Акция 9'!$O:$O,0,0))% -> 0 | AQ8: =AO8/(100%-AP8) -> 0 | AR8: =_xlfn.XLOOKUP($A8,'Акция 10'!$F:$F,'Акция 10'!$L:$L,0,0) -> 0 | AS8: =(_xlfn.XLOOKUP($A8,'Акция 10'!$F:$F,'Акция 10'!$O:$O,0,0))% -> 0 | AT8: =AR8/(100%-AS8) -> 0 | AU8: =_xlfn.XLOOKUP($A8,'Акция 11'!$F:$F,'Акция 11'!$L:$L,0,0) -> 0 | AV8: =(_xlfn.XLOOKUP($A8,'Акция 11'!$F:$F,'Акция 11'!$O:$O,0,0))% -> 0 | AW8: =AU8/(100%-AV8) -> 0 | BA8: =MAX($Q8,$T8,W8,Z8,AC8,AF8,AL8,AO8,AR8,AU8,AX8,AI8) -> 1045 | BB8: =IF(BA8=0,0,_xlfn.XLOOKUP($BA8,$Q8:$AZ8,$Q$1:$AZ$1,0,0)) -> 1 | BC8: =_xlfn.XLOOKUP($BB8,$Q$1:$AZ$1,$Q8:$AZ8,0,0) -> 1045 | BD8: =IF(BA8=0,0,$BD$3) -> 0.4 | BE8: =BC8/(100%-BD8) -> 1741.6667 | BF8: =_xlfn.XLOOKUP(A8,[1]Юнит!$A:$A,[1]Юнит!$AU:$AU,0) -> 0.22761572 | BG8: =P8 -> 0.22775012 | BH8: * | BI8: =MROUND(IF($BH8="*",$BE8,K8),1) -> 1742 | BJ8: =IF($BH8="*",$BD8,J8) -> 0.4 | BK8: =MROUND(BI8-BI8*BJ8,1) -> 1045 | BL8: =IF(BH8="*",1,0) -> 1 | BM8: =_xlfn.XLOOKUP(A8,'Текущая цена на ВБ'!C:C,'Текущая цена на ВБ'!F:F) -> 202 | BN8: =_xlfn.XLOOKUP(A8,'Текущая цена на ВБ'!C:C,'Текущая цена на ВБ'!H:H) -> 999
A9: =[1]Юнит!A8 -> 172832355 | B9: =[1]Юнит!C8 -> AHMA7BW101BG | C9: =[1]Юнит!D8 -> Мешки 7 шт. | D9: =[1]Юнит!E8 -> 2038337652454 | E9: 2097 | F9: 0.4 | G9: 3495 | H9: 0.2678246 | I9: =_xlfn.XLOOKUP(D9,[1]Юнит!$E:$E,[1]Юнит!$AN:$AN) -> 2119 | J9: =$J$4 -> 0.3 | K9: =I9/(100%-$J$4) -> 3027.1429 | L9: =_xlfn.XLOOKUP(D9,[1]Юнит!$E:$E,[1]Юнит!$AR:$AR) -> 0.2760005 | M9: =MROUND(O9-O9*N9,1) -> 2097 | N9: =_xlfn.XLOOKUP($A9,'Текущая цена на ВБ'!$C:$C,'Текущая цена на ВБ'!$K:$K,0,0)% -> 0.4 | O9: =_xlfn.XLOOKUP($A9,'Текущая цена на ВБ'!$C:$C,'Текущая цена на ВБ'!$I:$I,0) -> 3495 | P9: =_xlfn.XLOOKUP($A9,[1]Юнит!$A:$A,[1]Юнит!$AJ:$AJ,0) -> 0.26913927 | Q9: =_xlfn.XLOOKUP($A9,'Акция 1'!$F:$F,'Акция 1'!$L:$L,0,0) -> 2097 | R9: =(_xlfn.XLOOKUP($A9,'Акция 1'!$F:$F,'Акция 1'!$P:$P,0,0))% -> 0.31 | S9: =Q9/(100%-R9) -> 3039.1304 | T9: =_xlfn.XLOOKUP($A9,'Акция 2'!$F:$F,'Акция 2'!$L:$L,0,0) -> 0 | U9: =(_xlfn.XLOOKUP($A9,'Акция 2'!$F:$F,'Акция 2'!$O:$O,0,0))% -> 0 | V9: =T9/(100%-U9) -> 0 | W9: =_xlfn.XLOOKUP($A9,'Акция 3'!$F:$F,'Акция 3'!$L:$L,0,0) -> 1101 | X9: =(_xlfn.XLOOKUP($A9,'Акция 3'!$F:$F,'Акция 3'!$P:$P,0,0))% -> 0.64 | Y9: =W9/(100%-X9) -> 3058.3333 | Z9: =_xlfn.XLOOKUP($A9,'Акция 4'!$F:$F,'Акция 4'!$L:$L,0,0) -> 0 | AA9: =(_xlfn.XLOOKUP($A9,'Акция 4'!$F:$F,'Акция 4'!$P:$P,0,0))% -> 0 | AB9: =Z9/(100%-AA9) -> 0 | AC9: =_xlfn.XLOOKUP($A9,'Акция 5'!$F:$F,'Акция 5'!$L:$L,0,0) -> 0 | AD9: =(_xlfn.XLOOKUP($A9,'Акция 5'!$F:$F,'Акция 5'!O:O,0,0))% -> 0 | AE9: =AC9/(100%-AD9) -> 0 | AF9: =_xlfn.XLOOKUP($A9,'Акция 6'!$F:$F,'Акция 6'!$L:$L,0,0) -> 0 | AG9: =(_xlfn.XLOOKUP($A9,'Акция 6'!$F:$F,'Акция 6'!$O:$O,0,0))% -> 0 | AH9: =AF9/(100%-AG9) -> 0 | AI9: =_xlfn.XLOOKUP($A9,'Акция 7'!$F:$F,'Акция 7'!$L:$L,0,0) -> 0 | AJ9: =(_xlfn.XLOOKUP($A9,'Акция 7'!$F:$F,'Акция 7'!$O:$O,0,0))% -> 0 | AK9: =AI9/(100%-AJ9) -> 0 | AL9: =_xlfn.XLOOKUP($A9,'Акция 8'!$F:$F,'Акция 8'!$L:$L,0,0) -> 0 | AM9: =(_xlfn.XLOOKUP($A9,'Акция 8'!$F:$F,'Акция 8'!$S:$S,0,0))% -> 0 | AN9: =AL9/(100%-AM9) -> 0 | AO9: =_xlfn.XLOOKUP($A9,'Акция 9'!$F:$F,'Акция 9'!$L:$L,0,0) -> 0 | AP9: =(_xlfn.XLOOKUP($A9,'Акция 9'!$F:$F,'Акция 9'!$O:$O,0,0))% -> 0 | AQ9: =AO9/(100%-AP9) -> 0 | AR9: =_xlfn.XLOOKUP($A9,'Акция 10'!$F:$F,'Акция 10'!$L:$L,0,0) -> 0 | AS9: =(_xlfn.XLOOKUP($A9,'Акция 10'!$F:$F,'Акция 10'!$O:$O,0,0))% -> 0 | AT9: =AR9/(100%-AS9) -> 0 | AU9: =_xlfn.XLOOKUP($A9,'Акция 11'!$F:$F,'Акция 11'!$L:$L,0,0) -> 0 | AV9: =(_xlfn.XLOOKUP($A9,'Акция 11'!$F:$F,'Акция 11'!$O:$O,0,0))% -> 0 | AW9: =AU9/(100%-AV9) -> 0 | BA9: =MAX($Q9,$T9,W9,Z9,AC9,AF9,AL9,AO9,AR9,AU9,AX9,AI9) -> 2097 | BB9: =IF(BA9=0,0,_xlfn.XLOOKUP($BA9,$Q9:$AZ9,$Q$1:$AZ$1,0,0)) -> 1 | BC9: =_xlfn.XLOOKUP($BB9,$Q$1:$AZ$1,$Q9:$AZ9,0,0) -> 2097 | BD9: =IF(BA9=0,0,$BD$3) -> 0.4 | BE9: =BC9/(100%-BD9) -> 3495 | BF9: =_xlfn.XLOOKUP(A9,[1]Юнит!$A:$A,[1]Юнит!$AU:$AU,0) -> 0.26913927 | BG9: =P9 -> 0.26913927 | BH9: * | BI9: =MROUND(IF($BH9="*",$BE9,K9),1) -> 3495 | BJ9: =IF($BH9="*",$BD9,J9) -> 0.4 | BK9: =MROUND(BI9-BI9*BJ9,1) -> 2097 | BL9: =IF(BH9="*",1,0) -> 1 | BM9: =_xlfn.XLOOKUP(A9,'Текущая цена на ВБ'!C:C,'Текущая цена на ВБ'!F:F) -> 139 | BN9: =_xlfn.XLOOKUP(A9,'Текущая цена на ВБ'!C:C,'Текущая цена на ВБ'!H:H) -> 269
A10: =[1]Юнит!A9 -> 176500218 | B10: =[1]Юнит!C9 -> AHMA1BW101BG | C10: =[1]Юнит!D9 -> Мешок для бюстгалтеров | D10: =[1]Юнит!E9 -> 2038597850744 | E10: 539 | F10: 0.4 | G10: 898 | H10: 0.1392272 | I10: =_xlfn.XLOOKUP(D10,[1]Юнит!$E:$E,[1]Юнит!$AN:$AN) -> 599 | J10: =$J$4 -> 0.3 | K10: =I10/(100%-$J$4) -> 855.71429 | L10: =_xlfn.XLOOKUP(D10,[1]Юнит!$E:$E,[1]Юнит!$AR:$AR) -> 0.26732668 | M10: =MROUND(O10-O10*N10,1) -> 539 | N10: =_xlfn.XLOOKUP($A10,'Текущая цена на ВБ'!$C:$C,'Текущая цена на ВБ'!$K:$K,0,0)% -> 0.4 | O10: =_xlfn.XLOOKUP($A10,'Текущая цена на ВБ'!$C:$C,'Текущая цена на ВБ'!$I:$I,0) -> 898 | P10: =_xlfn.XLOOKUP($A10,[1]Юнит!$A:$A,[1]Юнит!$AJ:$AJ,0) -> 0.19328635 | Q10: =_xlfn.XLOOKUP($A10,'Акция 1'!$F:$F,'Акция 1'!$L:$L,0,0) -> 539 | R10: =(_xlfn.XLOOKUP($A10,'Акция 1'!$F:$F,'Акция 1'!$P:$P,0,0))% -> 0.4 | S10: =Q10/(100%-R10) -> 898.33333 | T10: =_xlfn.XLOOKUP($A10,'Акция 2'!$F:$F,'Акция 2'!$L:$L,0,0) -> 0 | U10: =(_xlfn.XLOOKUP($A10,'Акция 2'!$F:$F,'Акция 2'!$O:$O,0,0))% -> 0 | V10: =T10/(100%-U10) -> 0 | W10: =_xlfn.XLOOKUP($A10,'Акция 3'!$F:$F,'Акция 3'!$L:$L,0,0) -> 475 | X10: =(_xlfn.XLOOKUP($A10,'Акция 3'!$F:$F,'Акция 3'!$P:$P,0,0))% -> 0.4 | Y10: =W10/(100%-X10) -> 791.66667 | Z10: =_xlfn.XLOOKUP($A10,'Акция 4'!$F:$F,'Акция 4'!$L:$L,0,0) -> 0 | AA10: =(_xlfn.XLOOKUP($A10,'Акция 4'!$F:$F,'Акция 4'!$P:$P,0,0))% -> 0 | AB10: =Z10/(100%-AA10) -> 0 | AC10: =_xlfn.XLOOKUP($A10,'Акция 5'!$F:$F,'Акция 5'!$L:$L,0,0) -> 0 | AD10: =(_xlfn.XLOOKUP($A10,'Акция 5'!$F:$F,'Акция 5'!O:O,0,0))% -> 0 | AE10: =AC10/(100%-AD10) -> 0 | AF10: =_xlfn.XLOOKUP($A10,'Акция 6'!$F:$F,'Акция 6'!$L:$L,0,0) -> 0 | AG10: =(_xlfn.XLOOKUP($A10,'Акция 6'!$F:$F,'Акция 6'!$O:$O,0,0))% -> 0 | AH10: =AF10/(100%-AG10) -> 0 | AI10: =_xlfn.XLOOKUP($A10,'Акция 7'!$F:$F,'Акция 7'!$L:$L,0,0) -> 0 | AJ10: =(_xlfn.XLOOKUP($A10,'Акция 7'!$F:$F,'Акция 7'!$O:$O,0,0))% -> 0 | AK10: =AI10/(100%-AJ10) -> 0 | AL10: =_xlfn.XLOOKUP($A10,'Акция 8'!$F:$F,'Акция 8'!$L:$L,0,0) -> 0 | AM10: =(_xlfn.XLOOKUP($A10,'Акция 8'!$F:$F,'Акция 8'!$S:$S,0,0))% -> 0 | AN10: =AL10/(100%-AM10) -> 0 | AO10: =_xlfn.XLOOKUP($A10,'Акция 9'!$F:$F,'Акция 9'!$L:$L,0,0) -> 0 | AP10: =(_xlfn.XLOOKUP($A10,'Акция 9'!$F:$F,'Акция 9'!$O:$O,0,0))% -> 0 | AQ10: =AO10/(100%-AP10) -> 0 | AR10: =_xlfn.XLOOKUP($A10,'Акция 10'!$F:$F,'Акция 10'!$L:$L,0,0) -> 0 | AS10: =(_xlfn.XLOOKUP($A10,'Акция 10'!$F:$F,'Акция 10'!$O:$O,0,0))% -> 0 | AT10: =AR10/(100%-AS10) -> 0 | AU10: =_xlfn.XLOOKUP($A10,'Акция 11'!$F:$F,'Акция 11'!$L:$L,0,0) -> 0 | AV10: =(_xlfn.XLOOKUP($A10,'Акция 11'!$F:$F,'Акция 11'!$O:$O,0,0))% -> 0 | AW10: =AU10/(100%-AV10) -> 0 | BA10: =MAX($Q10,$T10,W10,Z10,AC10,AF10,AL10,AO10,AR10,AU10,AX10,AI10) -> 539 | BB10: =IF(BA10=0,0,_xlfn.XLOOKUP($BA10,$Q10:$AZ10,$Q$1:$AZ$1,0,0)) -> 1 | BC10: =_xlfn.XLOOKUP($BB10,$Q$1:$AZ$1,$Q10:$AZ10,0,0) -> 539 | BD10: =IF(BA10=0,0,$BD$3) -> 0.4 | BE10: =BC10/(100%-BD10) -> 898.33333 | BF10: =_xlfn.XLOOKUP(A10,[1]Юнит!$A:$A,[1]Юнит!$AU:$AU,0) -> 0.19355971 | BG10: =P10 -> 0.19328635 | BH10: * | BI10: =MROUND(IF($BH10="*",$BE10,K10),1) -> 898 | BJ10: =IF($BH10="*",$BD10,J10) -> 0.4 | BK10: =MROUND(BI10-BI10*BJ10,1) -> 539 | BL10: =IF(BH10="*",1,0) -> 1 | BM10: =_xlfn.XLOOKUP(A10,'Текущая цена на ВБ'!C:C,'Текущая цена на ВБ'!F:F) -> 320 | BN10: =_xlfn.XLOOKUP(A10,'Текущая цена на ВБ'!C:C,'Текущая цена на ВБ'!H:H) -> 726
A11: =[1]Юнит!A10 -> 177404837 | B11: =[1]Юнит!C10 -> AHMA3BW101BG | C11: =[1]Юнит!D10 -> Мешки 3 шт. | D11: =[1]Юнит!E10 -> 2038627692689 | E11: 1246 | F11: 0.4 | G11: 2077 | H11: 0.23293966 | I11: =_xlfn.XLOOKUP(D11,[1]Юнит!$E:$E,[1]Юнит!$AN:$AN) -> 1259 | J11: =$J$4 -> 0.3 | K11: =I11/(100%-$J$4) -> 1798.5714 | L11: =_xlfn.XLOOKUP(D11,[1]Юнит!$E:$E,[1]Юнит!$AR:$AR) -> 0.24144133 | M11: =MROUND(O11-O11*N11,1) -> 1246 | N11: =_xlfn.XLOOKUP($A11,'Текущая цена на ВБ'!$C:$C,'Текущая цена на ВБ'!$K:$K,0,0)% -> 0.4 | O11: =_xlfn.XLOOKUP($A11,'Текущая цена на ВБ'!$C:$C,'Текущая цена на ВБ'!$I:$I,0) -> 2077 | P11: =_xlfn.XLOOKUP($A11,[1]Юнит!$A:$A,[1]Юнит!$AJ:$AJ,0) -> 0.23436899 | Q11: =_xlfn.XLOOKUP($A11,'Акция 1'!$F:$F,'Акция 1'!$L:$L,0,0) -> 1246 | R11: =(_xlfn.XLOOKUP($A11,'Акция 1'!$F:$F,'Акция 1'!$P:$P,0,0))% -> 0.31 | S11: =Q11/(100%-R11) -> 1805.7971 | T11: =_xlfn.XLOOKUP($A11,'Акция 2'!$F:$F,'Акция 2'!$L:$L,0,0) -> 0 | U11: =(_xlfn.XLOOKUP($A11,'Акция 2'!$F:$F,'Акция 2'!$O:$O,0,0))% -> 0 | V11: =T11/(100%-U11) -> 0 | W11: =_xlfn.XLOOKUP($A11,'Акция 3'!$F:$F,'Акция 3'!$L:$L,0,0) -> 696 | X11: =(_xlfn.XLOOKUP($A11,'Акция 3'!$F:$F,'Акция 3'!$P:$P,0,0))% -> 0.62 | Y11: =W11/(100%-X11) -> 1831.5789 | Z11: =_xlfn.XLOOKUP($A11,'Акция 4'!$F:$F,'Акция 4'!$L:$L,0,0) -> 0 | AA11: =(_xlfn.XLOOKUP($A11,'Акция 4'!$F:$F,'Акция 4'!$P:$P,0,0))% -> 0 | AB11: =Z11/(100%-AA11) -> 0 | AC11: =_xlfn.XLOOKUP($A11,'Акция 5'!$F:$F,'Акция 5'!$L:$L,0,0) -> 0 | AD11: =(_xlfn.XLOOKUP($A11,'Акция 5'!$F:$F,'Акция 5'!O:O,0,0))% -> 0 | AE11: =AC11/(100%-AD11) -> 0 | AF11: =_xlfn.XLOOKUP($A11,'Акция 6'!$F:$F,'Акция 6'!$L:$L,0,0) -> 0 | AG11: =(_xlfn.XLOOKUP($A11,'Акция 6'!$F:$F,'Акция 6'!$O:$O,0,0))% -> 0 | AH11: =AF11/(100%-AG11) -> 0 | AI11: =_xlfn.XLOOKUP($A11,'Акция 7'!$F:$F,'Акция 7'!$L:$L,0,0) -> 0 | AJ11: =(_xlfn.XLOOKUP($A11,'Акция 7'!$F:$F,'Акция 7'!$O:$O,0,0))% -> 0 | AK11: =AI11/(100%-AJ11) -> 0 | AL11: =_xlfn.XLOOKUP($A11,'Акция 8'!$F:$F,'Акция 8'!$L:$L,0,0) -> 0 | AM11: =(_xlfn.XLOOKUP($A11,'Акция 8'!$F:$F,'Акция 8'!$S:$S,0,0))% -> 0 | AN11: =AL11/(100%-AM11) -> 0 | AO11: =_xlfn.XLOOKUP($A11,'Акция 9'!$F:$F,'Акция 9'!$L:$L,0,0) -> 0 | AP11: =(_xlfn.XLOOKUP($A11,'Акция 9'!$F:$F,'Акция 9'!$O:$O,0,0))% -> 0 | AQ11: =AO11/(100%-AP11) -> 0 | AR11: =_xlfn.XLOOKUP($A11,'Акция 10'!$F:$F,'Акция 10'!$L:$L,0,0) -> 0 | AS11: =(_xlfn.XLOOKUP($A11,'Акция 10'!$F:$F,'Акция 10'!$O:$O,0,0))% -> 0 | AT11: =AR11/(100%-AS11) -> 0 | AU11: =_xlfn.XLOOKUP($A11,'Акция 11'!$F:$F,'Акция 11'!$L:$L,0,0) -> 0 | AV11: =(_xlfn.XLOOKUP($A11,'Акция 11'!$F:$F,'Акция 11'!$O:$O,0,0))% -> 0 | AW11: =AU11/(100%-AV11) -> 0 | BA11: =MAX($Q11,$T11,W11,Z11,AC11,AF11,AL11,AO11,AR11,AU11,AX11,AI11) -> 1246 | BB11: =IF(BA11=0,0,_xlfn.XLOOKUP($BA11,$Q11:$AZ11,$Q$1:$AZ$1,0,0)) -> 1 | BC11: =_xlfn.XLOOKUP($BB11,$Q$1:$AZ$1,$Q11:$AZ11,0,0) -> 1246 | BD11: =IF(BA11=0,0,$BD$3) -> 0.4 | BE11: =BC11/(100%-BD11) -> 2076.6667 | BF11: =_xlfn.XLOOKUP(A11,[1]Юнит!$A:$A,[1]Юнит!$AU:$AU,0) -> 0.23425734 | BG11: =P11 -> 0.23436899 | BH11: * | BI11: =MROUND(IF($BH11="*",$BE11,K11),1) -> 2077 | BJ11: =IF($BH11="*",$BD11,J11) -> 0.4 | BK11: =MROUND(BI11-BI11*BJ11,1) -> 1246 | BL11: =IF(BH11="*",1,0) -> 1 | BM11: =_xlfn.XLOOKUP(A11,'Текущая цена на ВБ'!C:C,'Текущая цена на ВБ'!F:F) -> 146 | BN11: =_xlfn.XLOOKUP(A11,'Текущая цена на ВБ'!C:C,'Текущая цена на ВБ'!H:H) -> 502
A12: =[1]Юнит!A11 -> 177405495 | B12: =[1]Юнит!C11 -> AHMA3BW102BG | C12: =[1]Юнит!D11 -> Мешки/деликат 3 шт. | D12: =[1]Юнит!E11 -> 2038627713902 | E12: 1108 | F12: 0.4 | G12: 1847 | H12: 0.23328655 | I12: =_xlfn.XLOOKUP(D12,[1]Юнит!$E:$E,[1]Юнит!$AN:$AN) -> 1119 | J12: =$J$4 -> 0.3 | K12: =I12/(100%-$J$4) -> 1598.5714 | L12: =_xlfn.XLOOKUP(D12,[1]Юнит!$E:$E,[1]Юнит!$AR:$AR) -> 0.24160115 | M12: =MROUND(O12-O12*N12,1) -> 1108 | N12: =_xlfn.XLOOKUP($A12,'Текущая цена на ВБ'!$C:$C,'Текущая цена на ВБ'!$K:$K,0,0)% -> 0.4 | O12: =_xlfn.XLOOKUP($A12,'Текущая цена на ВБ'!$C:$C,'Текущая цена на ВБ'!$I:$I,0) -> 1847 | P12: =_xlfn.XLOOKUP($A12,[1]Юнит!$A:$A,[1]Юнит!$AJ:$AJ,0) -> 0.23489234 | Q12: =_xlfn.XLOOKUP($A12,'Акция 1'!$F:$F,'Акция 1'!$L:$L,0,0) -> 1108 | R12: =(_xlfn.XLOOKUP($A12,'Акция 1'!$F:$F,'Акция 1'!$P:$P,0,0))% -> 0.31 | S12: =Q12/(100%-R12) -> 1605.7971 | T12: =_xlfn.XLOOKUP($A12,'Акция 2'!$F:$F,'Акция 2'!$L:$L,0,0) -> 0 | U12: =(_xlfn.XLOOKUP($A12,'Акция 2'!$F:$F,'Акция 2'!$O:$O,0,0))% -> 0 | V12: =T12/(100%-U12) -> 0 | W12: =_xlfn.XLOOKUP($A12,'Акция 3'!$F:$F,'Акция 3'!$L:$L,0,0) -> 842 | X12: =(_xlfn.XLOOKUP($A12,'Акция 3'!$F:$F,'Акция 3'!$P:$P,0,0))% -> 0.48 | Y12: =W12/(100%-X12) -> 1619.2308 | Z12: =_xlfn.XLOOKUP($A12,'Акция 4'!$F:$F,'Акция 4'!$L:$L,0,0) -> 0 | AA12: =(_xlfn.XLOOKUP($A12,'Акция 4'!$F:$F,'Акция 4'!$P:$P,0,0))% -> 0 | AB12: =Z12/(100%-AA12) -> 0 | AC12: =_xlfn.XLOOKUP($A12,'Акция 5'!$F:$F,'Акция 5'!$L:$L,0,0) -> 0 | AD12: =(_xlfn.XLOOKUP($A12,'Акция 5'!$F:$F,'Акция 5'!O:O,0,0))% -> 0 | AE12: =AC12/(100%-AD12) -> 0 | AF12: =_xlfn.XLOOKUP($A12,'Акция 6'!$F:$F,'Акция 6'!$L:$L,0,0) -> 0 | AG12: =(_xlfn.XLOOKUP($A12,'Акция 6'!$F:$F,'Акция 6'!$O:$O,0,0))% -> 0 | AH12: =AF12/(100%-AG12) -> 0 | AI12: =_xlfn.XLOOKUP($A12,'Акция 7'!$F:$F,'Акция 7'!$L:$L,0,0) -> 0 | AJ12: =(_xlfn.XLOOKUP($A12,'Акция 7'!$F:$F,'Акция 7'!$O:$O,0,0))% -> 0 | AK12: =AI12/(100%-AJ12) -> 0 | AL12: =_xlfn.XLOOKUP($A12,'Акция 8'!$F:$F,'Акция 8'!$L:$L,0,0) -> 0 | AM12: =(_xlfn.XLOOKUP($A12,'Акция 8'!$F:$F,'Акция 8'!$S:$S,0,0))% -> 0 | AN12: =AL12/(100%-AM12) -> 0 | AO12: =_xlfn.XLOOKUP($A12,'Акция 9'!$F:$F,'Акция 9'!$L:$L,0,0) -> 0 | AP12: =(_xlfn.XLOOKUP($A12,'Акция 9'!$F:$F,'Акция 9'!$O:$O,0,0))% -> 0 | AQ12: =AO12/(100%-AP12) -> 0 | AR12: =_xlfn.XLOOKUP($A12,'Акция 10'!$F:$F,'Акция 10'!$L:$L,0,0) -> 0 | AS12: =(_xlfn.XLOOKUP($A12,'Акция 10'!$F:$F,'Акция 10'!$O:$O,0,0))% -> 0 | AT12: =AR12/(100%-AS12) -> 0 | AU12: =_xlfn.XLOOKUP($A12,'Акция 11'!$F:$F,'Акция 11'!$L:$L,0,0) -> 0 | AV12: =(_xlfn.XLOOKUP($A12,'Акция 11'!$F:$F,'Акция 11'!$O:$O,0,0))% -> 0 | AW12: =AU12/(100%-AV12) -> 0 | BA12: =MAX($Q12,$T12,W12,Z12,AC12,AF12,AL12,AO12,AR12,AU12,AX12,AI12) -> 1108 | BB12: =IF(BA12=0,0,_xlfn.XLOOKUP($BA12,$Q12:$AZ12,$Q$1:$AZ$1,0,0)) -> 1 | BC12: =_xlfn.XLOOKUP($BB12,$Q$1:$AZ$1,$Q12:$AZ12,0,0) -> 1108 | BD12: =IF(BA12=0,0,$BD$3) -> 0.4 | BE12: =BC12/(100%-BD12) -> 1846.6667 | BF12: =_xlfn.XLOOKUP(A12,[1]Юнит!$A:$A,[1]Юнит!$AU:$AU,0) -> 0.23476687 | BG12: =P12 -> 0.23489234 | BH12: * | BI12: =MROUND(IF($BH12="*",$BE12,K12),1) -> 1847 | BJ12: =IF($BH12="*",$BD12,J12) -> 0.4 | BK12: =MROUND(BI12-BI12*BJ12,1) -> 1108 | BL12: =IF(BH12="*",1,0) -> 1 | BM12: =_xlfn.XLOOKUP(A12,'Текущая цена на ВБ'!C:C,'Текущая цена на ВБ'!F:F) -> 264 | BN12: =_xlfn.XLOOKUP(A12,'Текущая цена на ВБ'!C:C,'Текущая цена на ВБ'!H:H) -> 999
A13: =[1]Юнит!A12 -> 176721350 | B13: =[1]Юнит!C12 -> AHMA3BW201WH | C13: =[1]Юнит!D12 -> Мешки/шнурок мелк 3 шт. | D13: =[1]Юнит!E12 -> 2038606201642 | E13: 757 | F13: 0.4 | G13: 1262 | H13: 0.17981188 | I13: =_xlfn.XLOOKUP(D13,[1]Юнит!$E:$E,[1]Юнит!$AN:$AN) -> 839 | J13: =$J$4 -> 0.3 | K13: =I13/(100%-$J$4) -> 1198.5714 | L13: =_xlfn.XLOOKUP(D13,[1]Юнит!$E:$E,[1]Юнит!$AR:$AR) -> 0.25386338 | M13: =MROUND(O13-O13*N13,1) -> 757 | N13: =_xlfn.XLOOKUP($A13,'Текущая цена на ВБ'!$C:$C,'Текущая цена на ВБ'!$K:$K,0,0)% -> 0.4 | O13: =_xlfn.XLOOKUP($A13,'Текущая цена на ВБ'!$C:$C,'Текущая цена на ВБ'!$I:$I,0) -> 1262 | P13: =_xlfn.XLOOKUP($A13,[1]Юнит!$A:$A,[1]Юнит!$AJ:$AJ,0) -> 0.18082062 | Q13: =_xlfn.XLOOKUP($A13,'Акция 1'!$F:$F,'Акция 1'!$L:$L,0,0) -> 757 | R13: =(_xlfn.XLOOKUP($A13,'Акция 1'!$F:$F,'Акция 1'!$P:$P,0,0))% -> 0.37 | S13: =Q13/(100%-R13) -> 1201.5873 | T13: =_xlfn.XLOOKUP($A13,'Акция 2'!$F:$F,'Акция 2'!$L:$L,0,0) -> 0 | U13: =(_xlfn.XLOOKUP($A13,'Акция 2'!$F:$F,'Акция 2'!$O:$O,0,0))% -> 0 | V13: =T13/(100%-U13) -> 0 | W13: =_xlfn.XLOOKUP($A13,'Акция 3'!$F:$F,'Акция 3'!$L:$L,0,0) -> 577 | X13: =(_xlfn.XLOOKUP($A13,'Акция 3'!$F:$F,'Акция 3'!$P:$P,0,0))% -> 0.52 | Y13: =W13/(100%-X13) -> 1202.0833 | Z13: =_xlfn.XLOOKUP($A13,'Акция 4'!$F:$F,'Акция 4'!$L:$L,0,0) -> 0 | AA13: =(_xlfn.XLOOKUP($A13,'Акция 4'!$F:$F,'Акция 4'!$P:$P,0,0))% -> 0 | AB13: =Z13/(100%-AA13) -> 0 | AC13: =_xlfn.XLOOKUP($A13,'Акция 5'!$F:$F,'Акция 5'!$L:$L,0,0) -> 0 | AD13: =(_xlfn.XLOOKUP($A13,'Акция 5'!$F:$F,'Акция 5'!O:O,0,0))% -> 0 | AE13: =AC13/(100%-AD13) -> 0 | AF13: =_xlfn.XLOOKUP($A13,'Акция 6'!$F:$F,'Акция 6'!$L:$L,0,0) -> 0 | AG13: =(_xlfn.XLOOKUP($A13,'Акция 6'!$F:$F,'Акция 6'!$O:$O,0,0))% -> 0 | AH13: =AF13/(100%-AG13) -> 0 | AI13: =_xlfn.XLOOKUP($A13,'Акция 7'!$F:$F,'Акция 7'!$L:$L,0,0) -> 0 | AJ13: =(_xlfn.XLOOKUP($A13,'Акция 7'!$F:$F,'Акция 7'!$O:$O,0,0))% -> 0 | AK13: =AI13/(100%-AJ13) -> 0 | AL13: =_xlfn.XLOOKUP($A13,'Акция 8'!$F:$F,'Акция 8'!$L:$L,0,0) -> 0 | AM13: =(_xlfn.XLOOKUP($A13,'Акция 8'!$F:$F,'Акция 8'!$S:$S,0,0))% -> 0 | AN13: =AL13/(100%-AM13) -> 0 | AO13: =_xlfn.XLOOKUP($A13,'Акция 9'!$F:$F,'Акция 9'!$L:$L,0,0) -> 0 | AP13: =(_xlfn.XLOOKUP($A13,'Акция 9'!$F:$F,'Акция 9'!$O:$O,0,0))% -> 0 | AQ13: =AO13/(100%-AP13) -> 0 | AR13: =_xlfn.XLOOKUP($A13,'Акция 10'!$F:$F,'Акция 10'!$L:$L,0,0) -> 0 | AS13: =(_xlfn.XLOOKUP($A13,'Акция 10'!$F:$F,'Акция 10'!$O:$O,0,0))% -> 0 | AT13: =AR13/(100%-AS13) -> 0 | AU13: =_xlfn.XLOOKUP($A13,'Акция 11'!$F:$F,'Акция 11'!$L:$L,0,0) -> 0 | AV13: =(_xlfn.XLOOKUP($A13,'Акция 11'!$F:$F,'Акция 11'!$O:$O,0,0))% -> 0 | AW13: =AU13/(100%-AV13) -> 0 | BA13: =MAX($Q13,$T13,W13,Z13,AC13,AF13,AL13,AO13,AR13,AU13,AX13,AI13) -> 757 | BB13: =IF(BA13=0,0,_xlfn.XLOOKUP($BA13,$Q13:$AZ13,$Q$1:$AZ$1,0,0)) -> 1 | BC13: =_xlfn.XLOOKUP($BB13,$Q$1:$AZ$1,$Q13:$AZ13,0,0) -> 757 | BD13: =IF(BA13=0,0,$BD$3) -> 0.4 | BE13: =BC13/(100%-BD13) -> 1261.6667 | BF13: =_xlfn.XLOOKUP(A13,[1]Юнит!$A:$A,[1]Юнит!$AU:$AU,0) -> 0.18062269 | BG13: =P13 -> 0.18082062 | BH13: * | BI13: =MROUND(IF($BH13="*",$BE13,K13),1) -> 1262 | BJ13: =IF($BH13="*",$BD13,J13) -> 0.4 | BK13: =MROUND(BI13-BI13*BJ13,1) -> 757 | BL13: =IF(BH13="*",1,0) -> 1 | BM13: =_xlfn.XLOOKUP(A13,'Текущая цена на ВБ'!C:C,'Текущая цена на ВБ'!F:F) -> 258 | BN13: =_xlfn.XLOOKUP(A13,'Текущая цена на ВБ'!C:C,'Текущая цена на ВБ'!H:H) -> 334
A14: =[1]Юнит!A13 -> 176723275 | B14: =[1]Юнит!C13 -> AHMA3BW202WH | C14: =[1]Юнит!D13 -> Мешки/шнурок крупн 3 шт. | D14: =[1]Юнит!E13 -> 2038606256161 | E14: 839 | F14: 0.4 | G14: 1398 | H14: 0.22155069 | I14: =_xlfn.XLOOKUP(D14,[1]Юнит!$E:$E,[1]Юнит!$AN:$AN) -> 839 | J14: =$J$4 -> 0.3 | K14: =I14/(100%-J12) -> 1198.5714 | L14: =_xlfn.XLOOKUP(D14,[1]Юнит!$E:$E,[1]Юнит!$AR:$AR) -> 0.2214957 | M14: =MROUND(O14-O14*N14,1) -> 839 | N14: =_xlfn.XLOOKUP($A14,'Текущая цена на ВБ'!$C:$C,'Текущая цена на ВБ'!$K:$K,0,0)% -> 0.4 | O14: =_xlfn.XLOOKUP($A14,'Текущая цена на ВБ'!$C:$C,'Текущая цена на ВБ'!$I:$I,0) -> 1398 | P14: =_xlfn.XLOOKUP($A14,[1]Юнит!$A:$A,[1]Юнит!$AJ:$AJ,0) -> 0.22132677 | Q14: =_xlfn.XLOOKUP($A14,'Акция 1'!$F:$F,'Акция 1'!$L:$L,0,0) -> 0 | R14: =(_xlfn.XLOOKUP($A14,'Акция 1'!$F:$F,'Акция 1'!$P:$P,0,0))% -> 0 | S14: =Q14/(100%-R14) -> 0 | T14: =_xlfn.XLOOKUP($A14,'Акция 2'!$F:$F,'Акция 2'!$L:$L,0,0) -> 839 | U14: =(_xlfn.XLOOKUP($A14,'Акция 2'!$F:$F,'Акция 2'!$O:$O,0,0))% -> 0.3 | V14: =T14/(100%-U14) -> 1198.5714 | W14: =_xlfn.XLOOKUP($A14,'Акция 3'!$F:$F,'Акция 3'!$L:$L,0,0) -> 752 | X14: =(_xlfn.XLOOKUP($A14,'Акция 3'!$F:$F,'Акция 3'!$P:$P,0,0))% -> 0.38 | Y14: =W14/(100%-X14) -> 1212.9032 | Z14: =_xlfn.XLOOKUP($A14,'Акция 4'!$F:$F,'Акция 4'!$L:$L,0,0) -> 0 | AA14: =(_xlfn.XLOOKUP($A14,'Акция 4'!$F:$F,'Акция 4'!$P:$P,0,0))% -> 0 | AB14: =Z14/(100%-AA14) -> 0 | AC14: =_xlfn.XLOOKUP($A14,'Акция 5'!$F:$F,'Акция 5'!$L:$L,0,0) -> 0 | AD14: =(_xlfn.XLOOKUP($A14,'Акция 5'!$F:$F,'Акция 5'!O:O,0,0))% -> 0 | AE14: =AC14/(100%-AD14) -> 0 | AF14: =_xlfn.XLOOKUP($A14,'Акция 6'!$F:$F,'Акция 6'!$L:$L,0,0) -> 0 | AG14: =(_xlfn.XLOOKUP($A14,'Акция 6'!$F:$F,'Акция 6'!$O:$O,0,0))% -> 0 | AH14: =AF14/(100%-AG14) -> 0 | AI14: =_xlfn.XLOOKUP($A14,'Акция 7'!$F:$F,'Акция 7'!$L:$L,0,0) -> 0 | AJ14: =(_xlfn.XLOOKUP($A14,'Акция 7'!$F:$F,'Акция 7'!$O:$O,0,0))% -> 0 | AK14: =AI14/(100%-AJ14) -> 0 | AL14: =_xlfn.XLOOKUP($A14,'Акция 8'!$F:$F,'Акция 8'!$L:$L,0,0) -> 0 | AM14: =(_xlfn.XLOOKUP($A14,'Акция 8'!$F:$F,'Акция 8'!$S:$S,0,0))% -> 0 | AN14: =AL14/(100%-AM14) -> 0 | AO14: =_xlfn.XLOOKUP($A14,'Акция 9'!$F:$F,'Акция 9'!$L:$L,0,0) -> 0 | AP14: =(_xlfn.XLOOKUP($A14,'Акция 9'!$F:$F,'Акция 9'!$O:$O,0,0))% -> 0 | AQ14: =AO14/(100%-AP14) -> 0 | AR14: =_xlfn.XLOOKUP($A14,'Акция 10'!$F:$F,'Акция 10'!$L:$L,0,0) -> 0 | AS14: =(_xlfn.XLOOKUP($A14,'Акция 10'!$F:$F,'Акция 10'!$O:$O,0,0))% -> 0 | AT14: =AR14/(100%-AS14) -> 0 | AU14: =_xlfn.XLOOKUP($A14,'Акция 11'!$F:$F,'Акция 11'!$L:$L,0,0) -> 0 | AV14: =(_xlfn.XLOOKUP($A14,'Акция 11'!$F:$F,'Акция 11'!$O:$O,0,0))% -> 0 | AW14: =AU14/(100%-AV14) -> 0 | BA14: =MAX($Q14,$T14,W14,Z14,AC14,AF14,AL14,AO14,AR14,AU14,AX14,AI14) -> 839 | BB14: =IF(BA14=0,0,_xlfn.XLOOKUP($BA14,$Q14:$AZ14,$Q$1:$AZ$1,0,0)) -> 2 | BC14: =_xlfn.XLOOKUP($BB14,$Q$1:$AZ$1,$Q14:$AZ14,0,0) -> 839 | BD14: =IF(BA14=0,0,$BD$3) -> 0.4 | BE14: =BC14/(100%-BD14) -> 1398.3333 | BF14: =_xlfn.XLOOKUP(A14,[1]Юнит!$A:$A,[1]Юнит!$AU:$AU,0) -> 0.2214957 | BG14: =P14 -> 0.22132677 | BI14: =MROUND(IF($BH14="*",$BE14,K14),1) -> 1199 | BJ14: =IF($BH14="*",$BD14,J14) -> 0.3 | BK14: =MROUND(BI14-BI14*BJ14,1) -> 839 | BL14: =IF(BH14="*",1,0) -> 0 | BM14: =_xlfn.XLOOKUP(A14,'Текущая цена на ВБ'!C:C,'Текущая цена на ВБ'!F:F) -> 92 | BN14: =_xlfn.XLOOKUP(A14,'Текущая цена на ВБ'!C:C,'Текущая цена на ВБ'!H:H) -> 87
A15: =[1]Юнит!A14 -> 204615141 | B15: =[1]Юнит!C14 -> AHMA2BW201WH | C15: =[1]Юнит!D14 -> Мешки 2 шт. серый | D15: =[1]Юнит!E14 -> 2039404446068 | E15: 598 | F15: 0.4 | G15: 997 | H15: 0.15895687 | I15: =_xlfn.XLOOKUP(D15,[1]Юнит!$E:$E,[1]Юнит!$AN:$AN) -> 659 | J15: =$J$4 -> 0.3 | K15: =I15/(100%-J13) -> 941.42857 | L15: =_xlfn.XLOOKUP(D15,[1]Юнит!$E:$E,[1]Юнит!$AR:$AR) -> 0.2336652 | M15: =MROUND(O15-O15*N15,1) -> 598 | N15: =_xlfn.XLOOKUP($A15,'Текущая цена на ВБ'!$C:$C,'Текущая цена на ВБ'!$K:$K,0,0)% -> 0.4 | O15: =_xlfn.XLOOKUP($A15,'Текущая цена на ВБ'!$C:$C,'Текущая цена на ВБ'!$I:$I,0) -> 997 | P15: =_xlfn.XLOOKUP($A15,[1]Юнит!$A:$A,[1]Юнит!$AJ:$AJ,0) -> 0.16289095 | Q15: =_xlfn.XLOOKUP($A15,'Акция 1'!$F:$F,'Акция 1'!$L:$L,0,0) -> 598 | R15: =(_xlfn.XLOOKUP($A15,'Акция 1'!$F:$F,'Акция 1'!$P:$P,0,0))% -> 0.37 | S15: =Q15/(100%-R15) -> 949.20635 | T15: =_xlfn.XLOOKUP($A15,'Акция 2'!$F:$F,'Акция 2'!$L:$L,0,0) -> 0 | U15: =(_xlfn.XLOOKUP($A15,'Акция 2'!$F:$F,'Акция 2'!$O:$O,0,0))% -> 0 | V15: =T15/(100%-U15) -> 0 | W15: =_xlfn.XLOOKUP($A15,'Акция 3'!$F:$F,'Акция 3'!$L:$L,0,0) -> 446 | X15: =(_xlfn.XLOOKUP($A15,'Акция 3'!$F:$F,'Акция 3'!$P:$P,0,0))% -> 0.53 | Y15: =W15/(100%-X15) -> 948.93617 | Z15: =_xlfn.XLOOKUP($A15,'Акция 4'!$F:$F,'Акция 4'!$L:$L,0,0) -> 0 | AA15: =(_xlfn.XLOOKUP($A15,'Акция 4'!$F:$F,'Акция 4'!$P:$P,0,0))% -> 0 | AB15: =Z15/(100%-AA15) -> 0 | AC15: =_xlfn.XLOOKUP($A15,'Акция 5'!$F:$F,'Акция 5'!$L:$L,0,0) -> 0 | AD15: =(_xlfn.XLOOKUP($A15,'Акция 5'!$F:$F,'Акция 5'!O:O,0,0))% -> 0 | AE15: =AC15/(100%-AD15) -> 0 | AF15: =_xlfn.XLOOKUP($A15,'Акция 6'!$F:$F,'Акция 6'!$L:$L,0,0) -> 0 | AG15: =(_xlfn.XLOOKUP($A15,'Акция 6'!$F:$F,'Акция 6'!$O:$O,0,0))% -> 0 | AH15: =AF15/(100%-AG15) -> 0 | AI15: =_xlfn.XLOOKUP($A15,'Акция 7'!$F:$F,'Акция 7'!$L:$L,0,0) -> 0 | AJ15: =(_xlfn.XLOOKUP($A15,'Акция 7'!$F:$F,'Акция 7'!$O:$O,0,0))% -> 0 | AK15: =AI15/(100%-AJ15) -> 0 | AL15: =_xlfn.XLOOKUP($A15,'Акция 8'!$F:$F,'Акция 8'!$L:$L,0,0) -> 0 | AM15: =(_xlfn.XLOOKUP($A15,'Акция 8'!$F:$F,'Акция 8'!$S:$S,0,0))% -> 0 | AN15: =AL15/(100%-AM15) -> 0 | AO15: =_xlfn.XLOOKUP($A15,'Акция 9'!$F:$F,'Акция 9'!$L:$L,0,0) -> 0 | AP15: =(_xlfn.XLOOKUP($A15,'Акция 9'!$F:$F,'Акция 9'!$O:$O,0,0))% -> 0 | AQ15: =AO15/(100%-AP15) -> 0 | AR15: =_xlfn.XLOOKUP($A15,'Акция 10'!$F:$F,'Акция 10'!$L:$L,0,0) -> 0 | AS15: =(_xlfn.XLOOKUP($A15,'Акция 10'!$F:$F,'Акция 10'!$O:$O,0,0))% -> 0 | AT15: =AR15/(100%-AS15) -> 0 | AU15: =_xlfn.XLOOKUP($A15,'Акция 11'!$F:$F,'Акция 11'!$L:$L,0,0) -> 0 | AV15: =(_xlfn.XLOOKUP($A15,'Акция 11'!$F:$F,'Акция 11'!$O:$O,0,0))% -> 0 | AW15: =AU15/(100%-AV15) -> 0 | BA15: =MAX($Q15,$T15,W15,Z15,AC15,AF15,AL15,AO15,AR15,AU15,AX15,AI15) -> 598 | BB15: =IF(BA15=0,0,_xlfn.XLOOKUP($BA15,$Q15:$AZ15,$Q$1:$AZ$1,0,0)) -> 1 | BC15: =_xlfn.XLOOKUP($BB15,$Q$1:$AZ$1,$Q15:$AZ15,0,0) -> 598 | BD15: =IF(BA15=0,0,$BD$3) -> 0.4 | BE15: =BC15/(100%-BD15) -> 996.66667 | BF15: =_xlfn.XLOOKUP(A15,[1]Юнит!$A:$A,[1]Юнит!$AU:$AU,0) -> 0.16263439 | BG15: =P15 -> 0.16289095 | BH15: * | BI15: =MROUND(IF($BH15="*",$BE15,K15),1) -> 997 | BJ15: =IF($BH15="*",$BD15,J15) -> 0.4 | BK15: =MROUND(BI15-BI15*BJ15,1) -> 598 | BL15: =IF(BH15="*",1,0) -> 1 | BM15: =_xlfn.XLOOKUP(A15,'Текущая цена на ВБ'!C:C,'Текущая цена на ВБ'!F:F) -> 222 | BN15: =_xlfn.XLOOKUP(A15,'Текущая цена на ВБ'!C:C,'Текущая цена на ВБ'!H:H) -> 602
A16: =[1]Юнит!A15 -> 236074677 | B16: =[1]Юнит!C15 -> AHMA2BW202WH | C16: =[1]Юнит!D15 -> Мешки 2 шт. розовый | D16: =[1]Юнит!E15 -> 2040278862540 | E16: 750 | F16: 0.4 | G16: 1250 | H16: 0.17359446 | I16: =_xlfn.XLOOKUP(D16,[1]Юнит!$E:$E,[1]Юнит!$AN:$AN) -> 759 | J16: =$J$4 -> 0.3 | K16: =I16/(100%-J14) -> 1084.2857 | L16: =_xlfn.XLOOKUP(D16,[1]Юнит!$E:$E,[1]Юнит!$AR:$AR) -> 0.18370224 | M16: =MROUND(O16-O16*N16,1) -> 750 | N16: =_xlfn.XLOOKUP($A16,'Текущая цена на ВБ'!$C:$C,'Текущая цена на ВБ'!$K:$K,0,0)% -> 0.4 | O16: =_xlfn.XLOOKUP($A16,'Текущая цена на ВБ'!$C:$C,'Текущая цена на ВБ'!$I:$I,0) -> 1250 | P16: =_xlfn.XLOOKUP($A16,[1]Юнит!$A:$A,[1]Юнит!$AJ:$AJ,0) -> 0.17474667 | Q16: =_xlfn.XLOOKUP($A16,'Акция 1'!$F:$F,'Акция 1'!$L:$L,0,0) -> 750 | R16: =(_xlfn.XLOOKUP($A16,'Акция 1'!$F:$F,'Акция 1'!$P:$P,0,0))% -> 0.31 | S16: =Q16/(100%-R16) -> 1086.9565 | T16: =_xlfn.XLOOKUP($A16,'Акция 2'!$F:$F,'Акция 2'!$L:$L,0,0) -> 0 | U16: =(_xlfn.XLOOKUP($A16,'Акция 2'!$F:$F,'Акция 2'!$O:$O,0,0))% -> 0 | V16: =T16/(100%-U16) -> 0 | W16: =_xlfn.XLOOKUP($A16,'Акция 3'!$F:$F,'Акция 3'!$L:$L,0,0) -> 582 | X16: =(_xlfn.XLOOKUP($A16,'Акция 3'!$F:$F,'Акция 3'!$P:$P,0,0))% -> 0.47 | Y16: =W16/(100%-X16) -> 1098.1132 | Z16: =_xlfn.XLOOKUP($A16,'Акция 4'!$F:$F,'Акция 4'!$L:$L,0,0) -> 0 | AA16: =(_xlfn.XLOOKUP($A16,'Акция 4'!$F:$F,'Акция 4'!$P:$P,0,0))% -> 0 | AB16: =Z16/(100%-AA16) -> 0 | AC16: =_xlfn.XLOOKUP($A16,'Акция 5'!$F:$F,'Акция 5'!$L:$L,0,0) -> 0 | AD16: =(_xlfn.XLOOKUP($A16,'Акция 5'!$F:$F,'Акция 5'!O:O,0,0))% -> 0 | AE16: =AC16/(100%-AD16) -> 0 | AF16: =_xlfn.XLOOKUP($A16,'Акция 6'!$F:$F,'Акция 6'!$L:$L,0,0) -> 0 | AG16: =(_xlfn.XLOOKUP($A16,'Акция 6'!$F:$F,'Акция 6'!$O:$O,0,0))% -> 0 | AH16: =AF16/(100%-AG16) -> 0 | AI16: =_xlfn.XLOOKUP($A16,'Акция 7'!$F:$F,'Акция 7'!$L:$L,0,0) -> 0 | AJ16: =(_xlfn.XLOOKUP($A16,'Акция 7'!$F:$F,'Акция 7'!$O:$O,0,0))% -> 0 | AK16: =AI16/(100%-AJ16) -> 0 | AL16: =_xlfn.XLOOKUP($A16,'Акция 8'!$F:$F,'Акция 8'!$L:$L,0,0) -> 0 | AM16: =(_xlfn.XLOOKUP($A16,'Акция 8'!$F:$F,'Акция 8'!$S:$S,0,0))% -> 0 | AN16: =AL16/(100%-AM16) -> 0 | AO16: =_xlfn.XLOOKUP($A16,'Акция 9'!$F:$F,'Акция 9'!$L:$L,0,0) -> 0 | AP16: =(_xlfn.XLOOKUP($A16,'Акция 9'!$F:$F,'Акция 9'!$O:$O,0,0))% -> 0 | AQ16: =AO16/(100%-AP16) -> 0 | AR16: =_xlfn.XLOOKUP($A16,'Акция 10'!$F:$F,'Акция 10'!$L:$L,0,0) -> 0 | AS16: =(_xlfn.XLOOKUP($A16,'Акция 10'!$F:$F,'Акция 10'!$O:$O,0,0))% -> 0 | AT16: =AR16/(100%-AS16) -> 0 | AU16: =_xlfn.XLOOKUP($A16,'Акция 11'!$F:$F,'Акция 11'!$L:$L,0,0) -> 0 | AV16: =(_xlfn.XLOOKUP($A16,'Акция 11'!$F:$F,'Акция 11'!$O:$O,0,0))% -> 0 | AW16: =AU16/(100%-AV16) -> 0 | BA16: =MAX($Q16,$T16,W16,Z16,AC16,AF16,AL16,AO16,AR16,AU16,AX16,AI16) -> 750 | BB16: =IF(BA16=0,0,_xlfn.XLOOKUP($BA16,$Q16:$AZ16,$Q$1:$AZ$1,0,0)) -> 1 | BC16: =_xlfn.XLOOKUP($BB16,$Q$1:$AZ$1,$Q16:$AZ16,0,0) -> 750 | BD16: =IF(BA16=0,0,$BD$3) -> 0.4 | BE16: =BC16/(100%-BD16) -> 1250 | BF16: =_xlfn.XLOOKUP(A16,[1]Юнит!$A:$A,[1]Юнит!$AU:$AU,0) -> 0.17474667 | BG16: =P16 -> 0.17474667 | BH16: * | BI16: =MROUND(IF($BH16="*",$BE16,K16),1) -> 1250 | BJ16: =IF($BH16="*",$BD16,J16) -> 0.4 | BK16: =MROUND(BI16-BI16*BJ16,1) -> 750 | BL16: =IF(BH16="*",1,0) -> 1 | BM16: =_xlfn.XLOOKUP(A16,'Текущая цена на ВБ'!C:C,'Текущая цена на ВБ'!F:F) -> 18 | BN16: =_xlfn.XLOOKUP(A16,'Текущая цена на ВБ'!C:C,'Текущая цена на ВБ'!H:H) -> 152
