Workbook

Sheet Дашборд
A1: ФИНАНСОВЫЙ ДАШБОРД 2025
A2: =TODAY() -> 46132
A5: КЛЮЧЕВЫЕ ПОКАЗАТЕЛИ
A7: Показатель | C7: Значение
A8: Годовая выручка (продажи) | C8: ='PL общ'!O14 -> 3706205 | E8: Выручка от реализации товаров
A9: Чистая прибыль | C9: ='PL общ'!O57 -> 841870.75 | E9: Прибыль после налогов
A10: Маржинальность | C10: ='PL общ'!O59 -> 0.2271517 | E10: Отношение прибыли к выручке
A11: Валовая прибыль | C11: ='PL общ'!O36 -> 1761272.4 | E11: Прибыль до расходов
A12: Рентабельность | C12: ='PL общ'!O58 -> 1.1451253 | E12: ROI вложений
A14: СРАВНЕНИЕ ПЛАТФОРМ
A16: Метрика | C16: Wildberries | F16: OZON
A17: Продажи (шт) | C17: ='PL WB'!O7 -> 4476 | D17: =C17/(C17+F17) -> 0.76748971 | F17: ='PL OZON'!O7 -> 1356 | G17: =100%-D17 -> 0.23251029
A18: Выручка (руб) | C18: ='PL WB'!O14 -> 2810873 | D18: =C18/(C18+F18) -> 0.75842351 | F18: ='PL OZON'!O14 -> 895332 | G18: =100%-D18 -> 0.24157649
A19: Чистая прибыль | C19: ='PL WB'!O57 -> 779514.99 | D19: =C19/(C19+F19) -> 0.92593191 | F19: ='PL OZON'!O57 -> 62355.76 | G19: =100%-D19 -> 0.074068092
A20: Средний чек | C20: =C18/C17 -> 627.98771 | F20: =F18/F17 -> 660.27434
A21: Маржа (%) | C21: ='PL WB'!O59 -> 0.27732131 | F21: ='PL OZON'!O59 -> 0.069645405
A23: СТРУКТУРА РАСХОДОВ
A25: Статья расходов | C25: Сумма (руб) | E25: Доля (%)
A26: Комиссии площадок | C26: ='PL общ'!O17 -> 1209754.8 | E26: =C26/'PL общ'!O14 -> 0.32641335
A27: Логистика | C27: ='PL общ'!O40 -> 519605 | E27: =C27/'PL общ'!O14 -> 0.14019867
A28: Продвижение | C28: ='PL общ'!O41 -> 23354 | E28: =C28/'PL общ'!O14 -> 0.0063013244
A29: Себестоимость | C29: ='PL общ'!O33 -> 735177.83 | E29: =C29/'PL общ'!O14 -> 0.19836405
A30: Хранение | C30: ='PL общ'!O43 -> 158529.89 | E30: =C30/'PL общ'!O14 -> 0.042774183
A31: Прочие расходы | C31: ='PL общ'!O38-'PL общ'!O40-'PL общ'!O41-'PL общ'!O43 -> 22959.81 | E31: =C31/'PL общ'!O14 -> 0.0061949649
A32: ИТОГО расходов | C32: ='PL общ'!O38+'PL общ'!O17+'PL общ'!O33 -> 2669381.3 | E32: =C32/'PL общ'!O14 -> 0.72024654
A34: ПОМЕСЯЧНАЯ ДИНАМИКА
A36: Месяц | B36: Янв | C36: Фев | D36: Мар | E36: Апр | F36: Май | G36: Июн | H36: Июл | I36: Авг | J36: Сен | K36: Окт | L36: Ноя | M36: Дек
A37: Выручка | B37: ='PL общ'!C15 -> 950524 | C37: ='PL общ'!D15 -> 834437 | D37: ='PL общ'!E15 -> 692756 | E37: ='PL общ'!F15 -> 313306 | F37: ='PL общ'!G15 -> 0 | G37: ='PL общ'!H15 -> 0 | H37: ='PL общ'!I15 -> 0 | I37: ='PL общ'!J15 -> 0 | ... M37: ='PL общ'!N15 -> 0
A38: Прибыль | B38: ='PL общ'!C57 -> 243054.14 | C38: ='PL общ'!D57 -> 288121.19 | D38: ='PL общ'!E57 -> 211258.46 | E38: ='PL общ'!F57 -> 99436.96 | F38: ='PL общ'!G57 -> 0 | G38: ='PL общ'!H57 -> 0 | H38: ='PL общ'!I57 -> 0 | I38: ='PL общ'!J57 -> 0 | ... M38: ='PL общ'!N57 -> 0

Sheet PL общ
A1: Заполняем PL и CF еженедельный!
A2: Прибыли и убытки | C2: 2025
C3: Январь | D3: Февраль | E3: Март | F3: Апрель | G3: Май | H3: Июнь | I3: Июль | J3: Август | K3: Сентябрь | L3: Октябрь | M3: Ноябрь | N3: Декабрь
A4: Товарооборот
A5: Остаток товара по цене закупки | C5: ='PL WB'!C5+'PL OZON'!C5 -> 1570857.7 | D5: ='PL WB'!D5+'PL OZON'!D5 -> 1522905.6 | E5: ='PL WB'!E5+'PL OZON'!E5 -> 1301418.9 | F5: ='PL WB'!F5+'PL OZON'!F5 -> 1109069.5 | G5: ='PL WB'!G5+'PL OZON'!G5 -> 1028078.6 | H5: ='PL WB'!H5+'PL OZON'!H5 -> 1028078.6 | I5: ='PL WB'!I5+'PL OZON'!I5 -> 1028078.6 | J5: ='PL WB'!J5+'PL OZON'!J5 -> 1028078.6 | ... N5: ='PL WB'!N5+'PL OZON'!N5 -> 1028078.6
B7: Продажи шт | C7: ='PL WB'!C7+'PL OZON'!C7 -> 1965 | D7: ='PL WB'!D7+'PL OZON'!D7 -> 1719 | E7: ='PL WB'!E7+'PL OZON'!E7 -> 1545 | F7: ='PL WB'!F7+'PL OZON'!F7 -> 603 | G7: ='PL WB'!G7+'PL OZON'!G7 -> 0 | H7: ='PL WB'!H7+'PL OZON'!H7 -> 0 | I7: ='PL WB'!I7+'PL OZON'!I7 -> 0 | J7: ='PL WB'!J7+'PL OZON'!J7 -> 0 | ... N7: ='PL WB'!N7+'PL OZON'!N7 -> 0 | O7: =SUM(C7:N7) -> 5832
B8: Отгрузки по себестоимости | C8: =C33 -> 240350.81 | D8: =D33 -> 221486.72 | E8: =E33 -> 192349.4 | F8: =F33 -> 80990.9 | G8: =G33 -> 0 | H8: =H33 -> 0 | I8: =I33 -> 0 | J8: =J33 -> 0 | ... N8: =N33 -> 0 | O8: =SUM(C8:N8) -> 735177.83
A10: Поступление товара, р | C10: ='PL WB'!C10+'PL OZON'!C10 -> 192398.77 | D10: ='PL WB'!D10+'PL OZON'!D10 -> 0 | E10: ='PL WB'!E10+'PL OZON'!E10 -> 0 | F10: ='PL WB'!F10+'PL OZON'!F10 -> 0 | G10: ='PL WB'!G10+'PL OZON'!G10 -> 0 | H10: ='PL WB'!H10+'PL OZON'!H10 -> 0 | I10: ='PL WB'!I10+'PL OZON'!I10 -> 0 | J10: ='PL WB'!J10+'PL OZON'!J10 -> 0 | ... N10: ='PL WB'!N10+'PL OZON'!N10 -> 0 | O10: =SUM(C10:N10) -> 192398.77
A11: Поступление товара, шт | C11: ='PL WB'!C11+'PL OZON'!C11 -> 1294 | D11: ='PL WB'!D11+'PL OZON'!D11 -> 0 | E11: ='PL WB'!E11+'PL OZON'!E11 -> 0 | F11: ='PL WB'!F11+'PL OZON'!F11 -> 0 | G11: ='PL WB'!G11+'PL OZON'!G11 -> 0 | H11: ='PL WB'!H11+'PL OZON'!H11 -> 0 | I11: ='PL WB'!I11+'PL OZON'!I11 -> 0 | J11: ='PL WB'!J11+'PL OZON'!J11 -> 0 | ... N11: ='PL WB'!N11+'PL OZON'!N11 -> 0 | O11: =SUM(C11:N11) -> 1294
A12: Доступно на складе по цене закупки | C12: ='PL WB'!C12+'PL OZON'!C12 -> 1522905.6 | D12: ='PL WB'!D12+'PL OZON'!D12 -> 1301418.9 | E12: ='PL WB'!E12+'PL OZON'!E12 -> 1109069.5 | F12: ='PL WB'!F12+'PL OZON'!F12 -> 1028078.6 | G12: ='PL WB'!G12+'PL OZON'!G12 -> 1028078.6 | H12: ='PL WB'!H12+'PL OZON'!H12 -> 1028078.6 | I12: ='PL WB'!I12+'PL OZON'!I12 -> 1028078.6 | J12: ='PL WB'!J12+'PL OZON'!J12 -> 1028078.6 | ... N12: ='PL WB'!N12+'PL OZON'!N12 -> 1028078.6
A13: Доступно на складе, шт | C13: ='PL WB'!C13+'PL OZON'!C13 -> 10153 | D13: ='PL WB'!D13+'PL OZON'!D13 -> 8438 | E13: ='PL WB'!E13+'PL OZON'!E13 -> 6908 | F13: ='PL WB'!F13+'PL OZON'!F13 -> 6309 | G13: ='PL WB'!G13+'PL OZON'!G13 -> 6309 | H13: ='PL WB'!H13+'PL OZON'!H13 -> 6306 | I13: ='PL WB'!I13+'PL OZON'!I13 -> 6306 | J13: ='PL WB'!J13+'PL OZON'!J13 -> 6306 | ... N13: ='PL WB'!N13+'PL OZON'!N13 -> 6306
A14: Продано товаров по цене в карточке | C14: ='PL WB'!C14+'PL OZON'!C14 -> 1213007 | D14: ='PL WB'!D14+'PL OZON'!D14 -> 1136792 | E14: ='PL WB'!E14+'PL OZON'!E14 -> 937183 | F14: ='PL WB'!F14+'PL OZON'!F14 -> 419223 | G14: ='PL WB'!G14+'PL OZON'!G14 -> 0 | H14: ='PL WB'!H14+'PL OZON'!H14 -> 0 | I14: ='PL WB'!I14+'PL OZON'!I14 -> 0 | J14: ='PL WB'!J14+'PL OZON'!J14 -> 0 | ... N14: ='PL WB'!N14+'PL OZON'!N14 -> 0 | O14: =SUM(C14:N14) -> 3706205
A15: Продано товаров -ПРОДАЖИ | C15: ='PL WB'!C15+'PL OZON'!C14 -> 950524 | D15: ='PL WB'!D15+'PL OZON'!D14 -> 834437 | E15: ='PL WB'!E15+'PL OZON'!E14 -> 692756 | F15: ='PL WB'!F15+'PL OZON'!F14 -> 313306 | G15: ='PL WB'!G15+'PL OZON'!G14 -> 0 | H15: ='PL WB'!H15+'PL OZON'!H14 -> 0 | I15: ='PL WB'!I15+'PL OZON'!I14 -> 0 | J15: ='PL WB'!J15+'PL OZON'!J14 -> 0 | ... N15: ='PL WB'!N15+'PL OZON'!N14 -> 0 | O15: =SUM(C15:N15) -> 2791023
O16: =SUM(C16:N16) -> 0
A17: Комиссия | C17: =C14-C20 -> 395838.84 | D17: =D14-D20 -> 369766.81 | E17: =E14-E20 -> 307275.59 | F17: =F14-F20 -> 136873.54 | G17: =G14-G20 -> 0 | H17: =H14-H20 -> 0 | I17: =I14-I20 -> 0 | J17: =J14-J20 -> 0 | ... M17: =M14-M20 -> 0 | N17: =N15-N20 -> 0 | O17: =SUM(C17:N17) -> 1209754.8
A18: % комиссии | C18: =C17/C14 -> 0.32632857 | D18: =D17/D15 -> 0.44313329 | E18: =E17/E15 -> 0.44355529 | F18: =F17/F15 -> 0.43686856 | G18: =G17/G15 -> #DIV/0! | H18: =H17/H15 -> #DIV/0! | I18: =I17/I15 -> #DIV/0! | J18: =J17/J15 -> #DIV/0! | K18: =K17/K15 -> #DIV/0! | ... O18: =O17/O15 -> 0.43344493
A20: Выручка от реализации (к перечислению за товар), руб | C20: ='PL WB'!C20+'PL OZON'!C20 -> 817168.16 | D20: ='PL WB'!D20+'PL OZON'!D20 -> 767025.19 | E20: ='PL WB'!E20+'PL OZON'!E20 -> 629907.41 | F20: ='PL WB'!F20+'PL OZON'!F20 -> 282349.46 | G20: ='PL WB'!G20+'PL OZON'!G20 -> 0 | H20: ='PL WB'!H20+'PL OZON'!H20 -> 0 | I20: ='PL WB'!I20+'PL OZON'!I20 -> 0 | J20: ='PL WB'!J20+'PL OZON'!J20 -> 0 | ... N20: ='PL WB'!N20+'PL OZON'!N20 -> 0 | O20: =SUM(C20:N20) -> 2496450.2
O21: =SUM(C21:N21) -> 0
A22: Возвраты, руб | C22: ='PL WB'!C22+'PL OZON'!C22 -> 6905 | D22: ='PL WB'!D22+'PL OZON'!D22 -> 3051 | E22: ='PL WB'!E22+'PL OZON'!E22 -> 11540 | F22: ='PL WB'!F22+'PL OZON'!F22 -> 2705 | G22: ='PL WB'!G22+'PL OZON'!G22 -> 0 | H22: ='PL WB'!H22+'PL OZON'!H22 -> 0 | I22: ='PL WB'!I22+'PL OZON'!I22 -> 0 | J22: ='PL WB'!J22+'PL OZON'!J22 -> 0 | ... N22: ='PL WB'!N22+'PL OZON'!N22 -> 0 | O22: =SUM(C22:N22) -> 24201
A23: Возвраты, шт | C23: ='PL WB'!C23+'PL OZON'!C23 -> 11 | D23: ='PL WB'!D23+'PL OZON'!D23 -> 4 | E23: ='PL WB'!E23+'PL OZON'!E23 -> 15 | F23: ='PL WB'!F23+'PL OZON'!F23 -> 5 | G23: ='PL WB'!G23+'PL OZON'!G23 -> 0 | H23: ='PL WB'!H23+'PL OZON'!H23 -> 0 | I23: ='PL WB'!I23+'PL OZON'!I23 -> 0 | J23: ='PL WB'!J23+'PL OZON'!J23 -> 0 | ... N23: ='PL WB'!N23+'PL OZON'!N23 -> 0 | O23: =SUM(C23:N23) -> 35
A24: % возвратов | C24: ='PL WB'!C24+'PL OZON'!C24 -> 0.017316571 | D24: =D22/D20 -> 0.0039777051 | E24: =E22/E20 -> 0.018320153 | F24: =F22/F20 -> 0.0095803265 | G24: =G22/G20 -> #DIV/0! | H24: =H22/H20 -> #DIV/0! | I24: =I22/I20 -> #DIV/0! | J24: =J22/J20 -> #DIV/0! | K24: =K22/K20 -> #DIV/0! | ... O24: =O22/O20 -> 0.0096941649
C25: ='PL WB'!C25+'PL OZON'!C25 -> 0
A26: Брак, руб | C26: ='PL WB'!C26+'PL OZON'!C26 -> 0
A27: Брак, шт | C27: ='PL WB'!C27+'PL OZON'!C27 -> 0 | D27: =SUM('PL WB (нед)'!H27:K27) -> 0 | E27: =SUM('PL WB (нед)'!L27:O27) -> 0 | F27: =SUM('PL WB (нед)'!P27:S27) -> 1 | G27: =SUM('PL WB (нед)'!T27:X27) -> 0 | H27: =SUM('PL WB (нед)'!Y27:AB27) -> 3 | I27: =SUM('PL WB (нед)'!AC27:AF27) -> 0 | J27: =SUM('PL WB (нед)'!AG27:AK27) -> 0 | K27: =SUM('PL WB (нед)'!AL27:AO27) -> 0 | L27: =SUM('PL WB (нед)'!AP27:AT27) -> 0 | M27: =SUM('PL WB (нед)'!AU27:AX27) -> 0 | N27: =SUM('PL WB (нед)'!AY27:BB27) -> 0
A28: % брака | C28: ='PL WB'!C28+'PL OZON'!C28 -> 0 | D28: =D27/D7 -> 0 | E28: =E27/E7 -> 0 | F28: =F27/F7 -> 0.0016583748 | G28: =G27/G7 -> #DIV/0! | H28: =H27/H7 -> #DIV/0! | I28: =I27/I7 -> #DIV/0! | J28: =J27/J7 -> #DIV/0! | K28: =K27/K7 -> #DIV/0! | ... N28: =N27/N7 -> #DIV/0!
A30: Поступление на счет | C30: ='PL WB'!C30+'PL OZON'!C30 -> 538094.63 | D30: ='PL WB'!D30+'PL OZON'!D30 -> 560103.5 | E30: ='PL WB'!E30+'PL OZON'!E30 -> 448883.78 | F30: ='PL WB'!F30+'PL OZON'!F30 -> 201984.28 | G30: ='PL WB'!G30+'PL OZON'!G30 -> 0 | H30: ='PL WB'!H30+'PL OZON'!H30 -> 0 | I30: ='PL WB'!I30+'PL OZON'!I30 -> 0 | J30: ='PL WB'!J30+'PL OZON'!J30 -> 0 | ... N30: ='PL WB'!N30+'PL OZON'!N30 -> 0 | O30: =SUM(C30:N30) -> 1749066.2
A31: в т.ч. Прочие доходы | C31: =SUM('PL WB (нед)'!C31:G31) -> 0 | D31: =SUM('PL WB (нед)'!H31:K31) -> 0 | E31: =SUM('PL WB (нед)'!L31:O31) -> 352.3 | F31: =SUM('PL WB (нед)'!P31:S31) -> 66.37 | G31: =SUM('PL WB (нед)'!T31:X31) -> 0 | H31: =SUM('PL WB (нед)'!Y31:AB31) -> 0 | I31: =SUM('PL WB (нед)'!AC31:AF31) -> 0 | J31: =SUM('PL WB (нед)'!AG31:AK31) -> 0 | K31: =SUM('PL WB (нед)'!AL31:AO31) -> 0 | L31: =SUM('PL WB (нед)'!AP31:AT31) -> 0 | M31: =SUM('PL WB (нед)'!AU31:AX31) -> 0 | N31: =SUM('PL WB (нед)'!AY31:BB31) -> 0 | O31: =SUM(C31:N31) -> 418.67
O32: =SUM(C32:N32) -> 0
A33: Себестоимость | C33: ='PL WB'!C33+'PL OZON'!C33 -> 240350.81 | D33: ='PL WB'!D33+'PL OZON'!D33 -> 221486.72 | E33: ='PL WB'!E33+'PL OZON'!E33 -> 192349.4 | F33: ='PL WB'!F33+'PL OZON'!F33 -> 80990.9 | G33: ='PL WB'!G33+'PL OZON'!G33 -> 0 | H33: ='PL WB'!H33+'PL OZON'!H33 -> 0 | I33: ='PL WB'!I33+'PL OZON'!I33 -> 0 | J33: ='PL WB'!J33+'PL OZON'!J33 -> 0 | ... N33: ='PL WB'!N33+'PL OZON'!N33 -> 0 | O33: =SUM(C33:N33) -> 735177.83
A34: % себестоимости | C34: =C33/C14 -> 0.19814462 | D34: =D33/D15 -> 0.26543253 | E34: =E33/E15 -> 0.27765822 | F34: =F33/F15 -> 0.25850415 | G34: =G33/G15 -> #DIV/0! | H34: =H33/H15 -> #DIV/0! | I34: =I33/I15 -> #DIV/0! | J34: =J33/J15 -> #DIV/0! | K34: =K33/K15 -> #DIV/0! | ... O34: =O33/O15 -> 0.26340802
A36: Валовая прибыль | C36: ='PL WB'!C36+'PL OZON'!C36 -> 576817.35 | D36: ='PL WB'!D36+'PL OZON'!D36 -> 545538.47 | E36: ='PL WB'!E36+'PL OZON'!E36 -> 437558.01 | F36: ='PL WB'!F36+'PL OZON'!F36 -> 201358.56 | G36: ='PL WB'!G36+'PL OZON'!G36 -> 0 | H36: ='PL WB'!H36+'PL OZON'!H36 -> 0 | I36: ='PL WB'!I36+'PL OZON'!I36 -> 0 | J36: ='PL WB'!J36+'PL OZON'!J36 -> 0 | K36: ='PL WB'!K36+'PL OZON'!K36 -> 0 | L36: =L20-L33 -> 0 | M36: =M20-M33 -> 0 | N36: =N20-N33 -> 0 | O36: =SUM(C36:N36) -> 1761272.4
O37: =SUM(C37:N37) -> 0
A38: Расходы | C38: ='PL WB'!C38+'PL OZON'!C38 -> 267226.53 | D38: ='PL WB'!D38+'PL OZON'!D38 -> 199006.69 | E38: ='PL WB'!E38+'PL OZON'!E38 -> 178158.93 | F38: ='PL WB'!F38+'PL OZON'!F38 -> 80056.55 | G38: ='PL WB'!G38+'PL OZON'!G38 -> 0 | H38: ='PL WB'!H38+'PL OZON'!H38 -> 0 | I38: ='PL WB'!I38+'PL OZON'!I38 -> 0 | J38: ='PL WB'!J38+'PL OZON'!J38 -> 0 | ... N38: ='PL WB'!N38+'PL OZON'!N38 -> 0 | O38: =SUM(C38:N38) -> 724448.7
A39: % расходы | C39: =C38/C14 -> 0.2203009 | D39: =D38/D14 -> 0.1750599 | E39: =E38/E14 -> 0.19010047 | F39: =F38/F14 -> 0.19096412 | G39: =G38/G14 -> #DIV/0! | H39: =H38/H14 -> #DIV/0! | I39: =I38/I14 -> #DIV/0! | J39: =J38/J14 -> #DIV/0! | ... N39: =N38/N14 -> #DIV/0!
A40: Логистика | C40: ='PL WB'!C40+'PL OZON'!C40 -> 183264 | D40: ='PL WB'!D40+'PL OZON'!D40 -> 153195 | E40: ='PL WB'!E40+'PL OZON'!E40 -> 134317 | F40: ='PL WB'!F40+'PL OZON'!F40 -> 48829 | G40: ='PL WB'!G40+'PL OZON'!G40 -> 0 | H40: ='PL WB'!H40+'PL OZON'!H40 -> 0 | I40: ='PL WB'!I40+'PL OZON'!I40 -> 0 | J40: ='PL WB'!J40+'PL OZON'!J40 -> 0 | ... N40: ='PL WB'!N40+'PL OZON'!N40 -> 0 | O40: =SUM(C40:N40) -> 519605
A41: Продвижение | C41: ='PL WB'!C41+'PL OZON'!C41 -> 11847 | D41: ='PL WB'!D41+'PL OZON'!D41 -> 7915 | E41: ='PL WB'!E41+'PL OZON'!E41 -> 3217 | F41: ='PL WB'!F41+'PL OZON'!F41 -> 375 | G41: ='PL WB'!G41+'PL OZON'!G41 -> 0 | H41: ='PL WB'!H41+'PL OZON'!H41 -> 0 | I41: ='PL WB'!I41+'PL OZON'!I41 -> 0 | J41: ='PL WB'!J41+'PL OZON'!J41 -> 0 | ... N41: ='PL WB'!N41+'PL OZON'!N41 -> 0 | O41: =SUM(C41:N41) -> 23354
A42: Эквайринг | C42: ='PL WB'!C42+'PL OZON'!C42 -> 3613 | D42: ='PL WB'!D42+'PL OZON'!D42 -> 2391 | E42: ='PL WB'!E42+'PL OZON'!E42 -> 1321 | F42: ='PL WB'!F42+'PL OZON'!F42 -> 773 | G42: ='PL WB'!G42+'PL OZON'!G42 -> 0 | H42: ='PL WB'!H42+'PL OZON'!H42 -> 0 | I42: ='PL WB'!I42+'PL OZON'!I42 -> 0 | J42: ='PL WB'!J42+'PL OZON'!J42 -> 0 | ... N42: ='PL WB'!N42+'PL OZON'!N42 -> 0 | O42: =SUM(C42:N42) -> 8098
A43: Хранение | C43: ='PL WB'!C43+'PL OZON'!C43 -> 53680.72 | D43: ='PL WB'!D43+'PL OZON'!D43 -> 35505.69 | E43: ='PL WB'!E43+'PL OZON'!E43 -> 39303.93 | F43: ='PL WB'!F43+'PL OZON'!F43 -> 30039.55 | G43: ='PL WB'!G43+'PL OZON'!G43 -> 0 | H43: ='PL WB'!H43+'PL OZON'!H43 -> 0 | I43: ='PL WB'!I43+'PL OZON'!I43 -> 0 | J43: ='PL WB'!J43+'PL OZON'!J43 -> 0 | ... N43: ='PL WB'!N43+'PL OZON'!N43 -> 0 | O43: =SUM(C43:N43) -> 158529.89
A44: Штрафы | C44: ='PL WB'!C44+'PL OZON'!C44 -> 741 | D44: ='PL WB'!D44+'PL OZON'!D44 -> 0 | E44: ='PL WB'!E44+'PL OZON'!E44 -> 0 | F44: ='PL WB'!F44+'PL OZON'!F44 -> 40 | G44: ='PL WB'!G44+'PL OZON'!G44 -> 0 | H44: ='PL WB'!H44+'PL OZON'!H44 -> 0 | I44: ='PL WB'!I44+'PL OZON'!I44 -> 0 | J44: ='PL WB'!J44+'PL OZON'!J44 -> 0 | ... N44: ='PL WB'!N44+'PL OZON'!N44 -> 0 | O44: =SUM(C44:N44) -> 781
A45: Платная приемка | C45: ='PL WB'!C45+'PL OZON'!C45 -> 14080.81 | D45: ='PL WB'!D45+'PL OZON'!D45 -> 0 | E45: ='PL WB'!E45+'PL OZON'!E45 -> 0 | F45: ='PL WB'!F45+'PL OZON'!F45 -> 0 | G45: ='PL WB'!G45+'PL OZON'!G45 -> 0 | H45: ='PL WB'!H45+'PL OZON'!H45 -> 0 | I45: ='PL WB'!I45+'PL OZON'!I45 -> 0 | J45: ='PL WB'!J45+'PL OZON'!J45 -> 0 | ... N45: ='PL WB'!N45+'PL OZON'!N45 -> 0 | O45: =SUM(C45:N45) -> 14080.81
...

Sheet PL WB (нед)
A1: Голубым выделены строки, которые заполняем! Заполняем эту вкладку, формулы не трогаем! Если добавляете строки - добавляете на всех листах PL и СF | C1: 1 | D1: 2 | E1: 3 | F1: 4 | G1: 5 | H1: 6 | I1: 7 | J1: 8 | K1: 9 | L1: 10 | M1: 11 | N1: 12 | O1: 13 | P1: 14 | Q1: 15 | R1: 16 | S1: 17 | T1: 18 | U1: 19 | V1: 20 | W1: 21 | X1: 22 | Y1: 23 | Z1: 24 | AA1: 25 | AB1: 26 | AC1: 27 | AD1: 28 | AE1: 29 | AF1: 30 | AG1: 31 | AH1: 32 | AI1: 33 | AJ1: 34 | AK1: 35 | AL1: 36 | AM1: 37 | AN1: 38 | AO1: 39 | AP1: 40 | AQ1: 41 | AR1: 42 | AS1: 43 | AT1: 44 | AU1: 45 | AV1: 46 | AW1: 47 | AX1: 48 | AY1: 49 | AZ1: 50 | BA1: 51 | BB1: 52 | BC1: Остаток года
A2: Прибыли и убытки, еженедельно | C2: Январь | H2: Февраль | L2: Март | P2: Апрель | T2: Май | Y2: Июнь | AC2: Июль | AG2: Август | AL2: Сентябрь | AP2: Октябрь | AU2: Ноябрь | AY2: Декабрь
C3: 01.01-04.01 | D3: 05.01-11.01 | E3: 12.01-18.01 | F3: 19.01-25.01 | G3: 26.01-01.02 | H3: 02.02-08.02 | I3: 09.02-15.02 | J3: 16.02-22.02 | K3: 23.02-01.03 | L3: 02.03-08.03 | M3: 09.03-15.03 | N3: 16.03-22.03 | O3: 23.03-29.03 | P3: 30.03-05.04 | Q3: 06.04-12.04 | R3: 13.04-19.04
A4: Товарооборот
A5: Остаток товара по цене закупки | C5: 1331789.1 | D5: =C12 -> 1514984.9 | E5: =D12 -> 1480919.9 | F5: =E12 -> 1434587.7 | G5: =F12 -> 1394134.5 | H5: =G12 -> 1355494.1 | I5: =H12 -> 1309516.1 | J5: =I12 -> 1263879 | K5: =J12 -> 1224679.8 | ... BB5: =BA12 -> 960491.03 | BC5: 1331789.1
A7: Продажи шт | C7: 0 | D7: 1202 | E7: 0 | F7: 0 | G7: 0 | H7: 0 | I7: 0 | J7: 0 | K7: 0 | L7: 0 | M7: 0 | N7: 0 | O7: 0 | P7: 0 | Q7: 0 | R7: 0 | S7: 0 | T7: 0 | U7: 0 | V7: 0 | W7: 0 | X7: 0 | Y7: 0 | Z7: 0 | AA7: 0 | AB7: 0 | AC7: 0 | AD7: 0 | AE7: 0 | AF7: 0 | AG7: 0 | AH7: 0 | AI7: 0 | AJ7: 0 | AK7: 0 | AL7: 0 | AM7: 0 | AN7: 0 | AO7: 0 | AP7: 0 | AQ7: 0 | AR7: 0 | AS7: 0 | AT7: 0 | AU7: 0 | AV7: 0 | AW7: 0 | AX7: 0 | AY7: 0 | AZ7: 0 | BA7: 0 | BB7: 0 | BC7: 484 | BD7: =SUM(C7:BC7) -> 4476
A8: Отгрузки по себестоимости | C8: =C33 -> 9203 | D8: =D33 -> 34065 | E8: =E33 -> 46332.16 | F8: =F33 -> 40453.2 | G8: =G33 -> 38640.45 | H8: =H33 -> 45978 | I8: =I33 -> 45637.06 | J8: =J33 -> 39199.24 | ... BC8: =BC33 -> 0 | BD8: =SUM(C8:BC8) -> 563696.83
BD9: =SUM(C9:BC9) -> 0
A10: Поступление товара, р | C10: 192398.77 | BD10: =SUM(C10:BC10) -> 192398.77
A11: Поступление товара, шт | C11: 1294 | BD11: =SUM(C11:BC11) -> 1294
A12: Доступно на складе по цене закупки | C12: =C10-C8+C5 -> 1514984.9 | D12: =D10-D8+D5 -> 1480919.9 | E12: =E10-E8+E5 -> 1434587.7 | F12: =F10-F8+F5 -> 1394134.5 | G12: =G10-G8+G5 -> 1355494.1 | H12: =H10-H8+H5 -> 1309516.1 | I12: =I10-I8+I5 -> 1263879 | J12: =J10-J8+J5 -> 1224679.8 | ... BC12: =BC10-BC8+BC5 -> 1331789.1 | BD12: =SUM(C12:BC12)/52.5 -> 1054175
A13: Доступно на складе, шт | C13: =9072-C7-C27+C11+C23 -> 10178 | D13: =C13-D7-D27+D11+D23 -> 9935 | E13: =D13-E7-E27+E11+E23 -> 9594 | F13: =E13-F7-F27+F11+F23 -> 9299 | G13: =F13-G7-G27+G11+G23 -> 9007 | H13: =G13-H7-H27+H11+H23 -> 8665 | I13: =H13-I7-I27+I11+I23 -> 8334 | J13: =I13-J7-J27+J11+J23 -> 8025 | K13: =J13-K7-K27+K11+K23 -> 7678 | ... BB13: =BA13-BB7-BB27+BB11+BB23 -> 5897 | BC13: 9072 | BD13: =SUM(C13:BC13)/53.5 -> 6497.4953
A14: Продано товаров WB по цене в карточке | C14: 48841 | D14: 164469 | E14: 219043 | F14: 192988 | G14: 188915 | H14: 218237 | I14: 231995 | J14: 209378 | K14: 219789 | L14: 210110 | M14: 193338 | N14: 193369 | O14: 175517 | P14: 132809 | Q14: 108682 | R14: 103393 | BD14: =SUM(C14:BC14) -> 2810873
A15: Продано товаров WB ВБ реализовал-ПРОДАЖИ | C15: 34445 | D15: 112779 | E15: 147256 | F15: 131182 | G15: 126111 | H15: 142988 | I15: 152014 | J15: 136874 | K15: 145168 | L15: 142232 | M15: 131792 | N15: 131955 | O15: 121928 | P15: 93126 | Q15: 75500 | R15: 70341 | BD15: =SUM(C15:BC15) -> 1895691
BD16: =SUM(C16:BC16) -> 0
A17: Комиссия ВБ | C17: =C14-C20 -> 14515 | D17: =D14-D20 -> 49977.42 | E17: =E14-E20 -> 66083.96 | F17: =F14-F20 -> 58319.03 | G17: =G14-G20 -> 56648.43 | H17: =H14-H20 -> 66021.4 | I17: =I14-I20 -> 71141.23 | J17: =J14-J20 -> 65610.81 | ... BC17: =BC14-BC20 -> 0 | BD17: =SUM(C17:BC17) -> 870568.78
A18: % комиссии | C18: =C17/C14 -> 0.29718884 | D18: =D17/D14 -> 0.30387137 | E18: =E17/E14 -> 0.30169401 | F18: =F17/F14 -> 0.30218993 | G18: =G17/G14 -> 0.299862 | H18: =H17/H14 -> 0.30252157 | I18: =I17/I14 -> 0.30664984 | J18: =J17/J14 -> 0.31336057 | ... BC18: =BC17/BC14 -> #DIV/0! | BD18: =SUM(C18:BC18) -> #DIV/0!
BD19: =SUM(C19:BC19) -> 0
A20: Выручка от реализации (к перечислению за товар), руб | C20: 34326 | D20: 114491.58 | E20: 152959.04 | F20: 134668.97 | G20: 132266.57 | H20: 152215.6 | I20: 160853.77 | J20: 143767.19 | K20: 150354.63 | L20: 142702.76 | M20: 131929.45 | N20: 132469.98 | O20: 120447.22 | P20: 91343.06 | Q20: 74011.04 | R20: 71497.36 | BD20: =SUM(C20:BC20) -> 1940304.2
BD21: =SUM(C21:BC21) -> 0
A22: Возвраты, руб | M22: 708 | N22: 1515 | O22: 2067 | P22: 1526 | Q22: 519 | BD22: =SUM(C22:BC22) -> 6335
A23: Возвраты, шт | M23: 1 | N23: 3 | O23: 3 | P23: 3 | Q23: 1 | BD23: =SUM(C23:BC23) -> 11
A24: % возвратов | C24: =C22/(C14-C22) -> 0 | D24: =D22/(D14-D22) -> 0 | E24: =E22/(E14-E22) -> 0 | F24: =F22/(F14-F22) -> 0 | G24: =G22/(G14-G22) -> 0 | H24: =H22/(H14-H22) -> 0 | I24: =I22/(I14-I22) -> 0 | J24: =J22/(J14-J22) -> 0 | ... BD24: =BD22/(BD14-BD22) -> 0.0022588391
A26: Брак, руб | BD26: =SUM(C26:BB26) -> 0
A27: Брак, шт | Q27: 1 | Z27: 2 | AA27: 1 | BD27: =SUM(C27:BC27) -> 4
A28: % брака | C28: =C27/C7 -> 0 | D28: =D27/D7 -> 0 | E28: =E27/E7 -> 0 | F28: =F27/F7 -> 0 | G28: =G27/G7 -> 0 | H28: =H27/H7 -> 0 | I28: =I27/I7 -> 0 | J28: =J27/J7 -> 0 | ... BC28: =BC27/BC7 -> #DIV/0!
BD29: =SUM(C29:BC29) -> 0
A30: Поступление на счет от ВБ | C30: =C20+C31-SUM(C40:C45)-C42 -> 26503.58 | D30: =D20+D31-SUM(D40:D45)-D42 -> 90050.43 | E30: =E20+E31-SUM(E40:E45)-E42 -> 122170.28 | F30: =F20+F31-SUM(F40:F45)-F41 -> 89431.22 | G30: =G20+G31-SUM(G40:G45)-G41 -> 95453.12 | H30: =H20+H31-SUM(H40:H45)-H41 -> 121464.16 | I30: =I20+I31-SUM(I40:I45)-I41 -> 131775.46 | J30: =J20+J31-SUM(J40:J45)-J41 -> 114834.31 | K30: =K20+K31-SUM(K40:K45)-K42 -> 119567.57 | L30: =L20+L31-SUM(L40:L45)-L42 -> 107669.87 | M30: =M20+M31-SUM(M40:M45)-M42 -> 99302.4 | N30: =N20+N31-SUM(N40:N45)-N42 -> 94859.58 | O30: =O20+O31-SUM(O40:O45)-O42 -> 88943.93 | P30: =P20+P31-SUM(P40:P45)-P42 -> 67847.65 | Q30: =Q20+Q31-SUM(Q40:Q45)-Q42 -> 53886.29 | R30: =R20+R31-SUM(R40:R45)-R42 -> 52150.34 | ... BC30: =BC20+BC31-SUM(BC40:BC45)-BC42 -> 0 | BD30: =SUM(C30:BC30) -> 1475910.2
A31: в т.ч. Прочие доходы | M31: 153.05 | N31: 128.25 | O31: 71 | P31: 11 | R31: 55.37 | BD31: =SUM(C31:BC31) -> 418.67
BD32: =SUM(C32:BC32) -> 0
A33: Себестоимость | C33: 9203 | D33: 34065 | E33: 46332.16 | F33: 40453.2 | G33: 38640.45 | H33: 45978 | I33: 45637.06 | J33: 39199.24 | K33: 40766.42 | L33: 39771 | M33: 38202.46 | N33: 45982.75 | O33: 36408.19 | P33: 24503.54 | Q33: 19559.56 | R33: 18994.8 | BD33: =SUM(C33:BC33) -> 563696.83
A34: % себестоимости в цене | C34: =C33/C14 -> 0.18842776 | D34: =D33/D14 -> 0.2071211 | E34: =E33/E14 -> 0.21152084 | F34: =F33/F14 -> 0.20961511 | G34: =G33/G14 -> 0.20453881 | H34: =H33/H14 -> 0.21067922 | I34: =I33/I14 -> 0.19671571 | J34: =J33/J14 -> 0.18721757 | ... BD34: =BD33/BD14 -> 0.20054155
BD35: =SUM(C35:BC35) -> 0
A36: Валовая прибыль | C36: =C20-C33 -> 25123 | D36: =D20-D33 -> 80426.58 | E36: =E20-E33 -> 106626.88 | F36: =F20-F33 -> 94215.77 | G36: =G20-G33 -> 93626.12 | H36: =H20-H33 -> 106237.6 | I36: =I20-I33 -> 115216.71 | J36: =J20-J33 -> 104567.95 | ... BC36: =BC20-BC33 -> 0 | BD36: =SUM(C36:BC36) -> 1376607.4
BD37: =SUM(C37:BC37) -> 0
A38: Расходы | C38: =SUM(C40:C51) -> 7822.42 | D38: =SUM(D40:D51) -> 24441.15 | E38: =SUM(E40:E51) -> 30788.76 | F38: =SUM(F40:F51) -> 45237.75 | G38: =SUM(G40:G51) -> 36813.45 | H38: =SUM(H40:H51) -> 30751.44 | I38: =SUM(I40:I51) -> 29078.31 | J38: =SUM(J40:J51) -> 28932.88 | ... BC38: =SUM(BC40:BC51) -> 0 | BD38: =SUM(C38:BC38) -> 464812.7
A39: % расходы | C39: =C38/C14 -> 0.16016093 | D39: =D38/D14 -> 0.14860642 | E39: =E38/E14 -> 0.14056035 | F39: =F38/F14 -> 0.23440706 | G39: =G38/G14 -> 0.1948678 | H39: =H38/H14 -> 0.14090846 | I39: =I38/I14 -> 0.12534024 | J39: =J38/J14 -> 0.13818491 | ... BC39: =BC38/BC14 -> #DIV/0!
A40: Логистика ВБ | C40: 4739 | D40: 19181 | E40: 25734 | F40: 26309 | G40: 31507 | H40: 24880 | I40: 23367 | J40: 23404 | K40: 24588 | L40: 25825 | M40: 23828 | N40: 29199 | O40: 23313 | P40: 15438 | Q40: 12164 | R40: 11631 | BD40: =SUM(C40:BC40) -> 345107
A41: Продвижение ВБ (взаимозачет) | BD41: =SUM(C41:BC41) -> 0
A42: Эквайринг ВБ | BD42: =SUM(C42:BC42) -> 0
...

Sheet PL WB
A1: Заполняем PL и CF еженедельный!
A2: Прибыли и убытки | C2: 2025
C3: Январь | D3: Февраль | E3: Март | F3: Апрель | G3: Май | H3: Июнь | I3: Июль | J3: Август | K3: Сентябрь | L3: Октябрь | M3: Ноябрь | N3: Декабрь
A4: Товарооборот | O4: =SUM(C4:N4) -> 0
A5: Остаток товара по цене закупки | C5: ='PL WB (нед)'!C5 -> 1331789.1 | D5: =C12 -> 1355494.1 | E5: =D12 -> 1183913.3 | F5: =E12 -> 1023548.9 | G5: =F12 -> 960491.03 | H5: =G12 -> 960491.03 | I5: =H12 -> 960491.03 | J5: =I12 -> 960491.03 | K5: =J12 -> 960491.03 | ... N5: =M12 -> 960491.03 | O5: =SUM(C5:N5)/12 -> 1048222.8
O6: =SUM(C6:N6) -> 0
B7: Продажи шт | C7: =SUM('PL WB (нед)'!C7:G7) -> 1359 | D7: =SUM('PL WB (нед)'!H7:K7) -> 1329 | E7: =SUM('PL WB (нед)'!L7:O7) -> 1307 | F7: =SUM('PL WB (нед)'!P7:S7) -> 481 | G7: =SUM('PL WB (нед)'!T7:X7) -> 0 | H7: =SUM('PL WB (нед)'!Y7:AB7) -> 0 | I7: =SUM('PL WB (нед)'!AC7:AF7) -> 0 | J7: =SUM('PL WB (нед)'!AG7:AK7) -> 0 | K7: =SUM('PL WB (нед)'!AL7:AO7) -> 0 | L7: =SUM('PL WB (нед)'!AP7:AT7) -> 0 | M7: =SUM('PL WB (нед)'!AU7:AX7) -> 0 | N7: =SUM('PL WB (нед)'!AY7:BC7) -> 0 | O7: =SUM(C7:N7) -> 4476
B8: Отгрузки по себестоимости | C8: =C33 -> 168693.81 | D8: =D33 -> 171580.72 | E8: =E33 -> 160364.4 | F8: =F33 -> 63057.9 | G8: =G33 -> 0 | H8: =H33 -> 0 | I8: =I33 -> 0 | J8: =J33 -> 0 | ... N8: =N33 -> 0 | O8: =SUM(C8:N8) -> 563696.83
O9: =SUM(C9:N9) -> 0
A10: Поступление товара, р | C10: =SUM('PL WB (нед)'!C10:G10) -> 192398.77 | D10: =SUM('PL WB (нед)'!H10:K10) -> 0 | E10: =SUM('PL WB (нед)'!L10:O10) -> 0 | F10: =SUM('PL WB (нед)'!P10:S10) -> 0 | G10: =SUM('PL WB (нед)'!T10:X10) -> 0 | H10: =SUM('PL WB (нед)'!Y10:AB10) -> 0 | I10: =SUM('PL WB (нед)'!AC10:AF10) -> 0 | J10: =SUM('PL WB (нед)'!AG10:AK10) -> 0 | K10: =SUM('PL WB (нед)'!AL10:AO10) -> 0 | L10: =SUM('PL WB (нед)'!AP10:AT10) -> 0 | M10: =SUM('PL WB (нед)'!AU10:AX10) -> 0 | N10: =SUM('PL WB (нед)'!AY10:BC10) -> 0 | O10: =SUM(C10:N10) -> 192398.77
A11: Поступление товара, шт | C11: =SUM('PL WB (нед)'!C11:G11) -> 1294 | D11: =SUM('PL WB (нед)'!H11:K11) -> 0 | E11: =SUM('PL WB (нед)'!L11:O11) -> 0 | F11: =SUM('PL WB (нед)'!P11:S11) -> 0 | G11: =SUM('PL WB (нед)'!T11:X11) -> 0 | H11: =SUM('PL WB (нед)'!Y11:AB11) -> 0 | I11: =SUM('PL WB (нед)'!AC11:AF11) -> 0 | J11: =SUM('PL WB (нед)'!AG11:AK11) -> 0 | K11: =SUM('PL WB (нед)'!AL11:AO11) -> 0 | L11: =SUM('PL WB (нед)'!AP11:AT11) -> 0 | M11: =SUM('PL WB (нед)'!AU11:AX11) -> 0 | N11: =SUM('PL WB (нед)'!AY11:BC11) -> 0 | O11: =SUM(C11:N11) -> 1294
A12: Доступно на складе по цене закупки | C12: =C10-C8+C5 -> 1355494.1 | D12: =D10-D8+D5 -> 1183913.3 | E12: =E10-E8+E5 -> 1023548.9 | F12: =F10-F8+F5 -> 960491.03 | G12: =G10-G8+G5 -> 960491.03 | H12: =H10-H8+H5 -> 960491.03 | I12: =I10-I8+I5 -> 960491.03 | J12: =J10-J8+J5 -> 960491.03 | ... N12: =N10-N8+N5 -> 960491.03 | O12: =SUM(C12:N12) -> 12207376
A13: Доступно на складе, шт | C13: ='PL WB (нед)'!G13 -> 9007 | D13: =C13-D7-D27+D11+D23 -> 7678 | E13: =D13-E7-E27+E11+E23 -> 6378 | F13: =E13-F7-F27+F11+F23 -> 5900 | G13: =F13-G7-G27+G11+G23 -> 5900 | H13: =G13-H7-H27+H11+H23 -> 5897 | I13: =H13-I7-I27+I11+I23 -> 5897 | J13: =I13-J7-J27+J11+J23 -> 5897 | K13: =J13-K7-K27+K11+K23 -> 5897 | ... N13: =M13-N7-N27+N11+N23 -> 5897 | O13: =SUM(C13:N13) -> 76142
A14: Продано товаров WB по цене в карточке | C14: =SUM('PL WB (нед)'!C14:G14) -> 814256 | D14: =SUM('PL WB (нед)'!H14:K14) -> 879399 | E14: =SUM('PL WB (нед)'!L14:O14) -> 772334 | F14: =SUM('PL WB (нед)'!P14:S14) -> 344884 | G14: =SUM('PL WB (нед)'!T14:X14) -> 0 | H14: =SUM('PL WB (нед)'!Y14:AB14) -> 0 | I14: =SUM('PL WB (нед)'!AC14:AF14) -> 0 | J14: =SUM('PL WB (нед)'!AG14:AK14) -> 0 | K14: =SUM('PL WB (нед)'!AL14:AO14) -> 0 | L14: =SUM('PL WB (нед)'!AP14:AT14) -> 0 | M14: =SUM('PL WB (нед)'!AU14:AX14) -> 0 | N14: =SUM('PL WB (нед)'!AY14:BC14) -> 0 | O14: =SUM(C14:N14) -> 2810873
A15: Продано товаров WB ВБ реализовал-ПРОДАЖИ | C15: =SUM('PL WB (нед)'!C15:G15) -> 551773 | D15: =SUM('PL WB (нед)'!H15:K15) -> 577044 | E15: =SUM('PL WB (нед)'!L15:O15) -> 527907 | F15: =SUM('PL WB (нед)'!P15:S15) -> 238967 | G15: =SUM('PL WB (нед)'!T15:X15) -> 0 | H15: =SUM('PL WB (нед)'!Y15:AB15) -> 0 | I15: =SUM('PL WB (нед)'!AC15:AF15) -> 0 | J15: =SUM('PL WB (нед)'!AG15:AK15) -> 0 | K15: =SUM('PL WB (нед)'!AL15:AO15) -> 0 | L15: =SUM('PL WB (нед)'!AP15:AT15) -> 0 | M15: =SUM('PL WB (нед)'!AU15:AX15) -> 0 | N15: =SUM('PL WB (нед)'!AY15:BC15) -> 0 | O15: =SUM(C15:N15) -> 1895691
O16: =SUM(C16:N16) -> 0
A17: Комиссия ВБ | C17: =C14-C20 -> 245543.84 | D17: =D14-D20 -> 272207.81 | E17: =E14-E20 -> 244784.59 | F17: =F14-F20 -> 108032.54 | G17: =G14-G20 -> 0 | H17: =H14-H20 -> 0 | I17: =I14-I20 -> 0 | J17: =J14-J20 -> 0 | ... M17: =M14-M20 -> 0 | N17: =N15-N20 -> 0 | O17: =SUM(C17:N17) -> 870568.78
A18: % комиссии | C18: =C17/C14 -> 0.30155607 | D18: =D17/D15 -> 0.471728 | E18: =E17/E15 -> 0.46368885 | F18: =F17/F15 -> 0.45208142 | G18: =G17/G15 -> #DIV/0! | H18: =H17/H15 -> #DIV/0! | I18: =I17/I15 -> #DIV/0! | J18: =J17/J15 -> #DIV/0! | K18: =K17/K15 -> #DIV/0! | ... N18: =N17/N15 -> #DIV/0! | O18: =SUM(C18:N18) -> #DIV/0!
O19: =SUM(C19:N19) -> 0
A20: Выручка от реализации (к перечислению за товар), руб | C20: =SUM('PL WB (нед)'!C20:G20) -> 568712.16 | D20: =SUM('PL WB (нед)'!H20:K20) -> 607191.19 | E20: =SUM('PL WB (нед)'!L20:O20) -> 527549.41 | F20: =SUM('PL WB (нед)'!P20:S20) -> 236851.46 | G20: =SUM('PL WB (нед)'!T20:X20) -> 0 | H20: =SUM('PL WB (нед)'!Y20:AB20) -> 0 | I20: =SUM('PL WB (нед)'!AC20:AF20) -> 0 | J20: =SUM('PL WB (нед)'!AG20:AK20) -> 0 | K20: =SUM('PL WB (нед)'!AL20:AO20) -> 0 | L20: =SUM('PL WB (нед)'!AP20:AT20) -> 0 | M20: =SUM('PL WB (нед)'!AU20:AX20) -> 0 | N20: =SUM('PL WB (нед)'!AY20:BC20) -> 0 | O20: =SUM(C20:N20) -> 1940304.2
O21: =SUM(C21:N21) -> 0
A22: Возвраты, руб | C22: =SUM('PL WB (нед)'!C22:G22) -> 0 | D22: =SUM('PL WB (нед)'!H22:K22) -> 0 | E22: =SUM('PL WB (нед)'!L22:O22) -> 4290 | F22: =SUM('PL WB (нед)'!P22:S22) -> 2045 | G22: =SUM('PL WB (нед)'!T22:X22) -> 0 | H22: =SUM('PL WB (нед)'!Y22:AB22) -> 0 | I22: =SUM('PL WB (нед)'!AC22:AF22) -> 0 | J22: =SUM('PL WB (нед)'!AG22:AK22) -> 0 | K22: =SUM('PL WB (нед)'!AL22:AO22) -> 0 | L22: =SUM('PL WB (нед)'!AP22:AT22) -> 0 | M22: =SUM('PL WB (нед)'!AU22:AX22) -> 0 | N22: =SUM('PL WB (нед)'!AY22:BC22) -> 0 | O22: =SUM(C22:N22) -> 6335
A23: Возвраты, шт | C23: =SUM('PL WB (нед)'!C23:G23) -> 0 | D23: =SUM('PL WB (нед)'!H23:K23) -> 0 | E23: =SUM('PL WB (нед)'!L23:O23) -> 7 | F23: =SUM('PL WB (нед)'!P23:S23) -> 4 | G23: =SUM('PL WB (нед)'!T23:X23) -> 0 | H23: =SUM('PL WB (нед)'!Y23:AB23) -> 0 | I23: =SUM('PL WB (нед)'!AC23:AF23) -> 0 | J23: =SUM('PL WB (нед)'!AG23:AK23) -> 0 | K23: =SUM('PL WB (нед)'!AL23:AO23) -> 0 | L23: =SUM('PL WB (нед)'!AP23:AT23) -> 0 | M23: =SUM('PL WB (нед)'!AU23:AX23) -> 0 | N23: =SUM('PL WB (нед)'!AY23:BC23) -> 0 | O23: =SUM(C23:N23) -> 11
A24: % возвратов | C24: =C22/C14 -> 0 | D24: =D22/D20 -> 0 | E24: =E22/E20 -> 0.0081319397 | F24: =F22/F20 -> 0.0086341034 | G24: =G22/G20 -> #DIV/0! | H24: =H22/H20 -> #DIV/0! | I24: =I22/I20 -> #DIV/0! | J24: =J22/J20 -> #DIV/0! | K24: =K22/K20 -> #DIV/0! | ... O24: =O22/O20 -> 0.0032649519
A26: Брак, руб
A27: Брак, шт | C27: =SUM('PL WB (нед)'!C27:G27) -> 0 | D27: =SUM('PL WB (нед)'!H27:K27) -> 0 | E27: =SUM('PL WB (нед)'!L27:O27) -> 0 | F27: =SUM('PL WB (нед)'!P27:S27) -> 1 | G27: =SUM('PL WB (нед)'!T27:X27) -> 0 | H27: =SUM('PL WB (нед)'!Y27:AB27) -> 3 | I27: =SUM('PL WB (нед)'!AC27:AF27) -> 0 | J27: =SUM('PL WB (нед)'!AG27:AK27) -> 0 | K27: =SUM('PL WB (нед)'!AL27:AO27) -> 0 | L27: =SUM('PL WB (нед)'!AP27:AT27) -> 0 | M27: =SUM('PL WB (нед)'!AU27:AX27) -> 0 | N27: =SUM('PL WB (нед)'!AY27:BB27) -> 0
A28: % брака | C28: =C27/C7 -> 0 | D28: =D27/D7 -> 0 | E28: =E27/E7 -> 0 | F28: =F27/F7 -> 0.0020790021 | G28: =G27/G7 -> #DIV/0! | H28: =H27/H7 -> #DIV/0! | I28: =I27/I7 -> #DIV/0! | J28: =J27/J7 -> #DIV/0! | ... N28: =N27/N7 -> #DIV/0!
A30: Поступление на счет от ВБ | C30: =C20+C31-SUM(C40:C45)-C42 -> 423608.63 | D30: =D20+D31-SUM(D40:D45)-D42 -> 487641.5 | E30: =E20+E31-SUM(E40:E45)-E42 -> 390775.78 | F30: =F20+F31-SUM(F40:F45)-F42 -> 173884.28 | G30: =G20+G31-SUM(G40:G45)-G42 -> 0 | H30: =H20+H31-SUM(H40:H45)-H42 -> 0 | I30: =I20+I31-SUM(I40:I45)-I42 -> 0 | J30: =J20+J31-SUM(J40:J45)-J42 -> 0 | ... N30: =N20+N31-SUM(N40:N45)-N42 -> 0 | O30: =SUM(C30:N30) -> 1475910.2
A31: в т.ч. Прочие доходы | C31: =SUM('PL WB (нед)'!C31:G31) -> 0 | D31: =SUM('PL WB (нед)'!H31:K31) -> 0 | E31: =SUM('PL WB (нед)'!L31:O31) -> 352.3 | F31: =SUM('PL WB (нед)'!P31:S31) -> 66.37 | G31: =SUM('PL WB (нед)'!T31:X31) -> 0 | H31: =SUM('PL WB (нед)'!Y31:AB31) -> 0 | I31: =SUM('PL WB (нед)'!AC31:AF31) -> 0 | J31: =SUM('PL WB (нед)'!AG31:AK31) -> 0 | K31: =SUM('PL WB (нед)'!AL31:AO31) -> 0 | L31: =SUM('PL WB (нед)'!AP31:AT31) -> 0 | M31: =SUM('PL WB (нед)'!AU31:AX31) -> 0 | N31: =SUM('PL WB (нед)'!AY31:BB31) -> 0
A33: Себестоимость | C33: =SUM('PL WB (нед)'!C33:G33) -> 168693.81 | D33: =SUM('PL WB (нед)'!H33:K33) -> 171580.72 | E33: =SUM('PL WB (нед)'!L33:O33) -> 160364.4 | F33: =SUM('PL WB (нед)'!P33:S33) -> 63057.9 | G33: =SUM('PL WB (нед)'!T33:X33) -> 0 | H33: =SUM('PL WB (нед)'!Y33:AB33) -> 0 | I33: =SUM('PL WB (нед)'!AC33:AF33) -> 0 | J33: =SUM('PL WB (нед)'!AG33:AK33) -> 0 | K33: =SUM('PL WB (нед)'!AL33:AO33) -> 0 | L33: =SUM('PL WB (нед)'!AP33:AT33) -> 0 | M33: =SUM('PL WB (нед)'!AU33:AX33) -> 0 | N33: =SUM('PL WB (нед)'!AY33:BC33) -> 0 | O33: =SUM('PL WB (нед)'!AZ33:BD33) -> 563696.83
A34: % себестоимости | C34: =C33/C14 -> 0.2071754 | D34: =D33/D15 -> 0.29734426 | E34: =E33/E15 -> 0.30377396 | F34: =F33/F15 -> 0.26387702 | G34: =G33/G15 -> #DIV/0! | H34: =H33/H15 -> #DIV/0! | I34: =I33/I15 -> #DIV/0! | J34: =J33/J15 -> #DIV/0! | K34: =K33/K15 -> #DIV/0! | ... O34: =O33/O15 -> 0.29735692
A36: Валовая прибыль | C36: =C20-C33 -> 400018.35 | D36: =D20-D33 -> 435610.47 | E36: =E20-E33 -> 367185.01 | F36: =F20-F33 -> 173793.56 | G36: =G20-G33 -> 0 | H36: =H20-H33 -> 0 | I36: =I20-I33 -> 0 | J36: =J20-J33 -> 0 | ... O36: =O20-O33 -> 1376607.4
A38: Расходы | C38: =SUM(C40:C51) -> 145103.53 | D38: =SUM(D40:D51) -> 119549.69 | E38: =SUM(E40:E51) -> 137125.93 | F38: =SUM(F40:F51) -> 63033.55 | G38: =SUM(G40:G51) -> 0 | H38: =SUM(H40:H51) -> 0 | I38: =SUM(I40:I51) -> 0 | J38: =SUM(J40:J51) -> 0 | ... N38: =SUM(N40:N51) -> 0 | O38: =SUM(C38:N38) -> 464812.7
A39: % расходы | C39: =C38/C14 -> 0.17820382 | D39: =D38/D14 -> 0.13594476 | E39: =E38/E14 -> 0.17754745 | F39: =F38/F14 -> 0.18276739 | G39: =G38/G14 -> #DIV/0! | H39: =H38/H14 -> #DIV/0! | I39: =I38/I14 -> #DIV/0! | J39: =J38/J14 -> #DIV/0! | ... O39: =O38/O14 -> 0.1653624
A40: Логистика ВБ | C40: =SUM('PL WB (нед)'!C40:G40) -> 107470 | D40: =SUM('PL WB (нед)'!H40:K40) -> 96239 | E40: =SUM('PL WB (нед)'!L40:O40) -> 102165 | F40: =SUM('PL WB (нед)'!P40:S40) -> 39233 | G40: =SUM('PL WB (нед)'!T40:X40) -> 0 | H40: =SUM('PL WB (нед)'!Y40:AB40) -> 0 | I40: =SUM('PL WB (нед)'!AC40:AF40) -> 0 | J40: =SUM('PL WB (нед)'!AG40:AK40) -> 0 | K40: =SUM('PL WB (нед)'!AL40:AO40) -> 0 | L40: =SUM('PL WB (нед)'!AP40:AT40) -> 0 | M40: =SUM('PL WB (нед)'!AU40:AX40) -> 0 | N40: =SUM('PL WB (нед)'!AY40:BC40) -> 0 | O40: =SUM(C40:N40) -> 345107
A41: Продвижение ВБ (взаимозачет) | C41: =SUM('PL WB (нед)'!C41:G41) -> 0 | D41: =SUM('PL WB (нед)'!H41:K41) -> 0 | E41: =SUM('PL WB (нед)'!L41:O41) -> 0 | F41: =SUM('PL WB (нед)'!P41:S41) -> 0 | G41: =SUM('PL WB (нед)'!T41:X41) -> 0 | H41: =SUM('PL WB (нед)'!Y41:AB41) -> 0 | I41: =SUM('PL WB (нед)'!AC41:AF41) -> 0 | J41: =SUM('PL WB (нед)'!AG41:AK41) -> 0 | K41: =SUM('PL WB (нед)'!AL41:AO41) -> 0 | L41: =SUM('PL WB (нед)'!AP41:AT41) -> 0 | M41: =SUM('PL WB (нед)'!AU41:AX41) -> 0 | N41: =SUM('PL WB (нед)'!AY41:BC41) -> 0 | O41: =SUM(C41:N41) -> 0
A42: Эквайринг ВБ | C42: =SUM('PL WB (нед)'!C42:G42) -> 0 | D42: =SUM('PL WB (нед)'!H42:K42) -> 0 | E42: =SUM('PL WB (нед)'!L42:O42) -> 0 | F42: =SUM('PL WB (нед)'!P42:S42) -> 0 | G42: =SUM('PL WB (нед)'!T42:X42) -> 0 | H42: =SUM('PL WB (нед)'!Y42:AB42) -> 0 | I42: =SUM('PL WB (нед)'!AC42:AF42) -> 0 | J42: =SUM('PL WB (нед)'!AG42:AK42) -> 0 | K42: =SUM('PL WB (нед)'!AL42:AO42) -> 0 | L42: =SUM('PL WB (нед)'!AP42:AT42) -> 0 | M42: =SUM('PL WB (нед)'!AU42:AX42) -> 0 | N42: =SUM('PL WB (нед)'!AY42:BC42) -> 0 | O42: =SUM(C42:N42) -> 0
A43: Хранение ВБ | C43: =SUM('PL WB (нед)'!C43:G43) -> 23611.72 | D43: =SUM('PL WB (нед)'!H43:K43) -> 23310.69 | E43: =SUM('PL WB (нед)'!L43:O43) -> 34960.93 | F43: =SUM('PL WB (нед)'!P43:S43) -> 23760.55 | G43: =SUM('PL WB (нед)'!T43:X43) -> 0 | H43: =SUM('PL WB (нед)'!Y43:AB43) -> 0 | I43: =SUM('PL WB (нед)'!AC43:AF43) -> 0 | J43: =SUM('PL WB (нед)'!AG43:AK43) -> 0 | K43: =SUM('PL WB (нед)'!AL43:AO43) -> 0 | L43: =SUM('PL WB (нед)'!AP43:AT43) -> 0 | M43: =SUM('PL WB (нед)'!AU43:AX43) -> 0 | N43: =SUM('PL WB (нед)'!AY43:BC43) -> 0 | O43: =SUM(C43:N43) -> 105643.89
A44: Штрафы ВБ | C44: =SUM('PL WB (нед)'!C44:G44) -> 741 | D44: =SUM('PL WB (нед)'!H44:K44) -> 0 | E44: =SUM('PL WB (нед)'!L44:O44) -> 0 | F44: =SUM('PL WB (нед)'!P44:S44) -> 40 | G44: =SUM('PL WB (нед)'!T44:X44) -> 0 | H44: =SUM('PL WB (нед)'!Y44:AB44) -> 0 | I44: =SUM('PL WB (нед)'!AC44:AF44) -> 0 | J44: =SUM('PL WB (нед)'!AG44:AK44) -> 0 | K44: =SUM('PL WB (нед)'!AL44:AO44) -> 0 | L44: =SUM('PL WB (нед)'!AP44:AT44) -> 0 | M44: =SUM('PL WB (нед)'!AU44:AX44) -> 0 | N44: =SUM('PL WB (нед)'!AY44:BC44) -> 0 | O44: =SUM(C44:N44) -> 781
A45: Платная приемка ВБ | C45: =SUM('PL WB (нед)'!C45:G45) -> 13280.81 | D45: =SUM('PL WB (нед)'!H45:K45) -> 0 | E45: =SUM('PL WB (нед)'!L45:O45) -> 0 | F45: =SUM('PL WB (нед)'!P45:S45) -> 0 | G45: =SUM('PL WB (нед)'!T45:X45) -> 0 | H45: =SUM('PL WB (нед)'!Y45:AB45) -> 0 | I45: =SUM('PL WB (нед)'!AC45:AF45) -> 0 | J45: =SUM('PL WB (нед)'!AG45:AK45) -> 0 | K45: =SUM('PL WB (нед)'!AL45:AO45) -> 0 | L45: =SUM('PL WB (нед)'!AP45:AT45) -> 0 | M45: =SUM('PL WB (нед)'!AU45:AX45) -> 0 | N45: =SUM('PL WB (нед)'!AY45:BC45) -> 0 | O45: =SUM(C45:N45) -> 13280.81
...

Sheet PL OZON (нед)
A1: Голубым выделены строки, которые заполняем! Заполняем эту вкладку, формулы не трогаем! Если добавляете строки - добавляете на всех листах PL и СF | C1: ='PL WB (нед)'!C1 -> 1 | D1: ='PL WB (нед)'!D1 -> 2 | E1: ='PL WB (нед)'!E1 -> 3 | F1: ='PL WB (нед)'!F1 -> 4 | G1: ='PL WB (нед)'!G1 -> 5 | H1: ='PL WB (нед)'!H1 -> 6 | I1: ='PL WB (нед)'!I1 -> 7 | J1: ='PL WB (нед)'!J1 -> 8 | ... BC1: ='PL WB (нед)'!BC1 -> Остаток года
A2: Прибыли и убытки, еженедельно | C2: Январь | H2: Февраль | L2: Март | P2: Апрель | T2: Май | Y2: Июнь | AC2: Июль | AG2: Август | AL2: Сентябрь | AP2: Октябрь | AU2: Ноябрь | AY2: Декабрь
C3: ='PL WB (нед)'!C3 -> NaN | D3: ='PL WB (нед)'!D3 -> NaN | E3: ='PL WB (нед)'!E3 -> NaN | F3: ='PL WB (нед)'!F3 -> NaN | G3: ='PL WB (нед)'!G3 -> NaN | H3: ='PL WB (нед)'!H3 -> NaN | I3: ='PL WB (нед)'!I3 -> NaN | J3: ='PL WB (нед)'!J3 -> NaN | ... BB3: ='PL WB (нед)'!BB3 -> 0 | BC3: 29.12-31.12
A4: Товарооборот
A5: Остаток товара по цене закупки | C5: 239068.58 | D5: =C12 -> 235066.58 | E5: =D12 -> 219001.58 | F5: =E12 -> 201900.58 | G5: =F12 -> 184577.58 | H5: =G12 -> 167411.58 | I5: =H12 -> 155448.58 | J5: =I12 -> 143723.58 | K5: =J12 -> 126685.58 | ... BC5: =BB12 -> 67587.58
BD6: =SUM(C6:BC6) -> 0
A7: Продажи шт | C7: 0 | D7: 0 | E7: 0 | F7: 0 | G7: 0 | H7: 0 | I7: 0 | J7: 0 | K7: 0 | L7: 0 | M7: 0 | N7: 0 | O7: 0 | P7: 0 | Q7: 0 | R7: 0 | S7: 0 | T7: 0 | U7: 0 | V7: 0 | W7: 0 | X7: 0 | Y7: 0 | Z7: 0 | AA7: 0 | AB7: 0 | AC7: 0 | AD7: 0 | AE7: 0 | AF7: 0 | AG7: 0 | AH7: 0 | AI7: 0 | AJ7: 0 | AK7: 0 | AL7: 0 | AM7: 0 | AN7: 0 | AO7: 0 | AP7: 0 | AQ7: 0 | AR7: 0 | AS7: 0 | AT7: 0 | AU7: 0 | AV7: 0 | AW7: 0 | AX7: 0 | AY7: 0 | AZ7: 0 | BA7: 0 | BB7: 0 | BC7: 0 | BD7: =SUM(C7:BC7) -> 1356
A8: Отгрузки по себестоимости | C8: =C33 -> 4002 | D8: =D33 -> 16065 | E8: =E33 -> 17101 | F8: =F33 -> 17323 | G8: =G33 -> 17166 | H8: =H33 -> 11963 | I8: =I33 -> 11725 | J8: =J33 -> 17038 | ... BC8: =BC33 -> 0 | BD8: =SUM(C8:BC8) -> 171481
BD9: =SUM(C9:BC9) -> 0
A10: Поступление товара, р | BD10: =SUM(C10:BC10) -> 0
A11: Поступление товара, шт | BD11: =SUM(C11:BC11) -> 0
A12: Доступно на складе по цене закупки | C12: =C10-C8+C5 -> 235066.58 | D12: =D10-D8+D5 -> 219001.58 | E12: =E10-E8+E5 -> 201900.58 | F12: =F10-F8+F5 -> 184577.58 | G12: =G10-G8+G5 -> 167411.58 | H12: =H10-H8+H5 -> 155448.58 | I12: =I10-I8+I5 -> 143723.58 | J12: =J10-J8+J5 -> 126685.58 | ... BC12: =BC10-BC8+BC5 -> 67587.58 | BD12: =SUM(C12:BC12) -> 4657878.7
A13: Доступно на складе, шт | C13: =1741-C7-C27+C11+C23 -> 1704 | D13: =C13-D7-D27+D11+D23 -> 1566 | E13: =D13-E7-E27+E11+E23 -> 1433 | F13: =E13-F7-F27+F11+F23 -> 1288 | G13: =F13-G7-G27+G11+G23 -> 1146 | H13: =G13-H7-H27+H11+H23 -> 1042 | I13: =H13-I7-I27+I11+I23 -> 942 | J13: =I13-J7-J27+J11+J23 -> 829 | K13: =J13-K7-K27+K11+K23 -> 760 | ... BC13: =BB13-BC7-BC27+BC11+BC23 -> 409
A14: Продано товаров OZON по цене в карточке-ВЫРУЧКА | C14: 23556 | D14: 92169 | E14: 91476 | F14: 98006 | G14: 93544 | H14: 65065 | I14: 64240 | J14: 80539 | K14: 47549 | L14: 54244 | M14: 46430 | N14: 34926 | O14: 29249 | P14: 21633 | Q14: 25109 | R14: 27597 | BD14: =SUM(C14:BC14) -> 895332
BD15: =SUM(C15:BC15) -> 0
BD16: =SUM(C16:BC16) -> 0
A17: Комиссия OZON | C17: 8844 | D17: 34710 | E17: 34473 | F17: 36913 | G17: 35355 | H17: 24418 | I17: 24277 | J17: 30783 | K17: 18081 | L17: 20446 | M17: 17665 | N17: 13238 | O17: 11142 | P17: 8115 | Q17: 9651 | R17: 11075 | BD17: 1741
A18: % комиссии | C18: =C17/C14 -> 0.37544575 | D18: =D17/D14 -> 0.37659083 | E18: =E17/E14 -> 0.37685295 | F18: =F17/F14 -> 0.37664021 | G18: =G17/G14 -> 0.37795048 | H18: =H17/H14 -> 0.37528625 | I18: =I17/I14 -> 0.37791096 | J18: =J17/J14 -> 0.38221234 | ... BC18: =BC17/BC14 -> #DIV/0!
BD19: =SUM(C19:BC19) -> 0
A20: Выручка от реализацииза вычетом комиссии, руб | C20: =C14-C17 -> 14712 | D20: =D14-D17 -> 57459 | E20: =E14-E17 -> 57003 | F20: =F14-F17 -> 61093 | G20: =G14-G17 -> 58189 | H20: =H14-H17 -> 40647 | I20: =I14-I17 -> 39963 | J20: =J14-J17 -> 49756 | ... T20: =T14-T17 -> 0 | BD20: =SUM(C20:BC20) -> 556146
BD21: =SUM(C21:BC21) -> 0
A22: Возвраты, руб | C22: 882 | D22: 3355 | E22: 471 | F22: 1771 | G22: 426 | H22: 1716 | I22: 635 | K22: 700 | L22: 2455 | M22: 2991 | N22: 1804 | R22: 660 | BD22: =SUM(C22:BC22) -> 17866
A23: Возвраты, шт | C23: 1 | D23: 6 | E23: 1 | F23: 2 | G23: 1 | H23: 2 | I23: 1 | K23: 1 | L23: 3 | M23: 3 | N23: 2 | R23: 1 | BD23: =SUM(C23:BC23) -> 24
A24: % возвратов | C24: =C22/(C14-C22) -> 0.03889918 | D24: =D22/(D14-D22) -> 0.037775576 | E24: =E22/(E14-E22) -> 0.0051755398 | F24: =F22/(F14-F22) -> 0.018402868 | G24: =G22/(G14-G22) -> 0.0045748405 | H24: =H22/(H14-H22) -> 0.027088036 | I24: =I22/(I14-I22) -> 0.0099834919 | J24: =J22/(J14-J22) -> 0 | ... BC24: =BC22/(BC14-BC22) -> #DIV/0! | BD24: =BD23/(BD7-BD23) -> 0.018018018
BD25: =SUM(C25:BC25) -> 0
A26: Брак, руб | BD26: =SUM(C26:BC26) -> 0
A27: Брак, шт | BD27: =SUM(C27:BC27) -> 0
A28: % брака | C28: =C27/C7 -> 0 | D28: =D27/D7 -> 0 | E28: =E27/E7 -> 0 | F28: =F27/F7 -> 0 | G28: =G27/G7 -> 0 | H28: =H27/H7 -> 0 | I28: =I27/I7 -> 0 | J28: =J27/J7 -> 0 | ... BD28: =BD27/BD7 -> 0
BD29: =SUM(C29:BC29) -> 0
A30: Поступление на счет от OZON | C30: =C20+C31-C38 -> 4783 | D30: =D20+D31-D38 -> 30486 | E30: =E20+E31-E38 -> 29296 | F30: =F20+F31-F38 -> 33501 | G30: =G20+G31-G38 -> 28267 | H30: =H20+H31-H38 -> 17859 | I30: =I20+I31-I38 -> 18826 | J30: =J20+J31-J38 -> 26376 | ... BC30: =BC20+BC31-BC38 -> 0 | BD30: =SUM(C30:BC30) -> 296510
A31: в т.ч. Прочие доходы | BD31: =SUM(C31:BC31) -> 0
BD32: =SUM(C32:BC32) -> 0
A33: Себестоимость | C33: 4002 | D33: 16065 | E33: 17101 | F33: 17323 | G33: 17166 | H33: 11963 | I33: 11725 | J33: 17038 | K33: 9180 | L33: 10041 | M33: 9258 | N33: 7105 | O33: 5581 | P33: 4485 | Q33: 6135 | R33: 7313 | BD33: =SUM(C33:BC33) -> 171481
A34: % себестоимости в цене | C34: =C33/C14 -> 0.16989302 | D34: =D33/D14 -> 0.17429938 | E34: =E33/E14 -> 0.18694521 | F34: =F33/F14 -> 0.17675448 | G34: =G33/G14 -> 0.18350723 | H34: =H33/H14 -> 0.18386229 | I34: =I33/I14 -> 0.18251868 | J34: =J33/J14 -> 0.21154968 | ... BD34: =BD33/BD14 -> 0.19152784
BD35: =SUM(C35:BC35) -> 0
A36: Валовая прибыль | C36: =C20-C33 -> 10710 | D36: =D20-D33 -> 41394 | E36: =E20-E33 -> 39902 | F36: =F20-F33 -> 43770 | G36: =G20-G33 -> 41023 | H36: =H20-H33 -> 28684 | I36: =I20-I33 -> 28238 | J36: =J20-J33 -> 32718 | ... BC36: =BC20-BC33 -> 0 | BD36: =SUM(C36:BC36) -> 384665
BD37: =SUM(C37:BC37) -> 0
A38: Расходы | C38: =SUM(C40:C51) -> 9929 | D38: =SUM(D40:D51) -> 26973 | E38: =SUM(E40:E51) -> 27707 | F38: =SUM(F40:F51) -> 27592 | G38: =SUM(G40:G51) -> 29922 | H38: =SUM(H40:H51) -> 22788 | I38: =SUM(I40:I51) -> 21137 | J38: =SUM(J40:J51) -> 23380 | ... BC38: =SUM(BC40:BC51) -> 0 | BD38: =SUM(C38:BC38) -> 259636
A39: % расходы | C39: =C38/C14 -> 0.4215062 | D39: =D38/D14 -> 0.2926472 | E39: =E38/E14 -> 0.30288819 | F39: =F38/F14 -> 0.28153378 | G39: =G38/G14 -> 0.31987086 | H39: =H38/H14 -> 0.35023438 | I39: =I38/I14 -> 0.32903176 | J39: =J38/J14 -> 0.29029414 | ... BD39: =BD38/BD14 -> 0.28998852
A40: Логистика OZON | C40: 4293 | D40: 16303 | E40: 18182 | F40: 18525 | G40: 18491 | H40: 15069 | I40: 13395 | J40: 18957 | K40: 9535 | L40: 10909 | M40: 11342 | N40: 6615 | O40: 3286 | P40: 2314 | Q40: 3054 | R40: 4228 | BD40: =SUM(C40:BC40) -> 174498
...

Sheet PL OZON
A1: Заполняем PL и CF еженедельный!
A2: Прибыли и убытки | C2: 2025
C3: Январь | D3: Февраль | E3: Март | F3: Апрель | G3: Май | H3: Июнь | I3: Июль | J3: Август | K3: Сентябрь | L3: Октябрь | M3: Ноябрь | N3: Декабрь
A4: Товарооборот
A5: Остаток товара по цене закупки | C5: ='PL OZON (нед)'!C5 -> 239068.58 | D5: =C12 -> 167411.58 | E5: =D12 -> 117505.58 | F5: =E12 -> 85520.58 | G5: =F12 -> 67587.58 | H5: =G12 -> 67587.58 | I5: =H12 -> 67587.58 | J5: =I12 -> 67587.58 | K5: =J12 -> 67587.58 | ... N5: =M12 -> 67587.58
B7: Продажи шт | C7: =SUM('PL OZON (нед)'!C7:G7) -> 606 | D7: =SUM('PL OZON (нед)'!H7:K7) -> 390 | E7: =SUM('PL OZON (нед)'!L7:O7) -> 238 | F7: =SUM('PL OZON (нед)'!P7:S7) -> 122 | G7: =SUM('PL OZON (нед)'!T7:X7) -> 0 | H7: =SUM('PL OZON (нед)'!Y7:AB7) -> 0 | I7: =SUM('PL OZON (нед)'!AC7:AF7) -> 0 | J7: =SUM('PL OZON (нед)'!AG7:AK7) -> 0 | K7: =SUM('PL OZON (нед)'!AL7:AO7) -> 0 | L7: =SUM('PL OZON (нед)'!AP7:AT7) -> 0 | M7: =SUM('PL OZON (нед)'!AU7:AX7) -> 0 | N7: =SUM('PL OZON (нед)'!AY7:BB7) -> 0 | O7: =SUM(C7:N7) -> 1356
B8: Отгрузки по себестоимости | C8: =C33 -> 71657 | D8: =D33 -> 49906 | E8: =E33 -> 31985 | F8: =F33 -> 17933 | G8: =G33 -> 0 | H8: =H33 -> 0 | I8: =I33 -> 0 | J8: =J33 -> 0 | ... N8: =N33 -> 0 | O8: =SUM(C8:N8) -> 171481
A10: Поступление товара, р | C10: =SUM('PL OZON (нед)'!C10:G10) -> 0 | D10: =SUM('PL OZON (нед)'!H10:K10) -> 0 | E10: =SUM('PL OZON (нед)'!L10:O10) -> 0 | F10: =SUM('PL OZON (нед)'!P10:S10) -> 0 | G10: =SUM('PL OZON (нед)'!T10:X10) -> 0 | H10: =SUM('PL OZON (нед)'!Y10:AB10) -> 0 | I10: =SUM('PL OZON (нед)'!AC10:AF10) -> 0 | J10: =SUM('PL OZON (нед)'!AG10:AK10) -> 0 | K10: =SUM('PL OZON (нед)'!AL10:AO10) -> 0 | L10: =SUM('PL OZON (нед)'!AP10:AT10) -> 0 | M10: =SUM('PL OZON (нед)'!AU10:AX10) -> 0 | N10: =SUM('PL OZON (нед)'!AY10:BB10) -> 0 | O10: =SUM(C10:N10) -> 0
A11: Поступление товара, шт | C11: =SUM('PL OZON (нед)'!C11:G11) -> 0 | D11: =SUM('PL OZON (нед)'!H11:K11) -> 0 | E11: =SUM('PL OZON (нед)'!L11:O11) -> 0 | F11: =SUM('PL OZON (нед)'!P11:S11) -> 0 | G11: =SUM('PL OZON (нед)'!T11:X11) -> 0 | H11: =SUM('PL OZON (нед)'!Y11:AB11) -> 0 | I11: =SUM('PL OZON (нед)'!AC11:AF11) -> 0 | J11: =SUM('PL OZON (нед)'!AG11:AK11) -> 0 | K11: =SUM('PL OZON (нед)'!AL11:AO11) -> 0 | L11: =SUM('PL OZON (нед)'!AP11:AT11) -> 0 | M11: =SUM('PL OZON (нед)'!AU11:AX11) -> 0 | N11: =SUM('PL OZON (нед)'!AY11:BB11) -> 0 | O11: =SUM(C11:N11) -> 0
A12: Доступно на складе по цене закупки | C12: =C10-C8+C5 -> 167411.58 | D12: =D10-D8+D5 -> 117505.58 | E12: =E10-E8+E5 -> 85520.58 | F12: =F10-F8+F5 -> 67587.58 | G12: =G10-G8+G5 -> 67587.58 | H12: =H10-H8+H5 -> 67587.58 | I12: =I10-I8+I5 -> 67587.58 | J12: =J10-J8+J5 -> 67587.58 | ... N12: =N10-N8+N5 -> 67587.58
A13: Доступно на складе, шт | C13: ='PL OZON (нед)'!G13 -> 1146 | D13: =C13-D7-D27+D11+D23 -> 760 | E13: =D13-E7-E27+E11+E23 -> 530 | F13: =E13-F7-F27+F11+F23 -> 409 | G13: =F13-G7-G27+G11+G23 -> 409 | H13: =G13-H7-H27+H11+H23 -> 409 | I13: =H13-I7-I27+I11+I23 -> 409 | J13: =I13-J7-J27+J11+J23 -> 409 | K13: =J13-K7-K27+K11+K23 -> 409 | ... N13: =M13-N7-N27+N11+N23 -> 409
A14: Продано товаров OZON по цене в карточке | C14: =SUM('PL OZON (нед)'!C14:G14) -> 398751 | D14: =SUM('PL OZON (нед)'!H14:K14) -> 257393 | E14: =SUM('PL OZON (нед)'!L14:O14) -> 164849 | F14: =SUM('PL OZON (нед)'!P14:S14) -> 74339 | G14: =SUM('PL OZON (нед)'!T14:X14) -> 0 | H14: =SUM('PL OZON (нед)'!Y14:AB14) -> 0 | I14: =SUM('PL OZON (нед)'!AC14:AF14) -> 0 | J14: =SUM('PL OZON (нед)'!AG14:AK14) -> 0 | K14: =SUM('PL OZON (нед)'!AL14:AO14) -> 0 | L14: =SUM('PL OZON (нед)'!AP14:AT14) -> 0 | M14: =SUM('PL OZON (нед)'!AU14:AX14) -> 0 | N14: =SUM('PL OZON (нед)'!AY14:BB14) -> 0 | O14: =SUM(C14:N14) -> 895332
O15: =SUM(C15:N15) -> 0
O16: =SUM(C16:N16) -> 0
A17: Комиссия OZON | C17: =C14-C20 -> 150295 | D17: =D14-D20 -> 97559 | E17: =E14-E20 -> 62491 | F17: =F14-F20 -> 28841 | G17: =G14-G20 -> 0 | H17: =H14-H20 -> 0 | I17: =I14-I20 -> 0 | J17: =J14-J20 -> 0 | ... N17: =N14-N20 -> 0 | O17: =SUM(C17:N17) -> 339186
A18: % комиссии | C18: =IFERROR(C17/C14,0) -> 0.37691442 | D18: =IFERROR(D17/D14,0) -> 0.3790274 | E18: =IFERROR(E17/E14,0) -> 0.37908025 | F18: =IFERROR(F17/F14,0) -> 0.38796594 | G18: =IFERROR(G17/G14,0) -> 0 | H18: =IFERROR(H17/H14,0) -> 0 | I18: =IFERROR(I17/I14,0) -> 0 | J18: =IFERROR(J17/J14,0) -> 0 | ... O18: =IFERROR(O17/O14,0) -> 0.37883824
A20: Выручка от реализации (к перечислению за товар), руб | C20: =SUM('PL OZON (нед)'!C20:G20) -> 248456 | D20: =SUM('PL OZON (нед)'!H20:K20) -> 159834 | E20: =SUM('PL OZON (нед)'!L20:O20) -> 102358 | F20: =SUM('PL OZON (нед)'!P20:S20) -> 45498 | G20: =SUM('PL OZON (нед)'!T20:X20) -> 0 | H20: =SUM('PL OZON (нед)'!Y20:AB20) -> 0 | I20: =SUM('PL OZON (нед)'!AC20:AF20) -> 0 | J20: =SUM('PL OZON (нед)'!AG20:AK20) -> 0 | K20: =SUM('PL OZON (нед)'!AL20:AO20) -> 0 | L20: =SUM('PL OZON (нед)'!AP20:AT20) -> 0 | M20: =SUM('PL OZON (нед)'!AU20:AX20) -> 0 | N20: =SUM('PL OZON (нед)'!AY20:BB20) -> 0 | O20: =SUM(C20:N20) -> 556146
O21: =SUM(C21:N21) -> 0
A22: Возвраты, руб | C22: =SUM('PL OZON (нед)'!C22:G22) -> 6905 | D22: =SUM('PL OZON (нед)'!H22:K22) -> 3051 | E22: =SUM('PL OZON (нед)'!L22:O22) -> 7250 | F22: =SUM('PL OZON (нед)'!P22:S22) -> 660 | G22: =SUM('PL OZON (нед)'!T22:X22) -> 0 | H22: =SUM('PL OZON (нед)'!Y22:AB22) -> 0 | I22: =SUM('PL OZON (нед)'!AC22:AF22) -> 0 | J22: =SUM('PL OZON (нед)'!AG22:AK22) -> 0 | K22: =SUM('PL WB (нед)'!AL22:AO22) -> 0 | L22: =SUM('PL WB (нед)'!AP22:AT22) -> 0 | M22: =SUM('PL WB (нед)'!AU22:AX22) -> 0 | N22: =SUM('PL WB (нед)'!AY22:BB22) -> 0 | O22: =SUM(C22:N22) -> 17866
A23: Возвраты, шт | C23: =SUM('PL OZON (нед)'!C23:G23) -> 11 | D23: =SUM('PL OZON (нед)'!H23:K23) -> 4 | E23: =SUM('PL OZON (нед)'!L23:O23) -> 8 | F23: =SUM('PL OZON (нед)'!P23:S23) -> 1 | G23: =SUM('PL OZON (нед)'!T23:X23) -> 0 | H23: =SUM('PL WB (нед)'!Y23:AB23) -> 0 | I23: =SUM('PL WB (нед)'!AC23:AF23) -> 0 | J23: =SUM('PL WB (нед)'!AG23:AK23) -> 0 | K23: =SUM('PL OZON (нед)'!AL23:AO23) -> 0 | L23: =SUM('PL OZON (нед)'!AP23:AT23) -> 0 | M23: =SUM('PL OZON (нед)'!AU23:AX23) -> 0 | N23: =SUM('PL OZON (нед)'!AY23:BB23) -> 0 | O23: =SUM(C23:N23) -> 24
A24: % возвратов | C24: =IFERROR(C22/C14,0) -> 0.017316571 | D24: =IFERROR(D22/D14,0) -> 0.011853469 | E24: =IFERROR(E22/E14,0) -> 0.043979642 | F24: =IFERROR(F22/F14,0) -> 0.0088782469 | G24: =IFERROR(G22/G14,0) -> 0 | H24: =IFERROR(H22/H14,0) -> 0 | I24: =IFERROR(I22/I14,0) -> 0 | J24: =IFERROR(J22/J14,0) -> 0 | ... O24: =IFERROR(O22/O14,0) -> 0.019954609
A26: Брак, руб
A27: Брак, шт | C27: =SUM('PL OZON (нед)'!C27:G27) -> 0 | D27: =SUM('PL OZON (нед)'!H27:K27) -> 0 | E27: =SUM('PL OZON (нед)'!L27:O27) -> 0 | F27: =SUM('PL OZON (нед)'!P27:S27) -> 0 | G27: =SUM('PL OZON (нед)'!T27:X27) -> 0 | H27: =SUM('PL OZON (нед)'!Y27:AB27) -> 0 | I27: =SUM('PL OZON (нед)'!AC27:AF27) -> 0 | J27: =SUM('PL OZON (нед)'!AG27:AK27) -> 0 | K27: =SUM('PL OZON (нед)'!AL27:AO27) -> 0 | L27: =SUM('PL OZON (нед)'!AP27:AT27) -> 0 | M27: =SUM('PL OZON (нед)'!AU27:AX27) -> 0 | N27: =SUM('PL OZON (нед)'!AY27:BB27) -> 0
A28: % брака | C28: =IFERROR(C27/C7,0) -> 0 | D28: =IFERROR(D27/D7,0) -> 0 | E28: =IFERROR(E27/E7,0) -> 0 | F28: =IFERROR(F27/F7,0) -> 0 | G28: =IFERROR(G27/G7,0) -> 0 | H28: =IFERROR(H27/H7,0) -> 0 | I28: =IFERROR(I27/I7,0) -> 0 | J28: =IFERROR(J27/J7,0) -> 0 | ... N28: =IFERROR(N27/N7,0) -> 0
A30: Поступление на счет от ВБ | C30: =C20+C31-SUM(C40:C45)-C41 -> 114486 | D30: =D20+D31-SUM(D40:D45)-D41 -> 72462 | E30: =E20+E31-SUM(E40:E45)-E41 -> 58108 | F30: =F20+F31-SUM(F40:F45)-F41 -> 28100 | G30: =G20+G31-SUM(G40:G45)-G41 -> 0 | H30: =H20+H31-SUM(H40:H45)-H41 -> 0 | I30: =I20+I31-SUM(I40:I45)-I41 -> 0 | J30: =J20+J31-SUM(J40:J45)-J41 -> 0 | ... N30: =N20+N31-SUM(N40:N45)-N41 -> 0 | O30: =SUM(C30:N30) -> 273156
A31: в т.ч. Прочие доходы | C31: =SUM('PL OZON (нед)'!C31:G31) -> 0 | D31: =SUM('PL OZON (нед)'!H31:K31) -> 0 | E31: =SUM('PL OZON (нед)'!L31:O31) -> 0 | F31: =SUM('PL OZON (нед)'!P31:S31) -> 0 | G31: =SUM('PL OZON (нед)'!T31:X31) -> 0 | H31: =SUM('PL OZON (нед)'!Y31:AB31) -> 0 | I31: =SUM('PL OZON (нед)'!AC31:AF31) -> 0 | J31: =SUM('PL OZON (нед)'!AG31:AK31) -> 0 | K31: =SUM('PL OZON (нед)'!AL31:AO31) -> 0 | L31: =SUM('PL OZON (нед)'!AP31:AT31) -> 0 | M31: =SUM('PL OZON (нед)'!AU31:AX31) -> 0 | N31: =SUM('PL OZON (нед)'!AY31:BB31) -> 0
A33: Себестоимость | C33: =SUM('PL OZON (нед)'!C33:G33) -> 71657 | D33: =SUM('PL OZON (нед)'!H33:K33) -> 49906 | E33: =SUM('PL OZON (нед)'!L33:O33) -> 31985 | F33: =SUM('PL OZON (нед)'!P33:S33) -> 17933 | G33: =SUM('PL OZON (нед)'!T33:X33) -> 0 | H33: =SUM('PL OZON (нед)'!Y33:AB33) -> 0 | I33: =SUM('PL OZON (нед)'!AC33:AF33) -> 0 | J33: =SUM('PL OZON (нед)'!AG33:AK33) -> 0 | K33: =SUM('PL OZON (нед)'!AL33:AO33) -> 0 | L33: =SUM('PL OZON (нед)'!AP33:AT33) -> 0 | M33: =SUM('PL OZON (нед)'!AU33:AX33) -> 0 | N33: =SUM('PL OZON (нед)'!AY33:BB33) -> 0 | O33: =SUM('PL OZON (нед)'!AZ33:BC33) -> 0
A34: % себестоимости | C34: =IFERROR(C33/C14,0) -> 0.17970362 | D34: =IFERROR(D33/D14,0) -> 0.19389028 | E34: =IFERROR(E33/E14,0) -> 0.19402605 | F34: =IFERROR(F33/F14,0) -> 0.24123273 | G34: =IFERROR(G33/G14,0) -> 0 | H34: =IFERROR(H33/H14,0) -> 0 | I34: =IFERROR(I33/I14,0) -> 0 | J34: =IFERROR(J33/J14,0) -> 0 | ... O34: =IFERROR(O33/O14,0) -> 0
A36: Валовая прибыль | C36: =C20-C33 -> 176799 | D36: =D20-D33 -> 109928 | E36: =E20-E33 -> 70373 | F36: =F20-F33 -> 27565 | G36: =G20-G33 -> 0 | H36: =H20-H33 -> 0 | I36: =I20-I33 -> 0 | J36: =J20-J33 -> 0 | ... O36: =O20-O33 -> 556146
A38: Расходы | C38: =SUM(C40:C51) -> 122123 | D38: =SUM(D40:D51) -> 79457 | E38: =SUM(E40:E51) -> 41033 | F38: =SUM(F40:F51) -> 17023 | G38: =SUM(G40:G51) -> 0 | H38: =SUM(H40:H51) -> 0 | I38: =SUM(I40:I51) -> 0 | J38: =SUM(J40:J51) -> 0 | ... N38: =SUM(N40:N51) -> 0 | O38: =SUM(C38:N38) -> 259636
A39: % расходы | C39: =IFERROR(C38/C14,0) -> 0.30626381 | D39: =IFERROR(D38/D14,0) -> 0.30869915 | E39: =IFERROR(E38/E14,0) -> 0.24891264 | F39: =IFERROR(F38/F14,0) -> 0.22899151 | G39: =IFERROR(G38/G14,0) -> 0 | H39: =IFERROR(H38/H14,0) -> 0 | I39: =IFERROR(I38/I14,0) -> 0 | J39: =IFERROR(J38/J14,0) -> 0 | ... N39: =IFERROR(N38/N14,0) -> 0
A40: Логистика OZON | C40: =SUM('PL OZON (нед)'!C40:G40) -> 75794 | D40: =SUM('PL OZON (нед)'!H40:K40) -> 56956 | E40: =SUM('PL OZON (нед)'!L40:O40) -> 32152 | F40: =SUM('PL OZON (нед)'!P40:S40) -> 9596 | G40: =SUM('PL OZON (нед)'!T40:X40) -> 0 | H40: =SUM('PL OZON (нед)'!Y40:AB40) -> 0 | I40: =SUM('PL OZON (нед)'!AC40:AF40) -> 0 | J40: =SUM('PL OZON (нед)'!AG40:AK40) -> 0 | K40: =SUM('PL OZON (нед)'!AL40:AO40) -> 0 | L40: =SUM('PL OZON (нед)'!AP40:AT40) -> 0 | M40: =SUM('PL OZON (нед)'!AU40:AX40) -> 0 | N40: =SUM('PL OZON (нед)'!AY40:BB40) -> 0 | O40: =SUM(C40:N40) -> 174498
A41: Продвижение OZON | C41: =SUM('PL OZON (нед)'!C41:G41) -> 11847 | D41: =SUM('PL OZON (нед)'!H41:K41) -> 7915 | E41: =SUM('PL OZON (нед)'!L41:O41) -> 3217 | F41: =SUM('PL OZON (нед)'!P41:S41) -> 375 | G41: =SUM('PL OZON (нед)'!T41:X41) -> 0 | H41: =SUM('PL OZON (нед)'!Y41:AB41) -> 0 | I41: =SUM('PL OZON (нед)'!AC41:AF41) -> 0 | J41: =SUM('PL OZON (нед)'!AG41:AK41) -> 0 | K41: =SUM('PL OZON (нед)'!AL41:AO41) -> 0 | L41: =SUM('PL OZON (нед)'!AP41:AT41) -> 0 | M41: =SUM('PL OZON (нед)'!AU41:AX41) -> 0 | N41: =SUM('PL OZON (нед)'!AY41:BB41) -> 0 | O41: =SUM(C41:N41) -> 23354
A42: Эквайринг OZON | C42: =SUM('PL OZON (нед)'!C42:G42) -> 3613 | D42: =SUM('PL OZON (нед)'!H42:K42) -> 2391 | E42: =SUM('PL OZON (нед)'!L42:O42) -> 1321 | F42: =SUM('PL OZON (нед)'!P42:S42) -> 773 | G42: =SUM('PL OZON (нед)'!T42:X42) -> 0 | H42: =SUM('PL OZON (нед)'!Y42:AB42) -> 0 | I42: =SUM('PL OZON (нед)'!AC42:AF42) -> 0 | J42: =SUM('PL OZON (нед)'!AG42:AK42) -> 0 | K42: =SUM('PL OZON (нед)'!AL42:AO42) -> 0 | L42: =SUM('PL OZON (нед)'!AP42:AT42) -> 0 | M42: =SUM('PL OZON (нед)'!AU42:AX42) -> 0 | N42: =SUM('PL OZON (нед)'!AY42:BB42) -> 0 | O42: =SUM(C42:N42) -> 8098
A43: Хранение OZON | C43: =SUM('PL OZON (нед)'!C43:G43) -> 30069 | D43: =SUM('PL OZON (нед)'!H43:K43) -> 12195 | E43: =SUM('PL OZON (нед)'!L43:O43) -> 4343 | F43: =SUM('PL OZON (нед)'!P43:S43) -> 6279 | G43: =SUM('PL OZON (нед)'!T43:X43) -> 0 | H43: =SUM('PL OZON (нед)'!Y43:AB43) -> 0 | I43: =SUM('PL OZON (нед)'!AC43:AF43) -> 0 | J43: =SUM('PL OZON (нед)'!AG43:AK43) -> 0 | K43: =SUM('PL OZON (нед)'!AL43:AO43) -> 0 | L43: =SUM('PL OZON (нед)'!AP43:AT43) -> 0 | M43: =SUM('PL OZON (нед)'!AU43:AX43) -> 0 | N43: =SUM('PL OZON (нед)'!AY43:BB43) -> 0 | O43: =SUM(C43:N43) -> 52886
A44: Штрафы OZON | C44: =SUM('PL OZON (нед)'!C44:G44) -> 0 | D44: =SUM('PL OZON (нед)'!H44:K44) -> 0 | E44: =SUM('PL OZON (нед)'!L44:O44) -> 0 | F44: =SUM('PL OZON (нед)'!P44:S44) -> 0 | G44: =SUM('PL OZON (нед)'!T44:X44) -> 0 | H44: =SUM('PL OZON (нед)'!Y44:AB44) -> 0 | I44: =SUM('PL OZON (нед)'!AC44:AF44) -> 0 | J44: =SUM('PL OZON (нед)'!AG44:AK44) -> 0 | K44: =SUM('PL OZON (нед)'!AL44:AO44) -> 0 | L44: =SUM('PL OZON (нед)'!AP44:AT44) -> 0 | M44: =SUM('PL OZON (нед)'!AU44:AX44) -> 0 | N44: =SUM('PL OZON (нед)'!AY44:BB44) -> 0 | O44: =SUM(C44:N44) -> 0
A45: Платная приемка OZON | C45: =SUM('PL OZON (нед)'!C45:G45) -> 800 | D45: =SUM('PL OZON (нед)'!H45:K45) -> 0 | E45: =SUM('PL OZON (нед)'!L45:O45) -> 0 | F45: =SUM('PL OZON (нед)'!P45:S45) -> 0 | G45: =SUM('PL OZON (нед)'!T45:X45) -> 0 | H45: =SUM('PL OZON (нед)'!Y45:AB45) -> 0 | I45: =SUM('PL OZON (нед)'!AC45:AF45) -> 0 | J45: =SUM('PL OZON (нед)'!AG45:AK45) -> 0 | K45: =SUM('PL OZON (нед)'!AL45:AO45) -> 0 | L45: =SUM('PL OZON (нед)'!AP45:AT45) -> 0 | M45: =SUM('PL OZON (нед)'!AU45:AX45) -> 0 | N45: =SUM('PL OZON (нед)'!AY45:BB45) -> 0 | O45: =SUM(C45:N45) -> 800
A46: Прочее OZON | C46: =SUM('PL OZON (нед)'!C46:G46) -> 0 | D46: =SUM('PL OZON (нед)'!H46:K46) -> 0 | E46: =SUM('PL OZON (нед)'!L46:O46) -> 0 | F46: =SUM('PL OZON (нед)'!P46:S46) -> 0 | G46: =SUM('PL OZON (нед)'!T46:X46) -> 0 | H46: =SUM('PL OZON (нед)'!Y46:AB46) -> 0 | I46: =SUM('PL OZON (нед)'!AC46:AF46) -> 0 | J46: =SUM('PL OZON (нед)'!AG46:AK46) -> 0 | K46: =SUM('PL OZON (нед)'!AL46:AO46) -> 0 | L46: =SUM('PL OZON (нед)'!AP46:AT46) -> 0 | M46: =SUM('PL OZON (нед)'!AU46:AX46) -> 0 | N46: =SUM('PL OZON (нед)'!AY46:BB46) -> 0 | O46: =SUM(C46:N46) -> 0
A47: Контент | C47: =SUM('PL OZON (нед)'!C47:G47) -> 0 | D47: =SUM('PL OZON (нед)'!H47:K47) -> 0 | E47: =SUM('PL OZON (нед)'!L47:O47) -> 0 | F47: =SUM('PL OZON (нед)'!P47:S47) -> 0 | G47: =SUM('PL OZON (нед)'!T47:X47) -> 0 | H47: =SUM('PL OZON (нед)'!Y47:AB47) -> 0 | I47: =SUM('PL OZON (нед)'!AC47:AF47) -> 0 | J47: =SUM('PL OZON (нед)'!AG47:AK47) -> 0 | K47: =SUM('PL OZON (нед)'!AL47:AO47) -> 0 | L47: =SUM('PL OZON (нед)'!AP47:AT47) -> 0 | M47: =SUM('PL OZON (нед)'!AU47:AX47) -> 0 | N47: =SUM('PL OZON (нед)'!AY47:BB47) -> 0 | O47: =SUM(C47:N47) -> 0
