Workbook

Sheet ТЗ_ФФ
A1: Товар | B1: Фото | C1: Описание комплекта | D1: Бар-код | E1: 1 | F1: 2 | G1: 3 | H1: 4 | I1: 5 | J1: 6 | K1: 7 | L1: 8 | M1: 9 | N1: 10 | O1: 11 | P1: 12 | Q1: ИТОГО ДЛЯ ВБ | U1: 2000034323999 | V1: 2000036433891 | W1: 2000034441802 | X1: 2000036463809 | Y1: 2000028842689, 2000028840524 | AA1: 2000036432717 | AB1: 2000028839261 | AC1: 2000036427557 | AF1: 2000034441612 | AG1: 2000036465304 | AH1: 2000036430897 | AI1: 2000034439660 | AJ1: 2000034436041 | AL1: 2000034445302 | AM1: 2000036433056 | AN1: 2000036465516 | AO1: 2000028843507 | AP1: 2000034439936 | AR1: 2000036447189 | AS1: ИТОГО для ОЗОН | AT1: Количество готовых комплектов | AU1: Услуга | AV1: Комментарий | AX1: Количество из Китая | AY1: Приемка | AZ1: Сортировка | BA1: Формирование комплекта | BB1: Упаковка в БОПП пакет | BC1: доп. расходы | BD1: Упаковка в мой пакет | BE1: Маркировка | BF1: Сортировка готового товара по городам | BG1: Услуга | BH1: ИТОГО ФФ на товар | BI1: Пакеты мои | BJ1: ИТОГО НА ПАРТИЮ ТОВАРА
E2: =[1]Сводный!BR2 -> Электросталь | F2: =[1]Сводный!BS2 -> Коледино | G2: =[1]Сводный!BT2 -> Тула | H2: =[1]Сводный!BU2 -> Рязань | I2: =[1]Сводный!BV2 -> Краснодар | J2: =[1]Сводный!BW2 -> Невинномысск | K2: =[1]Сводный!BX2 -> Волгоград | L2: =[1]Сводный!BY2 -> Самара (Новосемейкино) | ... P2: =[1]Сводный!CC2 -> Новосибирск | R2: АДЫГЕЙСК_РФЦ | S2: АСТАНА_РФЦ | T2: ДОМОДЕДОВО_РФЦ | U2: ПУШКИНО_1_РФЦ | V2: СОФЬИНО_РФЦ | W2: Екатеринбург_РФЦ_НОВЫЙ | X2: Казань_РФЦ_НОВЫЙ | Y2: КАЛИНИНГРАД_МРФЦ | Z2: КРАСНОЯРСК_МРФЦ | AA2: МИНСК_МПСЦ | AB2: НЕВИННОМЫССК_РФЦ | AC2: НОВОРОССИЙСК_МРФЦ | AD2: Новосибирск_РФЦ_Новый | AE2: ОМСК_РФЦ | AF2: ОРЕНБУРГ_РФЦ | AG2: ПЕРМЬ_РФЦ | AH2: Ростов_на_Дону_РФЦ | AI2: САМАРА_РФЦ | AJ2: ВОЛГОГРАД_МРФЦ | AK2: Санкт_Петербург_РФЦ | AL2: СПБ_КОЛПИНО_РФЦ | AM2: СПБ_ШУШАРЫ_РФЦ | AN2: ТВЕРЬ_РФЦ | AO2: ТЮМЕНЬ_РФЦ | AP2: УФА_РФЦ | AQ2: ХАБАРОВСК_2_РФЦ | AR2: ЯРОСЛАВЛЬ_РФЦ | AY2: 3 | AZ2: 5 | BA2: 5 | BB2: 13 | BD2: 10 | BE2: 6 | BF2: 5 | BG2: Цена на ед.
D3: дата поставки | E3: 46183 | F3: 46184 | G3: 46185 | H3: 46186 | I3: 46187 | J3: 46183 | L3: 46183 | N3: 46183 | O3: 46183 | U3: 45993 | V3: 45994 | W3: 45993 | X3: 45994 | Y3: 45993 | AA3: 45994 | AB3: 45993 | AC3: 45994 | AF3: 45993 | AG3: 45995 | AH3: 45994 | AI3: 45993 | AJ3: 45993 | AL3: 45993 | AM3: 45995 | AN3: 45995 | AO3: 45993 | AP3: 45993 | AR3: 45995
D4: время отгрузки | U4: 12-13 | V4: 16-17 | W4: 12-13 | X4: 16-17 | Y4: 12-13 | AA4: 16-17 | AB4: 12-13 | AC4: 16-17 | AF4: 12-13 | AG4: 16-17 | AH4: 16-17 | AI4: 12-13 | AJ4: 12-13 | AL4: 12-13 | AM4: 16-17 | AN4: 16-17 | AO4: 12-13 | AP4: 12-13 | AR4: 16-17
D5: Точка отгрузки | E5: Электросталь | J5: Обухово | L5: Чехов 1, Новоселки вл 11 стр 2 | N5: Обухово | O5: Чашниково | U5: МО_ЮРЛОВО_2 | V5: ЮРЛОВО_1 | W5: МО_ЮРЛОВО_2 | X5: ЮРЛОВО_1 | Y5: МО_ЮРЛОВО_2 | AA5: ЮРЛОВО_1 | AB5: МО_ЮРЛОВО_2 | AC5: МО_ЮРЛОВО_2 | AF5: МО_ЮРЛОВО_2 | AG5: ЮРЛОВО_1 | AH5: МО_ЮРЛОВО_2 | AI5: МО_ЮРЛОВО_2 | AJ5: МО_ЮРЛОВО_2 | AL5: МО_ЮРЛОВО_2 | AM5: ЮРЛОВО_1 | AN5: ЮРЛОВО_1 | AO5: МО_ЮРЛОВО_2 | AP5: МО_ЮРЛОВО_2 | AR5: ЮРЛОВО_1
A6: Бандаж для лица | C6: Бандаж для лица черный лайкра в пакете OPP - 1 шт. | D6: 2038162681926 | E6: =_xlfn.XLOOKUP($D6,[1]Сводный!$E:$E,[1]Сводный!BR:BR,0) -> 0 | F6: =_xlfn.XLOOKUP($D6,[1]Сводный!$E:$E,[1]Сводный!BS:BS,0) -> 0 | G6: =_xlfn.XLOOKUP($D6,[1]Сводный!$E:$E,[1]Сводный!BT:BT,0) -> 0 | H6: =_xlfn.XLOOKUP($D6,[1]Сводный!$E:$E,[1]Сводный!BU:BU,0) -> 0 | I6: =_xlfn.XLOOKUP($D6,[1]Сводный!$E:$E,[1]Сводный!BV:BV,0) -> 0 | J6: =_xlfn.XLOOKUP($D6,[1]Сводный!$E:$E,[1]Сводный!BW:BW,0) -> 0 | K6: =_xlfn.XLOOKUP($D6,[1]Сводный!$E:$E,[1]Сводный!BX:BX,0) -> 0 | L6: =_xlfn.XLOOKUP($D6,[1]Сводный!$E:$E,[1]Сводный!BY:BY,0) -> 0 | M6: =_xlfn.XLOOKUP($D6,[1]Сводный!$E:$E,[1]Сводный!BZ:BZ,0) -> 0 | N6: =_xlfn.XLOOKUP($D6,[1]Сводный!$E:$E,[1]Сводный!CA:CA,0) -> 20 | O6: =_xlfn.XLOOKUP($D6,[1]Сводный!$E:$E,[1]Сводный!CB:CB,0) -> 20 | P6: =_xlfn.XLOOKUP($D6,[1]Сводный!$E:$E,[1]Сводный!CC:CC,0) -> 0 | Q6: =SUM(E6:P6) -> 40 | R6: {=_xlfn.XLOOKUP($D6,INDIRECT(R$2&"!"&"E:E"),INDIRECT(R$2&"!"&"C:C"),0)} -> 0 | S6: {=_xlfn.XLOOKUP($D6,INDIRECT(S$2&"!"&"E:E"),INDIRECT(S$2&"!"&"C:C"),0)} -> 0 | T6: {=_xlfn.XLOOKUP($D6,INDIRECT(T$2&"!"&"E:E"),INDIRECT(T$2&"!"&"C:C"),0)} -> 0 | U6: {=_xlfn.XLOOKUP($D6,INDIRECT(U$2&"!"&"E:E"),INDIRECT(U$2&"!"&"C:C"),0)} -> 0 | V6: {=_xlfn.XLOOKUP($D6,INDIRECT(V$2&"!"&"E:E"),INDIRECT(V$2&"!"&"C:C"),0)} -> 0 | W6: {=_xlfn.XLOOKUP($D6,INDIRECT(W$2&"!"&"E:E"),INDIRECT(W$2&"!"&"C:C"),0)} -> 0 | X6: {=_xlfn.XLOOKUP($D6,INDIRECT(X$2&"!"&"E:E"),INDIRECT(X$2&"!"&"C:C"),0)} -> 0 | Y6: {=_xlfn.XLOOKUP($D6,INDIRECT(Y$2&"!"&"E:E"),INDIRECT(Y$2&"!"&"C:C"),0)} -> 0 | ... AR6: {=_xlfn.XLOOKUP($D6,INDIRECT(AR$2&"!"&"E:E"),INDIRECT(AR$2&"!"&"C:C"),0)} -> 0 | AS6: =SUM(R6:AR6) -> 0 | AT6: =Q6+AS6 -> 40 | AU6: Приемка, маркировка (1 этикетка), короб, отгрузка. | AV6: Бандаж упакован в заводской прозрачный БОПП пакет. Этикетку с ШК клеить на переднюю сторону упаковки. | AX6: =AT6 -> 40 | AY6: * | BE6: * | BF6: * | BG6: =SUMIF(AY6:BF6,"*",$AY$2:$BF$2)+BC6 -> 14 | BH6: =AT6*BG6 -> 560 | BJ6: =BH6+AT6*BI6 -> 560
C7: Бандаж для лица серый силиконовый в пакете OPP - 1 шт. | D7: 2038172050200 | E7: =_xlfn.XLOOKUP($D7,[1]Сводный!$E:$E,[1]Сводный!BR:BR,0) -> 0 | F7: =_xlfn.XLOOKUP($D7,[1]Сводный!$E:$E,[1]Сводный!BS:BS,0) -> 0 | G7: =_xlfn.XLOOKUP($D7,[1]Сводный!$E:$E,[1]Сводный!BT:BT,0) -> 0 | H7: =_xlfn.XLOOKUP($D7,[1]Сводный!$E:$E,[1]Сводный!BU:BU,0) -> 0 | I7: =_xlfn.XLOOKUP($D7,[1]Сводный!$E:$E,[1]Сводный!BV:BV,0) -> 0 | J7: =_xlfn.XLOOKUP($D7,[1]Сводный!$E:$E,[1]Сводный!BW:BW,0) -> 0 | K7: =_xlfn.XLOOKUP($D7,[1]Сводный!$E:$E,[1]Сводный!BX:BX,0) -> 0 | L7: =_xlfn.XLOOKUP($D7,[1]Сводный!$E:$E,[1]Сводный!BY:BY,0) -> 0 | M7: =_xlfn.XLOOKUP($D7,[1]Сводный!$E:$E,[1]Сводный!BZ:BZ,0) -> 0 | N7: =_xlfn.XLOOKUP($D7,[1]Сводный!$E:$E,[1]Сводный!CA:CA,0) -> 20 | O7: =_xlfn.XLOOKUP($D7,[1]Сводный!$E:$E,[1]Сводный!CB:CB,0) -> 20 | P7: =_xlfn.XLOOKUP($D7,[1]Сводный!$E:$E,[1]Сводный!CC:CC,0) -> 0 | Q7: =SUM(E7:P7) -> 40 | R7: {=_xlfn.XLOOKUP($D7,INDIRECT(R$2&"!"&"E:E"),INDIRECT(R$2&"!"&"C:C"),0)} -> 0 | S7: {=_xlfn.XLOOKUP($D7,INDIRECT(S$2&"!"&"E:E"),INDIRECT(S$2&"!"&"C:C"),0)} -> 0 | T7: {=_xlfn.XLOOKUP($D7,INDIRECT(T$2&"!"&"E:E"),INDIRECT(T$2&"!"&"C:C"),0)} -> 0 | U7: {=_xlfn.XLOOKUP($D7,INDIRECT(U$2&"!"&"E:E"),INDIRECT(U$2&"!"&"C:C"),0)} -> 0 | V7: {=_xlfn.XLOOKUP($D7,INDIRECT(V$2&"!"&"E:E"),INDIRECT(V$2&"!"&"C:C"),0)} -> 0 | W7: {=_xlfn.XLOOKUP($D7,INDIRECT(W$2&"!"&"E:E"),INDIRECT(W$2&"!"&"C:C"),0)} -> 0 | X7: {=_xlfn.XLOOKUP($D7,INDIRECT(X$2&"!"&"E:E"),INDIRECT(X$2&"!"&"C:C"),0)} -> 0 | Y7: {=_xlfn.XLOOKUP($D7,INDIRECT(Y$2&"!"&"E:E"),INDIRECT(Y$2&"!"&"C:C"),0)} -> 0 | ... AR7: {=_xlfn.XLOOKUP($D7,INDIRECT(AR$2&"!"&"E:E"),INDIRECT(AR$2&"!"&"C:C"),0)} -> 0 | AS7: =SUM(R7:AR7) -> 0 | AT7: =Q7+AS7 -> 40 | AU7: Приемка, маркировка (1 этикетка), короб, отгрузка. | AV7: Бандаж упакован в заводской прозрачный БОПП пакет. Этикетку с ШК клеить на переднюю сторону упаковки. | AX7: =AT7 -> 40 | AY7: * | BE7: * | BF7: * | BG7: =SUMIF(AY7:BF7,"*",$AY$2:$BF$2)+BC7 -> 14 | BH7: =AT7*BG7 -> 560 | BJ7: =BH7+AT7*BI7 -> 560
A8: Массажер для пальцев | C8: Массажер для пальцев | D8: 2038430289250 | E8: =_xlfn.XLOOKUP($D8,[1]Сводный!$E:$E,[1]Сводный!BR:BR,0) -> 0 | F8: =_xlfn.XLOOKUP($D8,[1]Сводный!$E:$E,[1]Сводный!BS:BS,0) -> 0 | G8: =_xlfn.XLOOKUP($D8,[1]Сводный!$E:$E,[1]Сводный!BT:BT,0) -> 0 | H8: =_xlfn.XLOOKUP($D8,[1]Сводный!$E:$E,[1]Сводный!BU:BU,0) -> 0 | I8: =_xlfn.XLOOKUP($D8,[1]Сводный!$E:$E,[1]Сводный!BV:BV,0) -> 0 | J8: =_xlfn.XLOOKUP($D8,[1]Сводный!$E:$E,[1]Сводный!BW:BW,0) -> 0 | K8: =_xlfn.XLOOKUP($D8,[1]Сводный!$E:$E,[1]Сводный!BX:BX,0) -> 0 | L8: =_xlfn.XLOOKUP($D8,[1]Сводный!$E:$E,[1]Сводный!BY:BY,0) -> 0 | M8: =_xlfn.XLOOKUP($D8,[1]Сводный!$E:$E,[1]Сводный!BZ:BZ,0) -> 0 | N8: =_xlfn.XLOOKUP($D8,[1]Сводный!$E:$E,[1]Сводный!CA:CA,0) -> 0 | O8: =_xlfn.XLOOKUP($D8,[1]Сводный!$E:$E,[1]Сводный!CB:CB,0) -> 0 | P8: =_xlfn.XLOOKUP($D8,[1]Сводный!$E:$E,[1]Сводный!CC:CC,0) -> 0 | Q8: =SUM(E8:P8) -> 0 | R8: {=_xlfn.XLOOKUP($D8,INDIRECT(R$2&"!"&"E:E"),INDIRECT(R$2&"!"&"C:C"),0)} -> 0 | S8: {=_xlfn.XLOOKUP($D8,INDIRECT(S$2&"!"&"E:E"),INDIRECT(S$2&"!"&"C:C"),0)} -> 0 | T8: {=_xlfn.XLOOKUP($D8,INDIRECT(T$2&"!"&"E:E"),INDIRECT(T$2&"!"&"C:C"),0)} -> 0 | U8: {=_xlfn.XLOOKUP($D8,INDIRECT(U$2&"!"&"E:E"),INDIRECT(U$2&"!"&"C:C"),0)} -> 0 | V8: {=_xlfn.XLOOKUP($D8,INDIRECT(V$2&"!"&"E:E"),INDIRECT(V$2&"!"&"C:C"),0)} -> 0 | W8: {=_xlfn.XLOOKUP($D8,INDIRECT(W$2&"!"&"E:E"),INDIRECT(W$2&"!"&"C:C"),0)} -> 0 | X8: {=_xlfn.XLOOKUP($D8,INDIRECT(X$2&"!"&"E:E"),INDIRECT(X$2&"!"&"C:C"),0)} -> 0 | Y8: {=_xlfn.XLOOKUP($D8,INDIRECT(Y$2&"!"&"E:E"),INDIRECT(Y$2&"!"&"C:C"),0)} -> 0 | ... AR8: {=_xlfn.XLOOKUP($D8,INDIRECT(AR$2&"!"&"E:E"),INDIRECT(AR$2&"!"&"C:C"),0)} -> 0 | AS8: =SUM(R8:AR8) -> 0 | AT8: =Q8+AS8 -> 0 | AU8: Приемка, маркировка (1 этикетка), короб, отгрузка. | AV8: Массажер упакован в заводскую цветную коробочку. Этикетку клеить на боковую сторону вдоль. При тоном наклеивании этикетка по ширине точно ложится на сторону. | AX8: =AT8 -> 0 | AY8: * | BE8: * | BF8: * | BG8: =SUMIF(AY8:BF8,"*",$AY$2:$BF$2)+BC8 -> 14 | BH8: =AT8*BG8 -> 0 | BJ8: =BH8+AT8*BI8 -> 0
A9: Массажер для спины | C9: Массажер для спины розовый в пакете - 1 шт. | D9: 2041591042329 | E9: =_xlfn.XLOOKUP($D9,[1]Сводный!$E:$E,[1]Сводный!BR:BR,0) -> 0 | F9: =_xlfn.XLOOKUP($D9,[1]Сводный!$E:$E,[1]Сводный!BS:BS,0) -> 0 | G9: =_xlfn.XLOOKUP($D9,[1]Сводный!$E:$E,[1]Сводный!BT:BT,0) -> 0 | H9: =_xlfn.XLOOKUP($D9,[1]Сводный!$E:$E,[1]Сводный!BU:BU,0) -> 0 | I9: =_xlfn.XLOOKUP($D9,[1]Сводный!$E:$E,[1]Сводный!BV:BV,0) -> 0 | J9: =_xlfn.XLOOKUP($D9,[1]Сводный!$E:$E,[1]Сводный!BW:BW,0) -> 0 | K9: =_xlfn.XLOOKUP($D9,[1]Сводный!$E:$E,[1]Сводный!BX:BX,0) -> 0 | L9: =_xlfn.XLOOKUP($D9,[1]Сводный!$E:$E,[1]Сводный!BY:BY,0) -> 0 | M9: =_xlfn.XLOOKUP($D9,[1]Сводный!$E:$E,[1]Сводный!BZ:BZ,0) -> 0 | N9: =_xlfn.XLOOKUP($D9,[1]Сводный!$E:$E,[1]Сводный!CA:CA,0) -> 0 | O9: =_xlfn.XLOOKUP($D9,[1]Сводный!$E:$E,[1]Сводный!CB:CB,0) -> 10 | P9: =_xlfn.XLOOKUP($D9,[1]Сводный!$E:$E,[1]Сводный!CC:CC,0) -> 0 | Q9: =SUM(E9:P9) -> 10 | R9: {=_xlfn.XLOOKUP($D9,INDIRECT(R$2&"!"&"E:E"),INDIRECT(R$2&"!"&"C:C"),0)} -> 0 | S9: {=_xlfn.XLOOKUP($D9,INDIRECT(S$2&"!"&"E:E"),INDIRECT(S$2&"!"&"C:C"),0)} -> 0 | T9: {=_xlfn.XLOOKUP($D9,INDIRECT(T$2&"!"&"E:E"),INDIRECT(T$2&"!"&"C:C"),0)} -> 0 | U9: {=_xlfn.XLOOKUP($D9,INDIRECT(U$2&"!"&"E:E"),INDIRECT(U$2&"!"&"C:C"),0)} -> 0 | V9: {=_xlfn.XLOOKUP($D9,INDIRECT(V$2&"!"&"E:E"),INDIRECT(V$2&"!"&"C:C"),0)} -> 0 | W9: {=_xlfn.XLOOKUP($D9,INDIRECT(W$2&"!"&"E:E"),INDIRECT(W$2&"!"&"C:C"),0)} -> 0 | X9: {=_xlfn.XLOOKUP($D9,INDIRECT(X$2&"!"&"E:E"),INDIRECT(X$2&"!"&"C:C"),0)} -> 0 | Y9: {=_xlfn.XLOOKUP($D9,INDIRECT(Y$2&"!"&"E:E"),INDIRECT(Y$2&"!"&"C:C"),0)} -> 0 | ... AR9: {=_xlfn.XLOOKUP($D9,INDIRECT(AR$2&"!"&"E:E"),INDIRECT(AR$2&"!"&"C:C"),0)} -> 0 | AS9: =SUM(R9:AR9) -> 0 | AT9: =Q9+AS9 -> 10 | AU9: Приемка, маркировка (1 этикетка), короб, отгрузка. | AV9: Массажеры упакованы в матовые пакеты. Этикетку с ШК клеить в место между ручками, раздвигая их (так удобнее). | AX9: =AT9 -> 10 | AY9: * | BE9: * | BF9: * | BG9: =SUMIF(AY9:BF9,"*",$AY$2:$BF$2)+BC9 -> 14 | BH9: =AT9*BG9 -> 140 | BJ9: =BH9+AT9*BI9 -> 140
C10: Массажер для спины голубой в пакете - 1 шт. | D10: 2041591055954 | E10: =_xlfn.XLOOKUP($D10,[1]Сводный!$E:$E,[1]Сводный!BR:BR,0) -> 20 | F10: =_xlfn.XLOOKUP($D10,[1]Сводный!$E:$E,[1]Сводный!BS:BS,0) -> 0 | G10: =_xlfn.XLOOKUP($D10,[1]Сводный!$E:$E,[1]Сводный!BT:BT,0) -> 0 | H10: =_xlfn.XLOOKUP($D10,[1]Сводный!$E:$E,[1]Сводный!BU:BU,0) -> 0 | I10: =_xlfn.XLOOKUP($D10,[1]Сводный!$E:$E,[1]Сводный!BV:BV,0) -> 0 | J10: =_xlfn.XLOOKUP($D10,[1]Сводный!$E:$E,[1]Сводный!BW:BW,0) -> 10 | K10: =_xlfn.XLOOKUP($D10,[1]Сводный!$E:$E,[1]Сводный!BX:BX,0) -> 0 | L10: =_xlfn.XLOOKUP($D10,[1]Сводный!$E:$E,[1]Сводный!BY:BY,0) -> 10 | M10: =_xlfn.XLOOKUP($D10,[1]Сводный!$E:$E,[1]Сводный!BZ:BZ,0) -> 0 | N10: =_xlfn.XLOOKUP($D10,[1]Сводный!$E:$E,[1]Сводный!CA:CA,0) -> 10 | O10: =_xlfn.XLOOKUP($D10,[1]Сводный!$E:$E,[1]Сводный!CB:CB,0) -> 10 | P10: =_xlfn.XLOOKUP($D10,[1]Сводный!$E:$E,[1]Сводный!CC:CC,0) -> 0 | Q10: =SUM(E10:P10) -> 60 | R10: {=_xlfn.XLOOKUP($D10,INDIRECT(R$2&"!"&"E:E"),INDIRECT(R$2&"!"&"C:C"),0)} -> 0 | S10: {=_xlfn.XLOOKUP($D10,INDIRECT(S$2&"!"&"E:E"),INDIRECT(S$2&"!"&"C:C"),0)} -> 0 | T10: {=_xlfn.XLOOKUP($D10,INDIRECT(T$2&"!"&"E:E"),INDIRECT(T$2&"!"&"C:C"),0)} -> 0 | U10: {=_xlfn.XLOOKUP($D10,INDIRECT(U$2&"!"&"E:E"),INDIRECT(U$2&"!"&"C:C"),0)} -> 0 | V10: {=_xlfn.XLOOKUP($D10,INDIRECT(V$2&"!"&"E:E"),INDIRECT(V$2&"!"&"C:C"),0)} -> 0 | W10: {=_xlfn.XLOOKUP($D10,INDIRECT(W$2&"!"&"E:E"),INDIRECT(W$2&"!"&"C:C"),0)} -> 0 | X10: {=_xlfn.XLOOKUP($D10,INDIRECT(X$2&"!"&"E:E"),INDIRECT(X$2&"!"&"C:C"),0)} -> 0 | Y10: {=_xlfn.XLOOKUP($D10,INDIRECT(Y$2&"!"&"E:E"),INDIRECT(Y$2&"!"&"C:C"),0)} -> 0 | ... AR10: {=_xlfn.XLOOKUP($D10,INDIRECT(AR$2&"!"&"E:E"),INDIRECT(AR$2&"!"&"C:C"),0)} -> 0 | AS10: =SUM(R10:AR10) -> 0 | AT10: =Q10+AS10 -> 60 | AU10: Приемка, маркировка (1 этикетка), короб, отгрузка. | AX10: =AT10 -> 60 | AY10: * | BE10: * | BF10: * | BG10: =SUMIF(AY10:BF10,"*",$AY$2:$BF$2)+BC10 -> 14 | BH10: =AT10*BG10 -> 840 | BJ10: =BH10+AT10*BI10 -> 840
C11: Массажер для спины оранжевый в пакете - 1 шт. | D11: 2039813223373 | E11: =_xlfn.XLOOKUP($D11,[1]Сводный!$E:$E,[1]Сводный!BR:BR,0) -> 20 | F11: =_xlfn.XLOOKUP($D11,[1]Сводный!$E:$E,[1]Сводный!BS:BS,0) -> 0 | G11: =_xlfn.XLOOKUP($D11,[1]Сводный!$E:$E,[1]Сводный!BT:BT,0) -> 0 | H11: =_xlfn.XLOOKUP($D11,[1]Сводный!$E:$E,[1]Сводный!BU:BU,0) -> 0 | I11: =_xlfn.XLOOKUP($D11,[1]Сводный!$E:$E,[1]Сводный!BV:BV,0) -> 0 | J11: =_xlfn.XLOOKUP($D11,[1]Сводный!$E:$E,[1]Сводный!BW:BW,0) -> 10 | K11: =_xlfn.XLOOKUP($D11,[1]Сводный!$E:$E,[1]Сводный!BX:BX,0) -> 0 | L11: =_xlfn.XLOOKUP($D11,[1]Сводный!$E:$E,[1]Сводный!BY:BY,0) -> 10 | M11: =_xlfn.XLOOKUP($D11,[1]Сводный!$E:$E,[1]Сводный!BZ:BZ,0) -> 0 | N11: =_xlfn.XLOOKUP($D11,[1]Сводный!$E:$E,[1]Сводный!CA:CA,0) -> 0 | O11: =_xlfn.XLOOKUP($D11,[1]Сводный!$E:$E,[1]Сводный!CB:CB,0) -> 10 | P11: =_xlfn.XLOOKUP($D11,[1]Сводный!$E:$E,[1]Сводный!CC:CC,0) -> 0 | Q11: =SUM(E11:P11) -> 50 | R11: {=_xlfn.XLOOKUP($D11,INDIRECT(R$2&"!"&"E:E"),INDIRECT(R$2&"!"&"C:C"),0)} -> 0 | S11: {=_xlfn.XLOOKUP($D11,INDIRECT(S$2&"!"&"E:E"),INDIRECT(S$2&"!"&"C:C"),0)} -> 0 | T11: {=_xlfn.XLOOKUP($D11,INDIRECT(T$2&"!"&"E:E"),INDIRECT(T$2&"!"&"C:C"),0)} -> 0 | U11: {=_xlfn.XLOOKUP($D11,INDIRECT(U$2&"!"&"E:E"),INDIRECT(U$2&"!"&"C:C"),0)} -> 0 | V11: {=_xlfn.XLOOKUP($D11,INDIRECT(V$2&"!"&"E:E"),INDIRECT(V$2&"!"&"C:C"),0)} -> 0 | W11: {=_xlfn.XLOOKUP($D11,INDIRECT(W$2&"!"&"E:E"),INDIRECT(W$2&"!"&"C:C"),0)} -> 0 | X11: {=_xlfn.XLOOKUP($D11,INDIRECT(X$2&"!"&"E:E"),INDIRECT(X$2&"!"&"C:C"),0)} -> 0 | Y11: {=_xlfn.XLOOKUP($D11,INDIRECT(Y$2&"!"&"E:E"),INDIRECT(Y$2&"!"&"C:C"),0)} -> 0 | ... AR11: {=_xlfn.XLOOKUP($D11,INDIRECT(AR$2&"!"&"E:E"),INDIRECT(AR$2&"!"&"C:C"),0)} -> 0 | AS11: =SUM(R11:AR11) -> 0 | AT11: =Q11+AS11 -> 50 | AU11: Приемка, маркировка (1 этикетка), короб, отгрузка. | AX11: =AT11 -> 50 | AY11: * | BE11: * | BF11: * | BG11: =SUMIF(AY11:BF11,"*",$AY$2:$BF$2)+BC11 -> 14 | BH11: =AT11*BG11 -> 700 | BJ11: =BH11+AT11*BI11 -> 700
A12: Мячик с шипами 6 см | C12: Мячик с шипами белый 6 см в пакете ОPP - 1 шт. | D12: 2040278804496 | E12: =_xlfn.XLOOKUP($D12,[1]Сводный!$E:$E,[1]Сводный!BR:BR,0) -> 75 | F12: =_xlfn.XLOOKUP($D12,[1]Сводный!$E:$E,[1]Сводный!BS:BS,0) -> 0 | G12: =_xlfn.XLOOKUP($D12,[1]Сводный!$E:$E,[1]Сводный!BT:BT,0) -> 0 | H12: =_xlfn.XLOOKUP($D12,[1]Сводный!$E:$E,[1]Сводный!BU:BU,0) -> 0 | I12: =_xlfn.XLOOKUP($D12,[1]Сводный!$E:$E,[1]Сводный!BV:BV,0) -> 0 | J12: =_xlfn.XLOOKUP($D12,[1]Сводный!$E:$E,[1]Сводный!BW:BW,0) -> 0 | K12: =_xlfn.XLOOKUP($D12,[1]Сводный!$E:$E,[1]Сводный!BX:BX,0) -> 0 | L12: =_xlfn.XLOOKUP($D12,[1]Сводный!$E:$E,[1]Сводный!BY:BY,0) -> 0 | M12: =_xlfn.XLOOKUP($D12,[1]Сводный!$E:$E,[1]Сводный!BZ:BZ,0) -> 0 | N12: =_xlfn.XLOOKUP($D12,[1]Сводный!$E:$E,[1]Сводный!CA:CA,0) -> 0 | O12: =_xlfn.XLOOKUP($D12,[1]Сводный!$E:$E,[1]Сводный!CB:CB,0) -> 50 | P12: =_xlfn.XLOOKUP($D12,[1]Сводный!$E:$E,[1]Сводный!CC:CC,0) -> 0 | Q12: =SUM(E12:P12) -> 125 | R12: {=_xlfn.XLOOKUP($D12,INDIRECT(R$2&"!"&"E:E"),INDIRECT(R$2&"!"&"C:C"),0)} -> 0 | S12: {=_xlfn.XLOOKUP($D12,INDIRECT(S$2&"!"&"E:E"),INDIRECT(S$2&"!"&"C:C"),0)} -> 0 | T12: {=_xlfn.XLOOKUP($D12,INDIRECT(T$2&"!"&"E:E"),INDIRECT(T$2&"!"&"C:C"),0)} -> 0 | U12: {=_xlfn.XLOOKUP($D12,INDIRECT(U$2&"!"&"E:E"),INDIRECT(U$2&"!"&"C:C"),0)} -> 0 | V12: {=_xlfn.XLOOKUP($D12,INDIRECT(V$2&"!"&"E:E"),INDIRECT(V$2&"!"&"C:C"),0)} -> 0 | W12: {=_xlfn.XLOOKUP($D12,INDIRECT(W$2&"!"&"E:E"),INDIRECT(W$2&"!"&"C:C"),0)} -> 0 | X12: {=_xlfn.XLOOKUP($D12,INDIRECT(X$2&"!"&"E:E"),INDIRECT(X$2&"!"&"C:C"),0)} -> 0 | Y12: {=_xlfn.XLOOKUP($D12,INDIRECT(Y$2&"!"&"E:E"),INDIRECT(Y$2&"!"&"C:C"),0)} -> 0 | ... AR12: {=_xlfn.XLOOKUP($D12,INDIRECT(AR$2&"!"&"E:E"),INDIRECT(AR$2&"!"&"C:C"),0)} -> 0 | AS12: =SUM(R12:AR12) -> 0 | AT12: =Q12+AS12 -> 125 | AU12: Приемка, маркировка (1 этикетка), короб, отгрузка. | AV12: Мячик с шипами упакован в заводской БОПП пакет. Этикетку с ШК клеить прямо на пакет. Внимательно, чтобы штрихкод не сжимался. Обычно мячики поставляются в коробах по норме упаковки 400 шт. Но я не всегда заказываю по норме упаковки. Тогда их смешивают, обычно разделяют картонкой или пленкой. | AX12: =AT12 -> 125 | AY12: * | BE12: * | BF12: * | BG12: =SUMIF(AY12:BF12,"*",$AY$2:$BF$2)+BC12 -> 14 | BH12: =AT12*BG12 -> 1750 | BJ12: =BH12+AT12*BI12 -> 1750
C13: Мячик розовый 6 см в пакете ОPP - 1 шт. | D13: 2040278810534 | E13: =_xlfn.XLOOKUP($D13,[1]Сводный!$E:$E,[1]Сводный!BR:BR,0) -> 100 | F13: =_xlfn.XLOOKUP($D13,[1]Сводный!$E:$E,[1]Сводный!BS:BS,0) -> 0 | G13: =_xlfn.XLOOKUP($D13,[1]Сводный!$E:$E,[1]Сводный!BT:BT,0) -> 0 | H13: =_xlfn.XLOOKUP($D13,[1]Сводный!$E:$E,[1]Сводный!BU:BU,0) -> 0 | I13: =_xlfn.XLOOKUP($D13,[1]Сводный!$E:$E,[1]Сводный!BV:BV,0) -> 0 | J13: =_xlfn.XLOOKUP($D13,[1]Сводный!$E:$E,[1]Сводный!BW:BW,0) -> 50 | K13: =_xlfn.XLOOKUP($D13,[1]Сводный!$E:$E,[1]Сводный!BX:BX,0) -> 0 | L13: =_xlfn.XLOOKUP($D13,[1]Сводный!$E:$E,[1]Сводный!BY:BY,0) -> 50 | M13: =_xlfn.XLOOKUP($D13,[1]Сводный!$E:$E,[1]Сводный!BZ:BZ,0) -> 0 | N13: =_xlfn.XLOOKUP($D13,[1]Сводный!$E:$E,[1]Сводный!CA:CA,0) -> 50 | O13: =_xlfn.XLOOKUP($D13,[1]Сводный!$E:$E,[1]Сводный!CB:CB,0) -> 50 | P13: =_xlfn.XLOOKUP($D13,[1]Сводный!$E:$E,[1]Сводный!CC:CC,0) -> 0 | Q13: =SUM(E13:P13) -> 300 | R13: {=_xlfn.XLOOKUP($D13,INDIRECT(R$2&"!"&"E:E"),INDIRECT(R$2&"!"&"C:C"),0)} -> 0 | S13: {=_xlfn.XLOOKUP($D13,INDIRECT(S$2&"!"&"E:E"),INDIRECT(S$2&"!"&"C:C"),0)} -> 0 | T13: {=_xlfn.XLOOKUP($D13,INDIRECT(T$2&"!"&"E:E"),INDIRECT(T$2&"!"&"C:C"),0)} -> 0 | U13: {=_xlfn.XLOOKUP($D13,INDIRECT(U$2&"!"&"E:E"),INDIRECT(U$2&"!"&"C:C"),0)} -> 0 | V13: {=_xlfn.XLOOKUP($D13,INDIRECT(V$2&"!"&"E:E"),INDIRECT(V$2&"!"&"C:C"),0)} -> 0 | W13: {=_xlfn.XLOOKUP($D13,INDIRECT(W$2&"!"&"E:E"),INDIRECT(W$2&"!"&"C:C"),0)} -> 0 | X13: {=_xlfn.XLOOKUP($D13,INDIRECT(X$2&"!"&"E:E"),INDIRECT(X$2&"!"&"C:C"),0)} -> 0 | Y13: {=_xlfn.XLOOKUP($D13,INDIRECT(Y$2&"!"&"E:E"),INDIRECT(Y$2&"!"&"C:C"),0)} -> 0 | ... AR13: {=_xlfn.XLOOKUP($D13,INDIRECT(AR$2&"!"&"E:E"),INDIRECT(AR$2&"!"&"C:C"),0)} -> 0 | AS13: =SUM(R13:AR13) -> 0 | AT13: =Q13+AS13 -> 300 | AU13: Приемка, маркировка (1 этикетка), короб, отгрузка. | AX13: =AT13 -> 300 | AY13: * | BE13: * | BF13: * | BG13: =SUMIF(AY13:BF13,"*",$AY$2:$BF$2)+BC13 -> 14 | BH13: =AT13*BG13 -> 4200 | BJ13: =BH13+AT13*BI13 -> 4200
C14: Мячик голубой 6 см в пакете ОPP - 1 шт. | D14: 2040278804649 | E14: =_xlfn.XLOOKUP($D14,[1]Сводный!$E:$E,[1]Сводный!BR:BR,0) -> 0 | F14: =_xlfn.XLOOKUP($D14,[1]Сводный!$E:$E,[1]Сводный!BS:BS,0) -> 0 | G14: =_xlfn.XLOOKUP($D14,[1]Сводный!$E:$E,[1]Сводный!BT:BT,0) -> 0 | H14: =_xlfn.XLOOKUP($D14,[1]Сводный!$E:$E,[1]Сводный!BU:BU,0) -> 0 | I14: =_xlfn.XLOOKUP($D14,[1]Сводный!$E:$E,[1]Сводный!BV:BV,0) -> 0 | J14: =_xlfn.XLOOKUP($D14,[1]Сводный!$E:$E,[1]Сводный!BW:BW,0) -> 0 | K14: =_xlfn.XLOOKUP($D14,[1]Сводный!$E:$E,[1]Сводный!BX:BX,0) -> 0 | L14: =_xlfn.XLOOKUP($D14,[1]Сводный!$E:$E,[1]Сводный!BY:BY,0) -> 20 | M14: =_xlfn.XLOOKUP($D14,[1]Сводный!$E:$E,[1]Сводный!BZ:BZ,0) -> 0 | N14: =_xlfn.XLOOKUP($D14,[1]Сводный!$E:$E,[1]Сводный!CA:CA,0) -> 50 | O14: =_xlfn.XLOOKUP($D14,[1]Сводный!$E:$E,[1]Сводный!CB:CB,0) -> 50 | P14: =_xlfn.XLOOKUP($D14,[1]Сводный!$E:$E,[1]Сводный!CC:CC,0) -> 0 | Q14: =SUM(E14:P14) -> 120 | R14: {=_xlfn.XLOOKUP($D14,INDIRECT(R$2&"!"&"E:E"),INDIRECT(R$2&"!"&"C:C"),0)} -> 0 | S14: {=_xlfn.XLOOKUP($D14,INDIRECT(S$2&"!"&"E:E"),INDIRECT(S$2&"!"&"C:C"),0)} -> 0 | T14: {=_xlfn.XLOOKUP($D14,INDIRECT(T$2&"!"&"E:E"),INDIRECT(T$2&"!"&"C:C"),0)} -> 0 | U14: {=_xlfn.XLOOKUP($D14,INDIRECT(U$2&"!"&"E:E"),INDIRECT(U$2&"!"&"C:C"),0)} -> 0 | V14: {=_xlfn.XLOOKUP($D14,INDIRECT(V$2&"!"&"E:E"),INDIRECT(V$2&"!"&"C:C"),0)} -> 0 | W14: {=_xlfn.XLOOKUP($D14,INDIRECT(W$2&"!"&"E:E"),INDIRECT(W$2&"!"&"C:C"),0)} -> 0 | X14: {=_xlfn.XLOOKUP($D14,INDIRECT(X$2&"!"&"E:E"),INDIRECT(X$2&"!"&"C:C"),0)} -> 0 | Y14: {=_xlfn.XLOOKUP($D14,INDIRECT(Y$2&"!"&"E:E"),INDIRECT(Y$2&"!"&"C:C"),0)} -> 0 | ... AR14: {=_xlfn.XLOOKUP($D14,INDIRECT(AR$2&"!"&"E:E"),INDIRECT(AR$2&"!"&"C:C"),0)} -> 0 | AS14: =SUM(R14:AR14) -> 0 | AT14: =Q14+AS14 -> 120 | AU14: Приемка, маркировка (1 этикетка), короб, отгрузка. | AX14: =AT14 -> 120 | AY14: * | BE14: * | BF14: * | BG14: =SUMIF(AY14:BF14,"*",$AY$2:$BF$2)+BC14 -> 14 | BH14: =AT14*BG14 -> 1680 | BJ14: =BH14+AT14*BI14 -> 1680
C15: Мячик оранжевый 6 см в пакете ОPP - 1 шт. | D15: 2039818580389 | E15: =_xlfn.XLOOKUP($D15,[1]Сводный!$E:$E,[1]Сводный!BR:BR,0) -> 0 | F15: =_xlfn.XLOOKUP($D15,[1]Сводный!$E:$E,[1]Сводный!BS:BS,0) -> 0 | G15: =_xlfn.XLOOKUP($D15,[1]Сводный!$E:$E,[1]Сводный!BT:BT,0) -> 0 | H15: =_xlfn.XLOOKUP($D15,[1]Сводный!$E:$E,[1]Сводный!BU:BU,0) -> 0 | I15: =_xlfn.XLOOKUP($D15,[1]Сводный!$E:$E,[1]Сводный!BV:BV,0) -> 0 | J15: =_xlfn.XLOOKUP($D15,[1]Сводный!$E:$E,[1]Сводный!BW:BW,0) -> 0 | K15: =_xlfn.XLOOKUP($D15,[1]Сводный!$E:$E,[1]Сводный!BX:BX,0) -> 0 | L15: =_xlfn.XLOOKUP($D15,[1]Сводный!$E:$E,[1]Сводный!BY:BY,0) -> 0 | M15: =_xlfn.XLOOKUP($D15,[1]Сводный!$E:$E,[1]Сводный!BZ:BZ,0) -> 0 | N15: =_xlfn.XLOOKUP($D15,[1]Сводный!$E:$E,[1]Сводный!CA:CA,0) -> 0 | O15: =_xlfn.XLOOKUP($D15,[1]Сводный!$E:$E,[1]Сводный!CB:CB,0) -> 20 | P15: =_xlfn.XLOOKUP($D15,[1]Сводный!$E:$E,[1]Сводный!CC:CC,0) -> 0 | Q15: =SUM(E15:P15) -> 20 | R15: {=_xlfn.XLOOKUP($D15,INDIRECT(R$2&"!"&"E:E"),INDIRECT(R$2&"!"&"C:C"),0)} -> 0 | S15: {=_xlfn.XLOOKUP($D15,INDIRECT(S$2&"!"&"E:E"),INDIRECT(S$2&"!"&"C:C"),0)} -> 0 | T15: {=_xlfn.XLOOKUP($D15,INDIRECT(T$2&"!"&"E:E"),INDIRECT(T$2&"!"&"C:C"),0)} -> 0 | U15: {=_xlfn.XLOOKUP($D15,INDIRECT(U$2&"!"&"E:E"),INDIRECT(U$2&"!"&"C:C"),0)} -> 0 | V15: {=_xlfn.XLOOKUP($D15,INDIRECT(V$2&"!"&"E:E"),INDIRECT(V$2&"!"&"C:C"),0)} -> 0 | W15: {=_xlfn.XLOOKUP($D15,INDIRECT(W$2&"!"&"E:E"),INDIRECT(W$2&"!"&"C:C"),0)} -> 0 | X15: {=_xlfn.XLOOKUP($D15,INDIRECT(X$2&"!"&"E:E"),INDIRECT(X$2&"!"&"C:C"),0)} -> 0 | Y15: {=_xlfn.XLOOKUP($D15,INDIRECT(Y$2&"!"&"E:E"),INDIRECT(Y$2&"!"&"C:C"),0)} -> 0 | ... AR15: {=_xlfn.XLOOKUP($D15,INDIRECT(AR$2&"!"&"E:E"),INDIRECT(AR$2&"!"&"C:C"),0)} -> 0 | AS15: =SUM(R15:AR15) -> 0 | AT15: =Q15+AS15 -> 20 | AU15: Приемка, маркировка (1 этикетка), короб, отгрузка. | AX15: =AT15 -> 20 | AY15: * | BE15: * | BF15: * | BG15: =SUMIF(AY15:BF15,"*",$AY$2:$BF$2)+BC15 -> 14 | BH15: =AT15*BG15 -> 280 | BJ15: =BH15+AT15*BI15 -> 280
C16: Мячик черный 6 см в пакете ОPP - 1 шт. | D16: 2043369663040 | E16: =_xlfn.XLOOKUP($D16,[1]Сводный!$E:$E,[1]Сводный!BR:BR,0) -> 50 | F16: =_xlfn.XLOOKUP($D16,[1]Сводный!$E:$E,[1]Сводный!BS:BS,0) -> 0 | G16: =_xlfn.XLOOKUP($D16,[1]Сводный!$E:$E,[1]Сводный!BT:BT,0) -> 0 | H16: =_xlfn.XLOOKUP($D16,[1]Сводный!$E:$E,[1]Сводный!BU:BU,0) -> 0 | I16: =_xlfn.XLOOKUP($D16,[1]Сводный!$E:$E,[1]Сводный!BV:BV,0) -> 0 | J16: =_xlfn.XLOOKUP($D16,[1]Сводный!$E:$E,[1]Сводный!BW:BW,0) -> 50 | K16: =_xlfn.XLOOKUP($D16,[1]Сводный!$E:$E,[1]Сводный!BX:BX,0) -> 0 | L16: =_xlfn.XLOOKUP($D16,[1]Сводный!$E:$E,[1]Сводный!BY:BY,0) -> 50 | M16: =_xlfn.XLOOKUP($D16,[1]Сводный!$E:$E,[1]Сводный!BZ:BZ,0) -> 0 | N16: =_xlfn.XLOOKUP($D16,[1]Сводный!$E:$E,[1]Сводный!CA:CA,0) -> 50 | O16: =_xlfn.XLOOKUP($D16,[1]Сводный!$E:$E,[1]Сводный!CB:CB,0) -> 50 | P16: =_xlfn.XLOOKUP($D16,[1]Сводный!$E:$E,[1]Сводный!CC:CC,0) -> 0 | Q16: =SUM(E16:P16) -> 250 | R16: {=_xlfn.XLOOKUP($D16,INDIRECT(R$2&"!"&"E:E"),INDIRECT(R$2&"!"&"C:C"),0)} -> 0 | S16: {=_xlfn.XLOOKUP($D16,INDIRECT(S$2&"!"&"E:E"),INDIRECT(S$2&"!"&"C:C"),0)} -> 0 | T16: {=_xlfn.XLOOKUP($D16,INDIRECT(T$2&"!"&"E:E"),INDIRECT(T$2&"!"&"C:C"),0)} -> 0 | U16: {=_xlfn.XLOOKUP($D16,INDIRECT(U$2&"!"&"E:E"),INDIRECT(U$2&"!"&"C:C"),0)} -> 0 | V16: {=_xlfn.XLOOKUP($D16,INDIRECT(V$2&"!"&"E:E"),INDIRECT(V$2&"!"&"C:C"),0)} -> 0 | W16: {=_xlfn.XLOOKUP($D16,INDIRECT(W$2&"!"&"E:E"),INDIRECT(W$2&"!"&"C:C"),0)} -> 0 | X16: {=_xlfn.XLOOKUP($D16,INDIRECT(X$2&"!"&"E:E"),INDIRECT(X$2&"!"&"C:C"),0)} -> 0 | Y16: {=_xlfn.XLOOKUP($D16,INDIRECT(Y$2&"!"&"E:E"),INDIRECT(Y$2&"!"&"C:C"),0)} -> 0 | ... AR16: {=_xlfn.XLOOKUP($D16,INDIRECT(AR$2&"!"&"E:E"),INDIRECT(AR$2&"!"&"C:C"),0)} -> 0 | AS16: =SUM(R16:AR16) -> 0 | AT16: =Q16+AS16 -> 250 | AU16: Приемка, маркировка (1 этикетка), короб, отгрузка. | AX16: =AT16 -> 250 | AY16: * | BE16: * | BF16: * | BG16: =SUMIF(AY16:BF16,"*",$AY$2:$BF$2)+BC16 -> 14 | BH16: =AT16*BG16 -> 3500 | BJ16: =BH16+AT16*BI16 -> 3500
A17: Мячик с шипами 7 см | C17: Мячик белый 7 см в пакете ОPP - 1 шт. | D17: 2044025326637 | E17: =_xlfn.XLOOKUP($D17,[1]Сводный!$E:$E,[1]Сводный!BR:BR,0) -> 100 | F17: =_xlfn.XLOOKUP($D17,[1]Сводный!$E:$E,[1]Сводный!BS:BS,0) -> 0 | G17: =_xlfn.XLOOKUP($D17,[1]Сводный!$E:$E,[1]Сводный!BT:BT,0) -> 0 | H17: =_xlfn.XLOOKUP($D17,[1]Сводный!$E:$E,[1]Сводный!BU:BU,0) -> 0 | I17: =_xlfn.XLOOKUP($D17,[1]Сводный!$E:$E,[1]Сводный!BV:BV,0) -> 0 | J17: =_xlfn.XLOOKUP($D17,[1]Сводный!$E:$E,[1]Сводный!BW:BW,0) -> 50 | K17: =_xlfn.XLOOKUP($D17,[1]Сводный!$E:$E,[1]Сводный!BX:BX,0) -> 0 | L17: =_xlfn.XLOOKUP($D17,[1]Сводный!$E:$E,[1]Сводный!BY:BY,0) -> 50 | M17: =_xlfn.XLOOKUP($D17,[1]Сводный!$E:$E,[1]Сводный!BZ:BZ,0) -> 0 | N17: =_xlfn.XLOOKUP($D17,[1]Сводный!$E:$E,[1]Сводный!CA:CA,0) -> 50 | O17: =_xlfn.XLOOKUP($D17,[1]Сводный!$E:$E,[1]Сводный!CB:CB,0) -> 50 | P17: =_xlfn.XLOOKUP($D17,[1]Сводный!$E:$E,[1]Сводный!CC:CC,0) -> 0 | Q17: =SUM(E17:P17) -> 300 | R17: {=_xlfn.XLOOKUP($D17,INDIRECT(R$2&"!"&"E:E"),INDIRECT(R$2&"!"&"C:C"),0)} -> 0 | S17: {=_xlfn.XLOOKUP($D17,INDIRECT(S$2&"!"&"E:E"),INDIRECT(S$2&"!"&"C:C"),0)} -> 0 | T17: {=_xlfn.XLOOKUP($D17,INDIRECT(T$2&"!"&"E:E"),INDIRECT(T$2&"!"&"C:C"),0)} -> 0 | U17: {=_xlfn.XLOOKUP($D17,INDIRECT(U$2&"!"&"E:E"),INDIRECT(U$2&"!"&"C:C"),0)} -> 0 | V17: {=_xlfn.XLOOKUP($D17,INDIRECT(V$2&"!"&"E:E"),INDIRECT(V$2&"!"&"C:C"),0)} -> 0 | W17: {=_xlfn.XLOOKUP($D17,INDIRECT(W$2&"!"&"E:E"),INDIRECT(W$2&"!"&"C:C"),0)} -> 0 | X17: {=_xlfn.XLOOKUP($D17,INDIRECT(X$2&"!"&"E:E"),INDIRECT(X$2&"!"&"C:C"),0)} -> 0 | Y17: {=_xlfn.XLOOKUP($D17,INDIRECT(Y$2&"!"&"E:E"),INDIRECT(Y$2&"!"&"C:C"),0)} -> 0 | ... AR17: {=_xlfn.XLOOKUP($D17,INDIRECT(AR$2&"!"&"E:E"),INDIRECT(AR$2&"!"&"C:C"),0)} -> 0 | AS17: =SUM(R17:AR17) -> 0 | AT17: =Q17+AS17 -> 300 | AU17: Приемка, маркировка (1 этикетка), короб, отгрузка. | AV17: Мячик с шипами упакован в заводской БОРР пакет. Этикетку с ШК клеить прямо на пакет. Внимательно, чтоб штрих-код не сжимался. | AX17: =AT17 -> 300 | AY17: * | BE17: * | BF17: * | BG17: =SUMIF(AY17:BF17,"*",$AY$2:$BF$2)+BC17 -> 14 | BH17: =AT17*BG17 -> 4200 | BJ17: =BH17+AT17*BI17 -> 4200
C18: Мячик розовый 7 см в пакете ОPP - 1 шт. | D18: 2044025316447 | E18: =_xlfn.XLOOKUP($D18,[1]Сводный!$E:$E,[1]Сводный!BR:BR,0) -> 20 | F18: =_xlfn.XLOOKUP($D18,[1]Сводный!$E:$E,[1]Сводный!BS:BS,0) -> 0 | G18: =_xlfn.XLOOKUP($D18,[1]Сводный!$E:$E,[1]Сводный!BT:BT,0) -> 0 | H18: =_xlfn.XLOOKUP($D18,[1]Сводный!$E:$E,[1]Сводный!BU:BU,0) -> 0 | I18: =_xlfn.XLOOKUP($D18,[1]Сводный!$E:$E,[1]Сводный!BV:BV,0) -> 0 | J18: =_xlfn.XLOOKUP($D18,[1]Сводный!$E:$E,[1]Сводный!BW:BW,0) -> 0 | K18: =_xlfn.XLOOKUP($D18,[1]Сводный!$E:$E,[1]Сводный!BX:BX,0) -> 0 | L18: =_xlfn.XLOOKUP($D18,[1]Сводный!$E:$E,[1]Сводный!BY:BY,0) -> 20 | M18: =_xlfn.XLOOKUP($D18,[1]Сводный!$E:$E,[1]Сводный!BZ:BZ,0) -> 0 | N18: =_xlfn.XLOOKUP($D18,[1]Сводный!$E:$E,[1]Сводный!CA:CA,0) -> 0 | O18: =_xlfn.XLOOKUP($D18,[1]Сводный!$E:$E,[1]Сводный!CB:CB,0) -> 20 | P18: =_xlfn.XLOOKUP($D18,[1]Сводный!$E:$E,[1]Сводный!CC:CC,0) -> 0 | Q18: =SUM(E18:P18) -> 60 | R18: {=_xlfn.XLOOKUP($D18,INDIRECT(R$2&"!"&"E:E"),INDIRECT(R$2&"!"&"C:C"),0)} -> 0 | S18: {=_xlfn.XLOOKUP($D18,INDIRECT(S$2&"!"&"E:E"),INDIRECT(S$2&"!"&"C:C"),0)} -> 0 | T18: {=_xlfn.XLOOKUP($D18,INDIRECT(T$2&"!"&"E:E"),INDIRECT(T$2&"!"&"C:C"),0)} -> 0 | U18: {=_xlfn.XLOOKUP($D18,INDIRECT(U$2&"!"&"E:E"),INDIRECT(U$2&"!"&"C:C"),0)} -> 0 | V18: {=_xlfn.XLOOKUP($D18,INDIRECT(V$2&"!"&"E:E"),INDIRECT(V$2&"!"&"C:C"),0)} -> 0 | W18: {=_xlfn.XLOOKUP($D18,INDIRECT(W$2&"!"&"E:E"),INDIRECT(W$2&"!"&"C:C"),0)} -> 0 | X18: {=_xlfn.XLOOKUP($D18,INDIRECT(X$2&"!"&"E:E"),INDIRECT(X$2&"!"&"C:C"),0)} -> 0 | Y18: {=_xlfn.XLOOKUP($D18,INDIRECT(Y$2&"!"&"E:E"),INDIRECT(Y$2&"!"&"C:C"),0)} -> 0 | ... AR18: {=_xlfn.XLOOKUP($D18,INDIRECT(AR$2&"!"&"E:E"),INDIRECT(AR$2&"!"&"C:C"),0)} -> 0 | AS18: =SUM(R18:AR18) -> 0 | AT18: =Q18+AS18 -> 60 | AU18: Приемка, маркировка (1 этикетка), короб, отгрузка. | AX18: =AT18 -> 60 | AY18: * | BE18: * | BF18: * | BG18: =SUMIF(AY18:BF18,"*",$AY$2:$BF$2)+BC18 -> 14 | BH18: =AT18*BG18 -> 840 | BJ18: =BH18+AT18*BI18 -> 840
C19: Мячик голубой 7 см в пакете ОPP - 1 шт. | D19: 2044025338661 | E19: =_xlfn.XLOOKUP($D19,[1]Сводный!$E:$E,[1]Сводный!BR:BR,0) -> 0 | F19: =_xlfn.XLOOKUP($D19,[1]Сводный!$E:$E,[1]Сводный!BS:BS,0) -> 0 | G19: =_xlfn.XLOOKUP($D19,[1]Сводный!$E:$E,[1]Сводный!BT:BT,0) -> 0 | H19: =_xlfn.XLOOKUP($D19,[1]Сводный!$E:$E,[1]Сводный!BU:BU,0) -> 0 | I19: =_xlfn.XLOOKUP($D19,[1]Сводный!$E:$E,[1]Сводный!BV:BV,0) -> 0 | J19: =_xlfn.XLOOKUP($D19,[1]Сводный!$E:$E,[1]Сводный!BW:BW,0) -> 0 | K19: =_xlfn.XLOOKUP($D19,[1]Сводный!$E:$E,[1]Сводный!BX:BX,0) -> 0 | L19: =_xlfn.XLOOKUP($D19,[1]Сводный!$E:$E,[1]Сводный!BY:BY,0) -> 20 | M19: =_xlfn.XLOOKUP($D19,[1]Сводный!$E:$E,[1]Сводный!BZ:BZ,0) -> 0 | N19: =_xlfn.XLOOKUP($D19,[1]Сводный!$E:$E,[1]Сводный!CA:CA,0) -> 0 | O19: =_xlfn.XLOOKUP($D19,[1]Сводный!$E:$E,[1]Сводный!CB:CB,0) -> 20 | P19: =_xlfn.XLOOKUP($D19,[1]Сводный!$E:$E,[1]Сводный!CC:CC,0) -> 0 | Q19: =SUM(E19:P19) -> 40 | R19: {=_xlfn.XLOOKUP($D19,INDIRECT(R$2&"!"&"E:E"),INDIRECT(R$2&"!"&"C:C"),0)} -> 0 | S19: {=_xlfn.XLOOKUP($D19,INDIRECT(S$2&"!"&"E:E"),INDIRECT(S$2&"!"&"C:C"),0)} -> 0 | T19: {=_xlfn.XLOOKUP($D19,INDIRECT(T$2&"!"&"E:E"),INDIRECT(T$2&"!"&"C:C"),0)} -> 0 | U19: {=_xlfn.XLOOKUP($D19,INDIRECT(U$2&"!"&"E:E"),INDIRECT(U$2&"!"&"C:C"),0)} -> 0 | V19: {=_xlfn.XLOOKUP($D19,INDIRECT(V$2&"!"&"E:E"),INDIRECT(V$2&"!"&"C:C"),0)} -> 0 | W19: {=_xlfn.XLOOKUP($D19,INDIRECT(W$2&"!"&"E:E"),INDIRECT(W$2&"!"&"C:C"),0)} -> 0 | X19: {=_xlfn.XLOOKUP($D19,INDIRECT(X$2&"!"&"E:E"),INDIRECT(X$2&"!"&"C:C"),0)} -> 0 | Y19: {=_xlfn.XLOOKUP($D19,INDIRECT(Y$2&"!"&"E:E"),INDIRECT(Y$2&"!"&"C:C"),0)} -> 0 | ... AR19: {=_xlfn.XLOOKUP($D19,INDIRECT(AR$2&"!"&"E:E"),INDIRECT(AR$2&"!"&"C:C"),0)} -> 0 | AS19: =SUM(R19:AR19) -> 0 | AT19: =Q19+AS19 -> 40 | AU19: Приемка, маркировка (1 этикетка), короб, отгрузка. | AX19: =AT19 -> 40 | AY19: * | BE19: * | BF19: * | BG19: =SUMIF(AY19:BF19,"*",$AY$2:$BF$2)+BC19 -> 14 | BH19: =AT19*BG19 -> 560 | BJ19: =BH19+AT19*BI19 -> 560
C20: Мячик оранжевый 7 см в пакете ОPP - 1 шт. | D20: 2044025288003 | E20: =_xlfn.XLOOKUP($D20,[1]Сводный!$E:$E,[1]Сводный!BR:BR,0) -> 10 | F20: =_xlfn.XLOOKUP($D20,[1]Сводный!$E:$E,[1]Сводный!BS:BS,0) -> 0 | G20: =_xlfn.XLOOKUP($D20,[1]Сводный!$E:$E,[1]Сводный!BT:BT,0) -> 0 | H20: =_xlfn.XLOOKUP($D20,[1]Сводный!$E:$E,[1]Сводный!BU:BU,0) -> 0 | I20: =_xlfn.XLOOKUP($D20,[1]Сводный!$E:$E,[1]Сводный!BV:BV,0) -> 0 | J20: =_xlfn.XLOOKUP($D20,[1]Сводный!$E:$E,[1]Сводный!BW:BW,0) -> 0 | K20: =_xlfn.XLOOKUP($D20,[1]Сводный!$E:$E,[1]Сводный!BX:BX,0) -> 0 | L20: =_xlfn.XLOOKUP($D20,[1]Сводный!$E:$E,[1]Сводный!BY:BY,0) -> 10 | M20: =_xlfn.XLOOKUP($D20,[1]Сводный!$E:$E,[1]Сводный!BZ:BZ,0) -> 0 | N20: =_xlfn.XLOOKUP($D20,[1]Сводный!$E:$E,[1]Сводный!CA:CA,0) -> 0 | O20: =_xlfn.XLOOKUP($D20,[1]Сводный!$E:$E,[1]Сводный!CB:CB,0) -> 10 | P20: =_xlfn.XLOOKUP($D20,[1]Сводный!$E:$E,[1]Сводный!CC:CC,0) -> 0 | Q20: =SUM(E20:P20) -> 30 | R20: {=_xlfn.XLOOKUP($D20,INDIRECT(R$2&"!"&"E:E"),INDIRECT(R$2&"!"&"C:C"),0)} -> 0 | S20: {=_xlfn.XLOOKUP($D20,INDIRECT(S$2&"!"&"E:E"),INDIRECT(S$2&"!"&"C:C"),0)} -> 0 | T20: {=_xlfn.XLOOKUP($D20,INDIRECT(T$2&"!"&"E:E"),INDIRECT(T$2&"!"&"C:C"),0)} -> 0 | U20: {=_xlfn.XLOOKUP($D20,INDIRECT(U$2&"!"&"E:E"),INDIRECT(U$2&"!"&"C:C"),0)} -> 0 | V20: {=_xlfn.XLOOKUP($D20,INDIRECT(V$2&"!"&"E:E"),INDIRECT(V$2&"!"&"C:C"),0)} -> 0 | W20: {=_xlfn.XLOOKUP($D20,INDIRECT(W$2&"!"&"E:E"),INDIRECT(W$2&"!"&"C:C"),0)} -> 0 | X20: {=_xlfn.XLOOKUP($D20,INDIRECT(X$2&"!"&"E:E"),INDIRECT(X$2&"!"&"C:C"),0)} -> 0 | Y20: {=_xlfn.XLOOKUP($D20,INDIRECT(Y$2&"!"&"E:E"),INDIRECT(Y$2&"!"&"C:C"),0)} -> 0 | ... AR20: {=_xlfn.XLOOKUP($D20,INDIRECT(AR$2&"!"&"E:E"),INDIRECT(AR$2&"!"&"C:C"),0)} -> 0 | AS20: =SUM(R20:AR20) -> 0 | AT20: =Q20+AS20 -> 30 | AU20: Приемка, маркировка (1 этикетка), короб, отгрузка. | AX20: =AT20 -> 30 | AY20: * | BE20: * | BF20: * | BG20: =SUMIF(AY20:BF20,"*",$AY$2:$BF$2)+BC20 -> 14 | BH20: =AT20*BG20 -> 420 | BJ20: =BH20+AT20*BI20 -> 420
C21: Мячик черный 7 см в пакете ОPP - 1 шт. | D21: 2044025344532 | E21: =_xlfn.XLOOKUP($D21,[1]Сводный!$E:$E,[1]Сводный!BR:BR,0) -> 0 | F21: =_xlfn.XLOOKUP($D21,[1]Сводный!$E:$E,[1]Сводный!BS:BS,0) -> 0 | G21: =_xlfn.XLOOKUP($D21,[1]Сводный!$E:$E,[1]Сводный!BT:BT,0) -> 0 | H21: =_xlfn.XLOOKUP($D21,[1]Сводный!$E:$E,[1]Сводный!BU:BU,0) -> 0 | I21: =_xlfn.XLOOKUP($D21,[1]Сводный!$E:$E,[1]Сводный!BV:BV,0) -> 0 | J21: =_xlfn.XLOOKUP($D21,[1]Сводный!$E:$E,[1]Сводный!BW:BW,0) -> 0 | K21: =_xlfn.XLOOKUP($D21,[1]Сводный!$E:$E,[1]Сводный!BX:BX,0) -> 0 | L21: =_xlfn.XLOOKUP($D21,[1]Сводный!$E:$E,[1]Сводный!BY:BY,0) -> 10 | M21: =_xlfn.XLOOKUP($D21,[1]Сводный!$E:$E,[1]Сводный!BZ:BZ,0) -> 0 | N21: =_xlfn.XLOOKUP($D21,[1]Сводный!$E:$E,[1]Сводный!CA:CA,0) -> 0 | O21: =_xlfn.XLOOKUP($D21,[1]Сводный!$E:$E,[1]Сводный!CB:CB,0) -> 20 | P21: =_xlfn.XLOOKUP($D21,[1]Сводный!$E:$E,[1]Сводный!CC:CC,0) -> 0 | Q21: =SUM(E21:P21) -> 30 | R21: {=_xlfn.XLOOKUP($D21,INDIRECT(R$2&"!"&"E:E"),INDIRECT(R$2&"!"&"C:C"),0)} -> 0 | S21: {=_xlfn.XLOOKUP($D21,INDIRECT(S$2&"!"&"E:E"),INDIRECT(S$2&"!"&"C:C"),0)} -> 0 | T21: {=_xlfn.XLOOKUP($D21,INDIRECT(T$2&"!"&"E:E"),INDIRECT(T$2&"!"&"C:C"),0)} -> 0 | U21: {=_xlfn.XLOOKUP($D21,INDIRECT(U$2&"!"&"E:E"),INDIRECT(U$2&"!"&"C:C"),0)} -> 0 | V21: {=_xlfn.XLOOKUP($D21,INDIRECT(V$2&"!"&"E:E"),INDIRECT(V$2&"!"&"C:C"),0)} -> 0 | W21: {=_xlfn.XLOOKUP($D21,INDIRECT(W$2&"!"&"E:E"),INDIRECT(W$2&"!"&"C:C"),0)} -> 0 | X21: {=_xlfn.XLOOKUP($D21,INDIRECT(X$2&"!"&"E:E"),INDIRECT(X$2&"!"&"C:C"),0)} -> 0 | Y21: {=_xlfn.XLOOKUP($D21,INDIRECT(Y$2&"!"&"E:E"),INDIRECT(Y$2&"!"&"C:C"),0)} -> 0 | ... AR21: {=_xlfn.XLOOKUP($D21,INDIRECT(AR$2&"!"&"E:E"),INDIRECT(AR$2&"!"&"C:C"),0)} -> 0 | AS21: =SUM(R21:AR21) -> 0 | AT21: =Q21+AS21 -> 30 | AU21: Приемка, маркировка (1 этикетка), короб, отгрузка. | AX21: =AT21 -> 30 | AY21: * | BE21: * | BF21: * | BG21: =SUMIF(AY21:BF21,"*",$AY$2:$BF$2)+BC21 -> 14 | BH21: =AT21*BG21 -> 420 | BJ21: =BH21+AT21*BI21 -> 420
A22: Мячик с шипами 9 см | C22: Мячик розовый 9 см в пакете ОPP - 1 шт. | D22: 2044025321588 | E22: =_xlfn.XLOOKUP($D22,[1]Сводный!$E:$E,[1]Сводный!BR:BR,0) -> 30 | F22: =_xlfn.XLOOKUP($D22,[1]Сводный!$E:$E,[1]Сводный!BS:BS,0) -> 0 | G22: =_xlfn.XLOOKUP($D22,[1]Сводный!$E:$E,[1]Сводный!BT:BT,0) -> 0 | H22: =_xlfn.XLOOKUP($D22,[1]Сводный!$E:$E,[1]Сводный!BU:BU,0) -> 0 | I22: =_xlfn.XLOOKUP($D22,[1]Сводный!$E:$E,[1]Сводный!BV:BV,0) -> 0 | J22: =_xlfn.XLOOKUP($D22,[1]Сводный!$E:$E,[1]Сводный!BW:BW,0) -> 30 | K22: =_xlfn.XLOOKUP($D22,[1]Сводный!$E:$E,[1]Сводный!BX:BX,0) -> 0 | L22: =_xlfn.XLOOKUP($D22,[1]Сводный!$E:$E,[1]Сводный!BY:BY,0) -> 30 | M22: =_xlfn.XLOOKUP($D22,[1]Сводный!$E:$E,[1]Сводный!BZ:BZ,0) -> 0 | N22: =_xlfn.XLOOKUP($D22,[1]Сводный!$E:$E,[1]Сводный!CA:CA,0) -> 30 | O22: =_xlfn.XLOOKUP($D22,[1]Сводный!$E:$E,[1]Сводный!CB:CB,0) -> 30 | P22: =_xlfn.XLOOKUP($D22,[1]Сводный!$E:$E,[1]Сводный!CC:CC,0) -> 0 | Q22: =SUM(E22:P22) -> 150 | R22: {=_xlfn.XLOOKUP($D22,INDIRECT(R$2&"!"&"E:E"),INDIRECT(R$2&"!"&"C:C"),0)} -> 0 | S22: {=_xlfn.XLOOKUP($D22,INDIRECT(S$2&"!"&"E:E"),INDIRECT(S$2&"!"&"C:C"),0)} -> 0 | T22: {=_xlfn.XLOOKUP($D22,INDIRECT(T$2&"!"&"E:E"),INDIRECT(T$2&"!"&"C:C"),0)} -> 0 | U22: {=_xlfn.XLOOKUP($D22,INDIRECT(U$2&"!"&"E:E"),INDIRECT(U$2&"!"&"C:C"),0)} -> 0 | V22: {=_xlfn.XLOOKUP($D22,INDIRECT(V$2&"!"&"E:E"),INDIRECT(V$2&"!"&"C:C"),0)} -> 0 | W22: {=_xlfn.XLOOKUP($D22,INDIRECT(W$2&"!"&"E:E"),INDIRECT(W$2&"!"&"C:C"),0)} -> 0 | X22: {=_xlfn.XLOOKUP($D22,INDIRECT(X$2&"!"&"E:E"),INDIRECT(X$2&"!"&"C:C"),0)} -> 0 | Y22: {=_xlfn.XLOOKUP($D22,INDIRECT(Y$2&"!"&"E:E"),INDIRECT(Y$2&"!"&"C:C"),0)} -> 0 | ... AR22: {=_xlfn.XLOOKUP($D22,INDIRECT(AR$2&"!"&"E:E"),INDIRECT(AR$2&"!"&"C:C"),0)} -> 0 | AS22: =SUM(R22:AR22) -> 0 | AT22: =Q22+AS22 -> 150 | AU22: Приемка, маркировка (1 этикетка), короб, отгрузка. | AV22: Мячик с шипами упакован в заводской ОРР пакет. Этикетку с ШК клеить прямо на пакет. Внимательно, чтоб штрих-код не сжимался. | AX22: =AT22 -> 150 | AY22: * | BE22: * | BF22: * | BG22: =SUMIF(AY22:BF22,"*",$AY$2:$BF$2)+BC22 -> 14 | BH22: =AT22*BG22 -> 2100 | BJ22: =BH22+AT22*BI22 -> 2100
C23: Мячик голубой 9 см в пакете ОPP - 1 шт. | D23: 2044025342057 | E23: =_xlfn.XLOOKUP($D23,[1]Сводный!$E:$E,[1]Сводный!BR:BR,0) -> 0 | F23: =_xlfn.XLOOKUP($D23,[1]Сводный!$E:$E,[1]Сводный!BS:BS,0) -> 0 | G23: =_xlfn.XLOOKUP($D23,[1]Сводный!$E:$E,[1]Сводный!BT:BT,0) -> 0 | H23: =_xlfn.XLOOKUP($D23,[1]Сводный!$E:$E,[1]Сводный!BU:BU,0) -> 0 | I23: =_xlfn.XLOOKUP($D23,[1]Сводный!$E:$E,[1]Сводный!BV:BV,0) -> 0 | J23: =_xlfn.XLOOKUP($D23,[1]Сводный!$E:$E,[1]Сводный!BW:BW,0) -> 0 | K23: =_xlfn.XLOOKUP($D23,[1]Сводный!$E:$E,[1]Сводный!BX:BX,0) -> 0 | L23: =_xlfn.XLOOKUP($D23,[1]Сводный!$E:$E,[1]Сводный!BY:BY,0) -> 20 | M23: =_xlfn.XLOOKUP($D23,[1]Сводный!$E:$E,[1]Сводный!BZ:BZ,0) -> 0 | N23: =_xlfn.XLOOKUP($D23,[1]Сводный!$E:$E,[1]Сводный!CA:CA,0) -> 0 | O23: =_xlfn.XLOOKUP($D23,[1]Сводный!$E:$E,[1]Сводный!CB:CB,0) -> 20 | P23: =_xlfn.XLOOKUP($D23,[1]Сводный!$E:$E,[1]Сводный!CC:CC,0) -> 0 | Q23: =SUM(E23:P23) -> 40 | R23: {=_xlfn.XLOOKUP($D23,INDIRECT(R$2&"!"&"E:E"),INDIRECT(R$2&"!"&"C:C"),0)} -> 0 | S23: {=_xlfn.XLOOKUP($D23,INDIRECT(S$2&"!"&"E:E"),INDIRECT(S$2&"!"&"C:C"),0)} -> 0 | T23: {=_xlfn.XLOOKUP($D23,INDIRECT(T$2&"!"&"E:E"),INDIRECT(T$2&"!"&"C:C"),0)} -> 0 | U23: {=_xlfn.XLOOKUP($D23,INDIRECT(U$2&"!"&"E:E"),INDIRECT(U$2&"!"&"C:C"),0)} -> 0 | V23: {=_xlfn.XLOOKUP($D23,INDIRECT(V$2&"!"&"E:E"),INDIRECT(V$2&"!"&"C:C"),0)} -> 0 | W23: {=_xlfn.XLOOKUP($D23,INDIRECT(W$2&"!"&"E:E"),INDIRECT(W$2&"!"&"C:C"),0)} -> 0 | X23: {=_xlfn.XLOOKUP($D23,INDIRECT(X$2&"!"&"E:E"),INDIRECT(X$2&"!"&"C:C"),0)} -> 0 | Y23: {=_xlfn.XLOOKUP($D23,INDIRECT(Y$2&"!"&"E:E"),INDIRECT(Y$2&"!"&"C:C"),0)} -> 0 | ... AR23: {=_xlfn.XLOOKUP($D23,INDIRECT(AR$2&"!"&"E:E"),INDIRECT(AR$2&"!"&"C:C"),0)} -> 0 | AS23: =SUM(R23:AR23) -> 0 | AT23: =Q23+AS23 -> 40 | AU23: Приемка, маркировка (1 этикетка), короб, отгрузка. | AX23: =AT23 -> 40 | AY23: * | BE23: * | BF23: * | BG23: =SUMIF(AY23:BF23,"*",$AY$2:$BF$2)+BC23 -> 14 | BH23: =AT23*BG23 -> 560 | BJ23: =BH23+AT23*BI23 -> 560
C24: Мячик оранжевый 9 см в пакете ОPP - 1 шт. | D24: 2044025291485 | E24: =_xlfn.XLOOKUP($D24,[1]Сводный!$E:$E,[1]Сводный!BR:BR,0) -> 20 | F24: =_xlfn.XLOOKUP($D24,[1]Сводный!$E:$E,[1]Сводный!BS:BS,0) -> 0 | G24: =_xlfn.XLOOKUP($D24,[1]Сводный!$E:$E,[1]Сводный!BT:BT,0) -> 0 | H24: =_xlfn.XLOOKUP($D24,[1]Сводный!$E:$E,[1]Сводный!BU:BU,0) -> 0 | I24: =_xlfn.XLOOKUP($D24,[1]Сводный!$E:$E,[1]Сводный!BV:BV,0) -> 0 | J24: =_xlfn.XLOOKUP($D24,[1]Сводный!$E:$E,[1]Сводный!BW:BW,0) -> 20 | K24: =_xlfn.XLOOKUP($D24,[1]Сводный!$E:$E,[1]Сводный!BX:BX,0) -> 0 | L24: =_xlfn.XLOOKUP($D24,[1]Сводный!$E:$E,[1]Сводный!BY:BY,0) -> 20 | M24: =_xlfn.XLOOKUP($D24,[1]Сводный!$E:$E,[1]Сводный!BZ:BZ,0) -> 0 | N24: =_xlfn.XLOOKUP($D24,[1]Сводный!$E:$E,[1]Сводный!CA:CA,0) -> 20 | O24: =_xlfn.XLOOKUP($D24,[1]Сводный!$E:$E,[1]Сводный!CB:CB,0) -> 20 | P24: =_xlfn.XLOOKUP($D24,[1]Сводный!$E:$E,[1]Сводный!CC:CC,0) -> 0 | Q24: =SUM(E24:P24) -> 100 | R24: {=_xlfn.XLOOKUP($D24,INDIRECT(R$2&"!"&"E:E"),INDIRECT(R$2&"!"&"C:C"),0)} -> 0 | S24: {=_xlfn.XLOOKUP($D24,INDIRECT(S$2&"!"&"E:E"),INDIRECT(S$2&"!"&"C:C"),0)} -> 0 | T24: {=_xlfn.XLOOKUP($D24,INDIRECT(T$2&"!"&"E:E"),INDIRECT(T$2&"!"&"C:C"),0)} -> 0 | U24: {=_xlfn.XLOOKUP($D24,INDIRECT(U$2&"!"&"E:E"),INDIRECT(U$2&"!"&"C:C"),0)} -> 0 | V24: {=_xlfn.XLOOKUP($D24,INDIRECT(V$2&"!"&"E:E"),INDIRECT(V$2&"!"&"C:C"),0)} -> 0 | W24: {=_xlfn.XLOOKUP($D24,INDIRECT(W$2&"!"&"E:E"),INDIRECT(W$2&"!"&"C:C"),0)} -> 0 | X24: {=_xlfn.XLOOKUP($D24,INDIRECT(X$2&"!"&"E:E"),INDIRECT(X$2&"!"&"C:C"),0)} -> 0 | Y24: {=_xlfn.XLOOKUP($D24,INDIRECT(Y$2&"!"&"E:E"),INDIRECT(Y$2&"!"&"C:C"),0)} -> 0 | ... AR24: {=_xlfn.XLOOKUP($D24,INDIRECT(AR$2&"!"&"E:E"),INDIRECT(AR$2&"!"&"C:C"),0)} -> 0 | AS24: =SUM(R24:AR24) -> 0 | AT24: =Q24+AS24 -> 100 | AU24: Приемка, маркировка (1 этикетка), короб, отгрузка. | AX24: =AT24 -> 100 | AY24: * | BE24: * | BF24: * | BG24: =SUMIF(AY24:BF24,"*",$AY$2:$BF$2)+BC24 -> 14 | BH24: =AT24*BG24 -> 1400 | BJ24: =BH24+AT24*BI24 -> 1400
C25: Мячик фиолетовый 9 см в пакете ОPP - 1 шт. | D25: 2044025354937 | E25: =_xlfn.XLOOKUP($D25,[1]Сводный!$E:$E,[1]Сводный!BR:BR,0) -> 25 | F25: =_xlfn.XLOOKUP($D25,[1]Сводный!$E:$E,[1]Сводный!BS:BS,0) -> 0 | G25: =_xlfn.XLOOKUP($D25,[1]Сводный!$E:$E,[1]Сводный!BT:BT,0) -> 0 | H25: =_xlfn.XLOOKUP($D25,[1]Сводный!$E:$E,[1]Сводный!BU:BU,0) -> 0 | I25: =_xlfn.XLOOKUP($D25,[1]Сводный!$E:$E,[1]Сводный!BV:BV,0) -> 0 | J25: =_xlfn.XLOOKUP($D25,[1]Сводный!$E:$E,[1]Сводный!BW:BW,0) -> 0 | K25: =_xlfn.XLOOKUP($D25,[1]Сводный!$E:$E,[1]Сводный!BX:BX,0) -> 0 | L25: =_xlfn.XLOOKUP($D25,[1]Сводный!$E:$E,[1]Сводный!BY:BY,0) -> 20 | M25: =_xlfn.XLOOKUP($D25,[1]Сводный!$E:$E,[1]Сводный!BZ:BZ,0) -> 0 | N25: =_xlfn.XLOOKUP($D25,[1]Сводный!$E:$E,[1]Сводный!CA:CA,0) -> 15 | O25: =_xlfn.XLOOKUP($D25,[1]Сводный!$E:$E,[1]Сводный!CB:CB,0) -> 20 | P25: =_xlfn.XLOOKUP($D25,[1]Сводный!$E:$E,[1]Сводный!CC:CC,0) -> 0 | Q25: =SUM(E25:P25) -> 80 | R25: {=_xlfn.XLOOKUP($D25,INDIRECT(R$2&"!"&"E:E"),INDIRECT(R$2&"!"&"C:C"),0)} -> 0 | S25: {=_xlfn.XLOOKUP($D25,INDIRECT(S$2&"!"&"E:E"),INDIRECT(S$2&"!"&"C:C"),0)} -> 0 | T25: {=_xlfn.XLOOKUP($D25,INDIRECT(T$2&"!"&"E:E"),INDIRECT(T$2&"!"&"C:C"),0)} -> 0 | U25: {=_xlfn.XLOOKUP($D25,INDIRECT(U$2&"!"&"E:E"),INDIRECT(U$2&"!"&"C:C"),0)} -> 0 | V25: {=_xlfn.XLOOKUP($D25,INDIRECT(V$2&"!"&"E:E"),INDIRECT(V$2&"!"&"C:C"),0)} -> 0 | W25: {=_xlfn.XLOOKUP($D25,INDIRECT(W$2&"!"&"E:E"),INDIRECT(W$2&"!"&"C:C"),0)} -> 0 | X25: {=_xlfn.XLOOKUP($D25,INDIRECT(X$2&"!"&"E:E"),INDIRECT(X$2&"!"&"C:C"),0)} -> 0 | Y25: {=_xlfn.XLOOKUP($D25,INDIRECT(Y$2&"!"&"E:E"),INDIRECT(Y$2&"!"&"C:C"),0)} -> 0 | ... AR25: {=_xlfn.XLOOKUP($D25,INDIRECT(AR$2&"!"&"E:E"),INDIRECT(AR$2&"!"&"C:C"),0)} -> 0 | AS25: =SUM(R25:AR25) -> 0 | AT25: =Q25+AS25 -> 80 | AU25: Приемка, маркировка (1 этикетка), короб, отгрузка. | AX25: =AT25 -> 80 | AY25: * | BE25: * | BF25: * | BG25: =SUMIF(AY25:BF25,"*",$AY$2:$BF$2)+BC25 -> 14 | BH25: =AT25*BG25 -> 1120 | BJ25: =BH25+AT25*BI25 -> 1120
C26: Мячик черный 9 см в пакете ОPP - 1 шт. | D26: 2044025347953 | E26: =_xlfn.XLOOKUP($D26,[1]Сводный!$E:$E,[1]Сводный!BR:BR,0) -> 10 | F26: =_xlfn.XLOOKUP($D26,[1]Сводный!$E:$E,[1]Сводный!BS:BS,0) -> 0 | G26: =_xlfn.XLOOKUP($D26,[1]Сводный!$E:$E,[1]Сводный!BT:BT,0) -> 0 | H26: =_xlfn.XLOOKUP($D26,[1]Сводный!$E:$E,[1]Сводный!BU:BU,0) -> 0 | I26: =_xlfn.XLOOKUP($D26,[1]Сводный!$E:$E,[1]Сводный!BV:BV,0) -> 0 | J26: =_xlfn.XLOOKUP($D26,[1]Сводный!$E:$E,[1]Сводный!BW:BW,0) -> 0 | K26: =_xlfn.XLOOKUP($D26,[1]Сводный!$E:$E,[1]Сводный!BX:BX,0) -> 0 | L26: =_xlfn.XLOOKUP($D26,[1]Сводный!$E:$E,[1]Сводный!BY:BY,0) -> 0 | M26: =_xlfn.XLOOKUP($D26,[1]Сводный!$E:$E,[1]Сводный!BZ:BZ,0) -> 0 | N26: =_xlfn.XLOOKUP($D26,[1]Сводный!$E:$E,[1]Сводный!CA:CA,0) -> 0 | O26: =_xlfn.XLOOKUP($D26,[1]Сводный!$E:$E,[1]Сводный!CB:CB,0) -> 20 | P26: =_xlfn.XLOOKUP($D26,[1]Сводный!$E:$E,[1]Сводный!CC:CC,0) -> 0 | Q26: =SUM(E26:P26) -> 30 | R26: {=_xlfn.XLOOKUP($D26,INDIRECT(R$2&"!"&"E:E"),INDIRECT(R$2&"!"&"C:C"),0)} -> 0 | S26: {=_xlfn.XLOOKUP($D26,INDIRECT(S$2&"!"&"E:E"),INDIRECT(S$2&"!"&"C:C"),0)} -> 0 | T26: {=_xlfn.XLOOKUP($D26,INDIRECT(T$2&"!"&"E:E"),INDIRECT(T$2&"!"&"C:C"),0)} -> 0 | U26: {=_xlfn.XLOOKUP($D26,INDIRECT(U$2&"!"&"E:E"),INDIRECT(U$2&"!"&"C:C"),0)} -> 0 | V26: {=_xlfn.XLOOKUP($D26,INDIRECT(V$2&"!"&"E:E"),INDIRECT(V$2&"!"&"C:C"),0)} -> 0 | W26: {=_xlfn.XLOOKUP($D26,INDIRECT(W$2&"!"&"E:E"),INDIRECT(W$2&"!"&"C:C"),0)} -> 0 | X26: {=_xlfn.XLOOKUP($D26,INDIRECT(X$2&"!"&"E:E"),INDIRECT(X$2&"!"&"C:C"),0)} -> 0 | Y26: {=_xlfn.XLOOKUP($D26,INDIRECT(Y$2&"!"&"E:E"),INDIRECT(Y$2&"!"&"C:C"),0)} -> 0 | ... AR26: {=_xlfn.XLOOKUP($D26,INDIRECT(AR$2&"!"&"E:E"),INDIRECT(AR$2&"!"&"C:C"),0)} -> 0 | AS26: =SUM(R26:AR26) -> 0 | AT26: =Q26+AS26 -> 30 | AU26: Приемка, маркировка (1 этикетка), короб, отгрузка. | AX26: =AT26 -> 30 | AY26: * | BE26: * | BF26: * | BG26: =SUMIF(AY26:BF26,"*",$AY$2:$BF$2)+BC26 -> 14 | BH26: =AT26*BG26 -> 420 | BJ26: =BH26+AT26*BI26 -> 420
A27: Мячик гладкий | C27: Мяч гладкий розовый | D27: 2042985583893 | E27: =_xlfn.XLOOKUP($D27,[1]Сводный!$E:$E,[1]Сводный!BR:BR,0) -> 0 | F27: =_xlfn.XLOOKUP($D27,[1]Сводный!$E:$E,[1]Сводный!BS:BS,0) -> 0 | G27: =_xlfn.XLOOKUP($D27,[1]Сводный!$E:$E,[1]Сводный!BT:BT,0) -> 0 | H27: =_xlfn.XLOOKUP($D27,[1]Сводный!$E:$E,[1]Сводный!BU:BU,0) -> 0 | I27: =_xlfn.XLOOKUP($D27,[1]Сводный!$E:$E,[1]Сводный!BV:BV,0) -> 0 | J27: =_xlfn.XLOOKUP($D27,[1]Сводный!$E:$E,[1]Сводный!BW:BW,0) -> 0 | K27: =_xlfn.XLOOKUP($D27,[1]Сводный!$E:$E,[1]Сводный!BX:BX,0) -> 0 | L27: =_xlfn.XLOOKUP($D27,[1]Сводный!$E:$E,[1]Сводный!BY:BY,0) -> 0 | M27: =_xlfn.XLOOKUP($D27,[1]Сводный!$E:$E,[1]Сводный!BZ:BZ,0) -> 0 | N27: =_xlfn.XLOOKUP($D27,[1]Сводный!$E:$E,[1]Сводный!CA:CA,0) -> 0 | O27: =_xlfn.XLOOKUP($D27,[1]Сводный!$E:$E,[1]Сводный!CB:CB,0) -> 0 | P27: =_xlfn.XLOOKUP($D27,[1]Сводный!$E:$E,[1]Сводный!CC:CC,0) -> 0 | Q27: =SUM(E27:P27) -> 0 | R27: {=_xlfn.XLOOKUP($D27,INDIRECT(R$2&"!"&"E:E"),INDIRECT(R$2&"!"&"C:C"),0)} -> 0 | S27: {=_xlfn.XLOOKUP($D27,INDIRECT(S$2&"!"&"E:E"),INDIRECT(S$2&"!"&"C:C"),0)} -> 0 | T27: {=_xlfn.XLOOKUP($D27,INDIRECT(T$2&"!"&"E:E"),INDIRECT(T$2&"!"&"C:C"),0)} -> 0 | U27: {=_xlfn.XLOOKUP($D27,INDIRECT(U$2&"!"&"E:E"),INDIRECT(U$2&"!"&"C:C"),0)} -> 0 | V27: {=_xlfn.XLOOKUP($D27,INDIRECT(V$2&"!"&"E:E"),INDIRECT(V$2&"!"&"C:C"),0)} -> 0 | W27: {=_xlfn.XLOOKUP($D27,INDIRECT(W$2&"!"&"E:E"),INDIRECT(W$2&"!"&"C:C"),0)} -> 0 | X27: {=_xlfn.XLOOKUP($D27,INDIRECT(X$2&"!"&"E:E"),INDIRECT(X$2&"!"&"C:C"),0)} -> 0 | Y27: {=_xlfn.XLOOKUP($D27,INDIRECT(Y$2&"!"&"E:E"),INDIRECT(Y$2&"!"&"C:C"),0)} -> 0 | ... AR27: {=_xlfn.XLOOKUP($D27,INDIRECT(AR$2&"!"&"E:E"),INDIRECT(AR$2&"!"&"C:C"),0)} -> 0 | AS27: =SUM(R27:AR27) -> 0 | AT27: =Q27+AS27 -> 0 | AU27: Приемка, короб, отгрузка. | AV27: Мячик с шипами упакован в заводской БОРР пакет. Этикетку с ШК клеить прямо на пакет. Внимательно, чтоб штрих-код не сжимался. | AX27: =AT27 -> 0 | AY27: * | BF27: * | BG27: =SUMIF(AY27:BF27,"*",$AY$2:$BF$2)+BC27 -> 8 | BH27: =AT27*BG27 -> 0 | BJ27: =BH27+AT27*BI27 -> 0
C28: Мяч гладкий голубой | D28: 2042986356632 | E28: =_xlfn.XLOOKUP($D28,[1]Сводный!$E:$E,[1]Сводный!BR:BR,0) -> 0 | F28: =_xlfn.XLOOKUP($D28,[1]Сводный!$E:$E,[1]Сводный!BS:BS,0) -> 0 | G28: =_xlfn.XLOOKUP($D28,[1]Сводный!$E:$E,[1]Сводный!BT:BT,0) -> 0 | H28: =_xlfn.XLOOKUP($D28,[1]Сводный!$E:$E,[1]Сводный!BU:BU,0) -> 0 | I28: =_xlfn.XLOOKUP($D28,[1]Сводный!$E:$E,[1]Сводный!BV:BV,0) -> 0 | J28: =_xlfn.XLOOKUP($D28,[1]Сводный!$E:$E,[1]Сводный!BW:BW,0) -> 0 | K28: =_xlfn.XLOOKUP($D28,[1]Сводный!$E:$E,[1]Сводный!BX:BX,0) -> 0 | L28: =_xlfn.XLOOKUP($D28,[1]Сводный!$E:$E,[1]Сводный!BY:BY,0) -> 0 | M28: =_xlfn.XLOOKUP($D28,[1]Сводный!$E:$E,[1]Сводный!BZ:BZ,0) -> 0 | N28: =_xlfn.XLOOKUP($D28,[1]Сводный!$E:$E,[1]Сводный!CA:CA,0) -> 0 | O28: =_xlfn.XLOOKUP($D28,[1]Сводный!$E:$E,[1]Сводный!CB:CB,0) -> 0 | P28: =_xlfn.XLOOKUP($D28,[1]Сводный!$E:$E,[1]Сводный!CC:CC,0) -> 0 | Q28: =SUM(E28:P28) -> 0 | R28: {=_xlfn.XLOOKUP($D28,INDIRECT(R$2&"!"&"E:E"),INDIRECT(R$2&"!"&"C:C"),0)} -> 0 | S28: {=_xlfn.XLOOKUP($D28,INDIRECT(S$2&"!"&"E:E"),INDIRECT(S$2&"!"&"C:C"),0)} -> 0 | T28: {=_xlfn.XLOOKUP($D28,INDIRECT(T$2&"!"&"E:E"),INDIRECT(T$2&"!"&"C:C"),0)} -> 0 | U28: {=_xlfn.XLOOKUP($D28,INDIRECT(U$2&"!"&"E:E"),INDIRECT(U$2&"!"&"C:C"),0)} -> 0 | V28: {=_xlfn.XLOOKUP($D28,INDIRECT(V$2&"!"&"E:E"),INDIRECT(V$2&"!"&"C:C"),0)} -> 0 | W28: {=_xlfn.XLOOKUP($D28,INDIRECT(W$2&"!"&"E:E"),INDIRECT(W$2&"!"&"C:C"),0)} -> 0 | X28: {=_xlfn.XLOOKUP($D28,INDIRECT(X$2&"!"&"E:E"),INDIRECT(X$2&"!"&"C:C"),0)} -> 0 | Y28: {=_xlfn.XLOOKUP($D28,INDIRECT(Y$2&"!"&"E:E"),INDIRECT(Y$2&"!"&"C:C"),0)} -> 0 | ... AR28: {=_xlfn.XLOOKUP($D28,INDIRECT(AR$2&"!"&"E:E"),INDIRECT(AR$2&"!"&"C:C"),0)} -> 0 | AS28: =SUM(R28:AR28) -> 0 | AT28: =Q28+AS28 -> 0 | AU28: Приемка, короб, отгрузка. | AX28: =AT28 -> 0 | AY28: * | BF28: * | BG28: =SUMIF(AY28:BF28,"*",$AY$2:$BF$2)+BC28 -> 8 | BH28: =AT28*BG28 -> 0 | BJ28: =BH28+AT28*BI28 -> 0
C29: Мяч гладкий сиреневый | D29: 2042986372359 | E29: =_xlfn.XLOOKUP($D29,[1]Сводный!$E:$E,[1]Сводный!BR:BR,0) -> 0 | F29: =_xlfn.XLOOKUP($D29,[1]Сводный!$E:$E,[1]Сводный!BS:BS,0) -> 0 | G29: =_xlfn.XLOOKUP($D29,[1]Сводный!$E:$E,[1]Сводный!BT:BT,0) -> 0 | H29: =_xlfn.XLOOKUP($D29,[1]Сводный!$E:$E,[1]Сводный!BU:BU,0) -> 0 | I29: =_xlfn.XLOOKUP($D29,[1]Сводный!$E:$E,[1]Сводный!BV:BV,0) -> 0 | J29: =_xlfn.XLOOKUP($D29,[1]Сводный!$E:$E,[1]Сводный!BW:BW,0) -> 0 | K29: =_xlfn.XLOOKUP($D29,[1]Сводный!$E:$E,[1]Сводный!BX:BX,0) -> 0 | L29: =_xlfn.XLOOKUP($D29,[1]Сводный!$E:$E,[1]Сводный!BY:BY,0) -> 0 | M29: =_xlfn.XLOOKUP($D29,[1]Сводный!$E:$E,[1]Сводный!BZ:BZ,0) -> 0 | N29: =_xlfn.XLOOKUP($D29,[1]Сводный!$E:$E,[1]Сводный!CA:CA,0) -> 0 | O29: =_xlfn.XLOOKUP($D29,[1]Сводный!$E:$E,[1]Сводный!CB:CB,0) -> 0 | P29: =_xlfn.XLOOKUP($D29,[1]Сводный!$E:$E,[1]Сводный!CC:CC,0) -> 0 | Q29: =SUM(E29:P29) -> 0 | R29: {=_xlfn.XLOOKUP($D29,INDIRECT(R$2&"!"&"E:E"),INDIRECT(R$2&"!"&"C:C"),0)} -> 0 | S29: {=_xlfn.XLOOKUP($D29,INDIRECT(S$2&"!"&"E:E"),INDIRECT(S$2&"!"&"C:C"),0)} -> 0 | T29: {=_xlfn.XLOOKUP($D29,INDIRECT(T$2&"!"&"E:E"),INDIRECT(T$2&"!"&"C:C"),0)} -> 0 | U29: {=_xlfn.XLOOKUP($D29,INDIRECT(U$2&"!"&"E:E"),INDIRECT(U$2&"!"&"C:C"),0)} -> 0 | V29: {=_xlfn.XLOOKUP($D29,INDIRECT(V$2&"!"&"E:E"),INDIRECT(V$2&"!"&"C:C"),0)} -> 0 | W29: {=_xlfn.XLOOKUP($D29,INDIRECT(W$2&"!"&"E:E"),INDIRECT(W$2&"!"&"C:C"),0)} -> 0 | X29: {=_xlfn.XLOOKUP($D29,INDIRECT(X$2&"!"&"E:E"),INDIRECT(X$2&"!"&"C:C"),0)} -> 0 | Y29: {=_xlfn.XLOOKUP($D29,INDIRECT(Y$2&"!"&"E:E"),INDIRECT(Y$2&"!"&"C:C"),0)} -> 0 | ... AR29: {=_xlfn.XLOOKUP($D29,INDIRECT(AR$2&"!"&"E:E"),INDIRECT(AR$2&"!"&"C:C"),0)} -> 0 | AS29: =SUM(R29:AR29) -> 0 | AT29: =Q29+AS29 -> 0 | AU29: Приемка, короб, отгрузка. | AX29: =AT29 -> 0 | AY29: * | BF29: * | BG29: =SUMIF(AY29:BF29,"*",$AY$2:$BF$2)+BC29 -> 8 | BH29: =AT29*BG29 -> 0 | BJ29: =BH29+AT29*BI29 -> 0
C30: Мяч гладкий оранжевый | D30: 2042986377583 | E30: =_xlfn.XLOOKUP($D30,[1]Сводный!$E:$E,[1]Сводный!BR:BR,0) -> 0 | F30: =_xlfn.XLOOKUP($D30,[1]Сводный!$E:$E,[1]Сводный!BS:BS,0) -> 0 | G30: =_xlfn.XLOOKUP($D30,[1]Сводный!$E:$E,[1]Сводный!BT:BT,0) -> 0 | H30: =_xlfn.XLOOKUP($D30,[1]Сводный!$E:$E,[1]Сводный!BU:BU,0) -> 0 | I30: =_xlfn.XLOOKUP($D30,[1]Сводный!$E:$E,[1]Сводный!BV:BV,0) -> 0 | J30: =_xlfn.XLOOKUP($D30,[1]Сводный!$E:$E,[1]Сводный!BW:BW,0) -> 0 | K30: =_xlfn.XLOOKUP($D30,[1]Сводный!$E:$E,[1]Сводный!BX:BX,0) -> 0 | L30: =_xlfn.XLOOKUP($D30,[1]Сводный!$E:$E,[1]Сводный!BY:BY,0) -> 0 | M30: =_xlfn.XLOOKUP($D30,[1]Сводный!$E:$E,[1]Сводный!BZ:BZ,0) -> 0 | N30: =_xlfn.XLOOKUP($D30,[1]Сводный!$E:$E,[1]Сводный!CA:CA,0) -> 0 | O30: =_xlfn.XLOOKUP($D30,[1]Сводный!$E:$E,[1]Сводный!CB:CB,0) -> 0 | P30: =_xlfn.XLOOKUP($D30,[1]Сводный!$E:$E,[1]Сводный!CC:CC,0) -> 0 | Q30: =SUM(E30:P30) -> 0 | R30: {=_xlfn.XLOOKUP($D30,INDIRECT(R$2&"!"&"E:E"),INDIRECT(R$2&"!"&"C:C"),0)} -> 0 | S30: {=_xlfn.XLOOKUP($D30,INDIRECT(S$2&"!"&"E:E"),INDIRECT(S$2&"!"&"C:C"),0)} -> 0 | T30: {=_xlfn.XLOOKUP($D30,INDIRECT(T$2&"!"&"E:E"),INDIRECT(T$2&"!"&"C:C"),0)} -> 0 | U30: {=_xlfn.XLOOKUP($D30,INDIRECT(U$2&"!"&"E:E"),INDIRECT(U$2&"!"&"C:C"),0)} -> 0 | V30: {=_xlfn.XLOOKUP($D30,INDIRECT(V$2&"!"&"E:E"),INDIRECT(V$2&"!"&"C:C"),0)} -> 0 | W30: {=_xlfn.XLOOKUP($D30,INDIRECT(W$2&"!"&"E:E"),INDIRECT(W$2&"!"&"C:C"),0)} -> 0 | X30: {=_xlfn.XLOOKUP($D30,INDIRECT(X$2&"!"&"E:E"),INDIRECT(X$2&"!"&"C:C"),0)} -> 0 | Y30: {=_xlfn.XLOOKUP($D30,INDIRECT(Y$2&"!"&"E:E"),INDIRECT(Y$2&"!"&"C:C"),0)} -> 0 | ... AR30: {=_xlfn.XLOOKUP($D30,INDIRECT(AR$2&"!"&"E:E"),INDIRECT(AR$2&"!"&"C:C"),0)} -> 0 | AS30: =SUM(R30:AR30) -> 0 | AT30: =Q30+AS30 -> 0 | AU30: Приемка, короб, отгрузка. | AX30: =AT30 -> 0 | AY30: * | BF30: * | BG30: =SUMIF(AY30:BF30,"*",$AY$2:$BF$2)+BC30 -> 8 | BH30: =AT30*BG30 -> 0 | BJ30: =BH30+AT30*BI30 -> 0
A31: Фитнес-резинки | C31: Набор эластичных лент 3 шт. в мешке | D31: 2048933027488 | E31: =_xlfn.XLOOKUP($D31,[1]Сводный!$E:$E,[1]Сводный!BR:BR,0) -> 0 | F31: =_xlfn.XLOOKUP($D31,[1]Сводный!$E:$E,[1]Сводный!BS:BS,0) -> 0 | G31: =_xlfn.XLOOKUP($D31,[1]Сводный!$E:$E,[1]Сводный!BT:BT,0) -> 0 | H31: =_xlfn.XLOOKUP($D31,[1]Сводный!$E:$E,[1]Сводный!BU:BU,0) -> 0 | I31: =_xlfn.XLOOKUP($D31,[1]Сводный!$E:$E,[1]Сводный!BV:BV,0) -> 0 | J31: =_xlfn.XLOOKUP($D31,[1]Сводный!$E:$E,[1]Сводный!BW:BW,0) -> 15 | K31: =_xlfn.XLOOKUP($D31,[1]Сводный!$E:$E,[1]Сводный!BX:BX,0) -> 0 | L31: =_xlfn.XLOOKUP($D31,[1]Сводный!$E:$E,[1]Сводный!BY:BY,0) -> 15 | M31: =_xlfn.XLOOKUP($D31,[1]Сводный!$E:$E,[1]Сводный!BZ:BZ,0) -> 0 | N31: =_xlfn.XLOOKUP($D31,[1]Сводный!$E:$E,[1]Сводный!CA:CA,0) -> 15 | O31: =_xlfn.XLOOKUP($D31,[1]Сводный!$E:$E,[1]Сводный!CB:CB,0) -> 15 | P31: =_xlfn.XLOOKUP($D31,[1]Сводный!$E:$E,[1]Сводный!CC:CC,0) -> 0 | Q31: =SUM(E31:P31) -> 60 | AT31: =Q31+AS31 -> 60 | AU31: Приемка, маркировка (1 этикетка), короб, отгрузка. | AV31: Ленты в сумочке упакованы в заводской БОПП пакет. Этикетку с ШК клеить прямо на пакет. Внимательно, чтоб штрих-код не сжимался. | AX31: =AT31 -> 60 | AY31: * | BB31: * | BE31: * | BF31: * | BG31: =SUMIF(AY31:BF31,"*",$AY$2:$BF$2)+BC31 -> 27 | BH31: =AT31*BG31 -> 1620 | BJ31: =BH31+AT31*BI31 -> 1620
C32: Набор эластичных лент 5 шт. в мешке | D32: 2046392546618 | E32: =_xlfn.XLOOKUP($D32,[1]Сводный!$E:$E,[1]Сводный!BR:BR,0) -> 0 | F32: =_xlfn.XLOOKUP($D32,[1]Сводный!$E:$E,[1]Сводный!BS:BS,0) -> 0 | G32: =_xlfn.XLOOKUP($D32,[1]Сводный!$E:$E,[1]Сводный!BT:BT,0) -> 0 | H32: =_xlfn.XLOOKUP($D32,[1]Сводный!$E:$E,[1]Сводный!BU:BU,0) -> 0 | I32: =_xlfn.XLOOKUP($D32,[1]Сводный!$E:$E,[1]Сводный!BV:BV,0) -> 0 | J32: =_xlfn.XLOOKUP($D32,[1]Сводный!$E:$E,[1]Сводный!BW:BW,0) -> 0 | K32: =_xlfn.XLOOKUP($D32,[1]Сводный!$E:$E,[1]Сводный!BX:BX,0) -> 0 | L32: =_xlfn.XLOOKUP($D32,[1]Сводный!$E:$E,[1]Сводный!BY:BY,0) -> 10 | M32: =_xlfn.XLOOKUP($D32,[1]Сводный!$E:$E,[1]Сводный!BZ:BZ,0) -> 0 | N32: =_xlfn.XLOOKUP($D32,[1]Сводный!$E:$E,[1]Сводный!CA:CA,0) -> 10 | O32: =_xlfn.XLOOKUP($D32,[1]Сводный!$E:$E,[1]Сводный!CB:CB,0) -> 10 | P32: =_xlfn.XLOOKUP($D32,[1]Сводный!$E:$E,[1]Сводный!CC:CC,0) -> 0 | Q32: =SUM(E32:P32) -> 30 | AT32: =Q32+AS32 -> 30 | AU32: Приемка, маркировка (1 этикетка), короб, отгрузка. | AV32: Ленты в сумочке упакованы в заводской БОПП пакет. Этикетку с ШК клеить прямо на пакет. Внимательно, чтоб штрих-код не сжимался. | AX32: =AT32 -> 30 | AY32: * | BB32: * | BE32: * | BF32: * | BG32: =SUMIF(AY32:BF32,"*",$AY$2:$BF$2)+BC32 -> 27 | BH32: =AT32*BG32 -> 810 | BJ32: =BH32+AT32*BI32 -> 810
C33: Набор эластичных лент 4 шт. | D33: 2046392546632 | E33: =_xlfn.XLOOKUP($D33,[1]Сводный!$E:$E,[1]Сводный!BR:BR,0) -> 0 | F33: =_xlfn.XLOOKUP($D33,[1]Сводный!$E:$E,[1]Сводный!BS:BS,0) -> 0 | G33: =_xlfn.XLOOKUP($D33,[1]Сводный!$E:$E,[1]Сводный!BT:BT,0) -> 0 | H33: =_xlfn.XLOOKUP($D33,[1]Сводный!$E:$E,[1]Сводный!BU:BU,0) -> 0 | I33: =_xlfn.XLOOKUP($D33,[1]Сводный!$E:$E,[1]Сводный!BV:BV,0) -> 0 | J33: =_xlfn.XLOOKUP($D33,[1]Сводный!$E:$E,[1]Сводный!BW:BW,0) -> 0 | K33: =_xlfn.XLOOKUP($D33,[1]Сводный!$E:$E,[1]Сводный!BX:BX,0) -> 0 | L33: =_xlfn.XLOOKUP($D33,[1]Сводный!$E:$E,[1]Сводный!BY:BY,0) -> 0 | M33: =_xlfn.XLOOKUP($D33,[1]Сводный!$E:$E,[1]Сводный!BZ:BZ,0) -> 0 | N33: =_xlfn.XLOOKUP($D33,[1]Сводный!$E:$E,[1]Сводный!CA:CA,0) -> 0 | O33: =_xlfn.XLOOKUP($D33,[1]Сводный!$E:$E,[1]Сводный!CB:CB,0) -> 0 | P33: =_xlfn.XLOOKUP($D33,[1]Сводный!$E:$E,[1]Сводный!CC:CC,0) -> 0 | Q33: =SUM(E33:P33) -> 0 | AT33: =Q33+AS33 -> 0 | AU33: Приемка, сортировка маркировка (1 этикетка), короб, отгрузка. | AV33: Каждая лента упакована в зип пакет. Сформировать комлект из 4 цветов (зип-пакеты не снимать). Упаковать комплект в ваш БООП пакет. Этикетку с ШК клеить прямо на пакет. Внимательно, чтоб штрих-код не сжимался. | AX33: =AT33 -> 0 | AY33: * | AZ33: * | BA33: * | BB33: * | BC33: 9 | BE33: * | BF33: * | BG33: =SUMIF(AY33:BF33,"*",$AY$2:$BF$2)+BC33 -> 46 | BH33: =AT33*BG33 -> 0 | BJ33: =BH33+AT33*BI33 -> 0
C34: Набор эластичных лент 5 шт. | D34: 2046392546656 | E34: =_xlfn.XLOOKUP($D34,[1]Сводный!$E:$E,[1]Сводный!BR:BR,0) -> 0 | F34: =_xlfn.XLOOKUP($D34,[1]Сводный!$E:$E,[1]Сводный!BS:BS,0) -> 0 | G34: =_xlfn.XLOOKUP($D34,[1]Сводный!$E:$E,[1]Сводный!BT:BT,0) -> 0 | H34: =_xlfn.XLOOKUP($D34,[1]Сводный!$E:$E,[1]Сводный!BU:BU,0) -> 0 | I34: =_xlfn.XLOOKUP($D34,[1]Сводный!$E:$E,[1]Сводный!BV:BV,0) -> 0 | J34: =_xlfn.XLOOKUP($D34,[1]Сводный!$E:$E,[1]Сводный!BW:BW,0) -> 0 | K34: =_xlfn.XLOOKUP($D34,[1]Сводный!$E:$E,[1]Сводный!BX:BX,0) -> 0 | L34: =_xlfn.XLOOKUP($D34,[1]Сводный!$E:$E,[1]Сводный!BY:BY,0) -> 0 | M34: =_xlfn.XLOOKUP($D34,[1]Сводный!$E:$E,[1]Сводный!BZ:BZ,0) -> 0 | N34: =_xlfn.XLOOKUP($D34,[1]Сводный!$E:$E,[1]Сводный!CA:CA,0) -> 0 | O34: =_xlfn.XLOOKUP($D34,[1]Сводный!$E:$E,[1]Сводный!CB:CB,0) -> 0 | P34: =_xlfn.XLOOKUP($D34,[1]Сводный!$E:$E,[1]Сводный!CC:CC,0) -> 0 | Q34: =SUM(E34:P34) -> 0 | AT34: =Q34+AS34 -> 0 | AU34: Приемка, сортировка, формирование комплекта, упаковка (ваши пакеты БОПП), маркировка (1 этикетка), короб, отгрузка | AV34: Каждая лента упакована в БОПП пакет. Сформировать комлект из 5 цветов (БОПП пакеты не снимать). Упаковать комплект в ваш БООП пакет. Этикетку с ШК клеить прямо на пакет. Внимательно, чтоб штрих-код не сжимался. | AX34: =AT34 -> 0 | AY34: * | AZ34: * | BA34: * | BB34: * | BE34: * | BF34: * | BG34: =SUMIF(AY34:BF34,"*",$AY$2:$BF$2)+BC34 -> 37 | BH34: =AT34*BG34 -> 0 | BJ34: =BH34+AT34*BI34 -> 0
