Workbook

Sheet  Расчет стоимости и веса
A1: ссылка | B1: фото | C1: комментарий | D1: Кол-во, шт. протянуть формулу и изменять в ручную. | E1: цена, юань | F1: сумма, юань | G1: доставка, юани | H1: Арт. Мой | I1: Арт ВБ | J1: Арт ВБ для комплекта | K1: ШК | L1: отгружено, шт | M1: вес ед., кг | N1: вес, кг | O1: норма упаковки | P1: размеры короба | Q1: вес по норме упаковки | R1: Комментарии
A2: https://detail.1688.com/offer/635893886704.html | C2: Бандаж для лица розовый лайкра. Пакет OPP | D2: =_xlfn.XLOOKUP(H2,[1]Сводный!$C:$C,[1]Сводный!$CE:$CE,0) -> 0 | E2: 5.5 | F2: =E2*D2 -> 0 | H2: =_xlfn.XLOOKUP(I2,[2]Юнит!$A:$A,[2]Юнит!$C:$C) -> ACRF1BN101PN | I2: 169112569 | J2: 169112569 | K2: =_xlfn.XLOOKUP(H2,[2]Юнит!$C:$C,[2]Юнит!$E:$E) -> 2038161736993 | L2: =D2 -> 0 | M2: 0.04 | N2: =M2*D2 -> 0 | O2: 500 | P2: 68*36*50 | Q2: =O2*M2 -> 20
A3: https://detail.1688.com/offer/635893886704.html | C3: Бандаж для лица черный лайкра. Пакет OPP | D3: =_xlfn.XLOOKUP(H3,[1]Сводный!$C:$C,[1]Сводный!$CE:$CE,0) -> 40 | E3: 5.5 | F3: =E3*D3 -> 220 | H3: =_xlfn.XLOOKUP(I3,[2]Юнит!$A:$A,[2]Юнит!$C:$C) -> ACRF1BN101BC | I3: 169153168 | J3: 169153168 | K3: =_xlfn.XLOOKUP(H3,[2]Юнит!$C:$C,[2]Юнит!$E:$E) -> 2038162681926 | L3: =D3 -> 40 | M3: 0.04 | N3: =M3*D3 -> 1.6 | O3: 500 | P3: 68*36*50 | Q3: =O3*M3 -> 20
D4: =_xlfn.XLOOKUP(H4,[1]Сводный!$C:$C,[1]Сводный!$CE:$CE,0) -> 0 | K4: =_xlfn.XLOOKUP(H4,[2]Юнит!$C:$C,[2]Юнит!$E:$E) -> 0
A5: https://detail.1688.com/offer/693810563823.html | C5: Силиконовая маска для лица серая. Пакет OPP | D5: =_xlfn.XLOOKUP(H5,[1]Сводный!$C:$C,[1]Сводный!$CE:$CE,0) -> 40 | E5: 13.5 | F5: =E5*D5 -> 540 | H5: =_xlfn.XLOOKUP(I5,[2]Юнит!$A:$A,[2]Юнит!$C:$C) -> ACRF1BN201GR | I5: 169395410 | J5: 169395410 | K5: =_xlfn.XLOOKUP(H5,[2]Юнит!$C:$C,[2]Юнит!$E:$E) -> 2038172050200 | L5: =D5 -> 40 | M5: 0.09 | N5: =M5*D5 -> 3.6 | O5: 100 | P5: 58*31*37 | Q5: =O5*M5 -> 9
D6: =_xlfn.XLOOKUP(H6,[1]Сводный!$C:$C,[1]Сводный!$CE:$CE,0) -> 0 | F6: =E6*D6 -> 0 | H6: =_xlfn.XLOOKUP(I6,[2]Юнит!$A:$A,[2]Юнит!$C:$C) -> 0 | J6: 0 | L6: =D6 -> 0 | N6: =M6*D6 -> 0 | Q6: =O6*M6 -> 0
A7: https://detail.1688.com/offer/566453154821.html | C7: Массажер для пальцев роликовый в подарочной коробке | D7: =_xlfn.XLOOKUP(H7,[1]Сводный!$C:$C,[1]Сводный!$CE:$CE,0) -> 0 | E7: 1.8 | F7: =E7*D7 -> 0 | H7: =_xlfn.XLOOKUP(I7,[2]Юнит!$A:$A,[2]Юнит!$C:$C) -> ACRH1MS101RJ | I7: 173605843 | J7: 173605843 | K7: =_xlfn.XLOOKUP(H7,[2]Юнит!$C:$C,[2]Юнит!$E:$E) -> 2038430289250 | L7: =D7 -> 0 | M7: 0.04 | N7: =M7*D7 -> 0 | O7: 400 | P7: 63*41,8*51 | Q7: =O7*M7 -> 16 | R7: https://detail.1688.com/offer/728663297092.html
D8: =_xlfn.XLOOKUP(H8,[1]Сводный!$C:$C,[1]Сводный!$CE:$CE,0) -> 0 | F8: =E8*D8 -> 0 | H8: =_xlfn.XLOOKUP(I8,[2]Юнит!$A:$A,[2]Юнит!$C:$C) -> 0 | L8: =D8 -> 0 | N8: =M8*D8 -> 0 | Q8: =O8*M8 -> 0
A9: https://detail.1688.com/offer/731940202915.html | C9: Массажер для спины розовый | D9: =_xlfn.XLOOKUP(H9,[1]Сводный!$C:$C,[1]Сводный!$CE:$CE,0) -> 10 | E9: 6.3 | F9: =E9*D9 -> 63 | G9: 80 | H9: =_xlfn.XLOOKUP(I9,[2]Юнит!$A:$A,[2]Юнит!$C:$C) -> ACRB1MS101PN | I9: 275208801 | J9: =I9 -> 275208801 | K9: =_xlfn.XLOOKUP(H9,[2]Юнит!$C:$C,[2]Юнит!$E:$E) -> 2041591042329 | L9: =D9 -> 10 | M9: 0.16 | N9: =M9*D9 -> 1.6 | O9: 100 | Q9: =O9*M9 -> 16 | R9: https://detail.1688.com/offer/653872589438.html
A10: https://detail.1688.com/offer/731940202915.html | C10: Массажер для спины голубой | D10: =_xlfn.XLOOKUP(H10,[1]Сводный!$C:$C,[1]Сводный!$CE:$CE,0) -> 60 | E10: 6.3 | F10: =E10*D10 -> 378 | H10: =_xlfn.XLOOKUP(I10,[2]Юнит!$A:$A,[2]Юнит!$C:$C) -> ACRB1MS101BL | I10: 275208802 | J10: =I10 -> 275208802 | K10: =_xlfn.XLOOKUP(H10,[2]Юнит!$C:$C,[2]Юнит!$E:$E) -> 2041591055954 | L10: =D10 -> 60 | M10: 0.16 | N10: =M10*D10 -> 9.6 | O10: 100 | Q10: =O10*M10 -> 16 | R10: https://detail.1688.com/offer/653872589438.html
A11: https://detail.1688.com/offer/731940202915.html | C11: Массажер для спины оранжевый | D11: =_xlfn.XLOOKUP(H11,[1]Сводный!$C:$C,[1]Сводный!$CE:$CE,0) -> 50 | E11: 6.3 | F11: =E11*D11 -> 315 | H11: =_xlfn.XLOOKUP(I11,[2]Юнит!$A:$A,[2]Юнит!$C:$C) -> ACRB1MS101RJ | I11: 223420736 | J11: =I11 -> 223420736 | K11: =_xlfn.XLOOKUP(H11,[2]Юнит!$C:$C,[2]Юнит!$E:$E) -> 2039813223373 | L11: =D11 -> 50 | M11: 0.16 | N11: =M11*D11 -> 8 | O11: 100 | Q11: =O11*M11 -> 16 | R11: https://detail.1688.com/offer/653872589438.html
D12: =_xlfn.XLOOKUP(H12,[1]Сводный!$C:$C,[1]Сводный!$CE:$CE,0) -> 0
A13: https://detail.1688.com/offer/694897445577.html | C13: Мячик белый 6 см | D13: =_xlfn.XLOOKUP(H13,[1]Сводный!$C:$C,[1]Сводный!$CE:$CE,0) -> 125 | E13: 2.9 | F13: =E13*D13 -> 362.5 | H13: =_xlfn.XLOOKUP(I13,[2]Юнит!$A:$A,[2]Юнит!$C:$C) -> ACRB1MS106WH | I13: 236072835 | J13: =I13 -> 236072835 | K13: =_xlfn.XLOOKUP(H13,[2]Юнит!$C:$C,[2]Юнит!$E:$E) -> 2040278804496 | L13: =D13 -> 125 | M13: 0.04 | N13: =M13*D13 -> 5 | O13: 400 | P13: 66*42*34 | Q13: =O13*M13 -> 16 | R13: https://detail.1688.com/offer/651566408943.html
A14: https://detail.1688.com/offer/694897445577.html | C14: Мячик розовый 6 см | D14: =_xlfn.XLOOKUP(H14,[1]Сводный!$C:$C,[1]Сводный!$CE:$CE,0) -> 300 | E14: 2.9 | F14: =E14*D14 -> 870 | H14: =_xlfn.XLOOKUP(I14,[2]Юнит!$A:$A,[2]Юнит!$C:$C) -> ACRB1MS106PN | I14: 236072836 | J14: =I14 -> 236072836 | K14: =_xlfn.XLOOKUP(H14,[2]Юнит!$C:$C,[2]Юнит!$E:$E) -> 2040278810534 | L14: =D14 -> 300 | M14: 0.04 | N14: =M14*D14 -> 12 | O14: 400 | P14: 66*42*34 | Q14: =O14*M14 -> 16 | R14: https://detail.1688.com/offer/651566408943.html
A15: https://detail.1688.com/offer/694897445577.html | C15: Мячик голубой 6 см | D15: =_xlfn.XLOOKUP(H15,[1]Сводный!$C:$C,[1]Сводный!$CE:$CE,0) -> 120 | E15: 2.9 | F15: =E15*D15 -> 348 | H15: =_xlfn.XLOOKUP(I15,[2]Юнит!$A:$A,[2]Юнит!$C:$C) -> ACRB1MS106BL | I15: 236072834 | J15: =I15 -> 236072834 | K15: =_xlfn.XLOOKUP(H15,[2]Юнит!$C:$C,[2]Юнит!$E:$E) -> 2040278804649 | L15: =D15 -> 120 | M15: 0.04 | N15: =M15*D15 -> 4.8 | O15: 400 | P15: 66*42*34 | Q15: =O15*M15 -> 16 | R15: https://detail.1688.com/offer/651566408943.html
A16: https://detail.1688.com/offer/694897445577.html | C16: Мячик оранжевый 6 см | D16: =_xlfn.XLOOKUP(H16,[1]Сводный!$C:$C,[1]Сводный!$CE:$CE,0) -> 20 | E16: 2.9 | F16: =E16*D16 -> 58 | H16: =_xlfn.XLOOKUP(I16,[2]Юнит!$A:$A,[2]Юнит!$C:$C) -> ACRB1MS106RJ | I16: 223671295 | J16: =I16 -> 223671295 | K16: =_xlfn.XLOOKUP(H16,[2]Юнит!$C:$C,[2]Юнит!$E:$E) -> 2039818580389 | L16: =D16 -> 20 | M16: 0.04 | N16: =M16*D16 -> 0.8 | O16: 400 | P16: 66*42*34 | Q16: =O16*M16 -> 16 | R16: https://detail.1688.com/offer/651566408943.html
A17: https://detail.1688.com/offer/650780571645.html | C17: Мячик черный 6 см | D17: =_xlfn.XLOOKUP(H17,[1]Сводный!$C:$C,[1]Сводный!$CE:$CE,0) -> 250 | E17: 1.9 | F17: =E17*D17 -> 475 | H17: =_xlfn.XLOOKUP(I17,[2]Юнит!$A:$A,[2]Юнит!$C:$C) -> ACRB1MS106BС | I17: 370591238 | J17: =I17 -> 370591238 | K17: =_xlfn.XLOOKUP(H17,[2]Юнит!$C:$C,[2]Юнит!$E:$E) -> 2043369663040 | L17: =D17 -> 250 | M17: 0.04 | N17: =M17*D17 -> 10 | O17: 450 | P17: 66*42*34 | Q17: =O17*M17 -> 18
D18: =_xlfn.XLOOKUP(H18,[1]Сводный!$C:$C,[1]Сводный!$CE:$CE,0) -> 0
A19: https://detail.1688.com/offer/650780571645.html | C19: Мячик белый 7 см | D19: =_xlfn.XLOOKUP(H19,[1]Сводный!$C:$C,[1]Сводный!$CE:$CE,0) -> 300 | E19: 2.1 | F19: =E19*D19 -> 630 | H19: =_xlfn.XLOOKUP(I19,[2]Юнит!$A:$A,[2]Юнит!$C:$C) -> ACRB1MS107WH | I19: 419145391 | J19: =I19 -> 419145391 | K19: =_xlfn.XLOOKUP(H19,[2]Юнит!$C:$C,[2]Юнит!$E:$E) -> 2044025326637 | L19: =D19 -> 300 | M19: 0.06 | N19: =M19*D19 -> 18 | Q19: =O19*M19 -> 0
A20: https://detail.1688.com/offer/650780571645.html | C20: Мячик розовый 7 см | D20: =_xlfn.XLOOKUP(H20,[1]Сводный!$C:$C,[1]Сводный!$CE:$CE,0) -> 60 | E20: 2.1 | F20: =E20*D20 -> 126 | H20: =_xlfn.XLOOKUP(I20,[2]Юнит!$A:$A,[2]Юнит!$C:$C) -> ACRB1MS107PN | I20: 419145389 | J20: =I20 -> 419145389 | K20: =_xlfn.XLOOKUP(H20,[2]Юнит!$C:$C,[2]Юнит!$E:$E) -> 2044025316447 | L20: =D20 -> 60 | M20: 0.06 | N20: =M20*D20 -> 3.6 | Q20: =O20*M20 -> 0
A21: https://detail.1688.com/offer/650780571645.html | C21: Мячик голубой 7 см | D21: =_xlfn.XLOOKUP(H21,[1]Сводный!$C:$C,[1]Сводный!$CE:$CE,0) -> 40 | E21: 2.1 | F21: =E21*D21 -> 84 | H21: =_xlfn.XLOOKUP(I21,[2]Юнит!$A:$A,[2]Юнит!$C:$C) -> ACRB1MS107BL | I21: 419145748 | J21: =I21 -> 419145748 | K21: =_xlfn.XLOOKUP(H21,[2]Юнит!$C:$C,[2]Юнит!$E:$E) -> 2044025338661 | L21: =D21 -> 40 | M21: 0.06 | N21: =M21*D21 -> 2.4 | Q21: =O21*M21 -> 0
A22: https://detail.1688.com/offer/650780571645.html | C22: Мячик оранжевый 7 см | D22: =_xlfn.XLOOKUP(H22,[1]Сводный!$C:$C,[1]Сводный!$CE:$CE,0) -> 30 | E22: 2.1 | F22: =E22*D22 -> 63 | H22: =_xlfn.XLOOKUP(I22,[2]Юнит!$A:$A,[2]Юнит!$C:$C) -> ACRB1MS107RJ | I22: 419141548 | J22: =I22 -> 419141548 | K22: =_xlfn.XLOOKUP(H22,[2]Юнит!$C:$C,[2]Юнит!$E:$E) -> 2044025288003 | L22: =D22 -> 30 | M22: 0.06 | N22: =M22*D22 -> 1.8 | Q22: =O22*M22 -> 0
A23: https://detail.1688.com/offer/650780571645.html | C23: Мячик черный 7 см | D23: =_xlfn.XLOOKUP(H23,[1]Сводный!$C:$C,[1]Сводный!$CE:$CE,0) -> 30 | E23: 2.1 | F23: =E23*D23 -> 63 | H23: =_xlfn.XLOOKUP(I23,[2]Юнит!$A:$A,[2]Юнит!$C:$C) -> ACRB1MS107BС | I23: 419145985 | J23: =I23 -> 419145985 | K23: =_xlfn.XLOOKUP(H23,[2]Юнит!$C:$C,[2]Юнит!$E:$E) -> 2044025344532 | L23: =D23 -> 30 | M23: 0.06 | N23: =M23*D23 -> 1.8 | Q23: =O23*M23 -> 0
D24: =_xlfn.XLOOKUP(H24,[1]Сводный!$C:$C,[1]Сводный!$CE:$CE,0) -> 0
A25: https://detail.1688.com/offer/650780571645.html | C25: Мячик розовый 9 см | D25: =_xlfn.XLOOKUP(H25,[1]Сводный!$C:$C,[1]Сводный!$CE:$CE,0) -> 150 | E25: 3.1 | F25: =E25*D25 -> 465 | G25: 356 | H25: =_xlfn.XLOOKUP(I25,[2]Юнит!$A:$A,[2]Юнит!$C:$C) -> ACRB1MS109PN | I25: 419145390 | J25: =I25 -> 419145390 | K25: =_xlfn.XLOOKUP(H25,[2]Юнит!$C:$C,[2]Юнит!$E:$E) -> 2044025321588 | L25: =D25 -> 150 | M25: 0.1 | N25: =M25*D25 -> 15 | Q25: =O25*M25 -> 0
A26: https://detail.1688.com/offer/650780571645.html | C26: Мячик голубой 9 см | D26: =_xlfn.XLOOKUP(H26,[1]Сводный!$C:$C,[1]Сводный!$CE:$CE,0) -> 40 | E26: 3.1 | F26: =E26*D26 -> 124 | H26: =_xlfn.XLOOKUP(I26,[2]Юнит!$A:$A,[2]Юнит!$C:$C) -> ACRB1MS109BL | I26: 419145749 | J26: =I26 -> 419145749 | K26: =_xlfn.XLOOKUP(H26,[2]Юнит!$C:$C,[2]Юнит!$E:$E) -> 2044025342057 | L26: =D26 -> 40 | M26: 0.1 | N26: =M26*D26 -> 4 | Q26: =O26*M26 -> 0
A27: https://detail.1688.com/offer/650780571645.html | C27: Мячик оранжевый 9 см | D27: =_xlfn.XLOOKUP(H27,[1]Сводный!$C:$C,[1]Сводный!$CE:$CE,0) -> 100 | E27: 3.1 | F27: =E27*D27 -> 310 | H27: =_xlfn.XLOOKUP(I27,[2]Юнит!$A:$A,[2]Юнит!$C:$C) -> ACRB1MS109RJ | I27: 419141549 | J27: =I27 -> 419141549 | K27: =_xlfn.XLOOKUP(H27,[2]Юнит!$C:$C,[2]Юнит!$E:$E) -> 2044025291485 | L27: =D27 -> 100 | M27: 0.1 | N27: =M27*D27 -> 10 | Q27: =O27*M27 -> 0
A28: https://detail.1688.com/offer/650780571645.html | C28: Мячик черный 9 см | D28: =_xlfn.XLOOKUP(H28,[1]Сводный!$C:$C,[1]Сводный!$CE:$CE,0) -> 30 | E28: 3.1 | F28: =E28*D28 -> 93 | H28: =_xlfn.XLOOKUP(I28,[2]Юнит!$A:$A,[2]Юнит!$C:$C) -> ACRB1MS109BС | I28: 419145986 | J28: =I28 -> 419145986 | K28: =_xlfn.XLOOKUP(H28,[2]Юнит!$C:$C,[2]Юнит!$E:$E) -> 2044025347953 | L28: =D28 -> 30 | M28: 0.1 | N28: =M28*D28 -> 3 | Q28: =O28*M28 -> 0
A29: https://detail.1688.com/offer/650780571645.html | C29: Мячик фиолетовый 9 см | D29: =_xlfn.XLOOKUP(H29,[1]Сводный!$C:$C,[1]Сводный!$CE:$CE,0) -> 80 | E29: 3.1 | F29: =E29*D29 -> 248 | H29: =_xlfn.XLOOKUP(I29,[2]Юнит!$A:$A,[2]Юнит!$C:$C) -> ACRB1MS109LI | I29: 419146579 | J29: =I29 -> 419146579 | K29: =_xlfn.XLOOKUP(H29,[2]Юнит!$C:$C,[2]Юнит!$E:$E) -> 2044025354937 | L29: =D29 -> 80 | M29: 0.1 | N29: =M29*D29 -> 8 | Q29: =O29*M29 -> 0
D30: =_xlfn.XLOOKUP(H30,[1]Сводный!$C:$C,[1]Сводный!$CE:$CE,0) -> 0
A31: https://detail.1688.com/offer/647492228920.html | C31: Набор эластичных лент 3 шт. в мешке | D31: =_xlfn.XLOOKUP(H31,[1]Сводный!$C:$C,[1]Сводный!$CE:$CE,0) -> 60 | E31: 21 | F31: =E31*D31 -> 1260 | H31: =_xlfn.XLOOKUP(I31,[2]Юнит!$A:$A,[2]Юнит!$C:$C) -> ACRB3FR101CL | I31: 820643010 | J31: =[2]Юнит!A43 -> 820643010 | K31: =_xlfn.XLOOKUP(H31,[2]Юнит!$C:$C,[2]Юнит!$E:$E) -> 2048933027488 | L31: =D31 -> 60 | M31: 0.365 | N31: =M31*D31 -> 21.9 | Q31: =O31*M31 -> 0
A32: https://detail.1688.com/offer/621533561519.html | C32: Набор эластичных лент 5 шт. в мешке | D32: =_xlfn.XLOOKUP(H32,[1]Сводный!$C:$C,[1]Сводный!$CE:$CE,0) -> 30 | E32: 29 | F32: =E32*D32 -> 870 | G32: 18 | H32: =_xlfn.XLOOKUP(I32,[2]Юнит!$A:$A,[2]Юнит!$C:$C) -> ACRB5FR200CL | I32: 550539998 | J32: =[2]Юнит!A44 -> 550539998 | K32: =_xlfn.XLOOKUP(H32,[2]Юнит!$C:$C,[2]Юнит!$E:$E) -> 2046392546618 | L32: =D32 -> 30 | M32: 0.24 | N32: =M32*D32 -> 7.2 | Q32: =O32*M32 -> 0
A33: https://detail.1688.com/offer/916107416098.html | C33: Набор эластичных лент 4 шт. | D33: =_xlfn.XLOOKUP(H33,[1]Сводный!$C:$C,[1]Сводный!$CE:$CE,0) -> 0 | E33: 15.2 | F33: =E33*D33 -> 0 | H33: =_xlfn.XLOOKUP(I33,[2]Юнит!$A:$A,[2]Юнит!$C:$C) -> ACRB4FR300CL | I33: 550539999 | J33: =[2]Юнит!A45 -> 550539999 | K33: =_xlfn.XLOOKUP(H33,[2]Юнит!$C:$C,[2]Юнит!$E:$E) -> 2046392546632 | L33: =D33 -> 0 | M33: 0.25 | N33: =M33*D33 -> 0 | Q33: =O33*M33 -> 0
A34: https://detail.1688.com/offer/684113921011.html | C34: Эластичная лента 600*50*0.5 Светло-голубой | D34: =_xlfn.XLOOKUP(H34,[1]Сводный!$C:$C,[1]Сводный!$CE:$CE,0) -> 0 | E34: 0.82 | F34: =E34*D34 -> 0 | H34: =_xlfn.XLOOKUP(I34,[2]Юнит!$A:$A,[2]Юнит!$C:$C) -> ACRB5FR400CL | I34: 550540000 | J34: 550540000/1 | K34: =_xlfn.XLOOKUP(H34,[2]Юнит!$C:$C,[2]Юнит!$E:$E) -> 2046392546656 | L34: =D34 -> 0 | M34: 0.014 | N34: =M34*D34 -> 0
A35: https://detail.1688.com/offer/684113921011.html | C35: Эластичная лента 600*50*0.7 Цвет Хаки | D35: =_xlfn.XLOOKUP(H35,[1]Сводный!$C:$C,[1]Сводный!$CE:$CE,0) -> 0 | E35: 1 | F35: =E35*D35 -> 0 | H35: =_xlfn.XLOOKUP(I35,[2]Юнит!$A:$A,[2]Юнит!$C:$C) -> ACRB5FR400CL | I35: 550540000 | J35: 550540000/2 | K35: =_xlfn.XLOOKUP(H35,[2]Юнит!$C:$C,[2]Юнит!$E:$E) -> 2046392546656 | L35: =D35 -> 0 | M35: 0.021 | N35: =M35*D35 -> 0
A36: https://detail.1688.com/offer/684113921011.html | C36: Эластичная лента 600*50*0.9 Голубое озеро | D36: =_xlfn.XLOOKUP(H36,[1]Сводный!$C:$C,[1]Сводный!$CE:$CE,0) -> 0 | E36: 1.23 | F36: =E36*D36 -> 0 | H36: =_xlfn.XLOOKUP(I36,[2]Юнит!$A:$A,[2]Юнит!$C:$C) -> ACRB5FR400CL | I36: 550540000 | J36: 550540000/3 | K36: =_xlfn.XLOOKUP(H36,[2]Юнит!$C:$C,[2]Юнит!$E:$E) -> 2046392546656 | L36: =D36 -> 0 | M36: 0.026 | N36: =M36*D36 -> 0
A37: https://detail.1688.com/offer/684113921011.html | C37: Эластичная лента 600*50*1.1 розовый | D37: =_xlfn.XLOOKUP(H37,[1]Сводный!$C:$C,[1]Сводный!$CE:$CE,0) -> 0 | E37: 1.3 | F37: =E37*D37 -> 0 | H37: =_xlfn.XLOOKUP(I37,[2]Юнит!$A:$A,[2]Юнит!$C:$C) -> ACRB5FR400CL | I37: 550540000 | J37: 550540000/4 | K37: =_xlfn.XLOOKUP(H37,[2]Юнит!$C:$C,[2]Юнит!$E:$E) -> 2046392546656 | L37: =D37 -> 0 | M37: 0.031 | N37: =M37*D37 -> 0
A38: https://detail.1688.com/offer/684113921011.html | C38: Эластичная лента 600*50*1.2 серый | D38: =_xlfn.XLOOKUP(H38,[1]Сводный!$C:$C,[1]Сводный!$CE:$CE,0) -> 0 | E38: 1.65 | F38: =E38*D38 -> 0 | H38: =_xlfn.XLOOKUP(I38,[2]Юнит!$A:$A,[2]Юнит!$C:$C) -> ACRB5FR400CL | I38: 550540000 | J38: 550540000/5 | K38: =_xlfn.XLOOKUP(H38,[2]Юнит!$C:$C,[2]Юнит!$E:$E) -> 2046392546656 | L38: =D38 -> 0 | M38: 0.033 | N38: =M38*D38 -> 0
D39: =_xlfn.XLOOKUP(H39,[1]Сводный!$C:$C,[1]Сводный!$CE:$CE,0) -> 0
A40: https://detail.1688.com/offer/795734023677.html | C40: скакалка черная | D40: =_xlfn.XLOOKUP(H40,[1]Сводный!$C:$C,[1]Сводный!$CE:$CE,0) -> 0 | E40: 17 | F40: =E40*D40 -> 0 | H40: =_xlfn.XLOOKUP(I40,[2]Юнит!$A:$A,[2]Юнит!$C:$C) -> ACRB1SK101BC | I40: 271440668 | J40: 271440668 | K40: =_xlfn.XLOOKUP(H40,[2]Юнит!$C:$C,[2]Юнит!$E:$E) -> 2041473034138 | L40: =D40 -> 0 | M40: 0.17 | N40: =M40*D40 -> 0 | O40: 200 | Q40: =O40*M40 -> 34
...

Sheet Лист1
A1: ссылка | B1: фото | C1: комментарий | D1: Кол-во, шт | E1: цена, юань | F1: сумма, юань | G1: доставка, юани
A2: https://detail.1688.com/offer/635893886704.html | C2: Бандаж для лица черный лайкра. Пакет OPP | D2: 40 | E2: 5.5 | F2: 220
A3: https://detail.1688.com/offer/693810563823.html | C3: Силиконовая маска для лица серая. Пакет OPP | D3: 40 | E3: 13.5 | F3: 540
A4: https://detail.1688.com/offer/731940202915.html | C4: Массажер для спины розовый | D4: 10 | E4: 6.3 | F4: 63
A5: https://detail.1688.com/offer/731940202915.html | C5: Массажер для спины голубой | D5: 60 | E5: 6.3 | F5: 378
A6: https://detail.1688.com/offer/731940202915.html | C6: Массажер для спины оранжевый | D6: 50 | E6: 6.3 | F6: 315
A7: https://detail.1688.com/offer/694897445577.html | C7: Мячик белый 6 см | D7: 125 | E7: 2.9 | F7: 362.5
A8: https://detail.1688.com/offer/694897445577.html | C8: Мячик розовый 6 см | D8: 300 | E8: 2.9 | F8: 870
A9: https://detail.1688.com/offer/694897445577.html | C9: Мячик голубой 6 см | D9: 120 | E9: 2.9 | F9: 348
A10: https://detail.1688.com/offer/694897445577.html | C10: Мячик оранжевый 6 см | D10: 20 | E10: 2.9 | F10: 58
A11: https://detail.1688.com/offer/650780571645.html | C11: Мячик черный 6 см | D11: 250 | E11: 1.9 | F11: 475
A12: https://detail.1688.com/offer/650780571645.html | C12: Мячик белый 7 см | D12: 300 | E12: 2.1 | F12: 630
A13: https://detail.1688.com/offer/650780571645.html | C13: Мячик розовый 7 см | D13: 60 | E13: 2.1 | F13: 126
... A52: https://detail.1688.com/offer/662009355667.html | C52: Пузырчатый пакет голубой 16,5*22 см | D52: 700 | E52: 0.19 | F52: 133
D53: =SUM(D2:D52) -> 4767 | F53: =SUM(F2:F52) -> 18728.1
