Workbook
Name discontinueDiscount: #REF!
Name formUrl: #REF!
Name g: #REF!
Name groupByArticles: #REF!
Name h: #REF!
Name instructionsUrl: #REF!
Name loadingPeriod: #REF!
Name loadsPerMonth: #REF!
Name logArticles: #REF!
Name logDeficiency: #REF!
Name logMovements: #REF!
Name logPredict: #REF!
Name logRemains: #REF!
Name logSells: #REF!
Name logStore: #REF!
Name logTransit: #REF!
Name logTurnover: #REF!
Name logWaiting: #REF!
Name minRemains: #REF!
Name packSize: #REF!
Name regionSellsPerMonth: #REF!
Name sellsPeriod: #REF!
Name t: #REF!
Name x: #REF!
Name y: #REF!

Sheet Сводный
A1: Артикул ВБ | B1: Артикул ОЗОН | C1: Артикул поставщика | D1: Наименование | E1: ШК | Q1: ЗАКАЗАНО ЗА | R1: 60 | S1: дн. | AH1: ОСТАТОК | AK1: Необходимо к поставке на -> дней (указать рядом сколько дней) | AY1: 60 | BL1: В период АКЦИЙ Необходимо к поставке на дней --> | BM1: 60 | BN1: 0.3 | BO1: Поставляется из Заказа | BP1: вставлены значения | BQ1: Остаток ФФ | BU1: ОТГРУЖАЮ НА СКЛАДЫ МП | CE1: ОТГРУЗКА НА МП ВСЕГО | CF1: Отгрузка на ФФ Всего | CG1: Останется на ФФ
A2: ВБ | B2: ОЗОН | F2: Электросталь | G2: Коледино | H2: Тула | I2: Рязань (Тюшевское) | J2: Краснодар | K2: Невинномысск | L2: Волгоград | M2: Самара (Новосемейкино) | N2: Казань | O2: Склад Шушары | P2: Екатеринбург - Перспективный 12 | Q2: Новосибирск | R2: ИТОГ ВБ | S2: ОЗОН | T2: ВСЕГО | U2: Электросталь | V2: Коледино | W2: Тула | X2: Рязань (Тюшевское) | Y2: Краснодар | Z2: Невинномысск | AA2: Волгоград | AB2: Самара (Новосемейкино) | AC2: Казань | AD2: СПБ Шушары | AE2: Екатеринбург - Перспективный 12 | AF2: Новосибирск | AG2: ИТОГ ВБ | AH2: Хватит , дней | AI2: ОЗОН | AJ2: ВСЕГО | AK2: Электросталь | AL2: Коледино | AM2: Тула | AN2: Рязань (Тюшевское) | AO2: Краснодар | AP2: Невинномысск | AQ2: Волгоград | AR2: Самара (Новосемейкино) | AS2: Казань | AT2: СПБ Шушары | AU2: Екатеринбург - Перспективный 12 | AV2: Новосибирск | AW2: ВСЕГО | AX2: ОЗОН | AY2: ВСЕГО на дней | AZ2: Электросталь | BA2: Коледино | BB2: Тула | BC2: Рязань (Тюшевское) | BD2: Краснодар | BE2: Невинномысск | BF2: Волгоград | BG2: Самара (Новосемейкино) | BH2: Казань | BI2: СПБ Шушары | BJ2: Екатеринбург - Перспективный 12 | BK2: Новосибирск | BL2: ВСЕГО | BM2: ОЗОН | BN2: ВСЕГО плюс % | BO2: Артикулов ВБ | BP2: Товары из Китая | BR2: Электросталь | BS2: Коледино | BT2: Тула | BU2: Рязань | BV2: Краснодар | BW2: Невинномысск | BX2: Волгоград | BY2: Самара (Новосемейкино) | BZ2: Казань | CA2: СПБ Шушары | CB2: Екатеринбург - Перспективный 12 | CC2: Новосибирск | CD2: OZON
A3: =[1]Юнит!A5 -> 169112569 | B3: =[1]Юнит!B5 -> 0 | C3: =[1]Юнит!C5 -> ACRF1BN101PN | D3: =[1]Юнит!D5 -> Бандаж для лица розовый | E3: =[1]Юнит!E5 -> 2038161736993 | F3: =ROUNDUP(SUMIFS('ВБ Отчет Продажи (за 60 дней)'!$L:$L,'ВБ Отчет Продажи (за 60 дней)'!$K:$K,"Электросталь",'ВБ Отчет Продажи (за 60 дней)'!$G:$G,$A3),0) -> 2 | G3: =ROUNDUP(SUMIFS('ВБ Отчет Продажи (за 60 дней)'!$L:$L,'ВБ Отчет Продажи (за 60 дней)'!$K:$K,"Коледино",'ВБ Отчет Продажи (за 60 дней)'!$G:$G,$A3),0) -> 3 | H3: =ROUNDUP(SUMIFS('ВБ Отчет Продажи (за 60 дней)'!$L:$L,'ВБ Отчет Продажи (за 60 дней)'!$K:$K,"Тула",'ВБ Отчет Продажи (за 60 дней)'!$G:$G,$A3),0) -> 1 | I3: =ROUNDUP(SUMIFS('ВБ Отчет Продажи (за 60 дней)'!$L:$L,'ВБ Отчет Продажи (за 60 дней)'!$K:$K,"Рязань (Тюшевское)",'ВБ Отчет Продажи (за 60 дней)'!$G:$G,$A3),0) -> 0 | J3: =ROUNDUP(SUMIFS('ВБ Отчет Продажи (за 60 дней)'!$L:$L,'ВБ Отчет Продажи (за 60 дней)'!$K:$K,"Краснодар",'ВБ Отчет Продажи (за 60 дней)'!$G:$G,$A3),0) -> 1 | K3: =ROUNDUP(SUMIFS('ВБ Отчет Продажи (за 60 дней)'!$L:$L,'ВБ Отчет Продажи (за 60 дней)'!$K:$K,"Невинномысск",'ВБ Отчет Продажи (за 60 дней)'!$G:$G,$A3),0) -> 0 | L3: =ROUNDUP(SUMIFS('ВБ Отчет Продажи (за 60 дней)'!$L:$L,'ВБ Отчет Продажи (за 60 дней)'!$K:$K,"Волгоград",'ВБ Отчет Продажи (за 60 дней)'!$G:$G,$A3),0) -> 0 | M3: =ROUNDUP(SUMIFS('ВБ Отчет Продажи (за 60 дней)'!$L:$L,'ВБ Отчет Продажи (за 60 дней)'!$K:$K,"Самара (Новосемейкино)",'ВБ Отчет Продажи (за 60 дней)'!$G:$G,$A3),0) -> 0 | N3: =ROUNDUP(SUMIFS('ВБ Отчет Продажи (за 60 дней)'!$L:$L,'ВБ Отчет Продажи (за 60 дней)'!$K:$K,"Казань",'ВБ Отчет Продажи (за 60 дней)'!$G:$G,$A3),0) -> 2 | O3: =ROUNDUP(SUMIFS('ВБ Отчет Продажи (за 60 дней)'!$L:$L,'ВБ Отчет Продажи (за 60 дней)'!$K:$K,"СПБ Шушары",'ВБ Отчет Продажи (за 60 дней)'!$G:$G,$A3),0) -> 0 | P3: =ROUNDUP(SUMIFS('ВБ Отчет Продажи (за 60 дней)'!$L:$L,'ВБ Отчет Продажи (за 60 дней)'!$K:$K,"Екатеринбург - Перспективный 12",'ВБ Отчет Продажи (за 60 дней)'!$G:$G,$A3),0) -> 0 | Q3: =ROUNDUP(SUMIFS('ВБ Отчет Продажи (за 60 дней)'!$L:$L,'ВБ Отчет Продажи (за 60 дней)'!$K:$K,"Новосибирск",'ВБ Отчет Продажи (за 60 дней)'!$G:$G,$A3),0) -> 0 | R3: =SUM(F3:Q3) -> 9 | S3: =SUMIFS('ОЗОН Оборот ведом (за 60 дней)'!I:I,'ОЗОН Оборот ведом (за 60 дней)'!A:A,B3) -> 0 | T3: =SUM(R3:S3) -> 9 | U3: =SUMIFS('ВБ Отчет Продажи (за 60 дней)'!$P:$P,'ВБ Отчет Продажи (за 60 дней)'!$K:$K,"Электросталь",'ВБ Отчет Продажи (за 60 дней)'!$G:$G,$A3) -> 75 | V3: =SUMIFS('ВБ Отчет Продажи (за 60 дней)'!$P:$P,'ВБ Отчет Продажи (за 60 дней)'!$K:$K,"Коледино",'ВБ Отчет Продажи (за 60 дней)'!$G:$G,$A3) -> 1 | W3: =SUMIFS('ВБ Отчет Продажи (за 60 дней)'!$P:$P,'ВБ Отчет Продажи (за 60 дней)'!$K:$K,"Тула",'ВБ Отчет Продажи (за 60 дней)'!$G:$G,$A3) -> 21 | X3: =SUMIFS('ВБ Отчет Продажи (за 60 дней)'!$P:$P,'ВБ Отчет Продажи (за 60 дней)'!$K:$K,"Рязань (Тюшевское)",'ВБ Отчет Продажи (за 60 дней)'!$G:$G,$A3) -> 0 | Y3: =SUMIFS('ВБ Отчет Продажи (за 60 дней)'!$P:$P,'ВБ Отчет Продажи (за 60 дней)'!$K:$K,"Краснодар",'ВБ Отчет Продажи (за 60 дней)'!$G:$G,$A3) -> 36 | Z3: =SUMIFS('ВБ Отчет Продажи (за 60 дней)'!$P:$P,'ВБ Отчет Продажи (за 60 дней)'!$K:$K,"Невинномысск",'ВБ Отчет Продажи (за 60 дней)'!$G:$G,$A3) -> 0 | AA3: =SUMIFS('ВБ Отчет Продажи (за 60 дней)'!$P:$P,'ВБ Отчет Продажи (за 60 дней)'!$K:$K,"Волгоград",'ВБ Отчет Продажи (за 60 дней)'!$G:$G,$A3) -> 0 | AB3: =SUMIFS('ВБ Отчет Продажи (за 60 дней)'!$P:$P,'ВБ Отчет Продажи (за 60 дней)'!$K:$K,"Самара (Новосемейкино)",'ВБ Отчет Продажи (за 60 дней)'!$G:$G,$A3) -> 1 | AC3: =SUMIFS('ВБ Отчет Продажи (за 60 дней)'!$P:$P,'ВБ Отчет Продажи (за 60 дней)'!$K:$K,"Казань",'ВБ Отчет Продажи (за 60 дней)'!$G:$G,$A3) -> 0 | AD3: =SUMIFS('ВБ Отчет Продажи (за 60 дней)'!$P:$P,'ВБ Отчет Продажи (за 60 дней)'!$K:$K,"СПБ Шушары",'ВБ Отчет Продажи (за 60 дней)'!$G:$G,$A3) -> 0 | AE3: =SUMIFS('ВБ Отчет Продажи (за 60 дней)'!$P:$P,'ВБ Отчет Продажи (за 60 дней)'!$K:$K,"Екатеринбург - Перспективный 12",'ВБ Отчет Продажи (за 60 дней)'!$G:$G,$A3) -> 0 | AF3: =SUMIFS('ВБ Отчет Продажи (за 60 дней)'!$P:$P,'ВБ Отчет Продажи (за 60 дней)'!$K:$K,"Новосибирск",'ВБ Отчет Продажи (за 60 дней)'!$G:$G,$A3) -> 0 | AG3: =SUM(U3:AF3) -> 134 | AH3: =IFERROR(AG3*$R$1/R3,0) -> 893.33333 | AI3: =SUMIFS('ОЗОН Оборот ведом (за 60 дней)'!J:J,'ОЗОН Оборот ведом (за 60 дней)'!A:A,B3) -> 0 | AJ3: =AG3+AI3 -> 134 | AK3: {=IFERROR(_xlfn.IFS((F3-U3)>0,F3/$R$1*$AY$1-U3,F3+U3=0,"нов"),0)} -> 0 | AL3: {=IFERROR(_xlfn.IFS((G3-V3)>0,G3/$R$1*$AY$1-V3,G3+V3=0,"нов"),0)} -> 2 | AM3: {=IFERROR(_xlfn.IFS((H3-W3)>0,H3/$R$1*$AY$1-W3,H3+W3=0,"нов"),0)} -> 0 | AN3: {=IFERROR(_xlfn.IFS((I3-X3)>0,I3/$R$1*$AY$1-X3,I3+X3=0,"нов"),0)} -> нов | AO3: {=IFERROR(_xlfn.IFS((J3-Y3)>0,J3/$R$1*$AY$1-Y3,J3+Y3=0,"нов"),0)} -> 0 | AP3: {=IFERROR(_xlfn.IFS((K3-Z3)>0,K3/$R$1*$AY$1-Z3,K3+Z3=0,"нов"),0)} -> нов | AQ3: {=IFERROR(_xlfn.IFS((L3-AA3)>0,L3/$R$1*$AY$1-AA3,L3+AA3=0,"нов"),0)} -> нов | AR3: {=IFERROR(_xlfn.IFS((M3-AB3)>0,M3/$R$1*$AY$1-AB3,M3+AB3=0,"нов"),0)} -> 0 | ... AV3: {=IFERROR(_xlfn.IFS((Q3-AF3)>0,Q3/$R$1*$AY$1-AF3,Q3+AF3=0,"нов"),0)} -> нов | AW3: =SUM(AK3:AV3) -> 4 | AX3: =SUMIF('ОЗОН Доступн товара'!D:D,_xlfn.XLOOKUP($B3,'ОЗОН Доступн товара'!$A:$A,'ОЗОН Доступн товара'!$D:$D,0)) -> 0 | AY3: =SUM(AW3:AX3) -> 4 | AZ3: =IF(AK3="нов","нов",ROUNDUP(AK3*1.3,0)) -> 0 | BA3: =IF(AL3="нов","нов",ROUNDUP(AL3*1.3,0)) -> 3 | BB3: =IF(AM3="нов","нов",ROUNDUP(AM3*1.3,0)) -> 0 | BC3: =IF(AN3="нов","нов",ROUNDUP(AN3*1.3,0)) -> нов | BD3: =IF(AO3="нов","нов",ROUNDUP(AO3*1.3,0)) -> 0 | BE3: =IF(AP3="нов","нов",ROUNDUP(AP3*1.3,0)) -> нов | BF3: =IF(AQ3="нов","нов",ROUNDUP(AQ3*1.3,0)) -> нов | BG3: =IF(AR3="нов","нов",ROUNDUP(AR3*1.3,0)) -> 0 | ... BK3: =IF(AV3="нов","нов",ROUNDUP(AV3*1.3,0)) -> нов | BL3: =SUM(AZ3:BK3) -> 6 | BM3: =AX3*1.3 -> 0 | BN3: =SUM(BL3:BM3) -> 6 | BO3: =IFERROR(_xlfn.XLOOKUP(A3,'[2] Расчет стоимости и веса'!$I:$I,'[2] Расчет стоимости и веса'!$D:$D),0) -> 0 | BP3: =BO3 -> 0 | CD3: =_xlfn.XLOOKUP(E3,[3]ТЗ_ФФ!$D:$D,[3]ТЗ_ФФ!$AS:$AS,0) -> 0 | CE3: =SUM(BR3:CD3) -> 0 | CF3: =MAX(BO3,CE3)-BQ3 -> 0 | CG3: =BO3+BQ3-CE3 -> 0
A4: =[1]Юнит!A6 -> 169153168 | B4: =[1]Юнит!B6 -> 2453533282 | C4: =[1]Юнит!C6 -> ACRF1BN101BC | D4: =[1]Юнит!D6 -> Бандаж для лица черный | E4: =[1]Юнит!E6 -> 2038162681926 | F4: =ROUNDUP(SUMIFS('ВБ Отчет Продажи (за 60 дней)'!$L:$L,'ВБ Отчет Продажи (за 60 дней)'!$K:$K,"Электросталь",'ВБ Отчет Продажи (за 60 дней)'!$G:$G,$A4),0) -> 4 | G4: =ROUNDUP(SUMIFS('ВБ Отчет Продажи (за 60 дней)'!$L:$L,'ВБ Отчет Продажи (за 60 дней)'!$K:$K,"Коледино",'ВБ Отчет Продажи (за 60 дней)'!$G:$G,$A4),0) -> 8 | H4: =ROUNDUP(SUMIFS('ВБ Отчет Продажи (за 60 дней)'!$L:$L,'ВБ Отчет Продажи (за 60 дней)'!$K:$K,"Тула",'ВБ Отчет Продажи (за 60 дней)'!$G:$G,$A4),0) -> 0 | I4: =ROUNDUP(SUMIFS('ВБ Отчет Продажи (за 60 дней)'!$L:$L,'ВБ Отчет Продажи (за 60 дней)'!$K:$K,"Рязань (Тюшевское)",'ВБ Отчет Продажи (за 60 дней)'!$G:$G,$A4),0) -> 0 | J4: =ROUNDUP(SUMIFS('ВБ Отчет Продажи (за 60 дней)'!$L:$L,'ВБ Отчет Продажи (за 60 дней)'!$K:$K,"Краснодар",'ВБ Отчет Продажи (за 60 дней)'!$G:$G,$A4),0) -> 7 | K4: =ROUNDUP(SUMIFS('ВБ Отчет Продажи (за 60 дней)'!$L:$L,'ВБ Отчет Продажи (за 60 дней)'!$K:$K,"Невинномысск",'ВБ Отчет Продажи (за 60 дней)'!$G:$G,$A4),0) -> 1 | L4: =ROUNDUP(SUMIFS('ВБ Отчет Продажи (за 60 дней)'!$L:$L,'ВБ Отчет Продажи (за 60 дней)'!$K:$K,"Волгоград",'ВБ Отчет Продажи (за 60 дней)'!$G:$G,$A4),0) -> 0 | M4: =ROUNDUP(SUMIFS('ВБ Отчет Продажи (за 60 дней)'!$L:$L,'ВБ Отчет Продажи (за 60 дней)'!$K:$K,"Самара (Новосемейкино)",'ВБ Отчет Продажи (за 60 дней)'!$G:$G,$A4),0) -> 3 | N4: =ROUNDUP(SUMIFS('ВБ Отчет Продажи (за 60 дней)'!$L:$L,'ВБ Отчет Продажи (за 60 дней)'!$K:$K,"Казань",'ВБ Отчет Продажи (за 60 дней)'!$G:$G,$A4),0) -> 4 | O4: =ROUNDUP(SUMIFS('ВБ Отчет Продажи (за 60 дней)'!$L:$L,'ВБ Отчет Продажи (за 60 дней)'!$K:$K,"СПБ Шушары",'ВБ Отчет Продажи (за 60 дней)'!$G:$G,$A4),0) -> 0 | P4: =ROUNDUP(SUMIFS('ВБ Отчет Продажи (за 60 дней)'!$L:$L,'ВБ Отчет Продажи (за 60 дней)'!$K:$K,"Екатеринбург - Перспективный 12",'ВБ Отчет Продажи (за 60 дней)'!$G:$G,$A4),0) -> 0 | Q4: =ROUNDUP(SUMIFS('ВБ Отчет Продажи (за 60 дней)'!$L:$L,'ВБ Отчет Продажи (за 60 дней)'!$K:$K,"Новосибирск",'ВБ Отчет Продажи (за 60 дней)'!$G:$G,$A4),0) -> 0 | R4: =SUM(F4:Q4) -> 27 | S4: =SUMIFS('ОЗОН Оборот ведом (за 60 дней)'!I:I,'ОЗОН Оборот ведом (за 60 дней)'!A:A,B4) -> 5 | T4: =SUM(R4:S4) -> 32 | U4: =SUMIFS('ВБ Отчет Продажи (за 60 дней)'!$P:$P,'ВБ Отчет Продажи (за 60 дней)'!$K:$K,"Электросталь",'ВБ Отчет Продажи (за 60 дней)'!$G:$G,$A4) -> 58 | V4: =SUMIFS('ВБ Отчет Продажи (за 60 дней)'!$P:$P,'ВБ Отчет Продажи (за 60 дней)'!$K:$K,"Коледино",'ВБ Отчет Продажи (за 60 дней)'!$G:$G,$A4) -> 8 | W4: =SUMIFS('ВБ Отчет Продажи (за 60 дней)'!$P:$P,'ВБ Отчет Продажи (за 60 дней)'!$K:$K,"Тула",'ВБ Отчет Продажи (за 60 дней)'!$G:$G,$A4) -> 0 | X4: =SUMIFS('ВБ Отчет Продажи (за 60 дней)'!$P:$P,'ВБ Отчет Продажи (за 60 дней)'!$K:$K,"Рязань (Тюшевское)",'ВБ Отчет Продажи (за 60 дней)'!$G:$G,$A4) -> 5 | Y4: =SUMIFS('ВБ Отчет Продажи (за 60 дней)'!$P:$P,'ВБ Отчет Продажи (за 60 дней)'!$K:$K,"Краснодар",'ВБ Отчет Продажи (за 60 дней)'!$G:$G,$A4) -> 23 | Z4: =SUMIFS('ВБ Отчет Продажи (за 60 дней)'!$P:$P,'ВБ Отчет Продажи (за 60 дней)'!$K:$K,"Невинномысск",'ВБ Отчет Продажи (за 60 дней)'!$G:$G,$A4) -> 13 | AA4: =SUMIFS('ВБ Отчет Продажи (за 60 дней)'!$P:$P,'ВБ Отчет Продажи (за 60 дней)'!$K:$K,"Волгоград",'ВБ Отчет Продажи (за 60 дней)'!$G:$G,$A4) -> 0 | AB4: =SUMIFS('ВБ Отчет Продажи (за 60 дней)'!$P:$P,'ВБ Отчет Продажи (за 60 дней)'!$K:$K,"Самара (Новосемейкино)",'ВБ Отчет Продажи (за 60 дней)'!$G:$G,$A4) -> 21 | AC4: =SUMIFS('ВБ Отчет Продажи (за 60 дней)'!$P:$P,'ВБ Отчет Продажи (за 60 дней)'!$K:$K,"Казань",'ВБ Отчет Продажи (за 60 дней)'!$G:$G,$A4) -> 44 | AD4: =SUMIFS('ВБ Отчет Продажи (за 60 дней)'!$P:$P,'ВБ Отчет Продажи (за 60 дней)'!$K:$K,"СПБ Шушары",'ВБ Отчет Продажи (за 60 дней)'!$G:$G,$A4) -> 0 | AE4: =SUMIFS('ВБ Отчет Продажи (за 60 дней)'!$P:$P,'ВБ Отчет Продажи (за 60 дней)'!$K:$K,"Екатеринбург - Перспективный 12",'ВБ Отчет Продажи (за 60 дней)'!$G:$G,$A4) -> 0 | AF4: =SUMIFS('ВБ Отчет Продажи (за 60 дней)'!$P:$P,'ВБ Отчет Продажи (за 60 дней)'!$K:$K,"Новосибирск",'ВБ Отчет Продажи (за 60 дней)'!$G:$G,$A4) -> 0 | AG4: =SUM(U4:AF4) -> 172 | AH4: =IFERROR(AG4*$R$1/R4,0) -> 382.22222 | AI4: =SUMIFS('ОЗОН Оборот ведом (за 60 дней)'!J:J,'ОЗОН Оборот ведом (за 60 дней)'!A:A,B4) -> 0 | AJ4: =AG4+AI4 -> 172 | AK4: {=IFERROR(_xlfn.IFS((F4-U4)>0,F4/$R$1*$AY$1-U4,F4+U4=0,"нов"),0)} -> 0 | AL4: {=IFERROR(_xlfn.IFS((G4-V4)>0,G4/$R$1*$AY$1-V4,G4+V4=0,"нов"),0)} -> 0 | AM4: {=IFERROR(_xlfn.IFS((H4-W4)>0,H4/$R$1*$AY$1-W4,H4+W4=0,"нов"),0)} -> нов | AN4: {=IFERROR(_xlfn.IFS((I4-X4)>0,I4/$R$1*$AY$1-X4,I4+X4=0,"нов"),0)} -> 0 | AO4: {=IFERROR(_xlfn.IFS((J4-Y4)>0,J4/$R$1*$AY$1-Y4,J4+Y4=0,"нов"),0)} -> 0 | AP4: {=IFERROR(_xlfn.IFS((K4-Z4)>0,K4/$R$1*$AY$1-Z4,K4+Z4=0,"нов"),0)} -> 0 | AQ4: {=IFERROR(_xlfn.IFS((L4-AA4)>0,L4/$R$1*$AY$1-AA4,L4+AA4=0,"нов"),0)} -> нов | AR4: {=IFERROR(_xlfn.IFS((M4-AB4)>0,M4/$R$1*$AY$1-AB4,M4+AB4=0,"нов"),0)} -> 0 | ... AV4: {=IFERROR(_xlfn.IFS((Q4-AF4)>0,Q4/$R$1*$AY$1-AF4,Q4+AF4=0,"нов"),0)} -> нов | AW4: =SUM(AK4:AV4) -> 0 | AX4: =SUMIF('ОЗОН Доступн товара'!D:D,_xlfn.XLOOKUP($B4,'ОЗОН Доступн товара'!$A:$A,'ОЗОН Доступн товара'!$D:$D,0)) -> 0 | AY4: =SUM(AW4:AX4) -> 0 | AZ4: =IF(AK4="нов","нов",ROUNDUP(AK4*1.3,0)) -> 0 | BA4: =IF(AL4="нов","нов",ROUNDUP(AL4*1.3,0)) -> 0 | BB4: =IF(AM4="нов","нов",ROUNDUP(AM4*1.3,0)) -> нов | BC4: =IF(AN4="нов","нов",ROUNDUP(AN4*1.3,0)) -> 0 | BD4: =IF(AO4="нов","нов",ROUNDUP(AO4*1.3,0)) -> 0 | BE4: =IF(AP4="нов","нов",ROUNDUP(AP4*1.3,0)) -> 0 | BF4: =IF(AQ4="нов","нов",ROUNDUP(AQ4*1.3,0)) -> нов | BG4: =IF(AR4="нов","нов",ROUNDUP(AR4*1.3,0)) -> 0 | ... BK4: =IF(AV4="нов","нов",ROUNDUP(AV4*1.3,0)) -> нов | BL4: =SUM(AZ4:BK4) -> 0 | BM4: =AX4*1.3 -> 0 | BN4: =SUM(BL4:BM4) -> 0 | BO4: =IFERROR(_xlfn.XLOOKUP(A4,'[2] Расчет стоимости и веса'!$I:$I,'[2] Расчет стоимости и веса'!$D:$D),0) -> 40 | BP4: =BO4 -> 40 | CA4: 20 | CB4: 20 | CE4: =SUM(BR4:CD4) -> 40 | CF4: =MAX(BO4,CE4)-BQ4 -> 40 | CG4: =BO4+BQ4-CE4 -> 0
A5: =[1]Юнит!A7 -> 169395410 | B5: =[1]Юнит!B7 -> 2419349210 | C5: =[1]Юнит!C7 -> ACRF1BN201GR | D5: =[1]Юнит!D7 -> Бандаж для лица серый | E5: =[1]Юнит!E7 -> 2038172050200 | F5: =ROUNDUP(SUMIFS('ВБ Отчет Продажи (за 60 дней)'!$L:$L,'ВБ Отчет Продажи (за 60 дней)'!$K:$K,"Электросталь",'ВБ Отчет Продажи (за 60 дней)'!$G:$G,$A5),0) -> 12 | G5: =ROUNDUP(SUMIFS('ВБ Отчет Продажи (за 60 дней)'!$L:$L,'ВБ Отчет Продажи (за 60 дней)'!$K:$K,"Коледино",'ВБ Отчет Продажи (за 60 дней)'!$G:$G,$A5),0) -> 6 | H5: =ROUNDUP(SUMIFS('ВБ Отчет Продажи (за 60 дней)'!$L:$L,'ВБ Отчет Продажи (за 60 дней)'!$K:$K,"Тула",'ВБ Отчет Продажи (за 60 дней)'!$G:$G,$A5),0) -> 2 | I5: =ROUNDUP(SUMIFS('ВБ Отчет Продажи (за 60 дней)'!$L:$L,'ВБ Отчет Продажи (за 60 дней)'!$K:$K,"Рязань (Тюшевское)",'ВБ Отчет Продажи (за 60 дней)'!$G:$G,$A5),0) -> 2 | J5: =ROUNDUP(SUMIFS('ВБ Отчет Продажи (за 60 дней)'!$L:$L,'ВБ Отчет Продажи (за 60 дней)'!$K:$K,"Краснодар",'ВБ Отчет Продажи (за 60 дней)'!$G:$G,$A5),0) -> 4 | K5: =ROUNDUP(SUMIFS('ВБ Отчет Продажи (за 60 дней)'!$L:$L,'ВБ Отчет Продажи (за 60 дней)'!$K:$K,"Невинномысск",'ВБ Отчет Продажи (за 60 дней)'!$G:$G,$A5),0) -> 2 | L5: =ROUNDUP(SUMIFS('ВБ Отчет Продажи (за 60 дней)'!$L:$L,'ВБ Отчет Продажи (за 60 дней)'!$K:$K,"Волгоград",'ВБ Отчет Продажи (за 60 дней)'!$G:$G,$A5),0) -> 0 | M5: =ROUNDUP(SUMIFS('ВБ Отчет Продажи (за 60 дней)'!$L:$L,'ВБ Отчет Продажи (за 60 дней)'!$K:$K,"Самара (Новосемейкино)",'ВБ Отчет Продажи (за 60 дней)'!$G:$G,$A5),0) -> 3 | N5: =ROUNDUP(SUMIFS('ВБ Отчет Продажи (за 60 дней)'!$L:$L,'ВБ Отчет Продажи (за 60 дней)'!$K:$K,"Казань",'ВБ Отчет Продажи (за 60 дней)'!$G:$G,$A5),0) -> 2 | O5: =ROUNDUP(SUMIFS('ВБ Отчет Продажи (за 60 дней)'!$L:$L,'ВБ Отчет Продажи (за 60 дней)'!$K:$K,"СПБ Шушары",'ВБ Отчет Продажи (за 60 дней)'!$G:$G,$A5),0) -> 0 | P5: =ROUNDUP(SUMIFS('ВБ Отчет Продажи (за 60 дней)'!$L:$L,'ВБ Отчет Продажи (за 60 дней)'!$K:$K,"Екатеринбург - Перспективный 12",'ВБ Отчет Продажи (за 60 дней)'!$G:$G,$A5),0) -> 0 | Q5: =ROUNDUP(SUMIFS('ВБ Отчет Продажи (за 60 дней)'!$L:$L,'ВБ Отчет Продажи (за 60 дней)'!$K:$K,"Новосибирск",'ВБ Отчет Продажи (за 60 дней)'!$G:$G,$A5),0) -> 0 | R5: =SUM(F5:Q5) -> 33 | S5: =SUMIFS('ОЗОН Оборот ведом (за 60 дней)'!I:I,'ОЗОН Оборот ведом (за 60 дней)'!A:A,B5) -> 28 | T5: =SUM(R5:S5) -> 61 | U5: =SUMIFS('ВБ Отчет Продажи (за 60 дней)'!$P:$P,'ВБ Отчет Продажи (за 60 дней)'!$K:$K,"Электросталь",'ВБ Отчет Продажи (за 60 дней)'!$G:$G,$A5) -> 26 | V5: =SUMIFS('ВБ Отчет Продажи (за 60 дней)'!$P:$P,'ВБ Отчет Продажи (за 60 дней)'!$K:$K,"Коледино",'ВБ Отчет Продажи (за 60 дней)'!$G:$G,$A5) -> 30 | W5: =SUMIFS('ВБ Отчет Продажи (за 60 дней)'!$P:$P,'ВБ Отчет Продажи (за 60 дней)'!$K:$K,"Тула",'ВБ Отчет Продажи (за 60 дней)'!$G:$G,$A5) -> 0 | X5: =SUMIFS('ВБ Отчет Продажи (за 60 дней)'!$P:$P,'ВБ Отчет Продажи (за 60 дней)'!$K:$K,"Рязань (Тюшевское)",'ВБ Отчет Продажи (за 60 дней)'!$G:$G,$A5) -> 15 | Y5: =SUMIFS('ВБ Отчет Продажи (за 60 дней)'!$P:$P,'ВБ Отчет Продажи (за 60 дней)'!$K:$K,"Краснодар",'ВБ Отчет Продажи (за 60 дней)'!$G:$G,$A5) -> 13 | Z5: =SUMIFS('ВБ Отчет Продажи (за 60 дней)'!$P:$P,'ВБ Отчет Продажи (за 60 дней)'!$K:$K,"Невинномысск",'ВБ Отчет Продажи (за 60 дней)'!$G:$G,$A5) -> 31 | AA5: =SUMIFS('ВБ Отчет Продажи (за 60 дней)'!$P:$P,'ВБ Отчет Продажи (за 60 дней)'!$K:$K,"Волгоград",'ВБ Отчет Продажи (за 60 дней)'!$G:$G,$A5) -> 0 | AB5: =SUMIFS('ВБ Отчет Продажи (за 60 дней)'!$P:$P,'ВБ Отчет Продажи (за 60 дней)'!$K:$K,"Самара (Новосемейкино)",'ВБ Отчет Продажи (за 60 дней)'!$G:$G,$A5) -> 31 | AC5: =SUMIFS('ВБ Отчет Продажи (за 60 дней)'!$P:$P,'ВБ Отчет Продажи (за 60 дней)'!$K:$K,"Казань",'ВБ Отчет Продажи (за 60 дней)'!$G:$G,$A5) -> 17 | AD5: =SUMIFS('ВБ Отчет Продажи (за 60 дней)'!$P:$P,'ВБ Отчет Продажи (за 60 дней)'!$K:$K,"СПБ Шушары",'ВБ Отчет Продажи (за 60 дней)'!$G:$G,$A5) -> 0 | AE5: =SUMIFS('ВБ Отчет Продажи (за 60 дней)'!$P:$P,'ВБ Отчет Продажи (за 60 дней)'!$K:$K,"Екатеринбург - Перспективный 12",'ВБ Отчет Продажи (за 60 дней)'!$G:$G,$A5) -> 0 | AF5: =SUMIFS('ВБ Отчет Продажи (за 60 дней)'!$P:$P,'ВБ Отчет Продажи (за 60 дней)'!$K:$K,"Новосибирск",'ВБ Отчет Продажи (за 60 дней)'!$G:$G,$A5) -> 0 | AG5: =SUM(U5:AF5) -> 163 | AH5: =IFERROR(AG5*$R$1/R5,0) -> 296.36364 | AI5: =SUMIFS('ОЗОН Оборот ведом (за 60 дней)'!J:J,'ОЗОН Оборот ведом (за 60 дней)'!A:A,B5) -> 1 | AJ5: =AG5+AI5 -> 164 | AK5: {=IFERROR(_xlfn.IFS((F5-U5)>0,F5/$R$1*$AY$1-U5,F5+U5=0,"нов"),0)} -> 0 | AL5: {=IFERROR(_xlfn.IFS((G5-V5)>0,G5/$R$1*$AY$1-V5,G5+V5=0,"нов"),0)} -> 0 | AM5: {=IFERROR(_xlfn.IFS((H5-W5)>0,H5/$R$1*$AY$1-W5,H5+W5=0,"нов"),0)} -> 2 | AN5: {=IFERROR(_xlfn.IFS((I5-X5)>0,I5/$R$1*$AY$1-X5,I5+X5=0,"нов"),0)} -> 0 | AO5: {=IFERROR(_xlfn.IFS((J5-Y5)>0,J5/$R$1*$AY$1-Y5,J5+Y5=0,"нов"),0)} -> 0 | AP5: {=IFERROR(_xlfn.IFS((K5-Z5)>0,K5/$R$1*$AY$1-Z5,K5+Z5=0,"нов"),0)} -> 0 | AQ5: {=IFERROR(_xlfn.IFS((L5-AA5)>0,L5/$R$1*$AY$1-AA5,L5+AA5=0,"нов"),0)} -> нов | AR5: {=IFERROR(_xlfn.IFS((M5-AB5)>0,M5/$R$1*$AY$1-AB5,M5+AB5=0,"нов"),0)} -> 0 | ... AV5: {=IFERROR(_xlfn.IFS((Q5-AF5)>0,Q5/$R$1*$AY$1-AF5,Q5+AF5=0,"нов"),0)} -> нов | AW5: =SUM(AK5:AV5) -> 2 | AX5: =SUMIF('ОЗОН Доступн товара'!D:D,_xlfn.XLOOKUP($B5,'ОЗОН Доступн товара'!$A:$A,'ОЗОН Доступн товара'!$D:$D,0)) -> 24 | AY5: =SUM(AW5:AX5) -> 26 | AZ5: =IF(AK5="нов","нов",ROUNDUP(AK5*1.3,0)) -> 0 | BA5: =IF(AL5="нов","нов",ROUNDUP(AL5*1.3,0)) -> 0 | BB5: =IF(AM5="нов","нов",ROUNDUP(AM5*1.3,0)) -> 3 | BC5: =IF(AN5="нов","нов",ROUNDUP(AN5*1.3,0)) -> 0 | BD5: =IF(AO5="нов","нов",ROUNDUP(AO5*1.3,0)) -> 0 | BE5: =IF(AP5="нов","нов",ROUNDUP(AP5*1.3,0)) -> 0 | BF5: =IF(AQ5="нов","нов",ROUNDUP(AQ5*1.3,0)) -> нов | BG5: =IF(AR5="нов","нов",ROUNDUP(AR5*1.3,0)) -> 0 | ... BK5: =IF(AV5="нов","нов",ROUNDUP(AV5*1.3,0)) -> нов | BL5: =SUM(AZ5:BK5) -> 3 | BM5: =AX5*1.3 -> 31.2 | BN5: =SUM(BL5:BM5) -> 34.2 | BO5: =IFERROR(_xlfn.XLOOKUP(A5,'[2] Расчет стоимости и веса'!$I:$I,'[2] Расчет стоимости и веса'!$D:$D),0) -> 40 | BP5: =BO5 -> 40 | CA5: 20 | CB5: 20 | CE5: =SUM(BR5:CD5) -> 40 | CF5: =MAX(BO5,CE5)-BQ5 -> 40 | CG5: =BO5+BQ5-CE5 -> 0
A6: =[1]Юнит!A8 -> 172832355 | B6: =[1]Юнит!B8 -> 2419349460 | C6: =[1]Юнит!C8 -> AHMA7BW101BG | D6: =[1]Юнит!D8 -> Мешки 7 шт. | E6: =[1]Юнит!E8 -> 2038337652454 | F6: =ROUNDUP(SUMIFS('ВБ Отчет Продажи (за 60 дней)'!$L:$L,'ВБ Отчет Продажи (за 60 дней)'!$K:$K,"Электросталь",'ВБ Отчет Продажи (за 60 дней)'!$G:$G,$A6),0) -> 3 | G6: =ROUNDUP(SUMIFS('ВБ Отчет Продажи (за 60 дней)'!$L:$L,'ВБ Отчет Продажи (за 60 дней)'!$K:$K,"Коледино",'ВБ Отчет Продажи (за 60 дней)'!$G:$G,$A6),0) -> 2 | H6: =ROUNDUP(SUMIFS('ВБ Отчет Продажи (за 60 дней)'!$L:$L,'ВБ Отчет Продажи (за 60 дней)'!$K:$K,"Тула",'ВБ Отчет Продажи (за 60 дней)'!$G:$G,$A6),0) -> 0 | I6: =ROUNDUP(SUMIFS('ВБ Отчет Продажи (за 60 дней)'!$L:$L,'ВБ Отчет Продажи (за 60 дней)'!$K:$K,"Рязань (Тюшевское)",'ВБ Отчет Продажи (за 60 дней)'!$G:$G,$A6),0) -> 2 | J6: =ROUNDUP(SUMIFS('ВБ Отчет Продажи (за 60 дней)'!$L:$L,'ВБ Отчет Продажи (за 60 дней)'!$K:$K,"Краснодар",'ВБ Отчет Продажи (за 60 дней)'!$G:$G,$A6),0) -> 1 | K6: =ROUNDUP(SUMIFS('ВБ Отчет Продажи (за 60 дней)'!$L:$L,'ВБ Отчет Продажи (за 60 дней)'!$K:$K,"Невинномысск",'ВБ Отчет Продажи (за 60 дней)'!$G:$G,$A6),0) -> 0 | L6: =ROUNDUP(SUMIFS('ВБ Отчет Продажи (за 60 дней)'!$L:$L,'ВБ Отчет Продажи (за 60 дней)'!$K:$K,"Волгоград",'ВБ Отчет Продажи (за 60 дней)'!$G:$G,$A6),0) -> 0 | M6: =ROUNDUP(SUMIFS('ВБ Отчет Продажи (за 60 дней)'!$L:$L,'ВБ Отчет Продажи (за 60 дней)'!$K:$K,"Самара (Новосемейкино)",'ВБ Отчет Продажи (за 60 дней)'!$G:$G,$A6),0) -> 1 | N6: =ROUNDUP(SUMIFS('ВБ Отчет Продажи (за 60 дней)'!$L:$L,'ВБ Отчет Продажи (за 60 дней)'!$K:$K,"Казань",'ВБ Отчет Продажи (за 60 дней)'!$G:$G,$A6),0) -> 0 | O6: =ROUNDUP(SUMIFS('ВБ Отчет Продажи (за 60 дней)'!$L:$L,'ВБ Отчет Продажи (за 60 дней)'!$K:$K,"СПБ Шушары",'ВБ Отчет Продажи (за 60 дней)'!$G:$G,$A6),0) -> 2 | P6: =ROUNDUP(SUMIFS('ВБ Отчет Продажи (за 60 дней)'!$L:$L,'ВБ Отчет Продажи (за 60 дней)'!$K:$K,"Екатеринбург - Перспективный 12",'ВБ Отчет Продажи (за 60 дней)'!$G:$G,$A6),0) -> 0 | Q6: =ROUNDUP(SUMIFS('ВБ Отчет Продажи (за 60 дней)'!$L:$L,'ВБ Отчет Продажи (за 60 дней)'!$K:$K,"Новосибирск",'ВБ Отчет Продажи (за 60 дней)'!$G:$G,$A6),0) -> 0 | R6: =SUM(F6:Q6) -> 11 | S6: =SUMIFS('ОЗОН Оборот ведом (за 60 дней)'!I:I,'ОЗОН Оборот ведом (за 60 дней)'!A:A,B6) -> 19 | T6: =SUM(R6:S6) -> 30 | U6: =SUMIFS('ВБ Отчет Продажи (за 60 дней)'!$P:$P,'ВБ Отчет Продажи (за 60 дней)'!$K:$K,"Электросталь",'ВБ Отчет Продажи (за 60 дней)'!$G:$G,$A6) -> 38 | V6: =SUMIFS('ВБ Отчет Продажи (за 60 дней)'!$P:$P,'ВБ Отчет Продажи (за 60 дней)'!$K:$K,"Коледино",'ВБ Отчет Продажи (за 60 дней)'!$G:$G,$A6) -> 9 | W6: =SUMIFS('ВБ Отчет Продажи (за 60 дней)'!$P:$P,'ВБ Отчет Продажи (за 60 дней)'!$K:$K,"Тула",'ВБ Отчет Продажи (за 60 дней)'!$G:$G,$A6) -> 0 | X6: =SUMIFS('ВБ Отчет Продажи (за 60 дней)'!$P:$P,'ВБ Отчет Продажи (за 60 дней)'!$K:$K,"Рязань (Тюшевское)",'ВБ Отчет Продажи (за 60 дней)'!$G:$G,$A6) -> 0 | Y6: =SUMIFS('ВБ Отчет Продажи (за 60 дней)'!$P:$P,'ВБ Отчет Продажи (за 60 дней)'!$K:$K,"Краснодар",'ВБ Отчет Продажи (за 60 дней)'!$G:$G,$A6) -> 2 | Z6: =SUMIFS('ВБ Отчет Продажи (за 60 дней)'!$P:$P,'ВБ Отчет Продажи (за 60 дней)'!$K:$K,"Невинномысск",'ВБ Отчет Продажи (за 60 дней)'!$G:$G,$A6) -> 26 | AA6: =SUMIFS('ВБ Отчет Продажи (за 60 дней)'!$P:$P,'ВБ Отчет Продажи (за 60 дней)'!$K:$K,"Волгоград",'ВБ Отчет Продажи (за 60 дней)'!$G:$G,$A6) -> 0 | AB6: =SUMIFS('ВБ Отчет Продажи (за 60 дней)'!$P:$P,'ВБ Отчет Продажи (за 60 дней)'!$K:$K,"Самара (Новосемейкино)",'ВБ Отчет Продажи (за 60 дней)'!$G:$G,$A6) -> 29 | AC6: =SUMIFS('ВБ Отчет Продажи (за 60 дней)'!$P:$P,'ВБ Отчет Продажи (за 60 дней)'!$K:$K,"Казань",'ВБ Отчет Продажи (за 60 дней)'!$G:$G,$A6) -> 0 | AD6: =SUMIFS('ВБ Отчет Продажи (за 60 дней)'!$P:$P,'ВБ Отчет Продажи (за 60 дней)'!$K:$K,"СПБ Шушары",'ВБ Отчет Продажи (за 60 дней)'!$G:$G,$A6) -> 8 | AE6: =SUMIFS('ВБ Отчет Продажи (за 60 дней)'!$P:$P,'ВБ Отчет Продажи (за 60 дней)'!$K:$K,"Екатеринбург - Перспективный 12",'ВБ Отчет Продажи (за 60 дней)'!$G:$G,$A6) -> 0 | AF6: =SUMIFS('ВБ Отчет Продажи (за 60 дней)'!$P:$P,'ВБ Отчет Продажи (за 60 дней)'!$K:$K,"Новосибирск",'ВБ Отчет Продажи (за 60 дней)'!$G:$G,$A6) -> 0 | AG6: =SUM(U6:AF6) -> 112 | AH6: =IFERROR(AG6*$R$1/R6,0) -> 610.90909 | AI6: =SUMIFS('ОЗОН Оборот ведом (за 60 дней)'!J:J,'ОЗОН Оборот ведом (за 60 дней)'!A:A,B6) -> 0 | AJ6: =AG6+AI6 -> 112 | AK6: {=IFERROR(_xlfn.IFS((F6-U6)>0,F6/$R$1*$AY$1-U6,F6+U6=0,"нов"),0)} -> 0 | AL6: {=IFERROR(_xlfn.IFS((G6-V6)>0,G6/$R$1*$AY$1-V6,G6+V6=0,"нов"),0)} -> 0 | AM6: {=IFERROR(_xlfn.IFS((H6-W6)>0,H6/$R$1*$AY$1-W6,H6+W6=0,"нов"),0)} -> нов | AN6: {=IFERROR(_xlfn.IFS((I6-X6)>0,I6/$R$1*$AY$1-X6,I6+X6=0,"нов"),0)} -> 2 | AO6: {=IFERROR(_xlfn.IFS((J6-Y6)>0,J6/$R$1*$AY$1-Y6,J6+Y6=0,"нов"),0)} -> 0 | AP6: {=IFERROR(_xlfn.IFS((K6-Z6)>0,K6/$R$1*$AY$1-Z6,K6+Z6=0,"нов"),0)} -> 0 | AQ6: {=IFERROR(_xlfn.IFS((L6-AA6)>0,L6/$R$1*$AY$1-AA6,L6+AA6=0,"нов"),0)} -> нов | AR6: {=IFERROR(_xlfn.IFS((M6-AB6)>0,M6/$R$1*$AY$1-AB6,M6+AB6=0,"нов"),0)} -> 0 | ... AV6: {=IFERROR(_xlfn.IFS((Q6-AF6)>0,Q6/$R$1*$AY$1-AF6,Q6+AF6=0,"нов"),0)} -> нов | AW6: =SUM(AK6:AV6) -> 2 | AX6: =SUMIF('ОЗОН Доступн товара'!D:D,_xlfn.XLOOKUP($B6,'ОЗОН Доступн товара'!$A:$A,'ОЗОН Доступн товара'!$D:$D,0)) -> 0 | AY6: =SUM(AW6:AX6) -> 2 | AZ6: =IF(AK6="нов","нов",ROUNDUP(AK6*1.3,0)) -> 0 | BA6: =IF(AL6="нов","нов",ROUNDUP(AL6*1.3,0)) -> 0 | BB6: =IF(AM6="нов","нов",ROUNDUP(AM6*1.3,0)) -> нов | BC6: =IF(AN6="нов","нов",ROUNDUP(AN6*1.3,0)) -> 3 | BD6: =IF(AO6="нов","нов",ROUNDUP(AO6*1.3,0)) -> 0 | BE6: =IF(AP6="нов","нов",ROUNDUP(AP6*1.3,0)) -> 0 | BF6: =IF(AQ6="нов","нов",ROUNDUP(AQ6*1.3,0)) -> нов | BG6: =IF(AR6="нов","нов",ROUNDUP(AR6*1.3,0)) -> 0 | ... BK6: =IF(AV6="нов","нов",ROUNDUP(AV6*1.3,0)) -> нов | BL6: =SUM(AZ6:BK6) -> 3 | BM6: =AX6*1.3 -> 0 | BN6: =SUM(BL6:BM6) -> 3 | BO6: =IFERROR(_xlfn.XLOOKUP(A6,'[2] Расчет стоимости и веса'!$I:$I,'[2] Расчет стоимости и веса'!$D:$D),0) -> 20 | BP6: =BO6 -> 20 | CB6: 20 | CE6: =SUM(BR6:CD6) -> 20 | CF6: =MAX(BO6,CE6)-BQ6 -> 20 | CG6: =BO6+BQ6-CE6 -> 0
A7: =[1]Юнит!A9 -> 176500218 | B7: =[1]Юнит!B9 -> 2138709303 | C7: =[1]Юнит!C9 -> AHMA1BW101BG | D7: =[1]Юнит!D9 -> Мешок для бюстгалтеров | E7: =[1]Юнит!E9 -> 2038597850744 | F7: =ROUNDUP(SUMIFS('ВБ Отчет Продажи (за 60 дней)'!$L:$L,'ВБ Отчет Продажи (за 60 дней)'!$K:$K,"Электросталь",'ВБ Отчет Продажи (за 60 дней)'!$G:$G,$A7),0) -> 8 | G7: =ROUNDUP(SUMIFS('ВБ Отчет Продажи (за 60 дней)'!$L:$L,'ВБ Отчет Продажи (за 60 дней)'!$K:$K,"Коледино",'ВБ Отчет Продажи (за 60 дней)'!$G:$G,$A7),0) -> 7 | H7: =ROUNDUP(SUMIFS('ВБ Отчет Продажи (за 60 дней)'!$L:$L,'ВБ Отчет Продажи (за 60 дней)'!$K:$K,"Тула",'ВБ Отчет Продажи (за 60 дней)'!$G:$G,$A7),0) -> 7 | I7: =ROUNDUP(SUMIFS('ВБ Отчет Продажи (за 60 дней)'!$L:$L,'ВБ Отчет Продажи (за 60 дней)'!$K:$K,"Рязань (Тюшевское)",'ВБ Отчет Продажи (за 60 дней)'!$G:$G,$A7),0) -> 0 | J7: =ROUNDUP(SUMIFS('ВБ Отчет Продажи (за 60 дней)'!$L:$L,'ВБ Отчет Продажи (за 60 дней)'!$K:$K,"Краснодар",'ВБ Отчет Продажи (за 60 дней)'!$G:$G,$A7),0) -> 0 | K7: =ROUNDUP(SUMIFS('ВБ Отчет Продажи (за 60 дней)'!$L:$L,'ВБ Отчет Продажи (за 60 дней)'!$K:$K,"Невинномысск",'ВБ Отчет Продажи (за 60 дней)'!$G:$G,$A7),0) -> 3 | L7: =ROUNDUP(SUMIFS('ВБ Отчет Продажи (за 60 дней)'!$L:$L,'ВБ Отчет Продажи (за 60 дней)'!$K:$K,"Волгоград",'ВБ Отчет Продажи (за 60 дней)'!$G:$G,$A7),0) -> 0 | M7: =ROUNDUP(SUMIFS('ВБ Отчет Продажи (за 60 дней)'!$L:$L,'ВБ Отчет Продажи (за 60 дней)'!$K:$K,"Самара (Новосемейкино)",'ВБ Отчет Продажи (за 60 дней)'!$G:$G,$A7),0) -> 4 | N7: =ROUNDUP(SUMIFS('ВБ Отчет Продажи (за 60 дней)'!$L:$L,'ВБ Отчет Продажи (за 60 дней)'!$K:$K,"Казань",'ВБ Отчет Продажи (за 60 дней)'!$G:$G,$A7),0) -> 0 | O7: =ROUNDUP(SUMIFS('ВБ Отчет Продажи (за 60 дней)'!$L:$L,'ВБ Отчет Продажи (за 60 дней)'!$K:$K,"СПБ Шушары",'ВБ Отчет Продажи (за 60 дней)'!$G:$G,$A7),0) -> 1 | P7: =ROUNDUP(SUMIFS('ВБ Отчет Продажи (за 60 дней)'!$L:$L,'ВБ Отчет Продажи (за 60 дней)'!$K:$K,"Екатеринбург - Перспективный 12",'ВБ Отчет Продажи (за 60 дней)'!$G:$G,$A7),0) -> 0 | Q7: =ROUNDUP(SUMIFS('ВБ Отчет Продажи (за 60 дней)'!$L:$L,'ВБ Отчет Продажи (за 60 дней)'!$K:$K,"Новосибирск",'ВБ Отчет Продажи (за 60 дней)'!$G:$G,$A7),0) -> 0 | R7: =SUM(F7:Q7) -> 30 | S7: =SUMIFS('ОЗОН Оборот ведом (за 60 дней)'!I:I,'ОЗОН Оборот ведом (за 60 дней)'!A:A,B7) -> 11 | T7: =SUM(R7:S7) -> 41 | U7: =SUMIFS('ВБ Отчет Продажи (за 60 дней)'!$P:$P,'ВБ Отчет Продажи (за 60 дней)'!$K:$K,"Электросталь",'ВБ Отчет Продажи (за 60 дней)'!$G:$G,$A7) -> 170 | V7: =SUMIFS('ВБ Отчет Продажи (за 60 дней)'!$P:$P,'ВБ Отчет Продажи (за 60 дней)'!$K:$K,"Коледино",'ВБ Отчет Продажи (за 60 дней)'!$G:$G,$A7) -> 11 | W7: =SUMIFS('ВБ Отчет Продажи (за 60 дней)'!$P:$P,'ВБ Отчет Продажи (за 60 дней)'!$K:$K,"Тула",'ВБ Отчет Продажи (за 60 дней)'!$G:$G,$A7) -> 20 | X7: =SUMIFS('ВБ Отчет Продажи (за 60 дней)'!$P:$P,'ВБ Отчет Продажи (за 60 дней)'!$K:$K,"Рязань (Тюшевское)",'ВБ Отчет Продажи (за 60 дней)'!$G:$G,$A7) -> 0 | Y7: =SUMIFS('ВБ Отчет Продажи (за 60 дней)'!$P:$P,'ВБ Отчет Продажи (за 60 дней)'!$K:$K,"Краснодар",'ВБ Отчет Продажи (за 60 дней)'!$G:$G,$A7) -> 0 | Z7: =SUMIFS('ВБ Отчет Продажи (за 60 дней)'!$P:$P,'ВБ Отчет Продажи (за 60 дней)'!$K:$K,"Невинномысск",'ВБ Отчет Продажи (за 60 дней)'!$G:$G,$A7) -> 50 | AA7: =SUMIFS('ВБ Отчет Продажи (за 60 дней)'!$P:$P,'ВБ Отчет Продажи (за 60 дней)'!$K:$K,"Волгоград",'ВБ Отчет Продажи (за 60 дней)'!$G:$G,$A7) -> 0 | AB7: =SUMIFS('ВБ Отчет Продажи (за 60 дней)'!$P:$P,'ВБ Отчет Продажи (за 60 дней)'!$K:$K,"Самара (Новосемейкино)",'ВБ Отчет Продажи (за 60 дней)'!$G:$G,$A7) -> 51 | AC7: =SUMIFS('ВБ Отчет Продажи (за 60 дней)'!$P:$P,'ВБ Отчет Продажи (за 60 дней)'!$K:$K,"Казань",'ВБ Отчет Продажи (за 60 дней)'!$G:$G,$A7) -> 0 | AD7: =SUMIFS('ВБ Отчет Продажи (за 60 дней)'!$P:$P,'ВБ Отчет Продажи (за 60 дней)'!$K:$K,"СПБ Шушары",'ВБ Отчет Продажи (за 60 дней)'!$G:$G,$A7) -> 11 | AE7: =SUMIFS('ВБ Отчет Продажи (за 60 дней)'!$P:$P,'ВБ Отчет Продажи (за 60 дней)'!$K:$K,"Екатеринбург - Перспективный 12",'ВБ Отчет Продажи (за 60 дней)'!$G:$G,$A7) -> 0 | AF7: =SUMIFS('ВБ Отчет Продажи (за 60 дней)'!$P:$P,'ВБ Отчет Продажи (за 60 дней)'!$K:$K,"Новосибирск",'ВБ Отчет Продажи (за 60 дней)'!$G:$G,$A7) -> 0 | AG7: =SUM(U7:AF7) -> 313 | AH7: =IFERROR(AG7*$R$1/R7,0) -> 626 | AI7: =SUMIFS('ОЗОН Оборот ведом (за 60 дней)'!J:J,'ОЗОН Оборот ведом (за 60 дней)'!A:A,B7) -> 3 | AJ7: =AG7+AI7 -> 316 | AK7: {=IFERROR(_xlfn.IFS((F7-U7)>0,F7/$R$1*$AY$1-U7,F7+U7=0,"нов"),0)} -> 0 | AL7: {=IFERROR(_xlfn.IFS((G7-V7)>0,G7/$R$1*$AY$1-V7,G7+V7=0,"нов"),0)} -> 0 | AM7: {=IFERROR(_xlfn.IFS((H7-W7)>0,H7/$R$1*$AY$1-W7,H7+W7=0,"нов"),0)} -> 0 | AN7: {=IFERROR(_xlfn.IFS((I7-X7)>0,I7/$R$1*$AY$1-X7,I7+X7=0,"нов"),0)} -> нов | AO7: {=IFERROR(_xlfn.IFS((J7-Y7)>0,J7/$R$1*$AY$1-Y7,J7+Y7=0,"нов"),0)} -> нов | AP7: {=IFERROR(_xlfn.IFS((K7-Z7)>0,K7/$R$1*$AY$1-Z7,K7+Z7=0,"нов"),0)} -> 0 | AQ7: {=IFERROR(_xlfn.IFS((L7-AA7)>0,L7/$R$1*$AY$1-AA7,L7+AA7=0,"нов"),0)} -> нов | AR7: {=IFERROR(_xlfn.IFS((M7-AB7)>0,M7/$R$1*$AY$1-AB7,M7+AB7=0,"нов"),0)} -> 0 | ... AV7: {=IFERROR(_xlfn.IFS((Q7-AF7)>0,Q7/$R$1*$AY$1-AF7,Q7+AF7=0,"нов"),0)} -> нов | AW7: =SUM(AK7:AV7) -> 0 | AX7: =SUMIF('ОЗОН Доступн товара'!D:D,_xlfn.XLOOKUP($B7,'ОЗОН Доступн товара'!$A:$A,'ОЗОН Доступн товара'!$D:$D,0)) -> 62 | AY7: =SUM(AW7:AX7) -> 62 | AZ7: =IF(AK7="нов","нов",ROUNDUP(AK7*1.3,0)) -> 0 | BA7: =IF(AL7="нов","нов",ROUNDUP(AL7*1.3,0)) -> 0 | BB7: =IF(AM7="нов","нов",ROUNDUP(AM7*1.3,0)) -> 0 | BC7: =IF(AN7="нов","нов",ROUNDUP(AN7*1.3,0)) -> нов | BD7: =IF(AO7="нов","нов",ROUNDUP(AO7*1.3,0)) -> нов | BE7: =IF(AP7="нов","нов",ROUNDUP(AP7*1.3,0)) -> 0 | BF7: =IF(AQ7="нов","нов",ROUNDUP(AQ7*1.3,0)) -> нов | BG7: =IF(AR7="нов","нов",ROUNDUP(AR7*1.3,0)) -> 0 | ... BK7: =IF(AV7="нов","нов",ROUNDUP(AV7*1.3,0)) -> нов | BL7: =SUM(AZ7:BK7) -> 0 | BM7: =AX7*1.3 -> 80.6 | BN7: =SUM(BL7:BM7) -> 80.6 | BO7: =IFERROR(_xlfn.XLOOKUP(A7,'[2] Расчет стоимости и веса'!$I:$I,'[2] Расчет стоимости и веса'!$D:$D),0) -> 20 | BP7: =BO7 -> 20 | CB7: 20 | CE7: =SUM(BR7:CD7) -> 20 | CF7: =MAX(BO7,CE7)-BQ7 -> 20 | CG7: =BO7+BQ7-CE7 -> 0
A8: =[1]Юнит!A10 -> 177404837 | B8: =[1]Юнит!B10 -> 2419349262 | C8: =[1]Юнит!C10 -> AHMA3BW101BG | D8: =[1]Юнит!D10 -> Мешки 3 шт. | E8: =[1]Юнит!E10 -> 2038627692689 | F8: =ROUNDUP(SUMIFS('ВБ Отчет Продажи (за 60 дней)'!$L:$L,'ВБ Отчет Продажи (за 60 дней)'!$K:$K,"Электросталь",'ВБ Отчет Продажи (за 60 дней)'!$G:$G,$A8),0) -> 1 | G8: =ROUNDUP(SUMIFS('ВБ Отчет Продажи (за 60 дней)'!$L:$L,'ВБ Отчет Продажи (за 60 дней)'!$K:$K,"Коледино",'ВБ Отчет Продажи (за 60 дней)'!$G:$G,$A8),0) -> 1 | H8: =ROUNDUP(SUMIFS('ВБ Отчет Продажи (за 60 дней)'!$L:$L,'ВБ Отчет Продажи (за 60 дней)'!$K:$K,"Тула",'ВБ Отчет Продажи (за 60 дней)'!$G:$G,$A8),0) -> 1 | I8: =ROUNDUP(SUMIFS('ВБ Отчет Продажи (за 60 дней)'!$L:$L,'ВБ Отчет Продажи (за 60 дней)'!$K:$K,"Рязань (Тюшевское)",'ВБ Отчет Продажи (за 60 дней)'!$G:$G,$A8),0) -> 0 | J8: =ROUNDUP(SUMIFS('ВБ Отчет Продажи (за 60 дней)'!$L:$L,'ВБ Отчет Продажи (за 60 дней)'!$K:$K,"Краснодар",'ВБ Отчет Продажи (за 60 дней)'!$G:$G,$A8),0) -> 1 | K8: =ROUNDUP(SUMIFS('ВБ Отчет Продажи (за 60 дней)'!$L:$L,'ВБ Отчет Продажи (за 60 дней)'!$K:$K,"Невинномысск",'ВБ Отчет Продажи (за 60 дней)'!$G:$G,$A8),0) -> 0 | L8: =ROUNDUP(SUMIFS('ВБ Отчет Продажи (за 60 дней)'!$L:$L,'ВБ Отчет Продажи (за 60 дней)'!$K:$K,"Волгоград",'ВБ Отчет Продажи (за 60 дней)'!$G:$G,$A8),0) -> 1 | M8: =ROUNDUP(SUMIFS('ВБ Отчет Продажи (за 60 дней)'!$L:$L,'ВБ Отчет Продажи (за 60 дней)'!$K:$K,"Самара (Новосемейкино)",'ВБ Отчет Продажи (за 60 дней)'!$G:$G,$A8),0) -> 1 | N8: =ROUNDUP(SUMIFS('ВБ Отчет Продажи (за 60 дней)'!$L:$L,'ВБ Отчет Продажи (за 60 дней)'!$K:$K,"Казань",'ВБ Отчет Продажи (за 60 дней)'!$G:$G,$A8),0) -> 2 | O8: =ROUNDUP(SUMIFS('ВБ Отчет Продажи (за 60 дней)'!$L:$L,'ВБ Отчет Продажи (за 60 дней)'!$K:$K,"СПБ Шушары",'ВБ Отчет Продажи (за 60 дней)'!$G:$G,$A8),0) -> 0 | P8: =ROUNDUP(SUMIFS('ВБ Отчет Продажи (за 60 дней)'!$L:$L,'ВБ Отчет Продажи (за 60 дней)'!$K:$K,"Екатеринбург - Перспективный 12",'ВБ Отчет Продажи (за 60 дней)'!$G:$G,$A8),0) -> 0 | Q8: =ROUNDUP(SUMIFS('ВБ Отчет Продажи (за 60 дней)'!$L:$L,'ВБ Отчет Продажи (за 60 дней)'!$K:$K,"Новосибирск",'ВБ Отчет Продажи (за 60 дней)'!$G:$G,$A8),0) -> 0 | R8: =SUM(F8:Q8) -> 8 | S8: =SUMIFS('ОЗОН Оборот ведом (за 60 дней)'!I:I,'ОЗОН Оборот ведом (за 60 дней)'!A:A,B8) -> 20 | T8: =SUM(R8:S8) -> 28 | U8: =SUMIFS('ВБ Отчет Продажи (за 60 дней)'!$P:$P,'ВБ Отчет Продажи (за 60 дней)'!$K:$K,"Электросталь",'ВБ Отчет Продажи (за 60 дней)'!$G:$G,$A8) -> 29 | V8: =SUMIFS('ВБ Отчет Продажи (за 60 дней)'!$P:$P,'ВБ Отчет Продажи (за 60 дней)'!$K:$K,"Коледино",'ВБ Отчет Продажи (за 60 дней)'!$G:$G,$A8) -> 10 | W8: =SUMIFS('ВБ Отчет Продажи (за 60 дней)'!$P:$P,'ВБ Отчет Продажи (за 60 дней)'!$K:$K,"Тула",'ВБ Отчет Продажи (за 60 дней)'!$G:$G,$A8) -> 6 | X8: =SUMIFS('ВБ Отчет Продажи (за 60 дней)'!$P:$P,'ВБ Отчет Продажи (за 60 дней)'!$K:$K,"Рязань (Тюшевское)",'ВБ Отчет Продажи (за 60 дней)'!$G:$G,$A8) -> 15 | Y8: =SUMIFS('ВБ Отчет Продажи (за 60 дней)'!$P:$P,'ВБ Отчет Продажи (за 60 дней)'!$K:$K,"Краснодар",'ВБ Отчет Продажи (за 60 дней)'!$G:$G,$A8) -> 3 | Z8: =SUMIFS('ВБ Отчет Продажи (за 60 дней)'!$P:$P,'ВБ Отчет Продажи (за 60 дней)'!$K:$K,"Невинномысск",'ВБ Отчет Продажи (за 60 дней)'!$G:$G,$A8) -> 43 | AA8: =SUMIFS('ВБ Отчет Продажи (за 60 дней)'!$P:$P,'ВБ Отчет Продажи (за 60 дней)'!$K:$K,"Волгоград",'ВБ Отчет Продажи (за 60 дней)'!$G:$G,$A8) -> 0 | AB8: =SUMIFS('ВБ Отчет Продажи (за 60 дней)'!$P:$P,'ВБ Отчет Продажи (за 60 дней)'!$K:$K,"Самара (Новосемейкино)",'ВБ Отчет Продажи (за 60 дней)'!$G:$G,$A8) -> 44 | AC8: =SUMIFS('ВБ Отчет Продажи (за 60 дней)'!$P:$P,'ВБ Отчет Продажи (за 60 дней)'!$K:$K,"Казань",'ВБ Отчет Продажи (за 60 дней)'!$G:$G,$A8) -> 1 | AD8: =SUMIFS('ВБ Отчет Продажи (за 60 дней)'!$P:$P,'ВБ Отчет Продажи (за 60 дней)'!$K:$K,"СПБ Шушары",'ВБ Отчет Продажи (за 60 дней)'!$G:$G,$A8) -> 0 | AE8: =SUMIFS('ВБ Отчет Продажи (за 60 дней)'!$P:$P,'ВБ Отчет Продажи (за 60 дней)'!$K:$K,"Екатеринбург - Перспективный 12",'ВБ Отчет Продажи (за 60 дней)'!$G:$G,$A8) -> 0 | AF8: =SUMIFS('ВБ Отчет Продажи (за 60 дней)'!$P:$P,'ВБ Отчет Продажи (за 60 дней)'!$K:$K,"Новосибирск",'ВБ Отчет Продажи (за 60 дней)'!$G:$G,$A8) -> 0 | AG8: =SUM(U8:AF8) -> 151 | AH8: =IFERROR(AG8*$R$1/R8,0) -> 1132.5 | AI8: =SUMIFS('ОЗОН Оборот ведом (за 60 дней)'!J:J,'ОЗОН Оборот ведом (за 60 дней)'!A:A,B8) -> 4 | AJ8: =AG8+AI8 -> 155 | AK8: {=IFERROR(_xlfn.IFS((F8-U8)>0,F8/$R$1*$AY$1-U8,F8+U8=0,"нов"),0)} -> 0 | AL8: {=IFERROR(_xlfn.IFS((G8-V8)>0,G8/$R$1*$AY$1-V8,G8+V8=0,"нов"),0)} -> 0 | AM8: {=IFERROR(_xlfn.IFS((H8-W8)>0,H8/$R$1*$AY$1-W8,H8+W8=0,"нов"),0)} -> 0 | AN8: {=IFERROR(_xlfn.IFS((I8-X8)>0,I8/$R$1*$AY$1-X8,I8+X8=0,"нов"),0)} -> 0 | AO8: {=IFERROR(_xlfn.IFS((J8-Y8)>0,J8/$R$1*$AY$1-Y8,J8+Y8=0,"нов"),0)} -> 0 | AP8: {=IFERROR(_xlfn.IFS((K8-Z8)>0,K8/$R$1*$AY$1-Z8,K8+Z8=0,"нов"),0)} -> 0 | AQ8: {=IFERROR(_xlfn.IFS((L8-AA8)>0,L8/$R$1*$AY$1-AA8,L8+AA8=0,"нов"),0)} -> 1 | AR8: {=IFERROR(_xlfn.IFS((M8-AB8)>0,M8/$R$1*$AY$1-AB8,M8+AB8=0,"нов"),0)} -> 0 | ... AV8: {=IFERROR(_xlfn.IFS((Q8-AF8)>0,Q8/$R$1*$AY$1-AF8,Q8+AF8=0,"нов"),0)} -> нов | AW8: =SUM(AK8:AV8) -> 2 | AX8: =SUMIF('ОЗОН Доступн товара'!D:D,_xlfn.XLOOKUP($B8,'ОЗОН Доступн товара'!$A:$A,'ОЗОН Доступн товара'!$D:$D,0)) -> 62 | AY8: =SUM(AW8:AX8) -> 64 | AZ8: =IF(AK8="нов","нов",ROUNDUP(AK8*1.3,0)) -> 0 | BA8: =IF(AL8="нов","нов",ROUNDUP(AL8*1.3,0)) -> 0 | BB8: =IF(AM8="нов","нов",ROUNDUP(AM8*1.3,0)) -> 0 | BC8: =IF(AN8="нов","нов",ROUNDUP(AN8*1.3,0)) -> 0 | BD8: =IF(AO8="нов","нов",ROUNDUP(AO8*1.3,0)) -> 0 | BE8: =IF(AP8="нов","нов",ROUNDUP(AP8*1.3,0)) -> 0 | BF8: =IF(AQ8="нов","нов",ROUNDUP(AQ8*1.3,0)) -> 2 | BG8: =IF(AR8="нов","нов",ROUNDUP(AR8*1.3,0)) -> 0 | ... BK8: =IF(AV8="нов","нов",ROUNDUP(AV8*1.3,0)) -> нов | BL8: =SUM(AZ8:BK8) -> 4 | BM8: =AX8*1.3 -> 80.6 | BN8: =SUM(BL8:BM8) -> 84.6 | BO8: =IFERROR(_xlfn.XLOOKUP(A8,'[2] Расчет стоимости и веса'!$I:$I,'[2] Расчет стоимости и веса'!$D:$D),0) -> 0 | BP8: =BO8*3 -> 0 | CE8: =SUM(BR8:CD8) -> 0 | CF8: =MAX(BO8,CE8)-BQ8 -> 0 | CG8: =BO8+BQ8-CE8 -> 0
A9: =[1]Юнит!A11 -> 177405495 | B9: =[1]Юнит!B11 -> 2576041357 | C9: =[1]Юнит!C11 -> AHMA3BW102BG | D9: =[1]Юнит!D11 -> Мешки/деликат 3 шт. | E9: =[1]Юнит!E11 -> 2038627713902 | F9: =ROUNDUP(SUMIFS('ВБ Отчет Продажи (за 60 дней)'!$L:$L,'ВБ Отчет Продажи (за 60 дней)'!$K:$K,"Электросталь",'ВБ Отчет Продажи (за 60 дней)'!$G:$G,$A9),0) -> 2 | G9: =ROUNDUP(SUMIFS('ВБ Отчет Продажи (за 60 дней)'!$L:$L,'ВБ Отчет Продажи (за 60 дней)'!$K:$K,"Коледино",'ВБ Отчет Продажи (за 60 дней)'!$G:$G,$A9),0) -> 2 | H9: =ROUNDUP(SUMIFS('ВБ Отчет Продажи (за 60 дней)'!$L:$L,'ВБ Отчет Продажи (за 60 дней)'!$K:$K,"Тула",'ВБ Отчет Продажи (за 60 дней)'!$G:$G,$A9),0) -> 0 | I9: =ROUNDUP(SUMIFS('ВБ Отчет Продажи (за 60 дней)'!$L:$L,'ВБ Отчет Продажи (за 60 дней)'!$K:$K,"Рязань (Тюшевское)",'ВБ Отчет Продажи (за 60 дней)'!$G:$G,$A9),0) -> 0 | J9: =ROUNDUP(SUMIFS('ВБ Отчет Продажи (за 60 дней)'!$L:$L,'ВБ Отчет Продажи (за 60 дней)'!$K:$K,"Краснодар",'ВБ Отчет Продажи (за 60 дней)'!$G:$G,$A9),0) -> 0 | K9: =ROUNDUP(SUMIFS('ВБ Отчет Продажи (за 60 дней)'!$L:$L,'ВБ Отчет Продажи (за 60 дней)'!$K:$K,"Невинномысск",'ВБ Отчет Продажи (за 60 дней)'!$G:$G,$A9),0) -> 0 | L9: =ROUNDUP(SUMIFS('ВБ Отчет Продажи (за 60 дней)'!$L:$L,'ВБ Отчет Продажи (за 60 дней)'!$K:$K,"Волгоград",'ВБ Отчет Продажи (за 60 дней)'!$G:$G,$A9),0) -> 0 | M9: =ROUNDUP(SUMIFS('ВБ Отчет Продажи (за 60 дней)'!$L:$L,'ВБ Отчет Продажи (за 60 дней)'!$K:$K,"Самара (Новосемейкино)",'ВБ Отчет Продажи (за 60 дней)'!$G:$G,$A9),0) -> 1 | N9: =ROUNDUP(SUMIFS('ВБ Отчет Продажи (за 60 дней)'!$L:$L,'ВБ Отчет Продажи (за 60 дней)'!$K:$K,"Казань",'ВБ Отчет Продажи (за 60 дней)'!$G:$G,$A9),0) -> 0 | O9: =ROUNDUP(SUMIFS('ВБ Отчет Продажи (за 60 дней)'!$L:$L,'ВБ Отчет Продажи (за 60 дней)'!$K:$K,"СПБ Шушары",'ВБ Отчет Продажи (за 60 дней)'!$G:$G,$A9),0) -> 0 | P9: =ROUNDUP(SUMIFS('ВБ Отчет Продажи (за 60 дней)'!$L:$L,'ВБ Отчет Продажи (за 60 дней)'!$K:$K,"Екатеринбург - Перспективный 12",'ВБ Отчет Продажи (за 60 дней)'!$G:$G,$A9),0) -> 0 | Q9: =ROUNDUP(SUMIFS('ВБ Отчет Продажи (за 60 дней)'!$L:$L,'ВБ Отчет Продажи (за 60 дней)'!$K:$K,"Новосибирск",'ВБ Отчет Продажи (за 60 дней)'!$G:$G,$A9),0) -> 0 | R9: =SUM(F9:Q9) -> 5 | S9: =SUMIFS('ОЗОН Оборот ведом (за 60 дней)'!I:I,'ОЗОН Оборот ведом (за 60 дней)'!A:A,B9) -> 1 | T9: =SUM(R9:S9) -> 6 | U9: =SUMIFS('ВБ Отчет Продажи (за 60 дней)'!$P:$P,'ВБ Отчет Продажи (за 60 дней)'!$K:$K,"Электросталь",'ВБ Отчет Продажи (за 60 дней)'!$G:$G,$A9) -> 62 | V9: =SUMIFS('ВБ Отчет Продажи (за 60 дней)'!$P:$P,'ВБ Отчет Продажи (за 60 дней)'!$K:$K,"Коледино",'ВБ Отчет Продажи (за 60 дней)'!$G:$G,$A9) -> 18 | W9: =SUMIFS('ВБ Отчет Продажи (за 60 дней)'!$P:$P,'ВБ Отчет Продажи (за 60 дней)'!$K:$K,"Тула",'ВБ Отчет Продажи (за 60 дней)'!$G:$G,$A9) -> 0 | X9: =SUMIFS('ВБ Отчет Продажи (за 60 дней)'!$P:$P,'ВБ Отчет Продажи (за 60 дней)'!$K:$K,"Рязань (Тюшевское)",'ВБ Отчет Продажи (за 60 дней)'!$G:$G,$A9) -> 9 | Y9: =SUMIFS('ВБ Отчет Продажи (за 60 дней)'!$P:$P,'ВБ Отчет Продажи (за 60 дней)'!$K:$K,"Краснодар",'ВБ Отчет Продажи (за 60 дней)'!$G:$G,$A9) -> 14 | Z9: =SUMIFS('ВБ Отчет Продажи (за 60 дней)'!$P:$P,'ВБ Отчет Продажи (за 60 дней)'!$K:$K,"Невинномысск",'ВБ Отчет Продажи (за 60 дней)'!$G:$G,$A9) -> 45 | AA9: =SUMIFS('ВБ Отчет Продажи (за 60 дней)'!$P:$P,'ВБ Отчет Продажи (за 60 дней)'!$K:$K,"Волгоград",'ВБ Отчет Продажи (за 60 дней)'!$G:$G,$A9) -> 0 | AB9: =SUMIFS('ВБ Отчет Продажи (за 60 дней)'!$P:$P,'ВБ Отчет Продажи (за 60 дней)'!$K:$K,"Самара (Новосемейкино)",'ВБ Отчет Продажи (за 60 дней)'!$G:$G,$A9) -> 52 | AC9: =SUMIFS('ВБ Отчет Продажи (за 60 дней)'!$P:$P,'ВБ Отчет Продажи (за 60 дней)'!$K:$K,"Казань",'ВБ Отчет Продажи (за 60 дней)'!$G:$G,$A9) -> 0 | AD9: =SUMIFS('ВБ Отчет Продажи (за 60 дней)'!$P:$P,'ВБ Отчет Продажи (за 60 дней)'!$K:$K,"СПБ Шушары",'ВБ Отчет Продажи (за 60 дней)'!$G:$G,$A9) -> 0 | AE9: =SUMIFS('ВБ Отчет Продажи (за 60 дней)'!$P:$P,'ВБ Отчет Продажи (за 60 дней)'!$K:$K,"Екатеринбург - Перспективный 12",'ВБ Отчет Продажи (за 60 дней)'!$G:$G,$A9) -> 0 | AF9: =SUMIFS('ВБ Отчет Продажи (за 60 дней)'!$P:$P,'ВБ Отчет Продажи (за 60 дней)'!$K:$K,"Новосибирск",'ВБ Отчет Продажи (за 60 дней)'!$G:$G,$A9) -> 0 | AG9: =SUM(U9:AF9) -> 200 | AH9: =IFERROR(AG9*$R$1/R9,0) -> 2400 | AI9: =SUMIFS('ОЗОН Оборот ведом (за 60 дней)'!J:J,'ОЗОН Оборот ведом (за 60 дней)'!A:A,B9) -> 0 | AJ9: =AG9+AI9 -> 200 | AK9: {=IFERROR(_xlfn.IFS((F9-U9)>0,F9/$R$1*$AY$1-U9,F9+U9=0,"нов"),0)} -> 0 | AL9: {=IFERROR(_xlfn.IFS((G9-V9)>0,G9/$R$1*$AY$1-V9,G9+V9=0,"нов"),0)} -> 0 | AM9: {=IFERROR(_xlfn.IFS((H9-W9)>0,H9/$R$1*$AY$1-W9,H9+W9=0,"нов"),0)} -> нов | AN9: {=IFERROR(_xlfn.IFS((I9-X9)>0,I9/$R$1*$AY$1-X9,I9+X9=0,"нов"),0)} -> 0 | AO9: {=IFERROR(_xlfn.IFS((J9-Y9)>0,J9/$R$1*$AY$1-Y9,J9+Y9=0,"нов"),0)} -> 0 | AP9: {=IFERROR(_xlfn.IFS((K9-Z9)>0,K9/$R$1*$AY$1-Z9,K9+Z9=0,"нов"),0)} -> 0 | AQ9: {=IFERROR(_xlfn.IFS((L9-AA9)>0,L9/$R$1*$AY$1-AA9,L9+AA9=0,"нов"),0)} -> нов | AR9: {=IFERROR(_xlfn.IFS((M9-AB9)>0,M9/$R$1*$AY$1-AB9,M9+AB9=0,"нов"),0)} -> 0 | ... AV9: {=IFERROR(_xlfn.IFS((Q9-AF9)>0,Q9/$R$1*$AY$1-AF9,Q9+AF9=0,"нов"),0)} -> нов | AW9: =SUM(AK9:AV9) -> 0 | AX9: =SUMIF('ОЗОН Доступн товара'!D:D,_xlfn.XLOOKUP($B9,'ОЗОН Доступн товара'!$A:$A,'ОЗОН Доступн товара'!$D:$D,0)) -> 0 | AY9: =SUM(AW9:AX9) -> 0 | AZ9: =IF(AK9="нов","нов",ROUNDUP(AK9*1.3,0)) -> 0 | BA9: =IF(AL9="нов","нов",ROUNDUP(AL9*1.3,0)) -> 0 | BB9: =IF(AM9="нов","нов",ROUNDUP(AM9*1.3,0)) -> нов | BC9: =IF(AN9="нов","нов",ROUNDUP(AN9*1.3,0)) -> 0 | BD9: =IF(AO9="нов","нов",ROUNDUP(AO9*1.3,0)) -> 0 | BE9: =IF(AP9="нов","нов",ROUNDUP(AP9*1.3,0)) -> 0 | BF9: =IF(AQ9="нов","нов",ROUNDUP(AQ9*1.3,0)) -> нов | BG9: =IF(AR9="нов","нов",ROUNDUP(AR9*1.3,0)) -> 0 | ... BK9: =IF(AV9="нов","нов",ROUNDUP(AV9*1.3,0)) -> нов | BL9: =SUM(AZ9:BK9) -> 0 | BM9: =AX9*1.3 -> 0 | BN9: =SUM(BL9:BM9) -> 0 | BO9: =IFERROR(_xlfn.XLOOKUP(A9,'[2] Расчет стоимости и веса'!$I:$I,'[2] Расчет стоимости и веса'!$D:$D),0) -> 40 | BP9: =BO9*3 -> 120 | CA9: 20 | CB9: 20 | CE9: =SUM(BR9:CD9) -> 40 | CF9: =MAX(BO9,CE9)-BQ9 -> 40 | CG9: =BO9+BQ9-CE9 -> 0
A10: =[1]Юнит!A12 -> 176721350 | B10: =[1]Юнит!B12 -> 2419349585 | C10: =[1]Юнит!C12 -> AHMA3BW201WH | D10: =[1]Юнит!D12 -> Мешки/шнурок мелк 3 шт. | E10: =[1]Юнит!E12 -> 2038606201642 | F10: =ROUNDUP(SUMIFS('ВБ Отчет Продажи (за 60 дней)'!$L:$L,'ВБ Отчет Продажи (за 60 дней)'!$K:$K,"Электросталь",'ВБ Отчет Продажи (за 60 дней)'!$G:$G,$A10),0) -> 6 | G10: =ROUNDUP(SUMIFS('ВБ Отчет Продажи (за 60 дней)'!$L:$L,'ВБ Отчет Продажи (за 60 дней)'!$K:$K,"Коледино",'ВБ Отчет Продажи (за 60 дней)'!$G:$G,$A10),0) -> 7 | H10: =ROUNDUP(SUMIFS('ВБ Отчет Продажи (за 60 дней)'!$L:$L,'ВБ Отчет Продажи (за 60 дней)'!$K:$K,"Тула",'ВБ Отчет Продажи (за 60 дней)'!$G:$G,$A10),0) -> 0 | I10: =ROUNDUP(SUMIFS('ВБ Отчет Продажи (за 60 дней)'!$L:$L,'ВБ Отчет Продажи (за 60 дней)'!$K:$K,"Рязань (Тюшевское)",'ВБ Отчет Продажи (за 60 дней)'!$G:$G,$A10),0) -> 1 | J10: =ROUNDUP(SUMIFS('ВБ Отчет Продажи (за 60 дней)'!$L:$L,'ВБ Отчет Продажи (за 60 дней)'!$K:$K,"Краснодар",'ВБ Отчет Продажи (за 60 дней)'!$G:$G,$A10),0) -> 2 | K10: =ROUNDUP(SUMIFS('ВБ Отчет Продажи (за 60 дней)'!$L:$L,'ВБ Отчет Продажи (за 60 дней)'!$K:$K,"Невинномысск",'ВБ Отчет Продажи (за 60 дней)'!$G:$G,$A10),0) -> 0 | L10: =ROUNDUP(SUMIFS('ВБ Отчет Продажи (за 60 дней)'!$L:$L,'ВБ Отчет Продажи (за 60 дней)'!$K:$K,"Волгоград",'ВБ Отчет Продажи (за 60 дней)'!$G:$G,$A10),0) -> 0 | M10: =ROUNDUP(SUMIFS('ВБ Отчет Продажи (за 60 дней)'!$L:$L,'ВБ Отчет Продажи (за 60 дней)'!$K:$K,"Самара (Новосемейкино)",'ВБ Отчет Продажи (за 60 дней)'!$G:$G,$A10),0) -> 0 | N10: =ROUNDUP(SUMIFS('ВБ Отчет Продажи (за 60 дней)'!$L:$L,'ВБ Отчет Продажи (за 60 дней)'!$K:$K,"Казань",'ВБ Отчет Продажи (за 60 дней)'!$G:$G,$A10),0) -> 0 | O10: =ROUNDUP(SUMIFS('ВБ Отчет Продажи (за 60 дней)'!$L:$L,'ВБ Отчет Продажи (за 60 дней)'!$K:$K,"СПБ Шушары",'ВБ Отчет Продажи (за 60 дней)'!$G:$G,$A10),0) -> 0 | P10: =ROUNDUP(SUMIFS('ВБ Отчет Продажи (за 60 дней)'!$L:$L,'ВБ Отчет Продажи (за 60 дней)'!$K:$K,"Екатеринбург - Перспективный 12",'ВБ Отчет Продажи (за 60 дней)'!$G:$G,$A10),0) -> 0 | Q10: =ROUNDUP(SUMIFS('ВБ Отчет Продажи (за 60 дней)'!$L:$L,'ВБ Отчет Продажи (за 60 дней)'!$K:$K,"Новосибирск",'ВБ Отчет Продажи (за 60 дней)'!$G:$G,$A10),0) -> 0 | R10: =SUM(F10:Q10) -> 16 | S10: =SUMIFS('ОЗОН Оборот ведом (за 60 дней)'!I:I,'ОЗОН Оборот ведом (за 60 дней)'!A:A,B10) -> 6 | T10: =SUM(R10:S10) -> 22 | U10: =SUMIFS('ВБ Отчет Продажи (за 60 дней)'!$P:$P,'ВБ Отчет Продажи (за 60 дней)'!$K:$K,"Электросталь",'ВБ Отчет Продажи (за 60 дней)'!$G:$G,$A10) -> 85 | V10: =SUMIFS('ВБ Отчет Продажи (за 60 дней)'!$P:$P,'ВБ Отчет Продажи (за 60 дней)'!$K:$K,"Коледино",'ВБ Отчет Продажи (за 60 дней)'!$G:$G,$A10) -> 49 | W10: =SUMIFS('ВБ Отчет Продажи (за 60 дней)'!$P:$P,'ВБ Отчет Продажи (за 60 дней)'!$K:$K,"Тула",'ВБ Отчет Продажи (за 60 дней)'!$G:$G,$A10) -> 0 | X10: =SUMIFS('ВБ Отчет Продажи (за 60 дней)'!$P:$P,'ВБ Отчет Продажи (за 60 дней)'!$K:$K,"Рязань (Тюшевское)",'ВБ Отчет Продажи (за 60 дней)'!$G:$G,$A10) -> 0 | Y10: =SUMIFS('ВБ Отчет Продажи (за 60 дней)'!$P:$P,'ВБ Отчет Продажи (за 60 дней)'!$K:$K,"Краснодар",'ВБ Отчет Продажи (за 60 дней)'!$G:$G,$A10) -> 7 | Z10: =SUMIFS('ВБ Отчет Продажи (за 60 дней)'!$P:$P,'ВБ Отчет Продажи (за 60 дней)'!$K:$K,"Невинномысск",'ВБ Отчет Продажи (за 60 дней)'!$G:$G,$A10) -> 27 | AA10: =SUMIFS('ВБ Отчет Продажи (за 60 дней)'!$P:$P,'ВБ Отчет Продажи (за 60 дней)'!$K:$K,"Волгоград",'ВБ Отчет Продажи (за 60 дней)'!$G:$G,$A10) -> 0 | AB10: =SUMIFS('ВБ Отчет Продажи (за 60 дней)'!$P:$P,'ВБ Отчет Продажи (за 60 дней)'!$K:$K,"Самара (Новосемейкино)",'ВБ Отчет Продажи (за 60 дней)'!$G:$G,$A10) -> 48 | AC10: =SUMIFS('ВБ Отчет Продажи (за 60 дней)'!$P:$P,'ВБ Отчет Продажи (за 60 дней)'!$K:$K,"Казань",'ВБ Отчет Продажи (за 60 дней)'!$G:$G,$A10) -> 0 | AD10: =SUMIFS('ВБ Отчет Продажи (за 60 дней)'!$P:$P,'ВБ Отчет Продажи (за 60 дней)'!$K:$K,"СПБ Шушары",'ВБ Отчет Продажи (за 60 дней)'!$G:$G,$A10) -> 0 | AE10: =SUMIFS('ВБ Отчет Продажи (за 60 дней)'!$P:$P,'ВБ Отчет Продажи (за 60 дней)'!$K:$K,"Екатеринбург - Перспективный 12",'ВБ Отчет Продажи (за 60 дней)'!$G:$G,$A10) -> 0 | AF10: =SUMIFS('ВБ Отчет Продажи (за 60 дней)'!$P:$P,'ВБ Отчет Продажи (за 60 дней)'!$K:$K,"Новосибирск",'ВБ Отчет Продажи (за 60 дней)'!$G:$G,$A10) -> 0 | AG10: =SUM(U10:AF10) -> 216 | AH10: =IFERROR(AG10*$R$1/R10,0) -> 810 | AI10: =SUMIFS('ОЗОН Оборот ведом (за 60 дней)'!J:J,'ОЗОН Оборот ведом (за 60 дней)'!A:A,B10) -> 18 | AJ10: =AG10+AI10 -> 234 | AK10: {=IFERROR(_xlfn.IFS((F10-U10)>0,F10/$R$1*$AY$1-U10,F10+U10=0,"нов"),0)} -> 0 | AL10: {=IFERROR(_xlfn.IFS((G10-V10)>0,G10/$R$1*$AY$1-V10,G10+V10=0,"нов"),0)} -> 0 | AM10: {=IFERROR(_xlfn.IFS((H10-W10)>0,H10/$R$1*$AY$1-W10,H10+W10=0,"нов"),0)} -> нов | AN10: {=IFERROR(_xlfn.IFS((I10-X10)>0,I10/$R$1*$AY$1-X10,I10+X10=0,"нов"),0)} -> 1 | AO10: {=IFERROR(_xlfn.IFS((J10-Y10)>0,J10/$R$1*$AY$1-Y10,J10+Y10=0,"нов"),0)} -> 0 | AP10: {=IFERROR(_xlfn.IFS((K10-Z10)>0,K10/$R$1*$AY$1-Z10,K10+Z10=0,"нов"),0)} -> 0 | AQ10: {=IFERROR(_xlfn.IFS((L10-AA10)>0,L10/$R$1*$AY$1-AA10,L10+AA10=0,"нов"),0)} -> нов | AR10: {=IFERROR(_xlfn.IFS((M10-AB10)>0,M10/$R$1*$AY$1-AB10,M10+AB10=0,"нов"),0)} -> 0 | ... AV10: {=IFERROR(_xlfn.IFS((Q10-AF10)>0,Q10/$R$1*$AY$1-AF10,Q10+AF10=0,"нов"),0)} -> нов | AW10: =SUM(AK10:AV10) -> 1 | AX10: =SUMIF('ОЗОН Доступн товара'!D:D,_xlfn.XLOOKUP($B10,'ОЗОН Доступн товара'!$A:$A,'ОЗОН Доступн товара'!$D:$D,0)) -> 0 | AY10: =SUM(AW10:AX10) -> 1 | AZ10: =IF(AK10="нов","нов",ROUNDUP(AK10*1.3,0)) -> 0 | BA10: =IF(AL10="нов","нов",ROUNDUP(AL10*1.3,0)) -> 0 | BB10: =IF(AM10="нов","нов",ROUNDUP(AM10*1.3,0)) -> нов | BC10: =IF(AN10="нов","нов",ROUNDUP(AN10*1.3,0)) -> 2 | BD10: =IF(AO10="нов","нов",ROUNDUP(AO10*1.3,0)) -> 0 | BE10: =IF(AP10="нов","нов",ROUNDUP(AP10*1.3,0)) -> 0 | BF10: =IF(AQ10="нов","нов",ROUNDUP(AQ10*1.3,0)) -> нов | BG10: =IF(AR10="нов","нов",ROUNDUP(AR10*1.3,0)) -> 0 | ... BK10: =IF(AV10="нов","нов",ROUNDUP(AV10*1.3,0)) -> нов | BL10: =SUM(AZ10:BK10) -> 2 | BM10: =AX10*1.3 -> 0 | BN10: =SUM(BL10:BM10) -> 2 | BO10: =IFERROR(_xlfn.XLOOKUP(A10,'[2] Расчет стоимости и веса'!$I:$I,'[2] Расчет стоимости и веса'!$D:$D),0) -> 40 | BP10: =BO10*3 -> 120 | CA10: 20 | CB10: 20 | CE10: =SUM(BR10:CD10) -> 40 | CF10: =MAX(BO10,CE10)-BQ10 -> 40 | CG10: =BO10+BQ10-CE10 -> 0
A11: =[1]Юнит!A13 -> 176723275 | B11: =[1]Юнит!B13 -> 2419349501 | C11: =[1]Юнит!C13 -> AHMA3BW202WH | D11: =[1]Юнит!D13 -> Мешки/шнурок крупн 3 шт. | E11: =[1]Юнит!E13 -> 2038606256161 | F11: =ROUNDUP(SUMIFS('ВБ Отчет Продажи (за 60 дней)'!$L:$L,'ВБ Отчет Продажи (за 60 дней)'!$K:$K,"Электросталь",'ВБ Отчет Продажи (за 60 дней)'!$G:$G,$A11),0) -> 31 | G11: =ROUNDUP(SUMIFS('ВБ Отчет Продажи (за 60 дней)'!$L:$L,'ВБ Отчет Продажи (за 60 дней)'!$K:$K,"Коледино",'ВБ Отчет Продажи (за 60 дней)'!$G:$G,$A11),0) -> 0 | H11: =ROUNDUP(SUMIFS('ВБ Отчет Продажи (за 60 дней)'!$L:$L,'ВБ Отчет Продажи (за 60 дней)'!$K:$K,"Тула",'ВБ Отчет Продажи (за 60 дней)'!$G:$G,$A11),0) -> 1 | I11: =ROUNDUP(SUMIFS('ВБ Отчет Продажи (за 60 дней)'!$L:$L,'ВБ Отчет Продажи (за 60 дней)'!$K:$K,"Рязань (Тюшевское)",'ВБ Отчет Продажи (за 60 дней)'!$G:$G,$A11),0) -> 1 | J11: =ROUNDUP(SUMIFS('ВБ Отчет Продажи (за 60 дней)'!$L:$L,'ВБ Отчет Продажи (за 60 дней)'!$K:$K,"Краснодар",'ВБ Отчет Продажи (за 60 дней)'!$G:$G,$A11),0) -> 0 | K11: =ROUNDUP(SUMIFS('ВБ Отчет Продажи (за 60 дней)'!$L:$L,'ВБ Отчет Продажи (за 60 дней)'!$K:$K,"Невинномысск",'ВБ Отчет Продажи (за 60 дней)'!$G:$G,$A11),0) -> 11 | L11: =ROUNDUP(SUMIFS('ВБ Отчет Продажи (за 60 дней)'!$L:$L,'ВБ Отчет Продажи (за 60 дней)'!$K:$K,"Волгоград",'ВБ Отчет Продажи (за 60 дней)'!$G:$G,$A11),0) -> 0 | M11: =ROUNDUP(SUMIFS('ВБ Отчет Продажи (за 60 дней)'!$L:$L,'ВБ Отчет Продажи (за 60 дней)'!$K:$K,"Самара (Новосемейкино)",'ВБ Отчет Продажи (за 60 дней)'!$G:$G,$A11),0) -> 16 | N11: =ROUNDUP(SUMIFS('ВБ Отчет Продажи (за 60 дней)'!$L:$L,'ВБ Отчет Продажи (за 60 дней)'!$K:$K,"Казань",'ВБ Отчет Продажи (за 60 дней)'!$G:$G,$A11),0) -> 0 | O11: =ROUNDUP(SUMIFS('ВБ Отчет Продажи (за 60 дней)'!$L:$L,'ВБ Отчет Продажи (за 60 дней)'!$K:$K,"СПБ Шушары",'ВБ Отчет Продажи (за 60 дней)'!$G:$G,$A11),0) -> 0 | P11: =ROUNDUP(SUMIFS('ВБ Отчет Продажи (за 60 дней)'!$L:$L,'ВБ Отчет Продажи (за 60 дней)'!$K:$K,"Екатеринбург - Перспективный 12",'ВБ Отчет Продажи (за 60 дней)'!$G:$G,$A11),0) -> 0 | Q11: =ROUNDUP(SUMIFS('ВБ Отчет Продажи (за 60 дней)'!$L:$L,'ВБ Отчет Продажи (за 60 дней)'!$K:$K,"Новосибирск",'ВБ Отчет Продажи (за 60 дней)'!$G:$G,$A11),0) -> 0 | R11: =SUM(F11:Q11) -> 60 | S11: =SUMIFS('ОЗОН Оборот ведом (за 60 дней)'!I:I,'ОЗОН Оборот ведом (за 60 дней)'!A:A,B11) -> 9 | T11: =SUM(R11:S11) -> 69 | U11: =SUMIFS('ВБ Отчет Продажи (за 60 дней)'!$P:$P,'ВБ Отчет Продажи (за 60 дней)'!$K:$K,"Электросталь",'ВБ Отчет Продажи (за 60 дней)'!$G:$G,$A11) -> 4 | V11: =SUMIFS('ВБ Отчет Продажи (за 60 дней)'!$P:$P,'ВБ Отчет Продажи (за 60 дней)'!$K:$K,"Коледино",'ВБ Отчет Продажи (за 60 дней)'!$G:$G,$A11) -> 0 | W11: =SUMIFS('ВБ Отчет Продажи (за 60 дней)'!$P:$P,'ВБ Отчет Продажи (за 60 дней)'!$K:$K,"Тула",'ВБ Отчет Продажи (за 60 дней)'!$G:$G,$A11) -> 0 | X11: =SUMIFS('ВБ Отчет Продажи (за 60 дней)'!$P:$P,'ВБ Отчет Продажи (за 60 дней)'!$K:$K,"Рязань (Тюшевское)",'ВБ Отчет Продажи (за 60 дней)'!$G:$G,$A11) -> 0 | Y11: =SUMIFS('ВБ Отчет Продажи (за 60 дней)'!$P:$P,'ВБ Отчет Продажи (за 60 дней)'!$K:$K,"Краснодар",'ВБ Отчет Продажи (за 60 дней)'!$G:$G,$A11) -> 0 | Z11: =SUMIFS('ВБ Отчет Продажи (за 60 дней)'!$P:$P,'ВБ Отчет Продажи (за 60 дней)'!$K:$K,"Невинномысск",'ВБ Отчет Продажи (за 60 дней)'!$G:$G,$A11) -> 15 | AA11: =SUMIFS('ВБ Отчет Продажи (за 60 дней)'!$P:$P,'ВБ Отчет Продажи (за 60 дней)'!$K:$K,"Волгоград",'ВБ Отчет Продажи (за 60 дней)'!$G:$G,$A11) -> 0 | AB11: =SUMIFS('ВБ Отчет Продажи (за 60 дней)'!$P:$P,'ВБ Отчет Продажи (за 60 дней)'!$K:$K,"Самара (Новосемейкино)",'ВБ Отчет Продажи (за 60 дней)'!$G:$G,$A11) -> 14 | AC11: =SUMIFS('ВБ Отчет Продажи (за 60 дней)'!$P:$P,'ВБ Отчет Продажи (за 60 дней)'!$K:$K,"Казань",'ВБ Отчет Продажи (за 60 дней)'!$G:$G,$A11) -> 0 | AD11: =SUMIFS('ВБ Отчет Продажи (за 60 дней)'!$P:$P,'ВБ Отчет Продажи (за 60 дней)'!$K:$K,"СПБ Шушары",'ВБ Отчет Продажи (за 60 дней)'!$G:$G,$A11) -> 0 | AE11: =SUMIFS('ВБ Отчет Продажи (за 60 дней)'!$P:$P,'ВБ Отчет Продажи (за 60 дней)'!$K:$K,"Екатеринбург - Перспективный 12",'ВБ Отчет Продажи (за 60 дней)'!$G:$G,$A11) -> 0 | AF11: =SUMIFS('ВБ Отчет Продажи (за 60 дней)'!$P:$P,'ВБ Отчет Продажи (за 60 дней)'!$K:$K,"Новосибирск",'ВБ Отчет Продажи (за 60 дней)'!$G:$G,$A11) -> 0 | AG11: =SUM(U11:AF11) -> 33 | AH11: =IFERROR(AG11*$R$1/R11,0) -> 33 | AI11: =SUMIFS('ОЗОН Оборот ведом (за 60 дней)'!J:J,'ОЗОН Оборот ведом (за 60 дней)'!A:A,B11) -> 8 | AJ11: =AG11+AI11 -> 41 | AK11: {=IFERROR(_xlfn.IFS((F11-U11)>0,F11/$R$1*$AY$1-U11,F11+U11=0,"нов"),0)} -> 27 | AL11: {=IFERROR(_xlfn.IFS((G11-V11)>0,G11/$R$1*$AY$1-V11,G11+V11=0,"нов"),0)} -> нов | AM11: {=IFERROR(_xlfn.IFS((H11-W11)>0,H11/$R$1*$AY$1-W11,H11+W11=0,"нов"),0)} -> 1 | AN11: {=IFERROR(_xlfn.IFS((I11-X11)>0,I11/$R$1*$AY$1-X11,I11+X11=0,"нов"),0)} -> 1 | AO11: {=IFERROR(_xlfn.IFS((J11-Y11)>0,J11/$R$1*$AY$1-Y11,J11+Y11=0,"нов"),0)} -> нов | AP11: {=IFERROR(_xlfn.IFS((K11-Z11)>0,K11/$R$1*$AY$1-Z11,K11+Z11=0,"нов"),0)} -> 0 | AQ11: {=IFERROR(_xlfn.IFS((L11-AA11)>0,L11/$R$1*$AY$1-AA11,L11+AA11=0,"нов"),0)} -> нов | AR11: {=IFERROR(_xlfn.IFS((M11-AB11)>0,M11/$R$1*$AY$1-AB11,M11+AB11=0,"нов"),0)} -> 2 | ... AV11: {=IFERROR(_xlfn.IFS((Q11-AF11)>0,Q11/$R$1*$AY$1-AF11,Q11+AF11=0,"нов"),0)} -> нов | AW11: =SUM(AK11:AV11) -> 31 | AX11: =SUMIF('ОЗОН Доступн товара'!D:D,_xlfn.XLOOKUP($B11,'ОЗОН Доступн товара'!$A:$A,'ОЗОН Доступн товара'!$D:$D,0)) -> 24 | AY11: =SUM(AW11:AX11) -> 55 | AZ11: =IF(AK11="нов","нов",ROUNDUP(AK11*1.3,0)) -> 36 | BA11: =IF(AL11="нов","нов",ROUNDUP(AL11*1.3,0)) -> нов | BB11: =IF(AM11="нов","нов",ROUNDUP(AM11*1.3,0)) -> 2 | BC11: =IF(AN11="нов","нов",ROUNDUP(AN11*1.3,0)) -> 2 | BD11: =IF(AO11="нов","нов",ROUNDUP(AO11*1.3,0)) -> нов | BE11: =IF(AP11="нов","нов",ROUNDUP(AP11*1.3,0)) -> 0 | BF11: =IF(AQ11="нов","нов",ROUNDUP(AQ11*1.3,0)) -> нов | BG11: =IF(AR11="нов","нов",ROUNDUP(AR11*1.3,0)) -> 3 | ... BK11: =IF(AV11="нов","нов",ROUNDUP(AV11*1.3,0)) -> нов | BL11: =SUM(AZ11:BK11) -> 43 | BM11: =AX11*1.3 -> 31.2 | BN11: =SUM(BL11:BM11) -> 74.2 | BO11: =IFERROR(_xlfn.XLOOKUP(A11,'[2] Расчет стоимости и веса'!$I:$I,'[2] Расчет стоимости и веса'!$D:$D),0) -> 80 | BP11: =BO11*3 -> 240 | BR11: 40 | CA11: 20 | CB11: 20 | CE11: =SUM(BR11:CD11) -> 80 | CF11: =MAX(BO11,CE11)-BQ11 -> 80 | CG11: =BO11+BQ11-CE11 -> 0
