Workbook
Name discontinueDiscount: #REF!
Name discontinueDiscount: #REF!
Name discontinueDiscount: #REF!
Name discontinueDiscount: #REF!
Name discontinueDiscount: #REF!
Name discontinueDiscount: #REF!
Name formUrl: #REF!
Name formUrl: #REF!
Name formUrl: #REF!
Name formUrl: #REF!
Name formUrl: #REF!
Name formUrl: #REF!
Name g: #REF!
Name g: #REF!
Name g: #REF!
Name g: #REF!
Name g: #REF!
Name g: #REF!
Name groupByArticles: #REF!
Name groupByArticles: #REF!
Name groupByArticles: #REF!
Name groupByArticles: #REF!
Name groupByArticles: #REF!
Name groupByArticles: #REF!
Name h: #REF!
Name h: #REF!
Name h: #REF!
Name h: #REF!
Name h: #REF!
Name h: #REF!
Name instructionsUrl: #REF!
Name instructionsUrl: #REF!
Name instructionsUrl: #REF!
Name instructionsUrl: #REF!
Name instructionsUrl: #REF!
Name instructionsUrl: #REF!
Name loadingPeriod: #REF!
Name loadingPeriod: #REF!
Name loadingPeriod: #REF!
Name loadingPeriod: #REF!
Name loadingPeriod: #REF!
Name loadingPeriod: #REF!
Name loadsPerMonth: #REF!
Name loadsPerMonth: #REF!
Name loadsPerMonth: #REF!
Name loadsPerMonth: #REF!
Name loadsPerMonth: #REF!
Name loadsPerMonth: #REF!
Name logArticles: #REF!
Name logArticles: #REF!
Name logArticles: #REF!
Name logArticles: #REF!
Name logArticles: #REF!
Name logArticles: #REF!
Name logDeficiency: #REF!
Name logDeficiency: #REF!
Name logDeficiency: #REF!
Name logDeficiency: #REF!
Name logDeficiency: #REF!
Name logDeficiency: #REF!

Sheet 1
C1: Обязательно написать номер недели | D1: 1 | AI1: на 1 единицу проданного товара
A2: Арт. ВБ | B2: Артикул поставщика | C2: Название | D2: ШК | E2: Остаток на начало недели, шт | F2: Себестоимость на 1 ед | G2: Себестоимость остатков | H2: Оборачиваемость, дн | I2: % выкупа за 30 дн с уч возврата | J2: Скорость продаж | K2: Кол-во ПРОДАЖИ | L2: Кол-во ВОЗВРАТЫ | M2: Кол-во ПРОДАЖИ-ВОЗВРАТЫ | N2: Выручка ПРОДАЖИ по Цене в карточке | O2: Выручка ПРОДАЖИ по Цене ВБ реализовал | P2: Выручка ВОЗВРАТЫ | Q2: Выручка ПРОДАЖИ (цена в карточке)- ВОЗВРАТЫ | R2: Выручка ПРОДАЖИ (ВБ реализовал)- ВОЗВРАТЫ | S2: Доля выручки, % от общего объема | T2: Себестоимость продаж | U2: Комиссия, руб | V2: Комиссия, % | W2: Логистика | X2: Хранение | Y2: Реклама | Z2: Налог 7% | AA2: Прибыль | AB2: Доля прибыли, % от общего объема | AC2: Остаток на конец недели, шт | AD2: Конверсия в корзину, % | AE2: Конверсия в заказ, % | AF2: Маржинальность, % | AG2: Рентабельность, % | AI2: Выручка на 1 ед (средняя цена продажи со скидкой) | AJ2: Себестоимость на 1 ед | AK2: Комиссия на 1 ед | AL2: Логистика на 1 ед | AM2: Хранение на 1 ед. | AN2: Реклама на 1 ед | AO2: Налог на 1 ед | AP2: Прибыль на 1 ед
A3: 1 | B3: 2 | C3: 3 | D3: 4 | E3: 5 | F3: 6 | G3: 7 | H3: 8 | I3: 9 | J3: 10 | K3: 11 | L3: 12 | M3: 13 | N3: 14 | O3: 15 | P3: 16 | Q3: 17 | R3: 18 | S3: 19 | T3: 20 | U3: 21 | V3: 22 | W3: 23 | X3: 24 | Y3: 25 | Z3: 26 | AA3: 27 | AB3: 19 | AC3: 28 | AD3: 30 | AE3: 31 | AF3: 32 | AG3: 33 | AH3: 34 | AI3: 35 | AJ3: 36 | AK3: 37 | AL3: 38 | AM3: 39 | AN3: 40 | AO3: 41 | AP3: 42
A4: 169112569 | B4: ACRF1BN101PN | C4: Бандаж для лица розовый | D4: 2038161736993 | E4: 0 | F4: 111 | G4: 0 | H4: 513.33333 | I4: 100 | J4: 0.3 | K4: 0 | L4: 0 | M4: 0 | N4: 0 | O4: 0 | P4: 0 | Q4: 0 | R4: 0 | S4: 0 | T4: 0 | U4: -6.532459 | V4: 0 | W4: 0 | X4: 150.92 | Z4: 0 | AA4: -144.38754 | AB4: -0.014696206 | AC4: 154 | AD4: 7 | AE4: 33 | AF4: 0 | AG4: 0 | AI4: 0 | AJ4: 111 | AK4: 0 | AL4: 0 | AM4: 150.92 | AN4: 0 | AP4: 0
A5: 169153168 | B5: ACRF1BN101BC | C5: Бандаж для лица черный | D5: 2038162681926 | E5: 0 | F5: 90 | G5: 0 | H5: 999 | I5: 0 | J5: 0 | K5: 0 | L5: 0 | M5: 0 | N5: 0 | O5: 0 | P5: 0 | Q5: 0 | R5: 0 | S5: 0 | T5: 0 | U5: -2.9990164 | V5: 0 | W5: 0 | X5: 222.46 | Z5: 0 | AA5: -219.46098 | AB5: -0.022337411 | AC5: 227 | AD5: 5 | AE5: 0 | AF5: 0 | AG5: 0 | AI5: 0 | AJ5: 90 | AK5: 0 | AL5: 0 | AM5: 222.46 | AN5: 0 | AP5: 0
A6: 169395410 | B6: ACRF1BN201GR | C6: Бандаж для лица серый | D6: 2038172050200 | E6: 0 | F6: 206 | G6: 0 | H6: 258.75 | I6: 100 | J6: 0.8 | K6: 0 | L6: 0 | M6: 0 | N6: 0 | O6: 0 | P6: 0 | Q6: 0 | R6: 0 | S6: 0 | T6: 0 | U6: -10.700492 | V6: 0 | W6: 0 | X6: 202.86 | Z6: 0 | AA6: -192.15951 | AB6: -0.019558583 | AC6: 207 | AD6: 15 | AE6: 30 | AF6: 0 | AG6: 0 | AI6: 0 | AJ6: 206 | AK6: 0 | AL6: 0 | AM6: 202.86 | AN6: 0 | AP6: 0
A7: 172832355 | B7: AHMA7BW101BG | C7: Мешки 7 шт. | D7: 2038337652454 | E7: 0 | F7: 375 | G7: 0 | H7: 999 | I7: 0 | J7: 0 | K7: 0 | L7: 0 | M7: 0 | N7: 0 | O7: 0 | P7: 0 | Q7: 0 | R7: 0 | S7: 0 | T7: 0 | U7: 0 | V7: 0 | W7: 0 | X7: 496.3896 | Z7: 0 | AA7: -496.3896 | AB7: -0.050524054 | AC7: 134 | AD7: 12 | AE7: 0 | AF7: 0 | AG7: 0 | AI7: 0 | AJ7: 375 | AK7: 0 | AL7: 0 | AM7: 496.3896 | AN7: 0 | AP7: 0
A8: 176500218 | B8: AHMA1BW101BG | C8: Мешок для бюстгалтеров | D8: 2038597850744 | E8: 0 | F8: 71 | G8: 0 | H8: 676 | I8: 100 | J8: 0.5 | K8: 2 | L8: 0 | M8: 2 | N8: 987 | O8: 613 | P8: 0 | Q8: 987 | R8: 613 | S8: 0.020208233 | T8: 142 | U8: 297.00557 | V8: 0.3009175 | W8: 121.96 | X8: 333.2 | Z8: 42.91 | AA8: 49.924426 | AB8: 0.005081461 | AC8: 338 | AD8: 10 | AE8: 40 | AF8: 0.050581992 | AG8: 0.35158047 | AI8: 493.5 | AJ8: 71 | AK8: 148.50279 | AL8: 60.98 | AM8: 166.6 | AN8: 0 | AO8: 21.455 | AP8: 24.962213
A9: 177404837 | B9: AHMA3BW101BG | C9: Мешки 3 шт. | D9: 2038627692689 | E9: 0 | F9: 166 | G9: 0 | H9: 413.33333 | I9: 100 | J9: 0.3 | K9: 0 | L9: 0 | M9: 0 | N9: 0 | O9: 0 | P9: 0 | Q9: 0 | R9: 0 | S9: 0 | T9: 0 | U9: -10.445574 | V9: 0 | W9: 0 | X9: 303.8 | Z9: 0 | AA9: -293.35443 | AB9: -0.029858512 | AC9: 124 | AD9: 5 | AE9: 50 | AF9: 0 | AG9: 0 | AI9: 0 | AJ9: 166 | AK9: 0 | AL9: 0 | AM9: 303.8 | AN9: 0 | AP9: 0
A10: 177405495 | B10: AHMA3BW102BG | C10: Мешки/деликат 3 шт. | D10: 2038627713902 | E10: 0 | F10: 156 | G10: 0 | H10: 416 | I10: 100 | J10: 0.5 | K10: 1 | L10: 0 | M10: 1 | N10: 989.4 | O10: 657 | P10: 0 | Q10: 989.4 | R10: 657 | S10: 0.020257371 | T10: 156 | U10: 287.17951 | V10: 0.29025622 | W10: 110.48 | X10: 348.194 | Z10: 45.99 | AA10: 41.556492 | AB10: 0.004229747 | AC10: 208 | AD10: 18 | AE10: 29 | AF10: 0.04200171 | AG10: 0.26638777 | AI10: 989.4 | AJ10: 156 | AK10: 287.17951 | AL10: 110.48 | AM10: 348.194 | AN10: 0 | AO10: 45.99 | AP10: 41.556492
A11: 176721350 | B11: AHMA3BW201WH | C11: Мешки/шнурок мелк 3 шт. | D11: 2038606201642 | E11: 0 | F11: 145 | G11: 0 | H11: 259 | I11: 100 | J11: 1 | K11: 1 | L11: 0 | M11: 1 | N11: 812 | O11: 543 | P11: 0 | Q11: 812 | R11: 543 | S11: 0.016625213 | T11: 145 | U11: 228.00508 | V11: 0.28079444 | W11: 61.77 | X11: 254.8 | Z11: 38.01 | AA11: 84.414918 | AB11: 0.0085920089 | AC11: 259 | AD11: 7 | AE11: 50 | AF11: 0.10395926 | AG11: 0.58217185 | AI11: 812 | AJ11: 145 | AK11: 228.00508 | AL11: 61.77 | AM11: 254.8 | AN11: 0 | AO11: 38.01 | AP11: 84.414918
A12: 176723275 | B12: AHMA3BW202WH | C12: Мешки/шнурок крупн 3 шт. | D12: 2038606256161 | E12: 0 | F12: 145 | G12: 0 | H12: 41.666667 | I12: 100 | J12: 3 | K12: 4 | L12: 0 | M12: 4 | N12: 3157 | O12: 2074 | P12: 0 | Q12: 3157 | R12: 2074 | S12: 0.064637681 | T12: 580 | U12: 879.75656 | V12: 0.27866853 | W12: 210.65 | X12: 126.42 | Z12: 145.18 | AA12: 1214.9934 | AB12: 0.12366575 | AC12: 125 | AD12: 16 | AE12: 52 | AF12: 0.38485697 | AG12: 2.0948163 | AI12: 789.25 | AJ12: 145 | AK12: 219.93914 | AL12: 52.6625 | AM12: 31.605 | AN12: 0 | AO12: 36.295 | AP12: 303.74836
A13: 204615141 | B13: AHMA2BW201WH | C13: Мешки 2 шт. серый | D13: 2039404446068 | E13: 0 | F13: 92 | G13: 0 | H13: 656.66667 | I13: 100 | J13: 0.3 | K13: 1 | L13: 0 | M13: 1 | N13: 654 | O13: 410 | P13: 0 | Q13: 654 | R13: 410 | S13: 0.013390258 | T13: 92 | U13: 175.14869 | V13: 0.26781145 | W13: 50.68 | X13: 194.04 | Z13: 28.7 | AA13: 113.43131 | AB13: 0.011545386 | AC13: 197 | AD13: 10 | AE13: 50 | AF13: 0.17344237 | AG13: 1.232949 | AI13: 654 | AJ13: 92 | AK13: 175.14869 | AL13: 50.68 | AM13: 194.04 | AN13: 0 | AO13: 28.7 | AP13: 113.43131
A14: 236074677 | B14: AHMA2BW202WH | C14: Мешки 2 шт. розовый | D14: 2040278862540 | E14: 0 | F14: 149 | G14: 0 | H14: 999 | I14: 0 | J14: 0 | K14: 0 | L14: 0 | M14: 0 | N14: 0 | O14: 0 | P14: 0 | Q14: 0 | R14: 0 | S14: 0 | T14: 0 | U14: 0 | V14: 0 | W14: 0 | X14: 49 | Z14: 0 | AA14: -49 | AB14: -0.0049873701 | AC14: 50 | AD14: 0 | AE14: 0 | AF14: 0 | AG14: 0 | AI14: 0 | AJ14: 149 | AK14: 0 | AL14: 0 | AM14: 49 | AN14: 0 | AP14: 0
A15: 236929187 | B15: AHMA1BW112WH | C15: Мешок 60*80 крупн | D15: 2040335626849 | E15: 0 | F15: 93 | G15: 0 | H15: 104.61538 | I15: 80 | J15: 1.3 | K15: 4 | L15: 0 | M15: 4 | N15: 2683 | O15: 1708 | P15: 0 | Q15: 2683 | R15: 1708 | S15: 0.054932815 | T15: 372 | U15: 798.35 | V15: 0.2975587 | W15: 190.08 | X15: 137.2 | Z15: 119.56 | AA15: 1065.81 | AB15: 0.10848141 | AC15: 136 | AD15: 16 | AE15: 25 | AF15: 0.39724562 | AG15: 2.8650806 | AI15: 670.75 | AJ15: 93 | AK15: 199.5875 | AL15: 47.52 | AM15: 34.3 | AN15: 0 | AO15: 29.89 | AP15: 266.4525
A16: 236929188 | B16: AHMA1BW111WH | C16: Мешок 60*80 мелк | D16: 2040335648124 | E16: 0 | F16: 93 | G16: 0 | H16: 22.325581 | I16: 94 | J16: 4.3 | K16: 5 | L16: 0 | M16: 5 | N16: 2932.96 | O16: 1895.06 | P16: 0 | Q16: 2932.96 | R16: 1895.06 | S16: 0.060050596 | T16: 465 | U16: 802.28311 | V16: 0.27354042 | W16: 230.17 | X16: 98.98 | Z16: 132.6542 | AA16: 1203.8727 | AB16: 0.12253385 | AC16: 96 | AD16: 23 | AE16: 34 | AF16: 0.41046338 | AG16: 2.5889735 | AI16: 586.592 | AJ16: 93 | AK16: 160.45662 | AL16: 46.034 | AM16: 19.796 | AN16: 0 | AO16: 26.53084 | AP16: 240.77454
A17: 239235150 | B17: AHMA1BW301WH | C17: Мешок для обуви L - 30 см | D17: 2040478720961 | E17: 0 | F17: 115 | G17: 0 | H17: 999 | I17: 0 | J17: 0 | K17: 0 | L17: 0 | M17: 0 | N17: 0 | O17: 0 | P17: 0 | Q17: 0 | R17: 0 | S17: 0 | T17: 0 | U17: 0 | V17: 0 | W17: 0 | X17: 59.78 | Z17: 0 | AA17: -59.78 | AB17: -0.0060845915 | AC17: 61 | AD17: 25 | AE17: 0 | AF17: 0 | AG17: 0 | AI17: 0 | AJ17: 115 | AK17: 0 | AL17: 0 | AM17: 59.78 | AN17: 0 | AP17: 0
A18: 239233529 | B18: AHMA1BW302WH | C18: Мешок для обуви XL - 35 см | D18: 2040478696884 | E18: 0 | F18: 144 | G18: 0 | H18: 276.66667 | I18: 100 | J18: 0.3 | K18: 0 | L18: 0 | M18: 0 | N18: 0 | O18: 0 | P18: 0 | Q18: 0 | R18: 0 | S18: 0 | T18: 0 | U18: -10.624918 | V18: 0 | W18: 0 | X18: 157.47424 | Z18: 0 | AA18: -146.84932 | AB18: -0.014946774 | AC18: 83 | AD18: 20 | AE18: 50 | AF18: 0 | AG18: 0 | AI18: 0 | AJ18: 144 | AK18: 0 | AL18: 0 | AM18: 157.47424 | AN18: 0 | AP18: 0
A19: 173605843 | B19: ACRH1MS101RJ | C19: Массажер для пальцев | D19: 2038430289250 | E19: 0 | F19: 66 | G19: 0 | H19: 1846.6667 | I19: 100 | J19: 0.3 | K19: 0 | L19: 0 | M19: 0 | N19: 0 | O19: 0 | P19: 0 | Q19: 0 | R19: 0 | S19: 0 | T19: 0 | U19: 0 | V19: 0 | W19: 0 | X19: 542.92 | Z19: 0 | AA19: -542.92 | AB19: -0.055260061 | AC19: 554 | AD19: 60 | AE19: 33 | AF19: 0 | AG19: 0 | AI19: 0 | AJ19: 66 | AK19: 0 | AL19: 0 | AM19: 542.92 | AN19: 0 | AP19: 0
A20: 223420736 | B20: ACRB1MS101RJ | C20: Массажер для тела оранжевый | D20: 2039813223373 | E20: 0 | F20: 151 | G20: 0 | H20: 41.25 | I20: 100 | J20: 0.8 | K20: 0 | L20: 0 | M20: 0 | N20: 0 | O20: 0 | P20: 0 | Q20: 0 | R20: 0 | S20: 0 | T20: 0 | U20: -8.7685246 | V20: 0 | W20: 0 | X20: 32.34 | Z20: 0 | AA20: -23.571475 | AB20: -0.002399177 | AC20: 33 | AD20: 9 | AE20: 43 | AF20: 0 | AG20: 0 | AI20: 0 | AJ20: 151 | AK20: 0 | AL20: 0 | AM20: 32.34 | AN20: 0 | AP20: 0
A21: 275208801 | B21: ACRB1MS101PN | C21: Массажер для тела розовый | D21: 2041591042329 | E21: 0 | F21: 151 | G21: 0 | H21: 999 | I21: 0 | J21: 0 | K21: 1 | L21: 0 | M21: 1 | N21: 698 | O21: 525 | P21: 0 | Q21: 698 | R21: 525 | S21: 0.014291131 | T21: 151 | U21: 203.60639 | V21: 0.2916997 | W21: 71.28 | X21: 74.48 | Z21: 36.75 | AA21: 160.88361 | AB21: 0.016375226 | AC21: 75 | AD21: 0 | AE21: 0 | AF21: 0.23049227 | AG21: 1.0654543 | AI21: 698 | AJ21: 151 | AK21: 203.60639 | AL21: 71.28 | AM21: 74.48 | AN21: 0 | AO21: 36.75 | AP21: 160.88361
A22: 275208802 | B22: ACRB1MS101BL | C22: Массажер для тела голубой | D22: 2041591055954 | E22: 0 | F22: 151 | G22: 0 | H22: 93.333333 | I22: 100 | J22: 0.3 | K22: 1 | L22: 0 | M22: 1 | N22: 794 | O22: 569 | P22: 0 | Q22: 794 | R22: 569 | S22: 0.016256674 | T22: 151 | U22: 217.82656 | V22: 0.27434075 | W22: 55.44 | X22: 28.42 | Z22: 39.83 | AA22: 301.48344 | AB22: 0.030685908 | AC22: 28 | AD22: 6 | AE22: 25 | AF22: 0.37970207 | AG22: 1.9965791 | AI22: 794 | AJ22: 151 | AK22: 217.82656 | AL22: 55.44 | AM22: 28.42 | AN22: 0 | AO22: 39.83 | AP22: 301.48344
A23: 236072835 | B23: ACRB1MS106WH | C23: Мяч с шипами белый 6 см | D23: 2040278804496 | E23: 0 | F23: 59 | G23: 0 | H23: 252.66667 | I23: 83 | J23: 1.5 | K23: 1 | L23: 0 | M23: 1 | N23: 802 | O23: 582 | P23: 0 | Q23: 802 | R23: 582 | S23: 0.016420469 | T23: 59 | U23: 234.1477 | V23: 0.29195474 | W23: 119.49 | X23: 372.4 | Z23: 40.74 | AA23: -23.777705 | AB23: -0.0024201676 | AC23: 379 | AD23: 19 | AE23: 46 | AF23: -0.029648011 | AG23: -0.40301195 | AI23: 802 | AJ23: 59 | AK23: 234.1477 | AL23: 119.49 | AM23: 372.4 | AN23: 0 | AO23: 40.74 | AP23: -23.777705
A24: 236072836 | B24: ACRB1MS106PN | C24: Мяч с шипами розовый 6 см | D24: 2040278810534 | E24: 0 | F24: 64 | G24: 0 | H24: 168.33333 | I24: 86 | J24: 1.8 | K24: 3 | L24: 0 | M24: 3 | N24: 1816 | O24: 1258 | P24: 0 | Q24: 1816 | R24: 1258 | S24: 0.03718151 | T24: 192 | U24: 549.52934 | V24: 0.30260426 | W24: 153.59 | X24: 299.88 | Z24: 88.06 | AA24: 532.94066 | AB24: 0.054244332 | AC24: 303 | AD24: 30 | AE24: 50 | AF24: 0.29346952 | AG24: 2.7757326 | AI24: 605.33333 | AJ24: 64 | AK24: 183.17645 | AL24: 51.196667 | AM24: 99.96 | AN24: 0 | AO24: 29.353333 | AP24: 177.64689
A25: 236072834 | B25: ACRB1MS106BL | C25: Мяч с шипами голубой 6 см | D25: 2040278804649 | E25: 0 | F25: 59 | G25: 0 | H25: 783.33333 | I25: 100 | J25: 0.3 | K25: 0 | L25: 0 | M25: 0 | N25: 0 | O25: 0 | P25: 0 | Q25: 0 | R25: 0 | S25: 0 | T25: 0 | U25: -9.8537705 | V25: 0 | W25: 0 | X25: 230.3 | Z25: 0 | AA25: -220.44623 | AB25: -0.022437693 | AC25: 235 | AD25: 20 | AE25: 25 | AF25: 0 | AG25: 0 | AI25: 0 | AJ25: 59 | AK25: 0 | AL25: 0 | AM25: 230.3 | AN25: 0 | AP25: 0
A26: 223671295 | B26: ACRB1MS106RJ | C26: Мяч с шипами оранжевый 6 см | D26: 2039818580389 | E26: 0 | F26: 59 | G26: 0 | H26: 999 | I26: 0 | J26: 0 | K26: 0 | L26: 0 | M26: 0 | N26: 0 | O26: 0 | P26: 0 | Q26: 0 | R26: 0 | S26: 0 | T26: 0 | U26: 0 | V26: 0 | W26: 0 | X26: 443.94 | Z26: 0 | AA26: -443.94 | AB26: -0.045185573 | AC26: 453 | AD26: 0 | AE26: 0 | AF26: 0 | AG26: 0 | AI26: 0 | AJ26: 59 | AK26: 0 | AL26: 0 | AM26: 443.94 | AN26: 0 | AP26: 0
A27: 370591238 | B27: ACRB1MS106BС | C27: Мяч с шипами черный 6 см | D27: 2043369663040 | E27: 0 | F27: 49 | G27: 0 | H27: 196 | I27: 67 | J27: 1 | K27: 1 | L27: 0 | M27: 1 | N27: 479 | O27: 343 | P27: 0 | Q27: 479 | R27: 343 | S27: 0.0098072376 | T27: 49 | U27: 112.90115 | V27: 0.23570177 | W27: 45.93 | X27: 193.06 | Z27: 24.01 | AA27: 54.098852 | AB27: 0.0055063469 | AC27: 196 | AD27: 25 | AE27: 67 | AF27: 0.11294124 | AG27: 1.1040582 | AI27: 479 | AJ27: 49 | AK27: 112.90115 | AL27: 45.93 | AM27: 193.06 | AN27: 0 | AO27: 24.01 | AP27: 54.098852
A28: 419145391 | B28: ACRB1MS107WH | C28: Мяч с шипами белый 7 см | D28: 2044025326637 | E28: 0 | F28: 62 | G28: 0 | H28: 3.8461538 | I28: 60 | J28: 1.3 | K28: 1 | L28: 0 | M28: 1 | N28: 753 | O28: 520 | P28: 0 | Q28: 753 | R28: 520 | S28: 0.015417223 | T28: 62 | U28: 201.5841 | V28: 0.26770797 | W28: 63.16 | X28: 5.88 | Z28: 36.4 | AA28: 383.9759 | AB28: 0.039082243 | AC28: 5 | AD28: 13 | AE28: 50 | AF28: 0.50992816 | AG28: 6.1931597 | AI28: 753 | AJ28: 62 | AK28: 201.5841 | AL28: 63.16 | AM28: 5.88 | AN28: 0 | AO28: 36.4 | AP28: 383.9759
A29: 419145389 | B29: ACRB1MS107PN | C29: Мяч с шипами розовый 7 см | D29: 2044025316447 | E29: 0 | F29: 63 | G29: 0 | H29: 999 | I29: 0 | J29: 0 | K29: 0 | L29: 0 | M29: 0 | N29: 0 | O29: 0 | P29: 0 | Q29: 0 | R29: 0 | S29: 0 | T29: 0 | U29: 0 | V29: 0 | W29: 0 | X29: 60.76 | Z29: 0 | AA29: -60.76 | AB29: -0.0061843389 | AC29: 62 | AD29: 0 | AE29: 0 | AF29: 0 | AG29: 0 | AI29: 0 | AJ29: 63 | AK29: 0 | AL29: 0 | AM29: 60.76 | AN29: 0 | AP29: 0
A30: 419145748 | B30: ACRB1MS107BL | C30: Мяч с шипами голубой 7 см | D30: 2044025338661 | E30: 0 | F30: 63 | G30: 0 | H30: 999 | I30: 0 | J30: 0 | K30: 0 | L30: 0 | M30: 0 | N30: 0 | O30: 0 | P30: 0 | Q30: 0 | R30: 0 | S30: 0 | T30: 0 | U30: 0 | V30: 0 | W30: 0 | X30: 78.4 | Z30: 0 | AA30: -78.4 | AB30: -0.0079797922 | AC30: 80 | AD30: 0 | AE30: 0 | AF30: 0 | AG30: 0 | AI30: 0 | AJ30: 63 | AK30: 0 | AL30: 0 | AM30: 78.4 | AN30: 0 | AP30: 0
A31: 419141548 | B31: ACRB1MS107RJ | C31: Мяч с шипами оранжевый 7 см | D31: 2044025288003 | E31: 0 | F31: 63 | G31: 0 | H31: 999 | I31: 0 | J31: 0 | K31: 0 | L31: 0 | M31: 0 | N31: 0 | O31: 0 | P31: 0 | Q31: 0 | R31: 0 | S31: 0 | T31: 0 | U31: 0 | V31: 0 | W31: 0 | X31: 75.46 | Z31: 0 | AA31: -75.46 | AB31: -0.0076805499 | AC31: 77 | AD31: 29 | AE31: 0 | AF31: 0 | AG31: 0 | AI31: 0 | AJ31: 63 | AK31: 0 | AL31: 0 | AM31: 75.46 | AN31: 0 | AP31: 0
A32: 419145985 | B32: ACRB1MS107BС | C32: Мяч с шипами черный 7 см | D32: 2044025344532 | E32: 0 | F32: 63 | G32: 0 | H32: 999 | I32: 0 | J32: 0 | K32: 0 | L32: 0 | M32: 0 | N32: 0 | O32: 0 | P32: 0 | Q32: 0 | R32: 0 | S32: 0 | T32: 0 | U32: 0 | V32: 0 | W32: 0 | X32: 71.54 | Z32: 0 | AA32: -71.54 | AB32: -0.0072815603 | AC32: 73 | AD32: 0 | AE32: 0 | AF32: 0 | AG32: 0 | AI32: 0 | AJ32: 63 | AK32: 0 | AL32: 0 | AM32: 71.54 | AN32: 0 | AP32: 0
A33: 419145390 | B33: ACRB1MS109PN | C33: Мяч с шипами розовый 9 см | D33: 2044025321588 | E33: 0 | F33: 91 | G33: 0 | H33: 134 | I33: 50 | J33: 0.5 | K33: 1 | L33: 0 | M33: 1 | N33: 553 | O33: 391 | P33: 0 | Q33: 553 | R33: 391 | S33: 0.011322343 | T33: 91 | U33: 152.9818 | V33: 0.27663979 | W33: 57.91 | X33: 66.64 | Z33: 27.37 | AA33: 157.0982 | AB33: 0.015989936 | AC33: 67 | AD33: 13 | AE33: 50 | AF33: 0.28408354 | AG33: 1.7263538 | AI33: 553 | AJ33: 91 | AK33: 152.9818 | AL33: 57.91 | AM33: 66.64 | AN33: 0 | AO33: 27.37 | AP33: 157.0982
A34: 419145749 | B34: ACRB1MS109BL | C34: Мяч с шипами голубой 9 см | D34: 2044025342057 | E34: 0 | F34: 91 | G34: 0 | H34: 266.66667 | I34: 100 | J34: 0.3 | K34: 1 | L34: 0 | M34: 1 | N34: 628 | O34: 449 | P34: 0 | Q34: 628 | R34: 449 | S34: 0.012857923 | T34: 91 | U34: 203.22967 | V34: 0.32361413 | W34: 51.97 | X34: 79.38 | Z34: 31.43 | AA34: 170.99033 | AB34: 0.017403919 | AC34: 80 | AD34: 8 | AE34: 100 | AF34: 0.27227759 | AG34: 1.8790146 | AI34: 628 | AJ34: 91 | AK34: 203.22967 | AL34: 51.97 | AM34: 79.38 | AN34: 0 | AO34: 31.43 | AP34: 170.99033
A35: 419141549 | B35: ACRB1MS109RJ | C35: Мяч с шипами оранжевый 9 см | D35: 2044025291485 | E35: 0 | F35: 91 | G35: 0 | H35: 206.66667 | I35: 100 | J35: 0.3 | K35: 0 | L35: 0 | M35: 0 | N35: 0 | O35: 0 | P35: 0 | Q35: 0 | R35: 0 | S35: 0 | T35: 0 | U35: -17.477869 | V35: 0 | W35: 0 | X35: 60.76 | Z35: 0 | AA35: -43.282131 | AB35: -0.0044053879 | AC35: 62 | AD35: 13 | AE35: 100 | AF35: 0 | AG35: 0 | AI35: 0 | AJ35: 91 | AK35: 0 | AL35: 0 | AM35: 60.76 | AN35: 0 | AP35: 0
A36: 419145986 | B36: ACRB1MS109BС | C36: Мяч с шипами черный 9 см | D36: 2044025347953 | E36: 0 | F36: 91 | G36: 0 | H36: 999 | I36: 0 | J36: 0 | K36: 0 | L36: 0 | M36: 0 | N36: 0 | O36: 0 | P36: 0 | Q36: 0 | R36: 0 | S36: 0 | T36: 0 | U36: 0 | V36: 0 | W36: 0 | X36: 96.04 | Z36: 0 | AA36: -96.04 | AB36: -0.0097752454 | AC36: 98 | AD36: 14 | AE36: 0 | AF36: 0 | AG36: 0 | AI36: 0 | AJ36: 91 | AK36: 0 | AL36: 0 | AM36: 96.04 | AN36: 0 | AP36: 0
A37: 419146579 | B37: ACRB1MS109LI | C37: Мяч с шипами фиолетовый 9 см | D37: 2044025354937 | E37: 0 | F37: 91 | G37: 0 | H37: 373.33333 | I37: 0 | J37: 0.3 | K37: 0 | L37: 0 | M37: 0 | N37: 0 | O37: 0 | P37: 0 | Q37: 0 | R37: 0 | S37: 0 | T37: 0 | U37: -16.351639 | V37: 0 | W37: 0 | X37: 109.76 | Z37: 0 | AA37: -93.408361 | AB37: -0.0095073891 | AC37: 112 | AD37: 16 | AE37: 33 | AF37: 0 | AG37: 0 | AI37: 0 | AJ37: 91 | AK37: 0 | AL37: 0 | AM37: 109.76 | AN37: 0 | AP37: 0
A38: 340734340 | B38: ACRB1MS103PN | C38: Мяч гладкий розовый | D38: 2042985583893 | E38: 0 | F38: 87 | G38: 0 | H38: 103.33333 | I38: 100 | J38: 0.3 | K38: 0 | L38: 0 | M38: 0 | N38: 0 | O38: 0 | P38: 0 | Q38: 0 | R38: 0 | S38: 0 | T38: 0 | U38: -8.362459 | V38: 0 | W38: 0 | X38: 30.38 | Z38: 0 | AA38: -22.017541 | AB38: -0.0022410128 | AC38: 31 | AD38: 8 | AE38: 100 | AF38: 0 | AG38: 0 | AI38: 0 | AJ38: 87 | AK38: 0 | AL38: 0 | AM38: 30.38 | AN38: 0 | AP38: 0
A39: 340741532 | B39: ACRB1MS103BL | C39: Мяч гладкий голубой | D39: 2042986356632 | E39: 0 | F39: 87 | G39: 0 | H39: 999 | I39: 0 | J39: 0 | K39: 0 | L39: 0 | M39: 0 | N39: 0 | O39: 0 | P39: 0 | Q39: 0 | R39: 0 | S39: 0 | T39: 0 | U39: 0 | V39: 0 | W39: 0 | X39: 80.36 | Z39: 0 | AA39: -80.36 | AB39: -0.008179287 | AC39: 82 | AD39: 17 | AE39: 0 | AF39: 0 | AG39: 0 | AI39: 0 | AJ39: 87 | AK39: 0 | AL39: 0 | AM39: 80.36 | AN39: 0 | AP39: 0
A40: 340743352 | B40: ACRB1MS103LI | C40: Мяч гладкий сиреневый | D40: 2042986372359 | E40: 0 | F40: 87 | G40: 0 | H40: 999 | I40: 0 | J40: 0 | K40: 0 | L40: 0 | M40: 0 | N40: 0 | O40: 0 | P40: 0 | Q40: 0 | R40: 0 | S40: 0 | T40: 0 | U40: 0 | V40: 0 | W40: 0 | X40: 53.9 | Z40: 0 | AA40: -53.9 | AB40: -0.0054861071 | AC40: 55 | AD40: 17 | AE40: 0 | AF40: 0 | AG40: 0 | AI40: 0 | AJ40: 87 | AK40: 0 | AL40: 0 | AM40: 53.9 | AN40: 0 | AP40: 0
...

Sheet 2
C1: Обязательно написать номер недели | D1: 2 | AI1: на 1 единицу проданного товара
A2: Арт. ВБ | B2: Артикул поставщика | C2: Название | D2: ШК | E2: Остаток на начало недели, шт | F2: Себестоимость на 1 ед | G2: Себестоимость остатков | H2: Оборачиваемость, дн | I2: % выкупа за 30 дн с уч возврата | J2: Скорость продаж | K2: Кол-во ПРОДАЖИ | L2: Кол-во ВОЗВРАТЫ | M2: Кол-во ПРОДАЖИ-ВОЗВРАТЫ | N2: Выручка ПРОДАЖИ по Цене в карточке | O2: Выручка ПРОДАЖИ по Цене ВБ реализовал | P2: Выручка ВОЗВРАТЫ | Q2: Выручка ПРОДАЖИ (цена в карточке)- ВОЗВРАТЫ | R2: Выручка ПРОДАЖИ (ВБ реализовал)- ВОЗВРАТЫ | S2: Доля выручки, % от общего объема | T2: Себестоимость продаж | U2: Комиссия, руб | V2: Комиссия, % | W2: Логистика | X2: Хранение | Y2: Реклама | Z2: Налог 7% | AA2: Прибыль | AB2: Доля прибыли, % от общего объема | AC2: Остаток на конец недели, шт | AD2: Конверсия в корзину, % | AE2: Конверсия в заказ, % | AF2: Маржинальность, % | AG2: Рентабельность, % | AI2: Выручка на 1 ед (средняя цена продажи со скидкой) | AJ2: Себестоимость на 1 ед | AK2: Комиссия на 1 ед | AL2: Логистика на 1 ед | AM2: Хранение на 1 ед. | AN2: Реклама на 1 ед | AO2: Налог на 1 ед | AP2: Прибыль на 1 ед
A3: 1 | B3: 2 | C3: 3 | D3: 4 | E3: 5 | F3: 6 | G3: 7 | H3: 8 | I3: 9 | J3: 10 | K3: 11 | L3: 12 | M3: 13 | N3: 14 | O3: 15 | P3: 16 | Q3: 17 | R3: 18 | S3: 19 | T3: 20 | U3: 21 | V3: 22 | W3: 23 | X3: 24 | Y3: 25 | Z3: 26 | AA3: 27 | AB3: 19 | AC3: 28 | AD3: 30 | AE3: 31 | AF3: 32 | AG3: 33 | AH3: 34 | AI3: 35 | AJ3: 36 | AK3: 37 | AL3: 38 | AM3: 39 | AN3: 40 | AO3: 41 | AP3: 42
A4: 169112569 | B4: ACRF1BN101PN | C4: Бандаж для лица розовый | D4: 2038161736993 | E4: 154 | F4: 111 | G4: 17094 | H4: 385 | I4: 50 | J4: 0.4 | K4: 2 | L4: 0 | M4: 2 | N4: 1251 | O4: 858 | P4: 0 | Q4: 1251 | R4: 858 | S4: 0.0076645972 | T4: 222 | U4: 417.90164 | V4: 0.33405407 | W4: 97.8 | X4: 152.88 | Z4: 60.06 | AA4: 300.35836 | AB4: 0.0059530199 | AC4: 154 | AD4: 11 | AE4: 43 | AF4: 0.24009461 | AG4: 1.3529656 | AI4: 625.5 | AJ4: 111 | AK4: 208.95082 | AL4: 48.9 | AM4: 76.44 | AN4: 0 | AO4: 30.03 | AP4: 150.17918
A5: 169153168 | B5: ACRF1BN101BC | C5: Бандаж для лица черный | D5: 2038162681926 | E5: 227 | F5: 90 | G5: 20430 | H5: 2270 | I5: 0 | J5: 0.1 | K5: 2 | L5: 0 | M5: 2 | N5: 1282 | O5: 1005 | P5: 0 | Q5: 1282 | R5: 1005 | S5: 0.0078545273 | T5: 180 | U5: 407.34 | V5: 0.31773791 | W5: 91.37 | X5: 224.42 | Z5: 70.35 | AA5: 308.52 | AB5: 0.0061147814 | AC5: 227 | AD5: 4 | AE5: 33 | AF5: 0.24065523 | AG5: 1.714 | AI5: 641 | AJ5: 90 | AK5: 203.67 | AL5: 45.685 | AM5: 112.21 | AN5: 0 | AO5: 35.175 | AP5: 154.26
A6: 169395410 | B6: ACRF1BN201GR | C6: Бандаж для лица серый | D6: 2038172050200 | E6: 207 | F6: 206 | G6: 42642 | H6: 295.71429 | I6: 100 | J6: 0.7 | K6: 6 | L6: 0 | M6: 6 | N6: 5864.7 | O6: 4090 | P6: 0 | Q6: 5864.7 | R6: 4090 | S6: 0.035931705 | T6: 1236 | U6: 1886.8077 | V6: 0.3217228 | W6: 283.63 | X6: 208.74 | Z6: 286.3 | AA6: 1963.2223 | AB6: 0.038910525 | AC6: 207 | AD6: 13 | AE6: 23 | AF6: 0.33475238 | AG6: 1.5883676 | AI6: 977.45 | AJ6: 206 | AK6: 314.46795 | AL6: 47.271667 | AM6: 34.79 | AN6: 0 | AO6: 47.716667 | AP6: 327.20372
A7: 172832355 | B7: AHMA7BW101BG | C7: Мешки 7 шт. | D7: 2038337652454 | E7: 134 | F7: 375 | G7: 50250 | H7: 446.66667 | I7: 100 | J7: 0.3 | K7: 1 | L7: 0 | M7: 1 | N7: 1684.61 | O7: 1227.42 | P7: 0 | Q7: 1684.61 | R7: 1227.42 | S7: 0.010321229 | T7: 375 | U7: 509.17426 | V7: 0.30225053 | W7: 189.15 | X7: 500.094 | Z7: 85.9194 | AA7: 25.272338 | AB7: 0.00050089077 | AC7: 134 | AD7: 3 | AE7: 50 | AF7: 0.015001892 | AG7: 0.067392901 | AI7: 1684.61 | AJ7: 375 | AK7: 509.17426 | AL7: 189.15 | AM7: 500.094 | AN7: 0 | AO7: 85.9194 | AP7: 25.272338
A8: 176500218 | B8: AHMA1BW101BG | C8: Мешок для бюстгалтеров | D8: 2038597850744 | E8: 338 | F8: 71 | G8: 23998 | H8: 375.55556 | I8: 100 | J8: 0.9 | K8: 5 | L8: 0 | M8: 5 | N8: 2315 | O8: 1435 | P8: 0 | Q8: 2315 | R8: 1435 | S8: 0.014183487 | T8: 355 | U8: 653.11721 | V8: 0.28212407 | W8: 289.85 | X8: 336.14 | Z8: 100.45 | AA8: 580.44279 | AB8: 0.011504216 | AC8: 338 | AD8: 15 | AE8: 35 | AF8: 0.25073123 | AG8: 1.6350501 | AI8: 463 | AJ8: 71 | AK8: 130.62344 | AL8: 57.97 | AM8: 67.228 | AN8: 0 | AO8: 20.09 | AP8: 116.08856
A9: 177404837 | B9: AHMA3BW101BG | C9: Мешки 3 шт. | D9: 2038627692689 | E9: 124 | F9: 166 | G9: 20584 | H9: 999 | I9: 0 | J9: 0 | K9: 1 | L9: 0 | M9: 1 | N9: 1103 | O9: 735 | P9: 0 | Q9: 1103 | R9: 735 | S9: 0.0067578343 | T9: 166 | U9: 317.74033 | V9: 0.2880692 | W9: 149.24 | X9: 306.25 | Z9: 51.45 | AA9: 112.31967 | AB9: 0.0022261449 | AC9: 124 | AD9: 6 | AE9: 0 | AF9: 0.10183107 | AG9: 0.67662453 | AI9: 1103 | AJ9: 166 | AK9: 317.74033 | AL9: 149.24 | AM9: 306.25 | AN9: 0 | AO9: 51.45 | AP9: 112.31967
A10: 177405495 | B10: AHMA3BW102BG | C10: Мешки/деликат 3 шт. | D10: 2038627713902 | E10: 208 | F10: 156 | G10: 32448 | H10: 2080 | I10: 0 | J10: 0.1 | K10: 1 | L10: 0 | M10: 1 | N10: 1020 | O10: 640 | P10: 0 | Q10: 1020 | R10: 640 | S10: 0.0062493119 | T10: 156 | U10: 284.37623 | V10: 0.27880023 | W10: 88.38 | X10: 348.194 | Z10: 44.8 | AA10: 98.24977 | AB10: 0.0019472834 | AC10: 208 | AD10: 4 | AE10: 20 | AF10: 0.096323304 | AG10: 0.62980622 | AI10: 1020 | AJ10: 156 | AK10: 284.37623 | AL10: 88.38 | AM10: 348.194 | AN10: 0 | AO10: 44.8 | AP10: 98.24977
A11: 176721350 | B11: AHMA3BW201WH | C11: Мешки/шнурок мелк 3 шт. | D11: 2038606201642 | E11: 259 | F11: 145 | G11: 37555 | H11: 161.875 | I11: 83 | J11: 1.6 | K11: 7 | L11: 0 | M11: 7 | N11: 5236 | O11: 3339 | P11: 0 | Q11: 5236 | R11: 3339 | S11: 0.032079801 | T11: 1015 | U11: 1565.7859 | V11: 0.29904238 | W11: 617.92 | X11: 260.68 | Z11: 233.73 | AA11: 1542.8841 | AB11: 0.030579538 | AC11: 259 | AD11: 9 | AE11: 48 | AF11: 0.29466847 | AG11: 1.5200829 | AI11: 748 | AJ11: 145 | AK11: 223.6837 | AL11: 88.274286 | AM11: 37.24 | AN11: 0 | AO11: 33.39 | AP11: 220.41201
A12: 176723275 | B12: AHMA3BW202WH | C12: Мешки/шнурок крупн 3 шт. | D12: 2038606256161 | E12: 125 | F12: 145 | G12: 18125 | H12: 41.666667 | I12: 100 | J12: 3 | K12: 23 | L12: 0 | M12: 23 | N12: 18686.2 | O12: 12026 | P12: 0 | Q12: 18686.2 | R12: 12026 | S12: 0.11448617 | T12: 3335 | U12: 5418.4638 | V12: 0.28997141 | W12: 1368.45 | X12: 145.04 | Z12: 841.82 | AA12: 7577.4262 | AB12: 0.1501825 | AC12: 125 | AD12: 13 | AE12: 43 | AF12: 0.40550921 | AG12: 2.2720918 | AI12: 812.44348 | AJ12: 145 | AK12: 235.58538 | AL12: 59.497826 | AM12: 6.306087 | AN12: 0 | AO12: 36.60087 | AP12: 329.45331
A13: 204615141 | B13: AHMA2BW201WH | C13: Мешки 2 шт. серый | D13: 2039404446068 | E13: 197 | F13: 92 | G13: 18124 | H13: 492.5 | I13: 100 | J13: 0.4 | K13: 1 | L13: 0 | M13: 1 | N13: 571.33 | O13: 342 | P13: 0 | Q13: 571.33 | R13: 342 | S13: 0.0035004111 | T13: 92 | U13: 162.39393 | V13: 0.28423842 | W13: 33.26 | X13: 194.04 | Z13: 23.94 | AA13: 65.696066 | AB13: 0.0013020779 | AC13: 197 | AD13: 14 | AE13: 60 | AF13: 0.11498795 | AG13: 0.71408767 | AI13: 571.33 | AJ13: 92 | AK13: 162.39393 | AL13: 33.26 | AM13: 194.04 | AN13: 0 | AO13: 23.94 | AP13: 65.696066
A14: 236074677 | B14: AHMA2BW202WH | C14: Мешки 2 шт. розовый | D14: 2040278862540 | E14: 50 | F14: 149 | G14: 7450 | H14: 125 | I14: 100 | J14: 0.4 | K14: 3 | L14: 0 | M14: 3 | N14: 1587.35 | O14: 1037.75 | P14: 0 | Q14: 1587.35 | R14: 1037.75 | S14: 0.0097253385 | T14: 447 | U14: 460.45934 | V14: 0.29008054 | W14: 152.04 | X14: 51.94 | Z14: 72.6425 | AA14: 403.26816 | AB14: 0.0079926637 | AC14: 50 | AD14: 29 | AE14: 27 | AF14: 0.25405119 | AG14: 0.9021659 | AI14: 529.11667 | AJ14: 149 | AK14: 153.48645 | AL14: 50.68 | AM14: 17.313333 | AN14: 0 | AO14: 24.214167 | AP14: 134.42272
A15: 236929187 | B15: AHMA1BW112WH | C15: Мешок 60*80 крупн | D15: 2040335626849 | E15: 136 | F15: 93 | G15: 12648 | H15: 64.761905 | I15: 100 | J15: 2.1 | K15: 10 | L15: 0 | M15: 10 | N15: 6562.38 | O15: 4165 | P15: 0 | Q15: 6562.38 | R15: 4165 | S15: 0.040206235 | T15: 930 | U15: 1913.6046 | V15: 0.29160222 | W15: 644.98 | X15: 143.08 | Z15: 291.55 | AA15: 2639.1654 | AB15: 0.052307531 | AC15: 136 | AD15: 11 | AE15: 33 | AF15: 0.40216589 | AG15: 2.8378123 | AI15: 656.238 | AJ15: 93 | AK15: 191.36046 | AL15: 64.498 | AM15: 14.308 | AN15: 0 | AO15: 29.155 | AP15: 263.91654
A16: 236929188 | B16: AHMA1BW111WH | C16: Мешок 60*80 мелк | D16: 2040335648124 | E16: 96 | F16: 93 | G16: 8928 | H16: 16.842105 | I16: 86 | J16: 5.7 | K16: 30 | L16: 0 | M16: 30 | N16: 17702.68 | O16: 11328 | P16: 0 | Q16: 17702.68 | R16: 11328 | S16: 0.10846036 | T16: 2790 | U16: 5018.8396 | V16: 0.28350733 | W16: 1848.32 | X16: 123.48 | Z16: 792.96 | AA16: 7129.0804 | AB16: 0.14129641 | AC16: 96 | AD16: 15 | AE16: 42 | AF16: 0.40271193 | AG16: 2.555226 | AI16: 590.08933 | AJ16: 93 | AK16: 167.29465 | AL16: 61.610667 | AM16: 4.116 | AN16: 0 | AO16: 26.432 | AP16: 237.63601
A17: 239235150 | B17: AHMA1BW301WH | C17: Мешок для обуви L - 30 см | D17: 2040478720961 | E17: 61 | F17: 115 | G17: 7015 | H17: 610 | I17: 100 | J17: 0.1 | K17: 0 | L17: 0 | M17: 0 | N17: 0 | O17: 0 | P17: 0 | Q17: 0 | R17: 0 | S17: 0 | T17: 0 | U17: 0 | V17: 0 | W17: 0 | X17: 59.78 | Z17: 0 | AA17: -59.78 | AB17: -0.0011848231 | AC17: 61 | AD17: 29 | AE17: 50 | AF17: 0 | AG17: 0 | AI17: 0 | AJ17: 115 | AK17: 0 | AL17: 0 | AM17: 59.78 | AN17: 0 | AP17: 0
A18: 239233529 | B18: AHMA1BW302WH | C18: Мешок для обуви XL - 35 см | D18: 2040478696884 | E18: 83 | F18: 144 | G18: 11952 | H18: 999 | I18: 0 | J18: 0 | K18: 1 | L18: 0 | M18: 1 | N18: 842 | O18: 536 | P18: 0 | Q18: 842 | R18: 536 | S18: 0.0051587457 | T18: 144 | U18: 245.62443 | V18: 0.29171547 | W18: 127.65 | X18: 159.37152 | Z18: 37.52 | AA18: 127.83405 | AB18: 0.0025336357 | AC18: 83 | AD18: 0 | AE18: 0 | AF18: 0.15182192 | AG18: 0.88773648 | AI18: 842 | AJ18: 144 | AK18: 245.62443 | AL18: 127.65 | AM18: 159.37152 | AN18: 0 | AO18: 37.52 | AP18: 127.83405
A19: 173605843 | B19: ACRH1MS101RJ | C19: Массажер для пальцев | D19: 2038430289250 | E19: 554 | F19: 66 | G19: 36564 | H19: 1846.6667 | I19: 100 | J19: 0.3 | K19: 2 | L19: 0 | M19: 2 | N19: 911 | O19: 629 | P19: 0 | Q19: 911 | R19: 629 | S19: 0.0055814933 | T19: 132 | U19: 274.51279 | V19: 0.30133127 | W19: 108.1 | X19: 544.88 | Z19: 44.03 | AA19: -192.52279 | AB19: -0.0038157486 | AC19: 554 | AD19: 30 | AE19: 29 | AF19: -0.21133127 | AG19: -1.458506 | AI19: 455.5 | AJ19: 66 | AK19: 137.25639 | AL19: 54.05 | AM19: 272.44 | AN19: 0 | AO19: 22.015 | AP19: -96.261393
A20: 223420736 | B20: ACRB1MS101RJ | C20: Массажер для тела оранжевый | D20: 2039813223373 | E20: 33 | F20: 151 | G20: 4983 | H20: 55 | I20: 100 | J20: 0.6 | K20: 4 | L20: 0 | M20: 4 | N20: 2619 | O20: 1837 | P20: 0 | Q20: 2619 | R20: 1837 | S20: 0.016046027 | T20: 604 | U20: 833.29295 | V20: 0.31817218 | W20: 217 | X20: 36.26 | Z20: 128.59 | AA20: 799.85705 | AB20: 0.015852946 | AC20: 33 | AD20: 9 | AE20: 29 | AF20: 0.30540552 | AG20: 1.3242666 | AI20: 654.75 | AJ20: 151 | AK20: 208.32324 | AL20: 54.25 | AM20: 9.065 | AN20: 0 | AO20: 32.1475 | AP20: 199.96426
A21: 275208801 | B21: ACRB1MS101PN | C21: Массажер для тела розовый | D21: 2041591042329 | E21: 75 | F21: 151 | G21: 11325 | H21: 999 | I21: 0 | J21: 0 | K21: 0 | L21: 0 | M21: 0 | N21: 0 | O21: 0 | P21: 0 | Q21: 0 | R21: 0 | S21: 0 | T21: 0 | U21: 0 | V21: 0 | W21: 0 | X21: 73.5 | Z21: 0 | AA21: -73.5 | AB21: -0.0014567497 | AC21: 75 | AD21: 4 | AE21: 0 | AF21: 0 | AG21: 0 | AI21: 0 | AJ21: 151 | AK21: 0 | AL21: 0 | AM21: 73.5 | AN21: 0 | AP21: 0
A22: 275208802 | B22: ACRB1MS101BL | C22: Массажер для тела голубой | D22: 2041591055954 | E22: 28 | F22: 151 | G22: 4228 | H22: 280 | I22: 100 | J22: 0.1 | K22: 1 | L22: 0 | M22: 1 | N22: 714 | O22: 485 | P22: 0 | Q22: 714 | R22: 485 | S22: 0.0043745183 | T22: 151 | U22: 224.83885 | V22: 0.31490035 | W22: 50.68 | X22: 28.42 | Z22: 33.95 | AA22: 225.11115 | AB22: 0.0044616409 | AC22: 28 | AD22: 9 | AE22: 6 | AF22: 0.31528172 | AG22: 1.4908023 | AI22: 714 | AJ22: 151 | AK22: 224.83885 | AL22: 50.68 | AM22: 28.42 | AN22: 0 | AO22: 33.95 | AP22: 225.11115
A23: 236072835 | B23: ACRB1MS106WH | C23: Мяч с шипами белый 6 см | D23: 2040278804496 | E23: 379 | F23: 59 | G23: 22361 | H23: 189.5 | I23: 78 | J23: 2 | K23: 8 | L23: 0 | M23: 8 | N23: 6756 | O23: 4862 | P23: 0 | Q23: 6756 | R23: 4862 | S23: 0.041392501 | T23: 472 | U23: 2069.5126 | V23: 0.30632218 | W23: 669.68 | X23: 379.26 | Z23: 340.34 | AA23: 2825.2074 | AB23: 0.055994832 | AC23: 379 | AD23: 18 | AE23: 29 | AF23: 0.41817753 | AG23: 5.9856088 | AI23: 844.5 | AJ23: 59 | AK23: 258.68908 | AL23: 83.71 | AM23: 47.4075 | AN23: 0 | AO23: 42.5425 | AP23: 353.15092
A24: 236072836 | B24: ACRB1MS106PN | C24: Мяч с шипами розовый 6 см | D24: 2040278810534 | E24: 303 | F24: 64 | G24: 19392 | H24: 178.23529 | I24: 100 | J24: 1.7 | K24: 8 | L24: 0 | M24: 8 | N24: 4623.01 | O24: 3113 | P24: 0 | Q24: 4623.01 | R24: 3113 | S24: 0.028324148 | T24: 512 | U24: 1390.0566 | V24: 0.30068214 | W24: 530.87 | X24: 304.78 | Z24: 217.91 | AA24: 1667.3934 | AB24: 0.033047278 | AC24: 303 | AD24: 18 | AE24: 31 | AF24: 0.36067269 | AG24: 3.2566278 | AI24: 577.87625 | AJ24: 64 | AK24: 173.75707 | AL24: 66.35875 | AM24: 38.0975 | AN24: 0 | AO24: 27.23875 | AP24: 208.42418
A25: 236072834 | B25: ACRB1MS106BL | C25: Мяч с шипами голубой 6 см | D25: 2040278804649 | E25: 235 | F25: 59 | G25: 13865 | H25: 587.5 | I25: 0 | J25: 0.4 | K25: 1 | L25: 0 | M25: 1 | N25: 595 | O25: 420 | P25: 0 | Q25: 595 | R25: 420 | S25: 0.0036454319 | T25: 59 | U25: 167.30016 | V25: 0.28117675 | W25: 381.1 | X25: 231.28 | Z25: 29.4 | AA25: -273.08016 | AB25: -0.0054123736 | AC25: 235 | AD25: 7 | AE25: 38 | AF25: -0.45895826 | AG25: -4.6284774 | AI25: 595 | AJ25: 59 | AK25: 167.30016 | AL25: 381.1 | AM25: 231.28 | AN25: 0 | AO25: 29.4 | AP25: -273.08016
A26: 223671295 | B26: ACRB1MS106RJ | C26: Мяч с шипами оранжевый 6 см | D26: 2039818580389 | E26: 453 | F26: 59 | G26: 26727 | H26: 1132.5 | I26: 0 | J26: 0.4 | K26: 0 | L26: 0 | M26: 0 | N26: 0 | O26: 0 | P26: 0 | Q26: 0 | R26: 0 | S26: 0 | T26: 0 | U26: -22.443443 | V26: 0 | W26: 106.62 | X26: 443.94 | Z26: 0 | AA26: -528.11656 | AB26: -0.010467125 | AC26: 453 | AD26: 10 | AE26: 30 | AF26: 0 | AG26: 0 | AI26: 0 | AJ26: 59 | AK26: 0 | AL26: 106.62 | AM26: 443.94 | AN26: 0 | AP26: 0
A27: 370591238 | B27: ACRB1MS106BС | C27: Мяч с шипами черный 6 см | D27: 2043369663040 | E27: 196 | F27: 49 | G27: 9604 | H27: 122.5 | I27: 71 | J27: 1.6 | K27: 6 | L27: 0 | M27: 6 | N27: 3068 | O27: 2125 | P27: 0 | Q27: 3068 | R27: 2125 | S27: 0.01879695 | T27: 294 | U27: 911.64426 | V27: 0.29714611 | W27: 648.08 | X27: 197.96 | Z27: 148.75 | AA27: 867.56574 | AB27: 0.017194914 | AC27: 196 | AD27: 20 | AE27: 38 | AF27: 0.28277892 | AG27: 2.9509039 | AI27: 511.33333 | AJ27: 49 | AK27: 151.94071 | AL27: 108.01333 | AM27: 32.993333 | AN27: 0 | AO27: 24.791667 | AP27: 144.59429
A28: 419145391 | B28: ACRB1MS107WH | C28: Мяч с шипами белый 7 см | D28: 2044025326637 | E28: 5 | F28: 62 | G28: 310 | H28: 4.5454545 | I28: 80 | J28: 1.1 | K28: 5 | L28: 0 | M28: 5 | N28: 3524.06 | O28: 2504 | P28: 0 | Q28: 3524.06 | R28: 2504 | S28: 0.021591127 | T28: 310 | U28: 1086.0475 | V28: 0.30818077 | W28: 433.01 | X28: 9.8 | Z28: 175.28 | AA28: 1509.9225 | AB28: 0.029926247 | AC28: 5 | AD28: 17 | AE28: 24 | AF28: 0.42846105 | AG28: 4.8707176 | AI28: 704.812 | AJ28: 62 | AK28: 217.20951 | AL28: 86.602 | AM28: 1.96 | AN28: 0 | AO28: 35.056 | AP28: 301.98449
A29: 419145389 | B29: ACRB1MS107PN | C29: Мяч с шипами розовый 7 см | D29: 2044025316447 | E29: 62 | F29: 63 | G29: 3906 | H29: 999 | I29: 0 | J29: 0 | K29: 0 | L29: 0 | M29: 0 | N29: 0 | O29: 0 | P29: 0 | Q29: 0 | R29: 0 | S29: 0 | T29: 0 | U29: 0 | V29: 0 | W29: 0 | X29: 60.76 | Z29: 0 | AA29: -60.76 | AB29: -0.0012042465 | AC29: 62 | AD29: 5 | AE29: 0 | AF29: 0 | AG29: 0 | AI29: 0 | AJ29: 63 | AK29: 0 | AL29: 0 | AM29: 60.76 | AN29: 0 | AP29: 0
A30: 419145748 | B30: ACRB1MS107BL | C30: Мяч с шипами голубой 7 см | D30: 2044025338661 | E30: 80 | F30: 63 | G30: 5040 | H30: 999 | I30: 0 | J30: 0 | K30: 0 | L30: 0 | M30: 0 | N30: 0 | O30: 0 | P30: 0 | Q30: 0 | R30: 0 | S30: 0 | T30: 0 | U30: 0 | V30: 0 | W30: 0 | X30: 78.4 | Z30: 0 | AA30: -78.4 | AB30: -0.0015538664 | AC30: 80 | AD30: 0 | AE30: 0 | AF30: 0 | AG30: 0 | AI30: 0 | AJ30: 63 | AK30: 0 | AL30: 0 | AM30: 78.4 | AN30: 0 | AP30: 0
A31: 419141548 | B31: ACRB1MS107RJ | C31: Мяч с шипами оранжевый 7 см | D31: 2044025288003 | E31: 77 | F31: 63 | G31: 4851 | H31: 999 | I31: 0 | J31: 0 | K31: 0 | L31: 0 | M31: 0 | N31: 0 | O31: 0 | P31: 0 | Q31: 0 | R31: 0 | S31: 0 | T31: 0 | U31: 0 | V31: 0 | W31: 0 | X31: 75.46 | Z31: 0 | AA31: -75.46 | AB31: -0.0014955964 | AC31: 77 | AD31: 8 | AE31: 0 | AF31: 0 | AG31: 0 | AI31: 0 | AJ31: 63 | AK31: 0 | AL31: 0 | AM31: 75.46 | AN31: 0 | AP31: 0
A32: 419145985 | B32: ACRB1MS107BС | C32: Мяч с шипами черный 7 см | D32: 2044025344532 | E32: 73 | F32: 63 | G32: 4599 | H32: 730 | I32: 0 | J32: 0.1 | K32: 0 | L32: 0 | M32: 0 | N32: 0 | O32: 0 | P32: 0 | Q32: 0 | R32: 0 | S32: 0 | T32: 0 | U32: -7.5831148 | V32: 0 | W32: 0 | X32: 71.54 | Z32: 0 | AA32: -63.956885 | AB32: -0.0012676078 | AC32: 73 | AD32: 4 | AE32: 100 | AF32: 0 | AG32: 0 | AI32: 0 | AJ32: 63 | AK32: 0 | AL32: 0 | AM32: 71.54 | AN32: 0 | AP32: 0
A33: 419145390 | B33: ACRB1MS109PN | C33: Мяч с шипами розовый 9 см | D33: 2044025321588 | E33: 67 | F33: 91 | G33: 6097 | H33: 670 | I33: 0 | J33: 0.1 | K33: 0 | L33: 0 | M33: 0 | N33: 0 | O33: 0 | P33: 0 | Q33: 0 | R33: 0 | S33: 0 | T33: 0 | U33: -3.4232787 | V33: 0 | W33: 94.55 | X33: 65.66 | Z33: 0 | AA33: -156.78672 | AB33: -0.0031074696 | AC33: 67 | AD33: 9 | AE33: 25 | AF33: 0 | AG33: 0 | AI33: 0 | AJ33: 91 | AK33: 0 | AL33: 94.55 | AM33: 65.66 | AN33: 0 | AP33: 0
A34: 419145749 | B34: ACRB1MS109BL | C34: Мяч с шипами голубой 9 см | D34: 2044025342057 | E34: 80 | F34: 91 | G34: 7280 | H34: 999 | I34: 0 | J34: 0 | K34: 0 | L34: 0 | M34: 0 | N34: 0 | O34: 0 | P34: 0 | Q34: 0 | R34: 0 | S34: 0 | T34: 0 | U34: 0 | V34: 0 | W34: 0 | X34: 78.4 | Z34: 0 | AA34: -78.4 | AB34: -0.0015538664 | AC34: 80 | AD34: 0 | AE34: 0 | AF34: 0 | AG34: 0 | AI34: 0 | AJ34: 91 | AK34: 0 | AL34: 0 | AM34: 78.4 | AN34: 0 | AP34: 0
A35: 419141549 | B35: ACRB1MS109RJ | C35: Мяч с шипами оранжевый 9 см | D35: 2044025291485 | E35: 62 | F35: 91 | G35: 5642 | H35: 155 | I35: 67 | J35: 0.4 | K35: 3 | L35: 0 | M35: 3 | N35: 1490 | O35: 1050 | P35: 0 | Q35: 1490 | R35: 1050 | S35: 0.0091288968 | T35: 273 | U35: 459.79902 | V35: 0.30858994 | W35: 166.31 | X35: 63.7 | Z35: 73.5 | AA35: 453.69098 | AB35: 0.0089920302 | AC35: 62 | AD35: 31 | AE35: 30 | AF35: 0.30449059 | AG35: 1.6618717 | AI35: 496.66667 | AJ35: 91 | AK35: 153.26634 | AL35: 55.436667 | AM35: 21.233333 | AN35: 0 | AO35: 24.5 | AP35: 151.23033
A36: 419145986 | B36: ACRB1MS109BС | C36: Мяч с шипами черный 9 см | D36: 2044025347953 | E36: 98 | F36: 91 | G36: 8918 | H36: 999 | I36: 0 | J36: 0 | K36: 0 | L36: 0 | M36: 0 | N36: 0 | O36: 0 | P36: 0 | Q36: 0 | R36: 0 | S36: 0 | T36: 0 | U36: 0 | V36: 0 | W36: 0 | X36: 96.04 | Z36: 0 | AA36: -96.04 | AB36: -0.0019034863 | AC36: 98 | AD36: 7 | AE36: 0 | AF36: 0 | AG36: 0 | AI36: 0 | AJ36: 91 | AK36: 0 | AL36: 0 | AM36: 96.04 | AN36: 0 | AP36: 0
A37: 419146579 | B37: ACRB1MS109LI | C37: Мяч с шипами фиолетовый 9 см | D37: 2044025354937 | E37: 112 | F37: 91 | G37: 10192 | H37: 1120 | I37: 100 | J37: 0.1 | K37: 0 | L37: 0 | M37: 0 | N37: 0 | O37: 0 | P37: 0 | Q37: 0 | R37: 0 | S37: 0 | T37: 0 | U37: -4.2108197 | V37: 0 | W37: 0 | X37: 109.76 | Z37: 0 | AA37: -105.54918 | AB37: -0.0020919557 | AC37: 112 | AD37: 20 | AE37: 14 | AF37: 0 | AG37: 0 | AI37: 0 | AJ37: 91 | AK37: 0 | AL37: 0 | AM37: 109.76 | AN37: 0 | AP37: 0
A38: 340734340 | B38: ACRB1MS103PN | C38: Мяч гладкий розовый | D38: 2042985583893 | E38: 31 | F38: 87 | G38: 2697 | H38: 28.181818 | I38: 100 | J38: 1.1 | K38: 2 | L38: 0 | M38: 2 | N38: 768.67 | O38: 530 | P38: 0 | Q38: 768.67 | R38: 530 | S38: 0.0047094692 | T38: 174 | U38: 219.5923 | V38: 0.28567824 | W38: 167.7 | X38: 32.34 | Z38: 37.1 | AA38: 137.9377 | AB38: 0.0027338873 | AC38: 31 | AD38: 24 | AE38: 57 | AF38: 0.17944984 | AG38: 0.79274543 | AI38: 384.335 | AJ38: 87 | AK38: 109.79615 | AL38: 83.85 | AM38: 16.17 | AN38: 0 | AO38: 18.55 | AP38: 68.968852
A39: 340741532 | B39: ACRB1MS103BL | C39: Мяч гладкий голубой | D39: 2042986356632 | E39: 82 | F39: 87 | G39: 7134 | H39: 999 | I39: 0 | J39: 0 | K39: 0 | L39: 0 | M39: 0 | N39: 0 | O39: 0 | P39: 0 | Q39: 0 | R39: 0 | S39: 0 | T39: 0 | U39: 0 | V39: 0 | W39: 0 | X39: 80.36 | Z39: 0 | AA39: -80.36 | AB39: -0.0015927131 | AC39: 82 | AD39: 0 | AE39: 0 | AF39: 0 | AG39: 0 | AI39: 0 | AJ39: 87 | AK39: 0 | AL39: 0 | AM39: 80.36 | AN39: 0 | AP39: 0
A40: 340743352 | B40: ACRB1MS103LI | C40: Мяч гладкий сиреневый | D40: 2042986372359 | E40: 55 | F40: 87 | G40: 4785 | H40: 137.5 | I40: 100 | J40: 0.4 | K40: 0 | L40: 0 | M40: 0 | N40: 0 | O40: 0 | P40: 0 | Q40: 0 | R40: 0 | S40: 0 | T40: 0 | U40: -17.916721 | V40: 0 | W40: 0 | X40: 53.9 | Z40: 0 | AA40: -35.983279 | AB40: -0.00071317867 | AC40: 55 | AD40: 22 | AE40: 30 | AF40: 0 | AG40: 0 | AI40: 0 | AJ40: 87 | AK40: 0 | AL40: 0 | AM40: 53.9 | AN40: 0 | AP40: 0
...

Sheet 3
C1: Обязательно написать номер недели | D1: 3 | AI1: на 1 единицу проданного товара
A2: Арт. ВБ | B2: Артикул поставщика | C2: Название | D2: ШК | E2: Остаток на начало недели, шт | F2: Себестоимость на 1 ед | G2: Себестоимость остатков | H2: Оборачиваемость, дн | I2: % выкупа за 30 дн с уч возврата | J2: Скорость продаж | K2: Кол-во ПРОДАЖИ | L2: Кол-во ВОЗВРАТЫ | M2: Кол-во ПРОДАЖИ-ВОЗВРАТЫ | N2: Выручка ПРОДАЖИ по Цене в карточке | O2: Выручка ПРОДАЖИ по Цене ВБ реализовал | P2: Выручка ВОЗВРАТЫ | Q2: Выручка ПРОДАЖИ (цена в карточке)- ВОЗВРАТЫ | R2: Выручка ПРОДАЖИ (ВБ реализовал)- ВОЗВРАТЫ | S2: Доля выручки, % от общего объема | T2: Себестоимость продаж | U2: Комиссия, руб | V2: Комиссия, % | W2: Логистика | X2: Хранение | Y2: Реклама | Z2: Налог 7% | AA2: Прибыль | AB2: Доля прибыли, % от общего объема | AC2: Остаток на конец недели, шт | AD2: Конверсия в корзину, % | AE2: Конверсия в заказ, % | AF2: Маржинальность, % | AG2: Рентабельность, % | AI2: Выручка на 1 ед (средняя цена продажи со скидкой) | AJ2: Себестоимость на 1 ед | AK2: Комиссия на 1 ед | AL2: Логистика на 1 ед | AM2: Хранение на 1 ед. | AN2: Реклама на 1 ед | AO2: Налог на 1 ед | AP2: Прибыль на 1 ед
A3: 1 | B3: 2 | C3: 3 | D3: 4 | E3: 5 | F3: 6 | G3: 7 | H3: 8 | I3: 9 | J3: 10 | K3: 11 | L3: 12 | M3: 13 | N3: 14 | O3: 15 | P3: 16 | Q3: 17 | R3: 18 | S3: 19 | T3: 20 | U3: 21 | V3: 22 | W3: 23 | X3: 24 | Y3: 25 | Z3: 26 | AA3: 27 | AB3: 19 | AC3: 28 | AD3: 30 | AE3: 31 | AF3: 32 | AG3: 33 | AH3: 34 | AI3: 35 | AJ3: 36 | AK3: 37 | AL3: 38 | AM3: 39 | AN3: 40 | AO3: 41 | AP3: 42
A4: 169112569 | B4: ACRF1BN101PN | C4: Бандаж для лица розовый | D4: 2038161736993 | E4: 154 | F4: 111 | G4: 17094 | H4: 1560 | I4: 0 | J4: 0.1 | K4: 1 | L4: 0 | M4: 1 | N4: 604 | O4: 435 | P4: 0 | Q4: 604 | R4: 435 | S4: 0.0027650774 | T4: 111 | U4: 181.98328 | V4: 0.30129682 | W4: 254.42 | X4: 153.86 | Z4: 30.45 | AA4: -127.71328 | AB4: -0.0017621929 | AC4: 156 | AD4: 10 | AE4: 14 | AF4: -0.21144583 | AG4: -1.1505701 | AI4: 604 | AJ4: 111 | AK4: 181.98328 | AL4: 254.42 | AM4: 153.86 | AN4: 0 | AO4: 30.45 | AP4: -127.71328
A5: 169153168 | B5: ACRF1BN101BC | C5: Бандаж для лица черный | D5: 2038162681926 | E5: 227 | F5: 90 | G5: 20430 | H5: 222.72727 | I5: 100 | J5: 1.1 | K5: 2 | L5: 0 | M5: 2 | N5: 1187.86 | O5: 1003.52 | P5: 0 | Q5: 1187.86 | R5: 1003.52 | S5: 0.0054379551 | T5: 180 | U5: 370.94754 | V5: 0.31228221 | W5: 197.99 | X5: 242.06 | Z5: 70.2464 | AA5: 126.61606 | AB5: 0.0017470535 | AC5: 245 | AD5: 17 | AE5: 35 | AF5: 0.10659174 | AG5: 0.70342255 | AI5: 593.93 | AJ5: 90 | AK5: 185.47377 | AL5: 98.995 | AM5: 121.03 | AN5: 0 | AO5: 35.1232 | AP5: 63.30803
A6: 169395410 | B6: ACRF1BN201GR | C6: Бандаж для лица серый | D6: 2038172050200 | E6: 207 | F6: 206 | G6: 42642 | H6: 341.42857 | I6: 100 | J6: 0.7 | K6: 6 | L6: 0 | M6: 6 | N6: 5651 | O6: 3807 | P6: 0 | Q6: 5651 | R6: 3807 | S6: 0.025869954 | T6: 1236 | U6: 1819.742 | V6: 0.32202123 | W6: 295.51 | X6: 240.1 | Z6: 266.49 | AA6: 1793.158 | AB6: 0.024742066 | AC6: 239 | AD6: 14 | AE6: 23 | AF6: 0.31731694 | AG6: 1.4507751 | AI6: 941.83333 | AJ6: 206 | AK6: 303.29033 | AL6: 49.251667 | AM6: 40.016667 | AN6: 0 | AO6: 44.415 | AP6: 298.85967
A7: 172832355 | B7: AHMA7BW101BG | C7: Мешки 7 шт. | D7: 2038337652454 | E7: 134 | F7: 375 | G7: 50250 | H7: 1640 | I7: 100 | J7: 0.1 | K7: 1 | L7: 0 | M7: 1 | N7: 1652 | O7: 996 | P7: 0 | Q7: 1652 | R7: 996 | S7: 0.0075627614 | T7: 375 | U7: 407.02393 | V7: 0.24638253 | W7: 373.66 | X7: 611.226 | Z7: 69.72 | AA7: -184.62993 | AB7: -0.0025475312 | AC7: 164 | AD7: 8 | AE7: 11 | AF7: -0.11176146 | AG7: -0.49234649 | AI7: 1652 | AJ7: 375 | AK7: 407.02393 | AL7: 373.66 | AM7: 611.226 | AN7: 0 | AO7: 69.72 | AP7: -184.62993
A8: 176500218 | B8: AHMA1BW101BG | C8: Мешок для бюстгалтеров | D8: 2038597850744 | E8: 338 | F8: 71 | G8: 23998 | H8: 658.33333 | I8: 100 | J8: 0.6 | K8: 8 | L8: 0 | M8: 8 | N8: 3642.74 | O8: 2261.7 | P8: 0 | Q8: 3642.74 | R8: 2261.7 | S8: 0.016676255 | T8: 568 | U8: 1042.2416 | V8: 0.28611475 | W8: 462.49 | X8: 394.94 | Z8: 158.319 | AA8: 1016.7494 | AB8: 0.014029148 | AC8: 395 | AD8: 10 | AE8: 40 | AF8: 0.27911664 | AG8: 1.7900517 | AI8: 455.3425 | AJ8: 71 | AK8: 130.2802 | AL8: 57.81125 | AM8: 49.3675 | AN8: 0 | AO8: 19.789875 | AP8: 127.09367
A9: 177404837 | B9: AHMA3BW101BG | C9: Мешки 3 шт. | D9: 2038627692689 | E9: 124 | F9: 166 | G9: 20584 | H9: 556.66667 | I9: 100 | J9: 0.3 | K9: 1 | L9: 0 | M9: 1 | N9: 993 | O9: 580 | P9: 0 | Q9: 993 | R9: 580 | S9: 0.0045458971 | T9: 166 | U9: 272.49443 | V9: 0.27441533 | W9: 106.12 | X9: 411.6 | Z9: 40.6 | AA9: -3.8144262 | AB9: -5.2631606e-05 | AC9: 167 | AD9: 4 | AE9: 67 | AF9: -0.0038413154 | AG9: -0.022978471 | AI9: 993 | AJ9: 166 | AK9: 272.49443 | AL9: 106.12 | AM9: 411.6 | AN9: 0 | AO9: 40.6 | AP9: -3.8144262
A10: 177405495 | B10: AHMA3BW102BG | C10: Мешки/деликат 3 шт. | D10: 2038627713902 | E10: 208 | F10: 156 | G10: 32448 | H10: 625 | I10: 100 | J10: 0.4 | K10: 2 | L10: 0 | M10: 2 | N10: 1777.88 | O10: 1002 | P10: 0 | Q10: 1777.88 | R10: 1002 | S10: 0.0081390329 | T10: 312 | U10: 508.18705 | V10: 0.28583878 | W10: 215.44 | X10: 419.832 | Z10: 70.14 | AA10: 252.28095 | AB10: 0.0034809827 | AC10: 250 | AD10: 6 | AE10: 43 | AF10: 0.14189988 | AG10: 0.80859279 | AI10: 888.94 | AJ10: 156 | AK10: 254.09352 | AL10: 107.72 | AM10: 209.916 | AN10: 0 | AO10: 35.07 | AP10: 126.14048
A11: 176721350 | B11: AHMA3BW201WH | C11: Мешки/шнурок мелк 3 шт. | D11: 2038606201642 | E11: 259 | F11: 145 | G11: 37555 | H11: 437.14286 | I11: 100 | J11: 0.7 | K11: 9 | L11: 0 | M11: 9 | N11: 6584.14 | O11: 4180.91 | P11: 0 | Q11: 6584.14 | R11: 4180.91 | S11: 0.030141816 | T11: 1305 | U11: 1840.5113 | V11: 0.27953709 | W11: 621.76 | X11: 308.7 | Z11: 292.6637 | AA11: 2215.505 | AB11: 0.030569627 | AC11: 306 | AD11: 7 | AE11: 38 | AF11: 0.33649117 | AG11: 1.697705 | AI11: 731.57111 | AJ11: 145 | AK11: 204.50126 | AL11: 69.084444 | AM11: 34.3 | AN11: 0 | AO11: 32.518189 | AP11: 246.16722
A12: 176723275 | B12: AHMA3BW202WH | C12: Мешки/шнурок крупн 3 шт. | D12: 2038606256161 | E12: 125 | F12: 145 | G12: 18125 | H12: 59.615385 | I12: 100 | J12: 2.6 | K12: 20 | L12: 0 | M12: 20 | N12: 16357.12 | O12: 10040 | P12: 0 | Q12: 16357.12 | R12: 10040 | S12: 0.074881959 | T12: 2900 | U12: 4486.7172 | V12: 0.27429751 | W12: 1081.74 | X12: 171.5 | Z12: 702.8 | AA12: 7014.3628 | AB12: 0.096784459 | AC12: 155 | AD12: 11 | AE12: 47 | AF12: 0.42882627 | AG12: 2.4187458 | AI12: 817.856 | AJ12: 145 | AK12: 224.33586 | AL12: 54.087 | AM12: 8.575 | AN12: 0 | AO12: 35.14 | AP12: 350.71814
A13: 204615141 | B13: AHMA2BW201WH | C13: Мешки 2 шт. серый | D13: 2039404446068 | E13: 197 | F13: 92 | G13: 18124 | H13: 853.33333 | I13: 0 | J13: 0.3 | K13: 1 | L13: 0 | M13: 1 | N13: 600 | O13: 358 | P13: 0 | Q13: 600 | R13: 358 | S13: 0.0027467656 | T13: 92 | U13: 143.20705 | V13: 0.23867842 | W13: 162.45 | X13: 251.86 | Z13: 25.06 | AA13: -74.577049 | AB13: -0.0010290171 | AC13: 256 | AD13: 13 | AE13: 33 | AF13: -0.12429508 | AG13: -0.8106201 | AI13: 600 | AJ13: 92 | AK13: 143.20705 | AL13: 162.45 | AM13: 251.86 | AN13: 0 | AO13: 25.06 | AP13: -74.577049
A14: 236074677 | B14: AHMA2BW202WH | C14: Мешки 2 шт. розовый | D14: 2040278862540 | E14: 50 | F14: 149 | G14: 7450 | H14: 163.33333 | I14: 100 | J14: 0.3 | K14: 1 | L14: 0 | M14: 1 | N14: 519 | O14: 295 | P14: 0 | Q14: 519 | R14: 295 | S14: 0.0023759523 | T14: 149 | U14: 114.97377 | V14: 0.22152942 | W14: 50.68 | X14: 49 | Z14: 20.65 | AA14: 134.69623 | AB14: 0.001858544 | AC14: 49 | AD14: 29 | AE14: 18 | AF14: 0.25953031 | AG14: 0.90400154 | AI14: 519 | AJ14: 149 | AK14: 114.97377 | AL14: 50.68 | AM14: 49 | AN14: 0 | AO14: 20.65 | AP14: 134.69623
A15: 236929187 | B15: AHMA1BW112WH | C15: Мешок 60*80 крупн | D15: 2040335626849 | E15: 136 | F15: 93 | G15: 12648 | H15: 73.043478 | I15: 92 | J15: 2.3 | K15: 16 | L15: 0 | M15: 16 | N15: 10247.48 | O15: 6280 | P15: 0 | Q15: 10247.48 | R15: 6280 | S15: 0.046912377 | T15: 1488 | U15: 2877.7649 | V15: 0.2808266 | W15: 881.56 | X15: 180.32 | Z15: 439.6 | AA15: 4380.2351 | AB15: 0.060438659 | AC15: 168 | AD15: 12 | AE15: 43 | AF15: 0.4274451 | AG15: 2.9437064 | AI15: 640.4675 | AJ15: 93 | AK15: 179.86031 | AL15: 55.0975 | AM15: 11.27 | AN15: 0 | AO15: 27.475 | AP15: 273.76469
... A20: 223420736 | B20: ACRB1MS101RJ | C20: Массажер для тела оранжевый | D20: 2039813223373 | E20: 33 | F20: 151 | G20: 4983 | H20: 48.571429 | I20: 100 | J20: 0.7 | K20: 7 | L20: 0 | M20: 7 | N20: 4325.43 | O20: 2890 | P20: 0 | Q20: 4325.43 | R20: 2890 | S20: 0.019801571 | T20: 1057 | U20: 1285.1595 | V20: 0.29711717 | W20: 362.73 | X20: 40.18 | Z20: 202.3 | AA20: 1378.0605 | AB20: 0.019014534 | AC20: 34 | AD20: 12 | AE20: 14 | AF20: 0.31859503 | AG20: 1.3037469 | AI20: 617.91857 | AJ20: 151 | AK20: 183.59422 | AL20: 51.818571 | AM20: 5.74 | AN20: 0 | AO20: 28.9 | AP20: 196.86578
A21: 275208801 | B21: ACRB1MS101PN | C21: Массажер для тела розовый | D21: 2041591042329 | E21: 75 | F21: 151 | G21: 11325 | H21: 250 | I21: 100 | J21: 0.3 | K21: 0 | L21: 0 | M21: 0 | N21: 0 | O21: 0 | P21: 0 | Q21: 0 | R21: 0 | S21: 0 | T21: 0 | U21: -5.2696721 | V21: 0 | W21: 0 | X21: 73.5 | Z21: 0 | AA21: -68.230328 | AB21: -0.0009414448 | AC21: 75 | AD21: 4 | AE21: 67 | AF21: 0 | AG21: 0 | AI21: 0 | AJ21: 151 | AK21: 0 | AL21: 0 | AM21: 73.5 | AN21: 0 | AP21: 0
A22: 275208802 | B22: ACRB1MS101BL | C22: Массажер для тела голубой | D22: 2041591055954 | E22: 28 | F22: 151 | G22: 4228 | H22: 90 | I22: 100 | J22: 0.3 | K22: 2 | L22: 0 | M22: 2 | N22: 1420 | O22: 964 | P22: 0 | Q22: 1420 | R22: 964 | S22: 0.0065006787 | T22: 302 | U22: 424.13262 | V22: 0.29868495 | W22: 126.72 | X22: 28.42 | Z22: 67.48 | AA22: 471.24738 | AB22: 0.0065022902 | AC22: 27 | AD22: 11 | AE22: 15 | AF22: 0.33186435 | AG22: 1.5604218 | AI22: 710 | AJ22: 151 | AK22: 212.06631 | AL22: 63.36 | AM22: 14.21 | AN22: 0 | AO22: 33.74 | AP22: 235.62369
A23: 236072835 | B23: ACRB1MS106WH | C23: Мяч с шипами белый 6 см | D23: 2040278804496 | E23: 379 | F23: 59 | G23: 22361 | H23: 236.5 | I23: 80 | J23: 2 | K23: 13 | L23: 0 | M23: 13 | N23: 9053.06 | O23: 6078 | P23: 0 | Q23: 9053.06 | R23: 6078 | S23: 0.04144439 | T23: 767 | U23: 2645.1401 | V23: 0.29218188 | W23: 821.73 | X23: 476.28 | Z23: 425.46 | AA23: 3917.4499 | AB23: 0.054053131 | AC23: 473 | AD23: 17 | AE23: 35 | AF23: 0.43272108 | AG23: 5.1074966 | AI23: 696.38923 | AJ23: 59 | AK23: 203.47231 | AL23: 63.21 | AM23: 36.636923 | AN23: 0 | AO23: 32.727692 | AP23: 301.3423
A24: 236072836 | B24: ACRB1MS106PN | C24: Мяч с шипами розовый 6 см | D24: 2040278810534 | E24: 303 | F24: 64 | G24: 19392 | H24: 127.3913 | I24: 82 | J24: 2.3 | K24: 13 | L24: 0 | M24: 13 | N24: 7205 | O24: 4931 | P24: 0 | Q24: 7205 | R24: 4931 | S24: 0.032984078 | T24: 832 | U24: 2066.1718 | V24: 0.28676916 | W24: 809.33 | X24: 299.88 | Z24: 345.17 | AA24: 2852.4482 | AB24: 0.039358194 | AC24: 293 | AD24: 22 | AE24: 33 | AF24: 0.39589843 | AG24: 3.4284233 | AI24: 554.23077 | AJ24: 64 | AK24: 158.93629 | AL24: 62.256154 | AM24: 23.067692 | AN24: 0 | AO24: 26.551538 | AP24: 219.41909
A25: 236072834 | B25: ACRB1MS106BL | C25: Мяч с шипами голубой 6 см | D25: 2040278804649 | E25: 235 | F25: 59 | G25: 13865 | H25: 281.11111 | I25: 100 | J25: 0.9 | K25: 3 | L25: 0 | M25: 3 | N25: 1645 | O25: 1159 | P25: 0 | Q25: 1645 | R25: 1159 | S25: 0.0075307158 | T25: 177 | U25: 466.94705 | V25: 0.28385839 | W25: 132.06 | X25: 250.88 | Z25: 81.13 | AA25: 536.98295 | AB25: 0.0074093122 | AC25: 253 | AD25: 13 | AE25: 55 | AF25: 0.3264334 | AG25: 3.033802 | AI25: 548.33333 | AJ25: 59 | AK25: 155.64902 | AL25: 44.02 | AM25: 83.626667 | AN25: 0 | AO25: 27.043333 | AP25: 178.99432
A26: 223671295 | B26: ACRB1MS106RJ | C26: Мяч с шипами оранжевый 6 см | D26: 2039818580389 | E26: 453 | F26: 59 | G26: 26727 | H26: 1660 | I26: 100 | J26: 0.3 | K26: 1 | L26: 0 | M26: 1 | N26: 525 | O26: 365 | P26: 0 | Q26: 525 | R26: 365 | S26: 0.0024034199 | T26: 59 | U26: 156.95049 | V26: 0.29895332 | W26: 142.66 | X26: 489.02 | Z26: 25.55 | AA26: -348.18049 | AB26: -0.0048042084 | AC26: 498 | AD26: 2 | AE26: 200 | AF26: -0.66320094 | AG26: -5.9013643 | AI26: 525 | AJ26: 59 | AK26: 156.95049 | AL26: 142.66 | AM26: 489.02 | AN26: 0 | AO26: 25.55 | AP26: -348.18049
A27: 370591238 | B27: ACRB1MS106BС | C27: Мяч с шипами черный 6 см | D27: 2043369663040 | E27: 196 | F27: 49 | G27: 9604 | H27: 104.5 | I27: 63 | J27: 2 | K27: 9 | L27: 0 | M27: 9 | N27: 4466 | O27: 3015 | P27: 0 | Q27: 4466 | R27: 3015 | S27: 0.020445092 | T27: 441 | U27: 1335.6044 | V27: 0.29906055 | W27: 909.08 | X27: 213.64 | Z27: 211.05 | AA27: 1355.6256 | AB27: 0.018704976 | AC27: 209 | AD27: 20 | AE27: 50 | AF27: 0.30354357 | AG27: 3.0739809 | AI27: 496.22222 | AJ27: 49 | AK27: 148.40049 | AL27: 101.00889 | AM27: 23.737778 | AN27: 0 | AO27: 23.45 | AP27: 150.62506
A28: 419145391 | B28: ACRB1MS107WH | C28: Мяч с шипами белый 7 см | D28: 2044025326637 | E28: 5 | F28: 62 | G28: 310 | H28: 2.6315789 | I28: 83 | J28: 1.9 | K28: 7 | L28: 0 | M28: 7 | N28: 4925 | O28: 3243 | P28: 0 | Q28: 4925 | R28: 3243 | S28: 0.022546368 | T28: 434 | U28: 1436.9616 | V28: 0.29176886 | W28: 656.7 | X28: 11.76 | Z28: 227.01 | AA28: 2158.5684 | AB28: 0.029784013 | AC28: 5 | AD28: 13 | AE28: 38 | AF28: 0.43828799 | AG28: 4.9736598 | AI28: 703.57143 | AJ28: 62 | AK28: 205.28023 | AL28: 93.814286 | AM28: 1.68 | AN28: 0 | AO28: 32.43 | AP28: 308.36691
A29: 419145389 | B29: ACRB1MS107PN | C29: Мяч с шипами розовый 7 см | D29: 2044025316447 | E29: 62 | F29: 63 | G29: 3906 | H29: 203.33333 | I29: 100 | J29: 0.3 | K29: 1 | L29: 0 | M29: 1 | N29: 615 | O29: 418 | P29: 0 | Q29: 615 | R29: 418 | S29: 0.0028154348 | T29: 63 | U29: 185.58393 | V29: 0.3017625 | W29: 64.59 | X29: 60.76 | Z29: 29.26 | AA29: 211.80607 | AB29: 0.0029225086 | AC29: 61 | AD29: 23 | AE29: 22 | AF29: 0.34440011 | AG29: 3.362001 | AI29: 615 | AJ29: 63 | AK29: 185.58393 | AL29: 64.59 | AM29: 60.76 | AN29: 0 | AO29: 29.26 | AP29: 211.80607
A30: 419145748 | B30: ACRB1MS107BL | C30: Мяч с шипами голубой 7 см | D30: 2044025338661 | E30: 80 | F30: 63 | G30: 5040 | H30: 790 | I30: 100 | J30: 0.1 | K30: 1 | L30: 0 | M30: 1 | N30: 525 | O30: 361 | P30: 0 | Q30: 525 | R30: 361 | S30: 0.0024034199 | T30: 63 | U30: 160.63869 | V30: 0.30597845 | W30: 55.98 | X30: 78.4 | Z30: 25.27 | AA30: 141.71131 | AB30: 0.0019553383 | AC30: 79 | AD30: 17 | AE30: 20 | AF30: 0.26992631 | AG30: 2.2493859 | AI30: 525 | AJ30: 63 | AK30: 160.63869 | AL30: 55.98 | AM30: 78.4 | AN30: 0 | AO30: 25.27 | AP30: 141.71131
A31: 419141548 | B31: ACRB1MS107RJ | C31: Мяч с шипами оранжевый 7 см | D31: 2044025288003 | E31: 77 | F31: 63 | G31: 4851 | H31: 250 | I31: 0 | J31: 0.3 | K31: 0 | L31: 0 | M31: 0 | N31: 0 | O31: 0 | P31: 0 | Q31: 0 | R31: 0 | S31: 0 | T31: 0 | U31: -8.4134426 | V31: 0 | W31: 0 | X31: 73.5 | Z31: 0 | AA31: -65.086557 | AB31: -0.00089806692 | AC31: 75 | AD31: 3 | AE31: 200 | AF31: 0 | AG31: 0 | AI31: 0 | AJ31: 63 | AK31: 0 | AL31: 0 | AM31: 73.5 | AN31: 0 | AP31: 0
A32: 419145985 | B32: ACRB1MS107BС | C32: Мяч с шипами черный 7 см | D32: 2044025344532 | E32: 73 | F32: 63 | G32: 4599 | H32: 999 | I32: 0 | J32: 0 | K32: 0 | L32: 0 | M32: 0 | N32: 0 | O32: 0 | P32: 0 | Q32: 0 | R32: 0 | S32: 0 | T32: 0 | U32: 0 | V32: 0 | W32: 95.93 | X32: 71.54 | Z32: 0 | AA32: -167.47 | AB32: -0.0023107578 | AC32: 73 | AD32: 3 | AE32: 0 | AF32: 0 | AG32: 0 | AI32: 0 | AJ32: 63 | AK32: 0 | AL32: 95.93 | AM32: 71.54 | AN32: 0 | AP32: 0
A33: 419145390 | B33: ACRB1MS109PN | C33: Мяч с шипами розовый 9 см | D33: 2044025321588 | E33: 67 | F33: 91 | G33: 6097 | H33: 200 | I33: 100 | J33: 0.4 | K33: 3 | L33: 0 | M33: 3 | N33: 1585 | O33: 1068 | P33: 0 | Q33: 1585 | R33: 1068 | S33: 0.0072560393 | T33: 273 | U33: 461.47525 | V33: 0.29115157 | W33: 277.19 | X33: 81.34 | Z33: 74.76 | AA33: 417.23475 | AB33: 0.0057570218 | AC33: 80 | AD33: 24 | AE33: 27 | AF33: 0.26323959 | AG33: 1.5283324 | AI33: 528.33333 | AJ33: 91 | AK33: 153.82508 | AL33: 92.396667 | AM33: 27.113333 | AN33: 0 | AO33: 24.92 | AP33: 139.07825
A34: 419145749 | B34: ACRB1MS109BL | C34: Мяч с шипами голубой 9 см | D34: 2044025342057 | E34: 80 | F34: 91 | G34: 7280 | H34: 900 | I34: 100 | J34: 0.1 | K34: 2 | L34: 0 | M34: 2 | N34: 1109 | O34: 768 | P34: 0 | Q34: 1109 | R34: 768 | S34: 0.0050769385 | T34: 182 | U34: 331.57115 | V34: 0.2989821 | W34: 87.61 | X34: 90.16 | Z34: 53.76 | AA34: 363.89885 | AB34: 0.0050210909 | AC34: 90 | AD34: 0 | AE34: 0 | AF34: 0.32813242 | AG34: 1.9994442 | AI34: 554.5 | AJ34: 91 | AK34: 165.78557 | AL34: 43.805 | AM34: 45.08 | AN34: 0 | AO34: 26.88 | AP34: 181.94943
A35: 419141549 | B35: ACRB1MS109RJ | C35: Мяч с шипами оранжевый 9 см | D35: 2044025291485 | E35: 62 | F35: 91 | G35: 5642 | H35: 999 | I35: 0 | J35: 0 | K35: 1 | L35: 0 | M35: 1 | N35: 482 | O35: 336 | P35: 0 | Q35: 482 | R35: 336 | S35: 0.0022065684 | T35: 91 | U35: 147.49148 | V35: 0.30599891 | W35: 167.31 | X35: 69.58 | Z35: 23.52 | AA35: -16.901475 | AB35: -0.00023320723 | AC35: 70 | AD35: 10 | AE35: 0 | AF35: -0.035065302 | AG35: -0.1857305 | AI35: 482 | AJ35: 91 | AK35: 147.49148 | AL35: 167.31 | AM35: 69.58 | AN35: 0 | AO35: 23.52 | AP35: -16.901475
A36: 419145986 | B36: ACRB1MS109BС | C36: Мяч с шипами черный 9 см | D36: 2044025347953 | E36: 98 | F36: 91 | G36: 8918 | H36: 999 | I36: 0 | J36: 0 | K36: 0 | L36: 0 | M36: 0 | N36: 0 | O36: 0 | P36: 0 | Q36: 0 | R36: 0 | S36: 0 | T36: 0 | U36: 0 | V36: 0 | W36: 0 | X36: 105.84 | Z36: 0 | AA36: -105.84 | AB36: -0.0014603846 | AC36: 108 | AD36: 5 | AE36: 0 | AF36: 0 | AG36: 0 | AI36: 0 | AJ36: 91 | AK36: 0 | AL36: 0 | AM36: 105.84 | AN36: 0 | AP36: 0
