Workbook
Name _12_18__15_3__утолщенный_шелк_7_100шт: #REF!
Name _14_20__17_3___утолщенный_шелк_7_100шт: #REF!
Name _169112569_2038161736993_ACRF1BN101PN_Маска_бандаж_для_лица_розовая: #REF!
Name _169153168_2038162681926_ACRF1BN101BC_Маска_бандаж_для_лица_черная: #REF!
Name _169395410_2038172050200_ACRF1BN201GR_Маска_бандаж_для_лица_серая: #REF!
Name _170899505_2038224716238_AHMA6BW101BG_Набор_мешков_для_стирки_6_шт.: #REF!
Name _172832355_2038337652454_AHMA7BW101BG_Набор_мешков_для_стирки_7_шт.: #REF!
Name _173605843_2038430289250_ACRH1MS101RJ_Массажер_для_пальцев_суставов: #REF!
Name _176170511_2038586639107_ACRF1SK101WH_Скребок_Гуаша_белый_короб: #REF!
Name _176500218_2038597850744_AHMA1BW101BG_Мешок_для_стирки_бюстгалтеров: #REF!
Name _176709293_2038605982115_ACRF2RS201NF_Комплект_Гуаша_роллер_и_скребок_бол_нефрит_прем: #REF!
Name _176721350_2038606201642_AHMA3BW201WH_Комплект_мешков_сетка_мелкая_на_шнурке_3_шт.: #REF!
Name _176723275_2038606256161_AHMA3BW202WH_Комплект_мешков_сетка_крупная_на_шнурке_3_шт.: #REF!
Name _177404837_2038627692689_AHMA3BW101BG_Комплект_мешков_для_стирки_3_шт.: #REF!
Name _177405495_2038627713902_AHMA3BW102BG_Комплект_мешков_для_деликатной_стирки_3_шт.: #REF!
Name _18_27__23_4___утолщенный_шелк_7_100шт: #REF!
Name _186800214_2038890789598_ACRA7TB101BC_Таблетница_круглая_7_2: #REF!
Name _186826338_2038891723249_ACRA7TB201BC_Таблетница_прямоугольная_7_2_черная: #REF!
Name _188194883_2038931439581_AHMA3BW211WH_Комплект_мешков_сетка_мелкая_на_шнурке_3_шт._с_шаром: #REF!
Name _199452263_2039291528267_AHMA3BW212WH_Комплект_мешков_сетка_крупная_на_шнурке_3_шт._с_шаром: #REF!
Name _20_30__26_4___утолщенный_шелк_7_100шт: #REF!
Name _20_34__30_4___утолщенный_шелк_7_100шт: #REF!
Name _200946531_2039323172727_AHMA3BW221WH_Комплект_мешков_сетка_крупная_на_шнурке_3_шт._с_цилиндром: #REF!
Name _200953158_2039323305576_ACRA7TB301BC_Таблетница_прямоугольная_7_3: #REF!
Name _204260887_2039399347548_AHMA3BW222WH_Комплект_мешков_мелкая_сетка_на_шнурке_3_шт._с_цилиндром: #REF!
Name _204615141_2039404446068_AHMA2BW201WH_Комплект_мешков_2_шт._серый: #REF!
Name _205841460_2039422231875_ACRF1SK202NF_Скребок_Гуаша_нефрит: #REF!
Name _22_34__30_4___утолщенный_шелк_7_100шт: #REF!
Name _220252787_2039735724354_ACRL1MS101RJ_Массажер_для_ног: #REF!
Name _223420736_2039813223373_ACRB1MS101RJ_Массажер_для_тела: #REF!
Name _223671295_2039818580389_ACRB1MS102RJ_Массажер_мяч_оранжевый: #REF!
Name _236072834_2040278804649_ACRB1MS102BL_Массажер_мяч_голубой: #REF!
Name _236072835_2040278804496_ACRB1MS102WH_Массажер_мяч_белый: #REF!
Name _236072836_2040278810534_ACRB1MS102PN_Массажер_мяч_розовый: #REF!
Name _236074677_2040278862540_AHMA2BW202WH_Комплект_мешков_2_шт._розовый: #REF!
Name _236929187_2040335626849_AHMA1BW112WH_Мешок_большой_крупная_сетка_60_80: #REF!
Name _236929188_2040335648124_AHMA1BW111WH_Мешок_большой_мелкая_сетка_60_80: #REF!
Name _239233529_2040478696884_AHMA1BW302WH_Мешок_для_стирки_обуви_XL___35_см: #REF!
Name _239235150_2040478720961_AHMA1BW301WH_Мешок_для_стирки_обуви_L___30_см: #REF!
Name _24_34__30_4___утолщенный_шелк_7_100шт: #REF!
Name _248267432_2040797652776_AAND1ST201BL_Палочка_для_жевания: #REF!
Name _251407392_2040900511679_AAND1BL102BL_Мяч_шина_синий: #REF!
Name _251516159_2040902555480_AAND1BL102RD_Мяч_шина_красный: #REF!
Name _251537223_2040903539366_AAND1BL101RD_Мяч_регби_красный: #REF!
Name _251537413_2040903547941_AAND1BL101BL_Мяч_регби_синий: #REF!
Name _253681275_2040957863936_ACRA7TB401CL_Таблетница_прямоугольная_7_2_цветная: #REF!
Name A1016__мелкое_отверстие_30_40: #REF!
Name A1016__толстое_отверстие_30_40: #REF!
Name A1016__толстое_отверстие_40_50: #REF!
Name A1016__толстое_отверстие_60_80: #REF!
Name A1016__тонкое_отверстие_40_50: #REF!
Name A1016__тонкое_отверстие_50_60: #REF!
Name A1016__тонкое_отверстие_60_80: #REF!
Name A1016_толстое_отверстие_50_60: #REF!
Name Бандаж_лайкра_розовый: #REF!
Name Бандаж_лайкра_черный: #REF!
Name Бандаж_силикон_серый: #REF!
Name Бежевые_трусики_20_20: #REF!
Name Бежевый_Бюстгальтер_Раковина_18_16: #REF!
Name Белый__скребок_Гуаша_в_коробке: #REF!

Sheet Юнит
F1: Себестоимость до ВБ | G1: % себестоимости от цены продажи | H1: Себестоимость Карго | I1: Инд обработка | J1: Доставка | K1: Параметры для логистики | L1: Параметры с упаковкой для расчета логистики | S1: Цена продажи на ВБ | T1: Цена на ВБ | V1: Расходы ВБ | W1: % Расходов ВБ в выручке | X1: доставка, руб | Y1: возврат, руб | Z1: Логистика, руб | AB1: хранение, руб | AC1: Стоимость услуг ВБ за одну проданную единицу | AD1: % расходов на услуги (от цены продажи) | AE1: Комиссия ВБ | AG1: Кэшбэк | AH1: Скидка Клуба | AI1: Себестоимость товара на ВБ | AJ1: Маржинальность | AK1: ФИНАНСЫ | AN1: ЖЕЛАЕМАЯ ЦЕНА | AO1: ФИНАНСЫ | AR1: ЖЕЛАЕМАЯ МАРЖА | AS1: Участие в акиции | AT1: Цена акции | AU1: Маржа акции | AV1: ФИНАНСЫ | AY1: Остатки | AZ1: Оборачиваемость | BA1: Себестоимость Карго х на … | BC1: Цена продажи на OZON | BD1: Цена на OZON | BF1: Расходы OZON | BG1: % Расходов OZON в выроучке | BH1: Ссылка на справочник | BL1: Справочник FBO | BM1: По среднее время доставки | BQ1: Ссылка на справочник | BR1: Про обработку возврата | BS1: Пояснение к расчёту логистики с учётом выкупа | BV1: Себестоимость товара на ОЗОН | BW1: Маржинальность | BX1: ФИНАНСЫ | CA1: Желаемая цена | CB1: ФИНАНСЫ | CE1: Желаемая маржа | CF1: Участие в акиции | CG1: Цена акции | CH1: Маржа акции | CI1: ФИНАНСЫ | CL1: Остатки | CM1: Оборачиваемость | CN1: Себестоимость Карго х на … | CO1: Мин. Цены | CP1: Платное размещение, шт.
T2: Цена в карточке | U2: Скидка | BD2: Цена в карточке | BE2: Скидка | BH2: Комиссия OZON | BJ2: Эквайринг | BK2: хранение | BL2: Логистика доставки | BR2: Выкуп | BS2: ЛОГИСТИКА ИТОГО | BT2: % Логистики в выручке | BU2: Мои акции
A3: Код WB | B3: Код OZON | C3: Арт. Поставщика | D3: Номенклатура | E3: Штрихкод | J3: 8 | K3: Обьем, л | L3: Длина | M3: Ширина | N3: Высота | O3: Вес | P3: Упаковка | Q3: Сколько в короб ВБ | T3: руб. | U3: 0.3 | Z3: руб | AA3: % | AC3: руб. | AD3: % | AE3: % | AF3: руб | AH3: 0.03 | AK3: Прибыль | AL3: Чистая прибыль | AM3: Рентабельность вложенных инвестиций | AO3: Прибыль | AP3: Чистая прибыль | AQ3: Рентабельность вложенных инвестиций | AV3: Прибыль | AW3: Чистая прибыль | AX3: Рентабельность вложенных инвестиций | BD3: руб. | BE3: ='[1]Рассчет акции'!$J$4 -> Скидка | BH3: % | BI3: руб. | BJ3: 0.02 | BL3: 1 | BM3: часы | BN3: 35 | BO3: % | BP3: 25 | BQ3: итого | BR3: 0.85 | BS3: ИТОГО | BT3: % | BX3: Прибыль | BY3: Чистая прибыль | BZ3: Рентабельность вложенных инвестиций | CB3: Прибыль | CC3: Чистая прибыль | CD3: Рентабельность вложенных инвестиций | CI3: Прибыль | CJ3: Чистая прибыль | CK3: Рентабельность вложенных инвестиций
A4: 1 | B4: 2 | C4: 3 | D4: 4 | E4: 5 | F4: 6 | G4: 7 | H4: 8 | I4: 9 | J4: 10 | K4: 11 | L4: 12 | M4: 13 | N4: 14 | O4: 15 | P4: 16 | Q4: 17 | R4: 18 | S4: 19 | T4: 20 | U4: 21 | V4: 22 | W4: 23 | X4: 24 | Y4: 28 | AB4: 25 | AC4: 29 | AD4: 30 | AE4: 31 | AF4: 32 | AG4: 33 | AH4: 34 | AI4: 35 | AJ4: 36 | AK4: 37 | AL4: 38 | AM4: 39 | AN4: 40 | AO4: 41 | AP4: 42 | AQ4: 43 | AR4: 44 | AS4: 45 | AT4: 46 | AU4: 47 | AV4: 48 | AW4: 49 | AX4: 50 | AY4: 51 | AZ4: 52 | BA4: 53 | BB4: 54 | BC4: 55 | BD4: 56 | BE4: 57 | BF4: 58 | BG4: 59 | BH4: 60 | BI4: 61 | BJ4: 62 | BL4: 63 | BM4: 64 | BN4: 65 | BO4: 66 | BP4: 67 | BQ4: 68 | BR4: 69 | BS4: 70 | BT4: 71 | BU4: 72 | BV4: 73 | BW4: 74 | BX4: 75 | BY4: 76 | BZ4: 77 | CA4: 78 | CB4: 79 | CC4: 80 | CD4: 81 | CE4: 82 | CF4: 83 | CG4: 84 | CH4: 85 | CI4: 86 | CJ4: 87 | CK4: 88 | CL4: 89 | CM4: 90 | CN4: 91 | CO4: 92 | CP4: 93
A5: 169112569 | C5: ACRF1BN101PN | D5: Бандаж для лица розовый | E5: 2038161736993 | F5: =SUM(H5:J5) -> 126 | G5: =IFERROR(F5/S5*100%,0) -> 0.1689461 | H5: =IF(_xlfn.XLOOKUP($C5,'Юнит Карго'!$A:$A,'Юнит Карго'!$G:$G)=0,_xlfn.XLOOKUP(E5,'Себес 1С текущ'!G:G,'Себес 1С текущ'!H:H,0),_xlfn.XLOOKUP($C5,'Юнит Карго'!$A:$A,'Юнит Карго'!$P:$P,0,0)) -> 104 | I5: 14 | J5: =$J$3 -> 8 | K5: =(L5*M5*N5)/1000 -> 0.336 | L5: 14 | M5: 12 | N5: 2 | O5: =_xlfn.XLOOKUP($C5,'Юнит Карго'!$A:$A,'Юнит Карго'!$T:$T,0,0) -> 0.04 | P5: своя | S5: =T5-(T5*U5) -> 745.8 | T5: =_xlfn.XLOOKUP(E5,'[2]Рассчет акции'!$D:$D,'[2]Рассчет акции'!$G:$G,0) -> 1243 | U5: =_xlfn.XLOOKUP(E5,'[2]Рассчет акции'!$D:$D,'[2]Рассчет акции'!$F:$F,0) -> 0.4 | V5: =AC5+AF5+AH5+AG5 -> 402.41624 | W5: =IFERROR(V5/S5,0) -> 0.53957662 | X5: =IF(K5>1,('Тарифы ВБ'!$B$9+(K5-1)*'Тарифы ВБ'!$B$10)*'Тарифы ВБ'!$B$15*'Тарифы ВБ'!$B$12+S5*'Тарифы ВБ'!$B$13,'Тарифы ВБ'!$B$8*'Тарифы ВБ'!$B$15*'Тарифы ВБ'!$B$12+S5*'Тарифы ВБ'!$B$13) -> 73.65724 | Y5: =IF(K5>1,'Тарифы ВБ'!$B$9+(K5-1)*'Тарифы ВБ'!$B$10,'Тарифы ВБ'!$B$8) -> 32 | Z5: =SUM(X5:Y5) -> 105.65724 | AA5: =IFERROR(Z5/S5,0) -> 0.14166967 | AB5: =IF(K5>1,'Тарифы ВБ'!$B$14*'Тарифы ВБ'!$B$16*'Тарифы ВБ'!$B$15+(K5-1)*'Тарифы ВБ'!$B$14,'Тарифы ВБ'!$B$14*'Тарифы ВБ'!B$16*'Тарифы ВБ'!$B$15) -> 32 | AC5: =+X5+AB5+Y5 -> 137.65724 | AD5: =AC5/S5*100% -> 0.18457662 | AE5: 0.325 | AF5: =S5*AE5 -> 242.385 | AG5: =1.1*S5*$AG$3 -> 0 | AH5: =S5*$AH$3 -> 22.374 | AI5: =F5+V5 -> 528.41624 | AJ5: =IFERROR(AL5/S5,0) -> 0.22147729 | AK5: =S5-AI5 -> 217.38376 | AL5: =AK5-S5*7% -> 165.17776 | AM5: =AL5/H5 -> 1.5882477 | AN5: 829 | AO5: =$AN5-$AI5 -> 300.58376 | AP5: =$AO5-$AN5*7% -> 242.55376 | AQ5: =$AP5/$H5*100% -> 2.3322477 | AR5: =$AP5/$AN5 -> 0.29258596 | AS5: =IFERROR(_xlfn.XLOOKUP(A5,'[2]Рассчет акции'!$A:$A,'[2]Рассчет акции'!$BH:$BH),0) -> * | AT5: =IFERROR(_xlfn.XLOOKUP($A5,'[2]Рассчет акции'!$A:$A,'[2]Рассчет акции'!$BC:$BC),0) -> 746 | AU5: =IFERROR($AW5/$AT5,0) -> 0.22166724 | AV5: =$AT5-$AI5 -> 217.58376 | AW5: =$AV5-$AT5*7% -> 165.36376 | AX5: =$AW5/$H5*100% -> 1.5900362 | AY5: =IFERROR(_xlfn.XLOOKUP(E5,'[2]Рассчет акции'!$D:$D,'[2]Рассчет акции'!$BM:$BM),0) -> 128 | AZ5: =IFERROR(_xlfn.XLOOKUP(E5,'[2]Рассчет акции'!$D:$D,'[2]Рассчет акции'!$BN:$BN),0) -> 984 | BA5: =S5/H5 -> 7.1711538 | BC5: =_xlfn.XLOOKUP(B5,#REF!,#REF!,0) -> #REF! | BD5: =BC5/(100%-BE5) -> #REF! | BE5: =_xlfn.XLOOKUP($B5,'[1]Рассчет акции'!$A:$A,'[1]Рассчет акции'!$J:$J) -> 0 | BF5: =BS5+BI5+BJ5+BU5+BK5 -> #REF! | BG5: =IFERROR(BF5/BC5,0) -> 0 | BH5: 0.39 | BI5: =BC5*BH5 -> #REF! | BJ5: =BC5*$BJ$3 -> #REF! | BK5: =K5*$BK$3*30 -> 0 | BL5: =(IF(K5>$BL$3,('Тарифы ОЗОН'!$G$3+ROUNDUP(K5-$BL$3,0)*'Тарифы ОЗОН'!$G$4),'Тарифы ОЗОН'!$G$3)) -> 46.77 | BM5: =$BN$3 -> 35 | BN5: =_xlfn.XLOOKUP(BM5,'Тарифы ОЗОН'!$A:$A,'Тарифы ОЗОН'!$B:$B) -> 1.32 | BO5: =_xlfn.XLOOKUP(BM5,'Тарифы ОЗОН'!$A:$A,'Тарифы ОЗОН'!C:C) -> 0.016 | BP5: =$BP$3 -> 25 | BQ5: =BL5*BN5+BC5*BO5+BP5 -> #REF! | BR5: =$BR$3 -> 0.85 | BS5: =(100%/BR5)*BQ5+(100%/BR5-1)*BL5 -> #REF! | BT5: =IFERROR(BS5/BC5*100%,0) -> 0 | BU5: =BC5*$BU$3 -> #REF! | BV5: =BF5+F5 -> #REF! | BW5: =IFERROR(BY5/BC5,0) -> 0 | BX5: =IFERROR(BC5-BV5,0) -> 0 | BY5: =BX5-BC5*7% -> #REF! | BZ5: =IFERROR(BY5/H5*100%,0) -> 0 | CA5: 0 | CB5: =IF(BC5=0,0,CA5-BV5) -> #REF! | CC5: =IF(CB5=0,0,CB5-CA5*7%) -> #REF! | CD5: =CC5/H5*100% -> #REF! | CE5: =IFERROR(CC5/CA5,0) -> 0 | CF5: =_xlfn.XLOOKUP(B5,'[1]Рассчет акции'!$A:$A,'[1]Рассчет акции'!$R:$R,0) -> 0 | CG5: =_xlfn.XLOOKUP(B5,'[1]Рассчет акции'!$A:$A,'[1]Рассчет акции'!$M:$M,0) -> 0 | CH5: =IFERROR($CJ5/$CG5,0) -> 0 | CI5: =IF(CG5>0,CG5-BV5,0) -> 0 | CJ5: =IF(CI5>0,$CI5-$CG5*7%,0) -> 0 | CK5: =$CJ5/$H5*100% -> 0 | CL5: =_xlfn.XLOOKUP(B5,'[1]Рассчет акции'!$A:$A,'[1]Рассчет акции'!$W:$W,0) -> 0 | CM5: =_xlfn.XLOOKUP(B5,'[1]Рассчет акции'!$A:$A,'[1]Рассчет акции'!$X:$X,0) -> 0 | CN5: =BC5/H5 -> #REF! | CO5: =CA5-10%*CA5 -> 0 | CP5: =_xlfn.XLOOKUP(B5,'[1]Рассчет акции'!$A:$A,'[1]Рассчет акции'!$Z:$Z,0) -> 0
A6: 169153168 | B6: 2453533282 | C6: ACRF1BN101BC | D6: Бандаж для лица черный | E6: 2038162681926 | F6: =SUM(H6:J6) -> 105.26245 | G6: =IFERROR(F6/S6*100%,0) -> 0.14114032 | H6: =IF(_xlfn.XLOOKUP($C6,'Юнит Карго'!$A:$A,'Юнит Карго'!$G:$G)=0,_xlfn.XLOOKUP(E6,'Себес 1С текущ'!G:G,'Себес 1С текущ'!H:H),_xlfn.XLOOKUP($C6,'Юнит Карго'!$A:$A,'Юнит Карго'!$P:$P,0,0)) -> 83.262451 | I6: =_xlfn.XLOOKUP(E6,[3]ТЗ_ФФ!$D:$D,[3]ТЗ_ФФ!$BG:$BG,0) -> 14 | J6: =$J$3 -> 8 | K6: =(L6*M6*N6)/1000 -> 0.336 | L6: 14 | M6: 12 | N6: 2 | O6: =_xlfn.XLOOKUP($C6,'Юнит Карго'!$A:$A,'Юнит Карго'!$T:$T,0,0) -> 0.04 | P6: своя | S6: =T6-(T6*U6) -> 745.8 | T6: =_xlfn.XLOOKUP(E6,'[2]Рассчет акции'!$D:$D,'[2]Рассчет акции'!$G:$G,0) -> 1243 | U6: =_xlfn.XLOOKUP(E6,'[2]Рассчет акции'!$D:$D,'[2]Рассчет акции'!$F:$F,0) -> 0.4 | V6: =AC6+AF6+AH6+AG6 -> 402.41624 | W6: =IFERROR(V6/S6,0) -> 0.53957662 | X6: =IF(K6>1,('Тарифы ВБ'!$B$9+(K6-1)*'Тарифы ВБ'!$B$10)*'Тарифы ВБ'!$B$15*'Тарифы ВБ'!$B$12+S6*'Тарифы ВБ'!$B$13,'Тарифы ВБ'!$B$8*'Тарифы ВБ'!$B$15*'Тарифы ВБ'!$B$12+S6*'Тарифы ВБ'!$B$13) -> 73.65724 | Y6: =IF(K6>1,'Тарифы ВБ'!$B$9+(K6-1)*'Тарифы ВБ'!$B$10,'Тарифы ВБ'!$B$8) -> 32 | Z6: =SUM(X6:Y6) -> 105.65724 | AA6: =IFERROR(Z6/S6,0) -> 0.14166967 | AB6: =IF(K6>1,'Тарифы ВБ'!$B$14*'Тарифы ВБ'!$B$16*'Тарифы ВБ'!$B$15+(K6-1)*'Тарифы ВБ'!$B$14,'Тарифы ВБ'!$B$14*'Тарифы ВБ'!B$16*'Тарифы ВБ'!$B$15) -> 32 | AC6: =+X6+AB6+Y6 -> 137.65724 | AD6: =AC6/S6*100% -> 0.18457662 | AE6: 0.325 | AF6: =S6*AE6 -> 242.385 | AG6: =1.1*S6*$AG$3 -> 0 | AH6: =S6*$AH$3 -> 22.374 | AI6: =F6+V6 -> 507.67869 | AJ6: =IFERROR(AL6/S6,0) -> 0.24928306 | AK6: =S6-AI6 -> 238.12131 | AL6: =AK6-S6*7% -> 185.91531 | AM6: =AL6/H6 -> 2.232883 | AN6: 829 | AO6: =$AN6-$AI6 -> 321.32131 | AP6: =$AO6-$AN6*7% -> 263.29131 | AQ6: =$AP6/$H6*100% -> 3.1621854 | AR6: =$AP6/$AN6 -> 0.3176011 | AS6: =IFERROR(_xlfn.XLOOKUP(A6,'[2]Рассчет акции'!$A:$A,'[2]Рассчет акции'!$BH:$BH),0) -> * | AT6: =IFERROR(_xlfn.XLOOKUP($A6,'[2]Рассчет акции'!$A:$A,'[2]Рассчет акции'!$BC:$BC),0) -> 746 | AU6: =IFERROR($AW6/$AT6,0) -> 0.24946556 | AV6: =$AT6-$AI6 -> 238.32131 | AW6: =$AV6-$AT6*7% -> 186.10131 | AX6: =$AW6/$H6*100% -> 2.2351169 | AY6: =IFERROR(_xlfn.XLOOKUP(E6,'[2]Рассчет акции'!$D:$D,'[2]Рассчет акции'!$BM:$BM),0) -> 216 | AZ6: =IFERROR(_xlfn.XLOOKUP(E6,'[2]Рассчет акции'!$D:$D,'[2]Рассчет акции'!$BN:$BN),0) -> 999 | BA6: =S6/H6 -> 8.9572189 | BC6: =_xlfn.XLOOKUP(B6,#REF!,#REF!,0) -> #REF! | BD6: =BC6/(100%-BE6) -> #REF! | BE6: =_xlfn.XLOOKUP($B6,'[1]Рассчет акции'!$A:$A,'[1]Рассчет акции'!$J:$J) -> 0.34996841 | BF6: =BS6+BI6+BJ6+BU6+BK6 -> #REF! | BG6: =IFERROR(BF6/BC6,0) -> 0 | BH6: 0.39 | BI6: =BC6*BH6 -> #REF! | BJ6: =BC6*$BJ$3 -> #REF! | BK6: =K6*$BK$3*30 -> 0 | BL6: =(IF(K6>$BL$3,('Тарифы ОЗОН'!$G$3+ROUNDUP(K6-$BL$3,0)*'Тарифы ОЗОН'!$G$4),'Тарифы ОЗОН'!$G$3)) -> 46.77 | BM6: =$BN$3 -> 35 | BN6: =_xlfn.XLOOKUP(BM6,'Тарифы ОЗОН'!$A:$A,'Тарифы ОЗОН'!$B:$B) -> 1.32 | BO6: =_xlfn.XLOOKUP(BM6,'Тарифы ОЗОН'!$A:$A,'Тарифы ОЗОН'!C:C) -> 0.016 | BP6: =$BP$3 -> 25 | BQ6: =BL6*BN6+BC6*BO6+BP6 -> #REF! | BR6: =$BR$3 -> 0.85 | BS6: =(100%/BR6)*BQ6+(100%/BR6-1)*BL6 -> #REF! | BT6: =IFERROR(BS6/BC6*100%,0) -> 0 | BU6: =BC6*$BU$3 -> #REF! | BV6: =BF6+F6 -> #REF! | BW6: =IFERROR(BY6/BC6,0) -> 0 | BX6: =IFERROR(BC6-BV6,0) -> 0 | BY6: =BX6-BC6*7% -> #REF! | BZ6: =IFERROR(BY6/H6*100%,0) -> 0 | CA6: 799 | CB6: =IF(BC6=0,0,CA6-BV6) -> #REF! | CC6: =IF(CB6=0,0,CB6-CA6*7%) -> #REF! | CD6: =CC6/H6*100% -> #REF! | CE6: =IFERROR(CC6/CA6,0) -> 0 | CF6: =_xlfn.XLOOKUP(B6,'[1]Рассчет акции'!$A:$A,'[1]Рассчет акции'!$R:$R,0) -> 0 | CG6: =_xlfn.XLOOKUP(B6,'[1]Рассчет акции'!$A:$A,'[1]Рассчет акции'!$M:$M,0) -> 710 | CH6: =IFERROR($CJ6/$CG6,0) -> 0 | CI6: =IF(BC6>0,CG6-BV6,0) -> #REF! | CJ6: =IF(CI6>0,$CI6-$CG6*7%,0) -> #REF! | CK6: =$CJ6/$H6*100% -> #REF! | CL6: =_xlfn.XLOOKUP(B6,'[1]Рассчет акции'!$A:$A,'[1]Рассчет акции'!$W:$W,0) -> 0 | CM6: =_xlfn.XLOOKUP(B6,'[1]Рассчет акции'!$A:$A,'[1]Рассчет акции'!$X:$X,0) -> 0 | CN6: =BC6/H6 -> #REF! | CO6: =CA6-10%*CA6 -> 719.1 | CP6: =_xlfn.XLOOKUP(B6,'[1]Рассчет акции'!$A:$A,'[1]Рассчет акции'!$Z:$Z,0) -> 0
A7: 169395410 | B7: 2419349210 | C7: ACRF1BN201GR | D7: Бандаж для лица серый | E7: 2038172050200 | F7: =SUM(H7:J7) -> 222.95301 | G7: =IFERROR(F7/S7*100%,0) -> 0.21331134 | H7: =IF(_xlfn.XLOOKUP($C7,'Юнит Карго'!$A:$A,'Юнит Карго'!$G:$G)=0,_xlfn.XLOOKUP(E7,'Себес 1С текущ'!G:G,'Себес 1С текущ'!H:H),_xlfn.XLOOKUP($C7,'Юнит Карго'!$A:$A,'Юнит Карго'!$P:$P,0,0)) -> 200.95301 | I7: =_xlfn.XLOOKUP(E7,[3]ТЗ_ФФ!$D:$D,[3]ТЗ_ФФ!$BG:$BG,0) -> 14 | J7: =$J$3 -> 8 | K7: =(L7*M7*N7)/1000 -> 0.798 | L7: 19 | M7: 14 | N7: 3 | O7: =_xlfn.XLOOKUP($C7,'Юнит Карго'!$A:$A,'Юнит Карго'!$T:$T,0,0) -> 0.09 | P7: своя | S7: =T7-(T7*U7) -> 1045.2 | T7: =_xlfn.XLOOKUP(E7,'[2]Рассчет акции'!$D:$D,'[2]Рассчет акции'!$G:$G,0) -> 1742 | U7: =_xlfn.XLOOKUP(E7,'[2]Рассчет акции'!$D:$D,'[2]Рассчет акции'!$F:$F,0) -> 0.4 | V7: =AC7+AF7+AH7+AG7 -> 511.03856 | W7: =IFERROR(V7/S7,0) -> 0.48893854 | X7: =IF(K7>1,('Тарифы ВБ'!$B$9+(K7-1)*'Тарифы ВБ'!$B$10)*'Тарифы ВБ'!$B$15*'Тарифы ВБ'!$B$12+S7*'Тарифы ВБ'!$B$13,'Тарифы ВБ'!$B$8*'Тарифы ВБ'!$B$15*'Тарифы ВБ'!$B$12+S7*'Тарифы ВБ'!$B$13) -> 75.99256 | Y7: =IF(K7>1,'Тарифы ВБ'!$B$9+(K7-1)*'Тарифы ВБ'!$B$10,'Тарифы ВБ'!$B$8) -> 32 | Z7: =SUM(X7:Y7) -> 107.99256 | AA7: =IFERROR(Z7/S7,0) -> 0.10332239 | AB7: =IF(K7>1,'Тарифы ВБ'!$B$14*'Тарифы ВБ'!$B$16*'Тарифы ВБ'!$B$15+(K7-1)*'Тарифы ВБ'!$B$14,'Тарифы ВБ'!$B$14*'Тарифы ВБ'!B$16*'Тарифы ВБ'!$B$15) -> 32 | AC7: =+X7+AB7+Y7 -> 139.99256 | AD7: =AC7/S7*100% -> 0.13393854 | AE7: 0.325 | AF7: =S7*AE7 -> 339.69 | AG7: =1.1*S7*$AG$3 -> 0 | AH7: =S7*$AH$3 -> 31.356 | AI7: =F7+V7 -> 733.99157 | AJ7: =IFERROR(AL7/S7,0) -> 0.22775012 | AK7: =S7-AI7 -> 311.20843 | AL7: =AK7-S7*7% -> 238.04443 | AM7: =AL7/H7 -> 1.1845775 | AN7: 1159 | AO7: =$AN7-$AI7 -> 425.00843 | AP7: =$AO7-$AN7*7% -> 343.87843 | AQ7: =$AP7/$H7*100% -> 1.711238 | AR7: =$AP7/$AN7 -> 0.2967027 | AS7: =IFERROR(_xlfn.XLOOKUP(A7,'[2]Рассчет акции'!$A:$A,'[2]Рассчет акции'!$BH:$BH),0) -> * | AT7: =IFERROR(_xlfn.XLOOKUP($A7,'[2]Рассчет акции'!$A:$A,'[2]Рассчет акции'!$BC:$BC),0) -> 1045 | AU7: =IFERROR($AW7/$AT7,0) -> 0.22761572 | AV7: =$AT7-$AI7 -> 311.00843 | AW7: =$AV7-$AT7*7% -> 237.85843 | AX7: =$AW7/$H7*100% -> 1.1836519 | AY7: =IFERROR(_xlfn.XLOOKUP(E7,'[2]Рассчет акции'!$D:$D,'[2]Рассчет акции'!$BM:$BM),0) -> 202 | AZ7: =IFERROR(_xlfn.XLOOKUP(E7,'[2]Рассчет акции'!$D:$D,'[2]Рассчет акции'!$BN:$BN),0) -> 999 | BA7: =S7/H7 -> 5.2012158 | BC7: =_xlfn.XLOOKUP(B7,#REF!,#REF!,0) -> #REF! | BD7: =BC7/(100%-BE7) -> #REF! | BE7: =_xlfn.XLOOKUP($B7,'[1]Рассчет акции'!$A:$A,'[1]Рассчет акции'!$J:$J) -> 0.3498749 | BF7: =BS7+BI7+BJ7+BU7+BK7 -> #REF! | BG7: =IFERROR(BF7/BC7,0) -> 0 | BH7: 0.39 | BI7: =BC7*BH7 -> #REF! | BJ7: =BC7*$BJ$3 -> #REF! | BK7: =K7*$BK$3*30 -> 0 | BL7: =(IF(K7>$BL$3,('Тарифы ОЗОН'!$G$3+ROUNDUP(K7-$BL$3,0)*'Тарифы ОЗОН'!$G$4),'Тарифы ОЗОН'!$G$3)) -> 46.77 | BM7: =$BN$3 -> 35 | BN7: =_xlfn.XLOOKUP(BM7,'Тарифы ОЗОН'!$A:$A,'Тарифы ОЗОН'!$B:$B) -> 1.32 | BO7: =_xlfn.XLOOKUP(BM7,'Тарифы ОЗОН'!$A:$A,'Тарифы ОЗОН'!C:C) -> 0.016 | BP7: =$BP$3 -> 25 | BQ7: =BL7*BN7+BC7*BO7+BP7 -> #REF! | BR7: =$BR$3 -> 0.85 | BS7: =(100%/BR7)*BQ7+(100%/BR7-1)*BL7 -> #REF! | BT7: =IFERROR(BS7/BC7*100%,0) -> 0 | BU7: =BC7*$BU$3 -> #REF! | BV7: =BF7+F7 -> #REF! | BW7: =IFERROR(BY7/BC7,0) -> 0 | BX7: =IFERROR(BC7-BV7,0) -> 0 | BY7: =BX7-BC7*7% -> #REF! | BZ7: =IFERROR(BY7/H7*100%,0) -> 0 | CA7: 1299 | CB7: =IF(BC7=0,0,CA7-BV7) -> #REF! | CC7: =IF(CB7=0,0,CB7-CA7*7%) -> #REF! | CD7: =CC7/H7*100% -> #REF! | CE7: =IFERROR(CC7/CA7,0) -> 0 | CF7: =_xlfn.XLOOKUP(B7,'[1]Рассчет акции'!$A:$A,'[1]Рассчет акции'!$R:$R,0) -> 0 | CG7: =_xlfn.XLOOKUP(B7,'[1]Рассчет акции'!$A:$A,'[1]Рассчет акции'!$M:$M,0) -> 1115 | CH7: =IFERROR($CJ7/$CG7,0) -> 0 | CI7: =IF(BC7>0,CG7-BV7,0) -> #REF! | CJ7: =IF(CI7>0,$CI7-$CG7*7%,0) -> #REF! | CK7: =$CJ7/$H7*100% -> #REF! | CL7: =_xlfn.XLOOKUP(B7,'[1]Рассчет акции'!$A:$A,'[1]Рассчет акции'!$W:$W,0) -> 0 | CM7: =_xlfn.XLOOKUP(B7,'[1]Рассчет акции'!$A:$A,'[1]Рассчет акции'!$X:$X,0) -> 0 | CN7: =BC7/H7 -> #REF! | CO7: =CA7-10%*CA7 -> 1169.1 | CP7: =_xlfn.XLOOKUP(B7,'[1]Рассчет акции'!$A:$A,'[1]Рассчет акции'!$Z:$Z,0) -> 0
A8: 172832355 | B8: 2419349460 | C8: AHMA7BW101BG | D8: Мешки 7 шт. | E8: 2038337652454 | F8: =SUM(H8:J8) -> 390.77055 | G8: =IFERROR(F8/S8*100%,0) -> 0.18634742 | H8: =IF(_xlfn.XLOOKUP($C8,'Юнит Карго'!$A:$A,'Юнит Карго'!$G:$G)=0,_xlfn.XLOOKUP(E8,'Себес 1С текущ'!G:G,'Себес 1С текущ'!H:H),_xlfn.XLOOKUP($C8,'Юнит Карго'!$A:$A,'Юнит Карго'!$P:$P,0,0)) -> 368.77055 | I8: =_xlfn.XLOOKUP(E8,[3]ТЗ_ФФ!$D:$D,[3]ТЗ_ФФ!$BG:$BG,0) -> 14 | J8: =$J$3 -> 8 | K8: =(L8*M8*N8)/1000 -> 3.78 | L8: 30 | M8: 21 | N8: 6 | O8: =_xlfn.XLOOKUP($C8,'Юнит Карго'!$A:$A,'Юнит Карго'!$T:$T,0,0) -> 0.315 | P8: своя | Q8: 20 | S8: =T8-(T8*U8) -> 2097 | T8: =_xlfn.XLOOKUP(E8,'[2]Рассчет акции'!$D:$D,'[2]Рассчет акции'!$G:$G,0) -> 3495 | U8: =_xlfn.XLOOKUP(E8,'[2]Рассчет акции'!$D:$D,'[2]Рассчет акции'!$F:$F,0) -> 0.4 | V8: =AC8+AF8+AH8+AG8 -> 995.0544 | W8: =IFERROR(V8/S8,0) -> 0.4745133 | X8: =IF(K8>1,('Тарифы ВБ'!$B$9+(K8-1)*'Тарифы ВБ'!$B$10)*'Тарифы ВБ'!$B$15*'Тарифы ВБ'!$B$12+S8*'Тарифы ВБ'!$B$13,'Тарифы ВБ'!$B$8*'Тарифы ВБ'!$B$15*'Тарифы ВБ'!$B$12+S8*'Тарифы ВБ'!$B$13) -> 196.387 | Y8: =IF(K8>1,'Тарифы ВБ'!$B$9+(K8-1)*'Тарифы ВБ'!$B$10,'Тарифы ВБ'!$B$8) -> 84.92 | Z8: =SUM(X8:Y8) -> 281.307 | AA8: =IFERROR(Z8/S8,0) -> 0.13414735 | AB8: =IF(K8>1,'Тарифы ВБ'!$B$14*'Тарифы ВБ'!$B$16*'Тарифы ВБ'!$B$15+(K8-1)*'Тарифы ВБ'!$B$14,'Тарифы ВБ'!$B$14*'Тарифы ВБ'!B$16*'Тарифы ВБ'!$B$15) -> 32.2224 | AC8: =+X8+AB8+Y8 -> 313.5294 | AD8: =AC8/S8*100% -> 0.1495133 | AE8: 0.295 | AF8: =S8*AE8 -> 618.615 | AG8: =1.1*S8*$AG$3 -> 0 | AH8: =S8*$AH$3 -> 62.91 | AI8: =F8+V8 -> 1385.8249 | AJ8: =IFERROR(AL8/S8,0) -> 0.26913927 | AK8: =S8-AI8 -> 711.17505 | AL8: =AK8-S8*7% -> 564.38505 | AM8: =AL8/H8 -> 1.5304504 | AN8: 2119 | AO8: =$AN8-$AI8 -> 733.17505 | AP8: =$AO8-$AN8*7% -> 584.84505 | AQ8: =$AP8/$H8*100% -> 1.5859321 | AR8: =$AP8/$AN8 -> 0.2760005 | AS8: =IFERROR(_xlfn.XLOOKUP(A8,'[2]Рассчет акции'!$A:$A,'[2]Рассчет акции'!$BH:$BH),0) -> * | AT8: =IFERROR(_xlfn.XLOOKUP($A8,'[2]Рассчет акции'!$A:$A,'[2]Рассчет акции'!$BC:$BC),0) -> 2097 | AU8: =IFERROR($AW8/$AT8,0) -> 0.26913927 | AV8: =$AT8-$AI8 -> 711.17505 | AW8: =$AV8-$AT8*7% -> 564.38505 | AX8: =$AW8/$H8*100% -> 1.5304504 | AY8: =IFERROR(_xlfn.XLOOKUP(E8,'[2]Рассчет акции'!$D:$D,'[2]Рассчет акции'!$BM:$BM),0) -> 139 | AZ8: =IFERROR(_xlfn.XLOOKUP(E8,'[2]Рассчет акции'!$D:$D,'[2]Рассчет акции'!$BN:$BN),0) -> 269 | BA8: =S8/H8 -> 5.6864628 | BC8: =_xlfn.XLOOKUP(B8,#REF!,#REF!,0) -> #REF! | BD8: =BC8/(100%-BE8) -> #REF! | BE8: =_xlfn.XLOOKUP($B8,'[1]Рассчет акции'!$A:$A,'[1]Рассчет акции'!$J:$J) -> 0.34997678 | BF8: =BS8+BI8+BJ8+BU8+BK8 -> #REF! | BG8: =IFERROR(BF8/BC8,0) -> 0 | BH8: 0.4 | BI8: =BC8*BH8 -> #REF! | BJ8: =BC8*$BJ$3 -> #REF! | BK8: =K8*$BK$3*30 -> 0 | BL8: =(IF(K8>$BL$3,('Тарифы ОЗОН'!$G$3+ROUNDUP(K8-$BL$3,0)*'Тарифы ОЗОН'!$G$4+5),'Тарифы ОЗОН'!$G$3)) -> 82.28 | BM8: =$BN$3 -> 35 | BN8: =_xlfn.XLOOKUP(BM8,'Тарифы ОЗОН'!$A:$A,'Тарифы ОЗОН'!$B:$B) -> 1.32 | BO8: =_xlfn.XLOOKUP(BM8,'Тарифы ОЗОН'!$A:$A,'Тарифы ОЗОН'!C:C) -> 0.016 | BP8: =$BP$3 -> 25 | BQ8: =BL8*BN8+BC8*BO8+BP8 -> #REF! | BR8: =$BR$3 -> 0.85 | BS8: =(100%/BR8)*BQ8+(100%/BR8-1)*BL8 -> #REF! | BT8: =IFERROR(BS8/BC8*100%,0) -> 0 | BU8: =BC8*$BU$3 -> #REF! | BV8: =BF8+F8 -> #REF! | BW8: =IFERROR(BY8/BC8,0) -> 0 | BX8: =IFERROR(BC8-BV8,0) -> 0 | BY8: =BX8-BC8*7% -> #REF! | BZ8: =IFERROR(BY8/H8*100%,0) -> 0 | CA8: 1959 | CB8: =IF(BC8=0,0,CA8-BV8) -> #REF! | CC8: =IF(CB8=0,0,CB8-CA8*7%) -> #REF! | CD8: =CC8/H8*100% -> #REF! | CE8: =IFERROR(CC8/CA8,0) -> 0 | CF8: =_xlfn.XLOOKUP(B8,'[1]Рассчет акции'!$A:$A,'[1]Рассчет акции'!$R:$R,0) -> 0 | CG8: =_xlfn.XLOOKUP(B8,'[1]Рассчет акции'!$A:$A,'[1]Рассчет акции'!$M:$M,0) -> 1719 | CH8: =IFERROR($CJ8/$CG8,0) -> 0 | CI8: =IF(BC8>0,CG8-BV8,0) -> #REF! | CJ8: =IF(CI8>0,$CI8-$CG8*7%,0) -> #REF! | CK8: =$CJ8/$H8*100% -> #REF! | CL8: =_xlfn.XLOOKUP(B8,'[1]Рассчет акции'!$A:$A,'[1]Рассчет акции'!$W:$W,0) -> 5 | CM8: =_xlfn.XLOOKUP(B8,'[1]Рассчет акции'!$A:$A,'[1]Рассчет акции'!$X:$X,0) -> 999 | CN8: =BC8/H8 -> #REF! | CO8: =CA8-10%*CA8 -> 1763.1 | CP8: =_xlfn.XLOOKUP(B8,'[1]Рассчет акции'!$A:$A,'[1]Рассчет акции'!$Z:$Z,0) -> 0
A9: 176500218 | B9: 2138709303 | C9: AHMA1BW101BG | D9: Мешок для бюстгалтеров | E9: 2038597850744 | F9: =SUM(H9:J9) -> 85.788676 | G9: =IFERROR(F9/S9*100%,0) -> 0.15922174 | H9: =IF(_xlfn.XLOOKUP($C9,'Юнит Карго'!$A:$A,'Юнит Карго'!$G:$G)=0,_xlfn.XLOOKUP(E9,'Себес 1С текущ'!G:G,'Себес 1С текущ'!H:H),_xlfn.XLOOKUP($C9,'Юнит Карго'!$A:$A,'Юнит Карго'!$P:$P,0,0)) -> 63.788676 | I9: =_xlfn.XLOOKUP(E9,[3]ТЗ_ФФ!$D:$D,[3]ТЗ_ФФ!$BG:$BG,0) -> 14 | J9: =$J$3 -> 8 | K9: =(L9*M9*N9)/1000 -> 0.918 | L9: 18 | M9: 17 | N9: 3 | O9: =_xlfn.XLOOKUP($C9,'Юнит Карго'!$A:$A,'Юнит Карго'!$T:$T,0,0) -> 0.06 | P9: своя, ОРР 24*34 | Q9: 140 | S9: =T9-(T9*U9) -> 538.8 | T9: =_xlfn.XLOOKUP(E9,'[2]Рассчет акции'!$D:$D,'[2]Рассчет акции'!$G:$G,0) -> 898 | U9: =_xlfn.XLOOKUP(E9,'[2]Рассчет акции'!$D:$D,'[2]Рассчет акции'!$F:$F,0) -> 0.4 | V9: =AC9+AF9+AH9+AG9 -> 311.15264 | W9: =IFERROR(V9/S9,0) -> 0.57749191 | X9: =IF(K9>1,('Тарифы ВБ'!$B$9+(K9-1)*'Тарифы ВБ'!$B$10)*'Тарифы ВБ'!$B$15*'Тарифы ВБ'!$B$12+S9*'Тарифы ВБ'!$B$13,'Тарифы ВБ'!$B$8*'Тарифы ВБ'!$B$15*'Тарифы ВБ'!$B$12+S9*'Тарифы ВБ'!$B$13) -> 72.04264 | Y9: =IF(K9>1,'Тарифы ВБ'!$B$9+(K9-1)*'Тарифы ВБ'!$B$10,'Тарифы ВБ'!$B$8) -> 32 | Z9: =SUM(X9:Y9) -> 104.04264 | AA9: =IFERROR(Z9/S9,0) -> 0.19310067 | AB9: =IF(K9>1,'Тарифы ВБ'!$B$14*'Тарифы ВБ'!$B$16*'Тарифы ВБ'!$B$15+(K9-1)*'Тарифы ВБ'!$B$14,'Тарифы ВБ'!$B$14*'Тарифы ВБ'!B$16*'Тарифы ВБ'!$B$15) -> 32 | AC9: =+X9+AB9+Y9 -> 136.04264 | AD9: =AC9/S9*100% -> 0.25249191 | AE9: 0.295 | AF9: =S9*AE9 -> 158.946 | AG9: =1.1*S9*$AG$3 -> 0 | AH9: =S9*$AH$3 -> 16.164 | AI9: =F9+V9 -> 396.94132 | AJ9: =IFERROR(AL9/S9,0) -> 0.19328635 | AK9: =S9-AI9 -> 141.85868 | AL9: =AK9-S9*7% -> 104.14268 | AM9: =AL9/H9 -> 1.6326202 | AN9: 599 | AO9: =$AN9-$AI9 -> 202.05868 | AP9: =$AO9-$AN9*7% -> 160.12868 | AQ9: =$AP9/$H9*100% -> 2.5102995 | AR9: =$AP9/$AN9 -> 0.26732668 | AS9: =IFERROR(_xlfn.XLOOKUP(A9,'[2]Рассчет акции'!$A:$A,'[2]Рассчет акции'!$BH:$BH),0) -> * | AT9: =IFERROR(_xlfn.XLOOKUP($A9,'[2]Рассчет акции'!$A:$A,'[2]Рассчет акции'!$BC:$BC),0) -> 539 | AU9: =IFERROR($AW9/$AT9,0) -> 0.19355971 | AV9: =$AT9-$AI9 -> 142.05868 | AW9: =$AV9-$AT9*7% -> 104.32868 | AX9: =$AW9/$H9*100% -> 1.6355361 | AY9: =IFERROR(_xlfn.XLOOKUP(E9,'[2]Рассчет акции'!$D:$D,'[2]Рассчет акции'!$BM:$BM),0) -> 320 | AZ9: =IFERROR(_xlfn.XLOOKUP(E9,'[2]Рассчет акции'!$D:$D,'[2]Рассчет акции'!$BN:$BN),0) -> 726 | BA9: =S9/H9 -> 8.4466403 | BC9: =_xlfn.XLOOKUP(B9,#REF!,#REF!,0) -> #REF! | BD9: =BC9/(100%-BE9) -> #REF! | BE9: =_xlfn.XLOOKUP($B9,'[1]Рассчет акции'!$A:$A,'[1]Рассчет акции'!$J:$J) -> 0.35003253 | BF9: =BS9+BI9+BJ9+BU9+BK9 -> #REF! | BG9: =IFERROR(BF9/BC9,0) -> 0 | BH9: 0.4 | BI9: =BC9*BH9 -> #REF! | BJ9: =BC9*$BJ$3 -> #REF! | BK9: =K9*$BK$3*30 -> 0 | BL9: =(IF(K9>$BL$3,('Тарифы ОЗОН'!$G$3+ROUNDUP(K9-$BL$3,0)*'Тарифы ОЗОН'!$G$4),'Тарифы ОЗОН'!$G$3)) -> 46.77 | BM9: =$BN$3 -> 35 | BN9: =_xlfn.XLOOKUP(BM9,'Тарифы ОЗОН'!$A:$A,'Тарифы ОЗОН'!$B:$B) -> 1.32 | BO9: =_xlfn.XLOOKUP(BM9,'Тарифы ОЗОН'!$A:$A,'Тарифы ОЗОН'!C:C) -> 0.016 | BP9: =$BP$3 -> 25 | BQ9: =BL9*BN9+BC9*BO9+BP9 -> #REF! | BR9: =$BR$3 -> 0.85 | BS9: =(100%/BR9)*BQ9+(100%/BR9-1)*BL9 -> #REF! | BT9: =IFERROR(BS9/BC9*100%,0) -> 0 | BU9: =BC9*$BU$3 -> #REF! | BV9: =BF9+F9 -> #REF! | BW9: =IFERROR(BY9/BC9,0) -> 0 | BX9: =IFERROR(BC9-BV9,0) -> 0 | BY9: =BX9-BC9*7% -> #REF! | BZ9: =IFERROR(BY9/H9*100%,0) -> 0 | CA9: 769 | CB9: =IF(BC9=0,0,CA9-BV9) -> #REF! | CC9: =IF(CB9=0,0,CB9-CA9*7%) -> #REF! | CD9: =CC9/H9*100% -> #REF! | CE9: =IFERROR(CC9/CA9,0) -> 0 | CF9: =_xlfn.XLOOKUP(B9,'[1]Рассчет акции'!$A:$A,'[1]Рассчет акции'!$R:$R,0) -> 0 | CG9: =_xlfn.XLOOKUP(B9,'[1]Рассчет акции'!$A:$A,'[1]Рассчет акции'!$M:$M,0) -> 0 | CH9: =IFERROR($CJ9/$CG9,0) -> 0 | CI9: =IF(BC9>0,CG9-BV9,0) -> #REF! | CJ9: =IF(CI9>0,$CI9-$CG9*7%,0) -> #REF! | CK9: =$CJ9/$H9*100% -> #REF! | CL9: =_xlfn.XLOOKUP(B9,'[1]Рассчет акции'!$A:$A,'[1]Рассчет акции'!$W:$W,0) -> 0 | CM9: =_xlfn.XLOOKUP(B9,'[1]Рассчет акции'!$A:$A,'[1]Рассчет акции'!$X:$X,0) -> 0 | CN9: =BC9/H9 -> #REF! | CO9: =CA9-10%*CA9 -> 692.1 | CP9: =_xlfn.XLOOKUP(B9,'[1]Рассчет акции'!$A:$A,'[1]Рассчет акции'!$Z:$Z,0) -> 0
A10: 177404837 | B10: 2419349262 | C10: AHMA3BW101BG | D10: Мешки 3 шт. | E10: 2038627692689 | F10: =SUM(H10:J10) -> 211 | G10: =IFERROR(F10/S10*100%,0) -> 0.16931472 | H10: =IF(_xlfn.XLOOKUP($C10,'Юнит Карго'!$A:$A,'Юнит Карго'!$G:$G)=0,_xlfn.XLOOKUP(E10,'Себес 1С текущ'!G:G,'Себес 1С текущ'!H:H),_xlfn.XLOOKUP($C10,'Юнит Карго'!$A:$A,'Юнит Карго'!$P:$P,0,0)) -> 165 | I10: =_xlfn.XLOOKUP(E10,[3]ТЗ_ФФ!$D:$D,[3]ТЗ_ФФ!$BG:$BG,0) -> 38 | J10: =$J$3 -> 8 | K10: =(L10*M10*N10)/1000 -> 2.5 | L10: 25 | M10: 20 | N10: 5 | O10: =_xlfn.XLOOKUP($C10,'Юнит Карго'!$A:$A,'Юнит Карго'!$T:$T,0,0) -> 0.14 | P10: слайдер 25*30, ОРР 24*34 | Q10: 40 | S10: =T10-(T10*U10) -> 1246.2 | T10: =_xlfn.XLOOKUP(E10,'[2]Рассчет акции'!$D:$D,'[2]Рассчет акции'!$G:$G,0) -> 2077 | U10: =_xlfn.XLOOKUP(E10,'[2]Рассчет акции'!$D:$D,'[2]Рассчет акции'!$F:$F,0) -> 0.4 | V10: =AC10+AF10+AH10+AG10 -> 655.89536 | W10: =IFERROR(V10/S10,0) -> 0.52631629 | X10: =IF(K10>1,('Тарифы ВБ'!$B$9+(K10-1)*'Тарифы ВБ'!$B$10)*'Тарифы ВБ'!$B$15*'Тарифы ВБ'!$B$12+S10*'Тарифы ВБ'!$B$13,'Тарифы ВБ'!$B$8*'Тарифы ВБ'!$B$15*'Тарифы ВБ'!$B$12+S10*'Тарифы ВБ'!$B$13) -> 151.76036 | Y10: =IF(K10>1,'Тарифы ВБ'!$B$9+(K10-1)*'Тарифы ВБ'!$B$10,'Тарифы ВБ'!$B$8) -> 67 | Z10: =SUM(X10:Y10) -> 218.76036 | AA10: =IFERROR(Z10/S10,0) -> 0.17554194 | AB10: =IF(K10>1,'Тарифы ВБ'!$B$14*'Тарифы ВБ'!$B$16*'Тарифы ВБ'!$B$15+(K10-1)*'Тарифы ВБ'!$B$14,'Тарифы ВБ'!$B$14*'Тарифы ВБ'!B$16*'Тарифы ВБ'!$B$15) -> 32.12 | AC10: =+X10+AB10+Y10 -> 250.88036 | AD10: =AC10/S10*100% -> 0.20131629 | AE10: 0.295 | AF10: =S10*AE10 -> 367.629 | AG10: =1.1*S10*$AG$3 -> 0 | AH10: =S10*$AH$3 -> 37.386 | AI10: =F10+V10 -> 866.89536 | AJ10: =IFERROR(AL10/S10,0) -> 0.23436899 | AK10: =S10-AI10 -> 379.30464 | AL10: =AK10-S10*7% -> 292.07064 | AM10: =AL10/H10 -> 1.7701251 | AN10: 1259 | AO10: =$AN10-$AI10 -> 392.10464 | AP10: =$AO10-$AN10*7% -> 303.97464 | AQ10: =$AP10/$H10*100% -> 1.8422705 | AR10: =$AP10/$AN10 -> 0.24144133 | AS10: =IFERROR(_xlfn.XLOOKUP(A10,'[2]Рассчет акции'!$A:$A,'[2]Рассчет акции'!$BH:$BH),0) -> * | AT10: =IFERROR(_xlfn.XLOOKUP($A10,'[2]Рассчет акции'!$A:$A,'[2]Рассчет акции'!$BC:$BC),0) -> 1246 | AU10: =IFERROR($AW10/$AT10,0) -> 0.23425734 | AV10: =$AT10-$AI10 -> 379.10464 | AW10: =$AV10-$AT10*7% -> 291.88464 | AX10: =$AW10/$H10*100% -> 1.7689978 | AY10: =IFERROR(_xlfn.XLOOKUP(E10,'[2]Рассчет акции'!$D:$D,'[2]Рассчет акции'!$BM:$BM),0) -> 146 | AZ10: =IFERROR(_xlfn.XLOOKUP(E10,'[2]Рассчет акции'!$D:$D,'[2]Рассчет акции'!$BN:$BN),0) -> 502 | BA10: =S10/H10 -> 7.5527273 | BC10: =_xlfn.XLOOKUP(B10,#REF!,#REF!,0) -> #REF! | BD10: =BC10/(100%-BE10) -> #REF! | BE10: =_xlfn.XLOOKUP($B10,'[1]Рассчет акции'!$A:$A,'[1]Рассчет акции'!$J:$J) -> 0.35007225 | BF10: =BS10+BI10+BJ10+BU10+BK10 -> #REF! | BG10: =IFERROR(BF10/BC10,0) -> 0 | BH10: 0.4 | BI10: =BC10*BH10 -> #REF! | BJ10: =BC10*$BJ$3 -> #REF! | BK10: =K10*$BK$3*30 -> 0 | BL10: =(IF(K10>$BL$3,('Тарифы ОЗОН'!$G$3+ROUNDUP(K10-$BL$3,0)*'Тарифы ОЗОН'!$G$4),'Тарифы ОЗОН'!$G$3)) -> 67.11 | BM10: =$BN$3 -> 35 | BN10: =_xlfn.XLOOKUP(BM10,'Тарифы ОЗОН'!$A:$A,'Тарифы ОЗОН'!$B:$B) -> 1.32 | BO10: =_xlfn.XLOOKUP(BM10,'Тарифы ОЗОН'!$A:$A,'Тарифы ОЗОН'!C:C) -> 0.016 | BP10: =$BP$3 -> 25 | BQ10: =BL10*BN10+BC10*BO10+BP10 -> #REF! | BR10: =$BR$3 -> 0.85 | BS10: =(100%/BR10)*BQ10+(100%/BR10-1)*BL10 -> #REF! | BT10: =IFERROR(BS10/BC10*100%,0) -> 0 | BU10: =BC10*$BU$3 -> #REF! | BV10: =BF10+F10 -> #REF! | BW10: =IFERROR(BY10/BC10,0) -> 0 | BX10: =IFERROR(BC10-BV10,0) -> 0 | BY10: =BX10-BC10*7% -> #REF! | BZ10: =IFERROR(BY10/H10*100%,0) -> 0 | CA10: 1099 | CB10: =IF(BC10=0,0,CA10-BV10) -> #REF! | CC10: =IF(CB10=0,0,CB10-CA10*7%) -> #REF! | CD10: =CC10/H10*100% -> #REF! | CE10: =IFERROR(CC10/CA10,0) -> 0 | CF10: =_xlfn.XLOOKUP(B10,'[1]Рассчет акции'!$A:$A,'[1]Рассчет акции'!$R:$R,0) -> 0 | CG10: =_xlfn.XLOOKUP(B10,'[1]Рассчет акции'!$A:$A,'[1]Рассчет акции'!$M:$M,0) -> 1071 | CH10: =IFERROR($CJ10/$CG10,0) -> 0 | CI10: =IF(BC10>0,CG10-BV10,0) -> #REF! | CJ10: =IF(CI10>0,$CI10-$CG10*7%,0) -> #REF! | CK10: =$CJ10/$H10*100% -> #REF! | CL10: =_xlfn.XLOOKUP(B10,'[1]Рассчет акции'!$A:$A,'[1]Рассчет акции'!$W:$W,0) -> 5 | CM10: =_xlfn.XLOOKUP(B10,'[1]Рассчет акции'!$A:$A,'[1]Рассчет акции'!$X:$X,0) -> 999 | CN10: =BC10/H10 -> #REF! | CO10: =CA10-10%*CA10 -> 989.1 | CP10: =_xlfn.XLOOKUP(B10,'[1]Рассчет акции'!$A:$A,'[1]Рассчет акции'!$Z:$Z,0) -> 0
A11: 177405495 | B11: 2576041357 | C11: AHMA3BW102BG | D11: Мешки/деликат 3 шт. | E11: 2038627713902 | F11: =SUM(H11:J11) -> 195.35735 | G11: =IFERROR(F11/S11*100%,0) -> 0.17628348 | H11: =IF(_xlfn.XLOOKUP($C11,'Юнит Карго'!$A:$A,'Юнит Карго'!$G:$G)=0,_xlfn.XLOOKUP(E11,'Себес 1С текущ'!G:G,'Себес 1С текущ'!H:H),_xlfn.XLOOKUP($C11,'Юнит Карго'!$A:$A,'Юнит Карго'!$P:$P,0,0)) -> 149.35735 | I11: =_xlfn.XLOOKUP(E11,[3]ТЗ_ФФ!$D:$D,[3]ТЗ_ФФ!$BG:$BG,0) -> 38 | J11: =$J$3 -> 8 | K11: =(L11*M11*N11)/1000 -> 1.7 | L11: 25 | M11: 17 | N11: 4 | O11: =_xlfn.XLOOKUP($C11,'Юнит Карго'!$A:$A,'Юнит Карго'!$T:$T,0,0) -> 0.12 | P11: ОРР 24*34 слайдер 20*30 | Q11: 50 | S11: =T11-(T11*U11) -> 1108.2 | T11: =_xlfn.XLOOKUP(E11,'[2]Рассчет акции'!$D:$D,'[2]Рассчет акции'!$G:$G,0) -> 1847 | U11: =_xlfn.XLOOKUP(E11,'[2]Рассчет акции'!$D:$D,'[2]Рассчет акции'!$F:$F,0) -> 0.4 | V11: =AC11+AF11+AH11+AG11 -> 574.96096 | W11: =IFERROR(V11/S11,0) -> 0.51882418 | X11: =IF(K11>1,('Тарифы ВБ'!$B$9+(K11-1)*'Тарифы ВБ'!$B$10)*'Тарифы ВБ'!$B$15*'Тарифы ВБ'!$B$12+S11*'Тарифы ВБ'!$B$13,'Тарифы ВБ'!$B$8*'Тарифы ВБ'!$B$15*'Тарифы ВБ'!$B$12+S11*'Тарифы ВБ'!$B$13) -> 126.93996 | Y11: =IF(K11>1,'Тарифы ВБ'!$B$9+(K11-1)*'Тарифы ВБ'!$B$10,'Тарифы ВБ'!$B$8) -> 55.8 | Z11: =SUM(X11:Y11) -> 182.73996 | AA11: =IFERROR(Z11/S11,0) -> 0.164898 | AB11: =IF(K11>1,'Тарифы ВБ'!$B$14*'Тарифы ВБ'!$B$16*'Тарифы ВБ'!$B$15+(K11-1)*'Тарифы ВБ'!$B$14,'Тарифы ВБ'!$B$14*'Тарифы ВБ'!B$16*'Тарифы ВБ'!$B$15) -> 32.056 | AC11: =+X11+AB11+Y11 -> 214.79596 | AD11: =AC11/S11*100% -> 0.19382418 | AE11: 0.295 | AF11: =S11*AE11 -> 326.919 | AG11: =1.1*S11*$AG$3 -> 0 | AH11: =S11*$AH$3 -> 33.246 | AI11: =F11+V11 -> 770.31831 | AJ11: =IFERROR(AL11/S11,0) -> 0.23489234 | AK11: =S11-AI11 -> 337.88169 | AL11: =AK11-S11*7% -> 260.30769 | AM11: =AL11/H11 -> 1.7428515 | AN11: 1119 | AO11: =$AN11-$AI11 -> 348.68169 | AP11: =$AO11-$AN11*7% -> 270.35169 | AQ11: =$AP11/$H11*100% -> 1.8100996 | AR11: =$AP11/$AN11 -> 0.24160115 | AS11: =IFERROR(_xlfn.XLOOKUP(A11,'[2]Рассчет акции'!$A:$A,'[2]Рассчет акции'!$BH:$BH),0) -> * | AT11: =IFERROR(_xlfn.XLOOKUP($A11,'[2]Рассчет акции'!$A:$A,'[2]Рассчет акции'!$BC:$BC),0) -> 1108 | AU11: =IFERROR($AW11/$AT11,0) -> 0.23476687 | AV11: =$AT11-$AI11 -> 337.68169 | AW11: =$AV11-$AT11*7% -> 260.12169 | AX11: =$AW11/$H11*100% -> 1.7416062 | AY11: =IFERROR(_xlfn.XLOOKUP(E11,'[2]Рассчет акции'!$D:$D,'[2]Рассчет акции'!$BM:$BM),0) -> 264 | AZ11: =IFERROR(_xlfn.XLOOKUP(E11,'[2]Рассчет акции'!$D:$D,'[2]Рассчет акции'!$BN:$BN),0) -> 999 | BA11: =S11/H11 -> 7.4197887 | BC11: =_xlfn.XLOOKUP(B11,#REF!,#REF!,0) -> #REF! | BD11: =BC11/(100%-BE11) -> #REF! | BE11: =_xlfn.XLOOKUP($B11,'[1]Рассчет акции'!$A:$A,'[1]Рассчет акции'!$J:$J) -> 0.35 | BF11: =BS11+BI11+BJ11+BU11+BK11 -> #REF! | BG11: =IFERROR(BF11/BC11,0) -> 0 | BH11: 0.4 | BI11: =BC11*BH11 -> #REF! | BJ11: =BC11*$BJ$3 -> #REF! | BK11: =K11*$BK$3*30 -> 0 | BL11: =(IF(K11>$BL$3,('Тарифы ОЗОН'!$G$3+ROUNDUP(K11-$BL$3,0)*'Тарифы ОЗОН'!$G$4),'Тарифы ОЗОН'!$G$3)) -> 56.94 | BM11: =$BN$3 -> 35 | BN11: =_xlfn.XLOOKUP(BM11,'Тарифы ОЗОН'!$A:$A,'Тарифы ОЗОН'!$B:$B) -> 1.32 | BO11: =_xlfn.XLOOKUP(BM11,'Тарифы ОЗОН'!$A:$A,'Тарифы ОЗОН'!C:C) -> 0.016 | BP11: =$BP$3 -> 25 | BQ11: =BL11*BN11+BC11*BO11+BP11 -> #REF! | BR11: =$BR$3 -> 0.85 | BS11: =(100%/BR11)*BQ11+(100%/BR11-1)*BL11 -> #REF! | BT11: =IFERROR(BS11/BC11*100%,0) -> 0 | BU11: =BC11*$BU$3 -> #REF! | BV11: =BF11+F11 -> #REF! | BW11: =IFERROR(BY11/BC11,0) -> 0 | BX11: =IFERROR(BC11-BV11,0) -> 0 | BY11: =BX11-BC11*7% -> #REF! | BZ11: =IFERROR(BY11/H11*100%,0) -> 0 | CA11: 1009 | CB11: =IF(BC11=0,0,CA11-BV11) -> #REF! | CC11: =IF(CB11=0,0,CB11-CA11*7%) -> #REF! | CD11: =CC11/H11*100% -> #REF! | CE11: =IFERROR(CC11/CA11,0) -> 0 | CF11: =_xlfn.XLOOKUP(B11,'[1]Рассчет акции'!$A:$A,'[1]Рассчет акции'!$R:$R,0) -> 0 | CG11: =_xlfn.XLOOKUP(B11,'[1]Рассчет акции'!$A:$A,'[1]Рассчет акции'!$M:$M,0) -> 1092 | CH11: =IFERROR($CJ11/$CG11,0) -> 0 | CI11: =IF(BC11>0,CG11-BV11,0) -> #REF! | CJ11: =IF(CI11>0,$CI11-$CG11*7%,0) -> #REF! | CK11: =$CJ11/$H11*100% -> #REF! | CL11: =_xlfn.XLOOKUP(B11,'[1]Рассчет акции'!$A:$A,'[1]Рассчет акции'!$W:$W,0) -> 2 | CM11: =_xlfn.XLOOKUP(B11,'[1]Рассчет акции'!$A:$A,'[1]Рассчет акции'!$X:$X,0) -> 7 | CN11: =BC11/H11 -> #REF! | CO11: =CA11-10%*CA11 -> 908.1 | CP11: =_xlfn.XLOOKUP(B11,'[1]Рассчет акции'!$A:$A,'[1]Рассчет акции'!$Z:$Z,0) -> 0
A12: 176721350 | B12: 2419349585 | C12: AHMA3BW201WH | D12: Мешки/шнурок мелк 3 шт. | E12: 2038606201642 | F12: =SUM(H12:J12) -> 183.44246 | G12: =IFERROR(F12/S12*100%,0) -> 0.24226422 | H12: =IF(_xlfn.XLOOKUP($C12,'Юнит Карго'!$A:$A,'Юнит Карго'!$G:$G)=0,_xlfn.XLOOKUP(E12,'Себес 1С текущ'!G:G,'Себес 1С текущ'!H:H),_xlfn.XLOOKUP($C12,'Юнит Карго'!$A:$A,'Юнит Карго'!$P:$P,0,0)) -> 137.44246 | I12: =_xlfn.XLOOKUP(E12,[3]ТЗ_ФФ!$D:$D,[3]ТЗ_ФФ!$BG:$BG,0) -> 38 | J12: =$J$3 -> 8 | K12: =(L12*M12*N12)/1000 -> 0.945 | L12: 21 | M12: 15 | N12: 3 | O12: =_xlfn.XLOOKUP($C12,'Юнит Карго'!$A:$A,'Юнит Карго'!$T:$T,0,0) -> 0.13 | P12: ОРР 24*34 слайдер 20*30 | Q12: 100 | S12: =T12-(T12*U12) -> 757.2 | T12: =_xlfn.XLOOKUP(E12,'[2]Рассчет акции'!$D:$D,'[2]Рассчет акции'!$G:$G,0) -> 1262 | U12: =_xlfn.XLOOKUP(E12,'[2]Рассчет акции'!$D:$D,'[2]Рассчет акции'!$F:$F,0) -> 0.4 | V12: =AC12+AF12+AH12+AG12 -> 383.83616 | W12: =IFERROR(V12/S12,0) -> 0.50691516 | X12: =IF(K12>1,('Тарифы ВБ'!$B$9+(K12-1)*'Тарифы ВБ'!$B$10)*'Тарифы ВБ'!$B$15*'Тарифы ВБ'!$B$12+S12*'Тарифы ВБ'!$B$13,'Тарифы ВБ'!$B$8*'Тарифы ВБ'!$B$15*'Тарифы ВБ'!$B$12+S12*'Тарифы ВБ'!$B$13) -> 73.74616 | Y12: =IF(K12>1,'Тарифы ВБ'!$B$9+(K12-1)*'Тарифы ВБ'!$B$10,'Тарифы ВБ'!$B$8) -> 32 | Z12: =SUM(X12:Y12) -> 105.74616 | AA12: =IFERROR(Z12/S12,0) -> 0.1396542 | AB12: =IF(K12>1,'Тарифы ВБ'!$B$14*'Тарифы ВБ'!$B$16*'Тарифы ВБ'!$B$15+(K12-1)*'Тарифы ВБ'!$B$14,'Тарифы ВБ'!$B$14*'Тарифы ВБ'!B$16*'Тарифы ВБ'!$B$15) -> 32 | AC12: =+X12+AB12+Y12 -> 137.74616 | AD12: =AC12/S12*100% -> 0.18191516 | AE12: 0.295 | AF12: =S12*AE12 -> 223.374 | AG12: =1.1*S12*$AG$3 -> 0 | AH12: =S12*$AH$3 -> 22.716 | AI12: =F12+V12 -> 567.27862 | AJ12: =IFERROR(AL12/S12,0) -> 0.18082062 | AK12: =S12-AI12 -> 189.92138 | AL12: =AK12-S12*7% -> 136.91738 | AM12: =AL12/H12 -> 0.99617957 | AN12: 839 | AO12: =$AN12-$AI12 -> 271.72138 | AP12: =$AO12-$AN12*7% -> 212.99138 | AQ12: =$AP12/$H12*100% -> 1.5496766 | AR12: =$AP12/$AN12 -> 0.25386338 | AS12: =IFERROR(_xlfn.XLOOKUP(A12,'[2]Рассчет акции'!$A:$A,'[2]Рассчет акции'!$BH:$BH),0) -> * | AT12: =IFERROR(_xlfn.XLOOKUP($A12,'[2]Рассчет акции'!$A:$A,'[2]Рассчет акции'!$BC:$BC),0) -> 757 | AU12: =IFERROR($AW12/$AT12,0) -> 0.18062269 | AV12: =$AT12-$AI12 -> 189.72138 | AW12: =$AV12-$AT12*7% -> 136.73138 | AX12: =$AW12/$H12*100% -> 0.99482627 | AY12: =IFERROR(_xlfn.XLOOKUP(E12,'[2]Рассчет акции'!$D:$D,'[2]Рассчет акции'!$BM:$BM),0) -> 258 | AZ12: =IFERROR(_xlfn.XLOOKUP(E12,'[2]Рассчет акции'!$D:$D,'[2]Рассчет акции'!$BN:$BN),0) -> 334 | BA12: =S12/H12 -> 5.5092144 | BC12: =_xlfn.XLOOKUP(B12,#REF!,#REF!,0) -> #REF! | BD12: =BC12/(100%-BE12) -> #REF! | BE12: =_xlfn.XLOOKUP($B12,'[1]Рассчет акции'!$A:$A,'[1]Рассчет акции'!$J:$J) -> 0.35011136 | BF12: =BS12+BI12+BJ12+BU12+BK12 -> #REF! | BG12: =IFERROR(BF12/BC12,0) -> 0 | BH12: 0.4 | BI12: =BC12*BH12 -> #REF! | BJ12: =BC12*$BJ$3 -> #REF! | BK12: =K12*$BK$3*30 -> 0 | BL12: =(IF(K12>$BL$3,('Тарифы ОЗОН'!$G$3+ROUNDUP(K12-$BL$3,0)*'Тарифы ОЗОН'!$G$4),'Тарифы ОЗОН'!$G$3)) -> 46.77 | BM12: =$BN$3 -> 35 | BN12: =_xlfn.XLOOKUP(BM12,'Тарифы ОЗОН'!$A:$A,'Тарифы ОЗОН'!$B:$B) -> 1.32 | BO12: =_xlfn.XLOOKUP(BM12,'Тарифы ОЗОН'!$A:$A,'Тарифы ОЗОН'!C:C) -> 0.016 | BP12: =$BP$3 -> 25 | BQ12: =BL12*BN12+BC12*BO12+BP12 -> #REF! | BR12: =$BR$3 -> 0.85 | BS12: =(100%/BR12)*BQ12+(100%/BR12-1)*BL12 -> #REF! | BT12: =IFERROR(BS12/BC12*100%,0) -> 0 | BU12: =BC12*$BU$3 -> #REF! | BV12: =BF12+F12 -> #REF! | BW12: =IFERROR(BY12/BC12,0) -> 0 | BX12: =IFERROR(BC12-BV12,0) -> 0 | BY12: =BX12-BC12*7% -> #REF! | BZ12: =IFERROR(BY12/H12*100%,0) -> 0 | CA12: 1099 | CB12: =IF(BC12=0,0,CA12-BV12) -> #REF! | CC12: =IF(CB12=0,0,CB12-CA12*7%) -> #REF! | CD12: =CC12/H12*100% -> #REF! | CE12: =IFERROR(CC12/CA12,0) -> 0 | CF12: =_xlfn.XLOOKUP(B12,'[1]Рассчет акции'!$A:$A,'[1]Рассчет акции'!$R:$R,0) -> 0 | CG12: =_xlfn.XLOOKUP(B12,'[1]Рассчет акции'!$A:$A,'[1]Рассчет акции'!$M:$M,0) -> 1060 | CH12: =IFERROR($CJ12/$CG12,0) -> 0 | CI12: =IF(BC12>0,CG12-BV12,0) -> #REF! | CJ12: =IF(CI12>0,$CI12-$CG12*7%,0) -> #REF! | CK12: =$CJ12/$H12*100% -> #REF! | CL12: =_xlfn.XLOOKUP(B12,'[1]Рассчет акции'!$A:$A,'[1]Рассчет акции'!$W:$W,0) -> 3 | CM12: =_xlfn.XLOOKUP(B12,'[1]Рассчет акции'!$A:$A,'[1]Рассчет акции'!$X:$X,0) -> 999 | CN12: =BC12/H12 -> #REF! | CO12: =CA12-10%*CA12 -> 989.1 | CP12: =_xlfn.XLOOKUP(B12,'[1]Рассчет акции'!$A:$A,'[1]Рассчет акции'!$Z:$Z,0) -> 0
A13: 176723275 | B13: 2419349501 | C13: AHMA3BW202WH | D13: Мешки/шнурок крупн 3 шт. | E13: 2038606256161 | F13: =SUM(H13:J13) -> 183.44246 | G13: =IFERROR(F13/S13*100%,0) -> 0.21869631 | H13: =IF(_xlfn.XLOOKUP($C13,'Юнит Карго'!$A:$A,'Юнит Карго'!$G:$G)=0,_xlfn.XLOOKUP(E13,'Себес 1С текущ'!G:G,'Себес 1С текущ'!H:H),_xlfn.XLOOKUP($C13,'Юнит Карго'!$A:$A,'Юнит Карго'!$P:$P,0,0)) -> 137.44246 | I13: =_xlfn.XLOOKUP(E13,[3]ТЗ_ФФ!$D:$D,[3]ТЗ_ФФ!$BG:$BG,0) -> 38 | J13: =$J$3 -> 8 | K13: =(L13*M13*N13)/1000 -> 0.945 | L13: 21 | M13: 15 | N13: 3 | O13: =_xlfn.XLOOKUP($C13,'Юнит Карго'!$A:$A,'Юнит Карго'!$T:$T,0,0) -> 0.13 | P13: OPP 20*34 слайдер 18*25 | Q13: 100 | S13: =T13-(T13*U13) -> 838.8 | T13: =_xlfn.XLOOKUP(E13,'[2]Рассчет акции'!$D:$D,'[2]Рассчет акции'!$G:$G,0) -> 1398 | U13: =_xlfn.XLOOKUP(E13,'[2]Рассчет акции'!$D:$D,'[2]Рассчет акции'!$F:$F,0) -> 0.4 | V13: =AC13+AF13+AH13+AG13 -> 410.99264 | W13: =IFERROR(V13/S13,0) -> 0.48997692 | X13: =IF(K13>1,('Тарифы ВБ'!$B$9+(K13-1)*'Тарифы ВБ'!$B$10)*'Тарифы ВБ'!$B$15*'Тарифы ВБ'!$B$12+S13*'Тарифы ВБ'!$B$13,'Тарифы ВБ'!$B$8*'Тарифы ВБ'!$B$15*'Тарифы ВБ'!$B$12+S13*'Тарифы ВБ'!$B$13) -> 74.38264 | Y13: =IF(K13>1,'Тарифы ВБ'!$B$9+(K13-1)*'Тарифы ВБ'!$B$10,'Тарифы ВБ'!$B$8) -> 32 | Z13: =SUM(X13:Y13) -> 106.38264 | AA13: =IFERROR(Z13/S13,0) -> 0.12682718 | AB13: =IF(K13>1,'Тарифы ВБ'!$B$14*'Тарифы ВБ'!$B$16*'Тарифы ВБ'!$B$15+(K13-1)*'Тарифы ВБ'!$B$14,'Тарифы ВБ'!$B$14*'Тарифы ВБ'!B$16*'Тарифы ВБ'!$B$15) -> 32 | AC13: =+X13+AB13+Y13 -> 138.38264 | AD13: =AC13/S13*100% -> 0.16497692 | AE13: 0.295 | AF13: =S13*AE13 -> 247.446 | AG13: =1.1*S13*$AG$3 -> 0 | AH13: =S13*$AH$3 -> 25.164 | AI13: =F13+V13 -> 594.4351 | AJ13: =IFERROR(AL13/S13,0) -> 0.22132677 | AK13: =S13-AI13 -> 244.3649 | AL13: =AK13-S13*7% -> 185.6489 | AM13: =AL13/H13 -> 1.350739 | AN13: 839 | AO13: =$AN13-$AI13 -> 244.5649 | AP13: =$AO13-$AN13*7% -> 185.8349 | AQ13: =$AP13/$H13*100% -> 1.3520923 | AR13: =$AP13/$AN13 -> 0.2214957 | AS13: =IFERROR(_xlfn.XLOOKUP(A13,'[2]Рассчет акции'!$A:$A,'[2]Рассчет акции'!$BH:$BH),0) -> 0 | AT13: =IFERROR(_xlfn.XLOOKUP($A13,'[2]Рассчет акции'!$A:$A,'[2]Рассчет акции'!$BC:$BC),0) -> 839 | AU13: =IFERROR($AW13/$AT13,0) -> 0.2214957 | AV13: =$AT13-$AI13 -> 244.5649 | AW13: =$AV13-$AT13*7% -> 185.8349 | AX13: =$AW13/$H13*100% -> 1.3520923 | AY13: =IFERROR(_xlfn.XLOOKUP(E13,'[2]Рассчет акции'!$D:$D,'[2]Рассчет акции'!$BM:$BM),0) -> 92 | AZ13: =IFERROR(_xlfn.XLOOKUP(E13,'[2]Рассчет акции'!$D:$D,'[2]Рассчет акции'!$BN:$BN),0) -> 87 | BA13: =S13/H13 -> 6.1029173 | BC13: =_xlfn.XLOOKUP(B13,#REF!,#REF!,0) -> #REF! | BD13: =BC13/(100%-BE13) -> #REF! | BE13: =_xlfn.XLOOKUP($B13,'[1]Рассчет акции'!$A:$A,'[1]Рассчет акции'!$J:$J) -> 0.35011136 | BF13: =BS13+BI13+BJ13+BU13+BK13 -> #REF! | BG13: =IFERROR(BF13/BC13,0) -> 0 | BH13: 0.4 | BI13: =BC13*BH13 -> #REF! | BJ13: =BC13*$BJ$3 -> #REF! | BK13: =K13*$BK$3*30 -> 0 | BL13: =(IF(K13>$BL$3,('Тарифы ОЗОН'!$G$3+ROUNDUP(K13-$BL$3,0)*'Тарифы ОЗОН'!$G$4),'Тарифы ОЗОН'!$G$3)) -> 46.77 | BM13: =$BN$3 -> 35 | BN13: =_xlfn.XLOOKUP(BM13,'Тарифы ОЗОН'!$A:$A,'Тарифы ОЗОН'!$B:$B) -> 1.32 | BO13: =_xlfn.XLOOKUP(BM13,'Тарифы ОЗОН'!$A:$A,'Тарифы ОЗОН'!C:C) -> 0.016 | BP13: =$BP$3 -> 25 | BQ13: =BL13*BN13+BC13*BO13+BP13 -> #REF! | BR13: =$BR$3 -> 0.85 | BS13: =(100%/BR13)*BQ13+(100%/BR13-1)*BL13 -> #REF! | BT13: =IFERROR(BS13/BC13*100%,0) -> 0 | BU13: =BC13*$BU$3 -> #REF! | BV13: =BF13+F13 -> #REF! | BW13: =IFERROR(BY13/BC13,0) -> 0 | BX13: =IFERROR(BC13-BV13,0) -> 0 | BY13: =BX13-BC13*7% -> #REF! | BZ13: =IFERROR(BY13/H13*100%,0) -> 0 | CA13: 1099 | CB13: =IF(BC13=0,0,CA13-BV13) -> #REF! | CC13: =IF(CB13=0,0,CB13-CA13*7%) -> #REF! | CD13: =CC13/H13*100% -> #REF! | CE13: =IFERROR(CC13/CA13,0) -> 0 | CF13: =_xlfn.XLOOKUP(B13,'[1]Рассчет акции'!$A:$A,'[1]Рассчет акции'!$R:$R,0) -> 0 | CG13: =_xlfn.XLOOKUP(B13,'[1]Рассчет акции'!$A:$A,'[1]Рассчет акции'!$M:$M,0) -> 1060 | CH13: =IFERROR($CJ13/$CG13,0) -> 0 | CI13: =IF(BC13>0,CG13-BV13,0) -> #REF! | CJ13: =IF(CI13>0,$CI13-$CG13*7%,0) -> #REF! | CK13: =$CJ13/$H13*100% -> #REF! | CL13: =_xlfn.XLOOKUP(B13,'[1]Рассчет акции'!$A:$A,'[1]Рассчет акции'!$W:$W,0) -> 8 | CM13: =_xlfn.XLOOKUP(B13,'[1]Рассчет акции'!$A:$A,'[1]Рассчет акции'!$X:$X,0) -> 56 | CN13: =BC13/H13 -> #REF! | CO13: =CA13-10%*CA13 -> 989.1 | CP13: =_xlfn.XLOOKUP(B13,'[1]Рассчет акции'!$A:$A,'[1]Рассчет акции'!$Z:$Z,0) -> 0
A14: 204615141 | B14: 2419349453 | C14: AHMA2BW201WH | D14: Мешки 2 шт. серый | E14: 2039404446068 | F14: =SUM(H14:J14) -> 127.96368 | G14: =IFERROR(F14/S14*100%,0) -> 0.21391454 | H14: =IF(_xlfn.XLOOKUP($C14,'Юнит Карго'!$A:$A,'Юнит Карго'!$G:$G)=0,_xlfn.XLOOKUP(E14,'Себес 1С текущ'!G:G,'Себес 1С текущ'!H:H),_xlfn.XLOOKUP($C14,'Юнит Карго'!$A:$A,'Юнит Карго'!$P:$P,0,0)) -> 84.963676 | I14: =_xlfn.XLOOKUP(E14,[3]ТЗ_ФФ!$D:$D,[3]ТЗ_ФФ!$BG:$BG,0) -> 35 | J14: =$J$3 -> 8 | K14: =(L14*M14*N14)/1000 -> 0.96 | L14: 20 | M14: 16 | N14: 3 | O14: =_xlfn.XLOOKUP($C14,'Юнит Карго'!$A:$A,'Юнит Карго'!$T:$T,0,0) -> 0.06 | P14: ОРР 22*34 слайдер 18*25 | Q14: 90 | S14: =T14-(T14*U14) -> 598.2 | T14: =_xlfn.XLOOKUP(E14,'[2]Рассчет акции'!$D:$D,'[2]Рассчет акции'!$G:$G,0) -> 997 | U14: =_xlfn.XLOOKUP(E14,'[2]Рассчет акции'!$D:$D,'[2]Рассчет акции'!$F:$F,0) -> 0.4 | V14: =AC14+AF14+AH14+AG14 -> 330.92096 | W14: =IFERROR(V14/S14,0) -> 0.55319452 | X14: =IF(K14>1,('Тарифы ВБ'!$B$9+(K14-1)*'Тарифы ВБ'!$B$10)*'Тарифы ВБ'!$B$15*'Тарифы ВБ'!$B$12+S14*'Тарифы ВБ'!$B$13,'Тарифы ВБ'!$B$8*'Тарифы ВБ'!$B$15*'Тарифы ВБ'!$B$12+S14*'Тарифы ВБ'!$B$13) -> 72.50596 | Y14: =IF(K14>1,'Тарифы ВБ'!$B$9+(K14-1)*'Тарифы ВБ'!$B$10,'Тарифы ВБ'!$B$8) -> 32 | Z14: =SUM(X14:Y14) -> 104.50596 | AA14: =IFERROR(Z14/S14,0) -> 0.1747007 | AB14: =IF(K14>1,'Тарифы ВБ'!$B$14*'Тарифы ВБ'!$B$16*'Тарифы ВБ'!$B$15+(K14-1)*'Тарифы ВБ'!$B$14,'Тарифы ВБ'!$B$14*'Тарифы ВБ'!B$16*'Тарифы ВБ'!$B$15) -> 32 | AC14: =+X14+AB14+Y14 -> 136.50596 | AD14: =AC14/S14*100% -> 0.22819452 | AE14: 0.295 | AF14: =S14*AE14 -> 176.469 | AG14: =1.1*S14*$AG$3 -> 0 | AH14: =S14*$AH$3 -> 17.946 | AI14: =F14+V14 -> 458.88464 | AJ14: =IFERROR(AL14/S14,0) -> 0.16289095 | AK14: =S14-AI14 -> 139.31536 | AL14: =AK14-S14*7% -> 97.441364 | AM14: =AL14/H14 -> 1.1468591 | AN14: 659 | AO14: =$AN14-$AI14 -> 200.11536 | AP14: =$AO14-$AN14*7% -> 153.98536 | AQ14: =$AP14/$H14*100% -> 1.812367 | AR14: =$AP14/$AN14 -> 0.2336652 | AS14: =IFERROR(_xlfn.XLOOKUP(A14,'[2]Рассчет акции'!$A:$A,'[2]Рассчет акции'!$BH:$BH),0) -> * | AT14: =IFERROR(_xlfn.XLOOKUP($A14,'[2]Рассчет акции'!$A:$A,'[2]Рассчет акции'!$BC:$BC),0) -> 598 | AU14: =IFERROR($AW14/$AT14,0) -> 0.16263439 | AV14: =$AT14-$AI14 -> 139.11536 | AW14: =$AV14-$AT14*7% -> 97.255364 | AX14: =$AW14/$H14*100% -> 1.1446699 | AY14: =IFERROR(_xlfn.XLOOKUP(E14,'[2]Рассчет акции'!$D:$D,'[2]Рассчет акции'!$BM:$BM),0) -> 222 | AZ14: =IFERROR(_xlfn.XLOOKUP(E14,'[2]Рассчет акции'!$D:$D,'[2]Рассчет акции'!$BN:$BN),0) -> 602 | BA14: =S14/H14 -> 7.0406558 | BC14: =_xlfn.XLOOKUP(B14,#REF!,#REF!,0) -> #REF! | BD14: =BC14/(100%-BE14) -> #REF! | BE14: =_xlfn.XLOOKUP($B14,'[1]Рассчет акции'!$A:$A,'[1]Рассчет акции'!$J:$J) -> 0.3501355 | BF14: =BS14+BI14+BJ14+BU14+BK14 -> #REF! | BG14: =IFERROR(BF14/BC14,0) -> 0 | BH14: 0.4 | BI14: =BC14*BH14 -> #REF! | BJ14: =BC14*$BJ$3 -> #REF! | BK14: =K14*$BK$3*30 -> 0 | BL14: =(IF(K14>$BL$3,('Тарифы ОЗОН'!$G$3+ROUNDUP(K14-$BL$3,0)*'Тарифы ОЗОН'!$G$4),'Тарифы ОЗОН'!$G$3)) -> 46.77 | BM14: =$BN$3 -> 35 | BN14: =_xlfn.XLOOKUP(BM14,'Тарифы ОЗОН'!$A:$A,'Тарифы ОЗОН'!$B:$B) -> 1.32 | BO14: =_xlfn.XLOOKUP(BM14,'Тарифы ОЗОН'!$A:$A,'Тарифы ОЗОН'!C:C) -> 0.016 | BP14: =$BP$3 -> 25 | BQ14: =BL14*BN14+BC14*BO14+BP14 -> #REF! | BR14: =$BR$3 -> 0.85 | BS14: =(100%/BR14)*BQ14+(100%/BR14-1)*BL14 -> #REF! | BT14: =IFERROR(BS14/BC14*100%,0) -> 0 | BU14: =BC14*$BU$3 -> #REF! | BV14: =BF14+F14 -> #REF! | BW14: =IFERROR(BY14/BC14,0) -> 0 | BX14: =IFERROR(BC14-BV14,0) -> 0 | BY14: =BX14-BC14*7% -> #REF! | BZ14: =IFERROR(BY14/H14*100%,0) -> 0 | CA14: 869 | CB14: =IF(BC14=0,0,CA14-BV14) -> #REF! | CC14: =IF(CB14=0,0,CB14-CA14*7%) -> #REF! | CD14: =CC14/H14*100% -> #REF! | CE14: =IFERROR(CC14/CA14,0) -> 0 | CF14: =_xlfn.XLOOKUP(B14,'[1]Рассчет акции'!$A:$A,'[1]Рассчет акции'!$R:$R,0) -> 0 | CG14: =_xlfn.XLOOKUP(B14,'[1]Рассчет акции'!$A:$A,'[1]Рассчет акции'!$M:$M,0) -> 827 | CH14: =IFERROR($CJ14/$CG14,0) -> 0 | CI14: =IF(BC14>0,CG14-BV14,0) -> #REF! | CJ14: =IF(CI14>0,$CI14-$CG14*7%,0) -> #REF! | CK14: =$CJ14/$H14*100% -> #REF! | CL14: =_xlfn.XLOOKUP(B14,'[1]Рассчет акции'!$A:$A,'[1]Рассчет акции'!$W:$W,0) -> 1 | CM14: =_xlfn.XLOOKUP(B14,'[1]Рассчет акции'!$A:$A,'[1]Рассчет акции'!$X:$X,0) -> 7 | CN14: =BC14/H14 -> #REF! | CO14: =CA14-10%*CA14 -> 782.1 | CP14: =_xlfn.XLOOKUP(B14,'[1]Рассчет акции'!$A:$A,'[1]Рассчет акции'!$Z:$Z,0) -> 0
A15: 236074677 | C15: AHMA2BW202WH | D15: Мешки 2 шт. розовый | E15: 2040278862540 | F15: =SUM(H15:J15) -> 185 | G15: =IFERROR(F15/S15*100%,0) -> 0.24666667 | H15: =IF(_xlfn.XLOOKUP($C15,'Юнит Карго'!$A:$A,'Юнит Карго'!$G:$G)=0,_xlfn.XLOOKUP(E15,'Себес 1С текущ'!G:G,'Себес 1С текущ'!H:H),_xlfn.XLOOKUP($C15,'Юнит Карго'!$A:$A,'Юнит Карго'!$P:$P,0,0)) -> 142 | I15: 35 | J15: =$J$3 -> 8 | K15: =(L15*M15*N15)/1000 -> 0.96 | L15: 20 | M15: 16 | N15: 3 | O15: =_xlfn.XLOOKUP($C15,'Юнит Карго'!$A:$A,'Юнит Карго'!$T:$T,0,0) -> 0.095 | P15: 18*25 | Q15: 90 | S15: =T15-(T15*U15) -> 750 | T15: =_xlfn.XLOOKUP(E15,'[2]Рассчет акции'!$D:$D,'[2]Рассчет акции'!$G:$G,0) -> 1250 | U15: =_xlfn.XLOOKUP(E15,'[2]Рассчет акции'!$D:$D,'[2]Рассчет акции'!$F:$F,0) -> 0.4 | V15: =AC15+AF15+AH15+AG15 -> 381.44 | W15: =IFERROR(V15/S15,0) -> 0.50858667 | X15: =IF(K15>1,('Тарифы ВБ'!$B$9+(K15-1)*'Тарифы ВБ'!$B$10)*'Тарифы ВБ'!$B$15*'Тарифы ВБ'!$B$12+S15*'Тарифы ВБ'!$B$13,'Тарифы ВБ'!$B$8*'Тарифы ВБ'!$B$15*'Тарифы ВБ'!$B$12+S15*'Тарифы ВБ'!$B$13) -> 73.69 | Y15: =IF(K15>1,'Тарифы ВБ'!$B$9+(K15-1)*'Тарифы ВБ'!$B$10,'Тарифы ВБ'!$B$8) -> 32 | Z15: =SUM(X15:Y15) -> 105.69 | AA15: =IFERROR(Z15/S15,0) -> 0.14092 | AB15: =IF(K15>1,'Тарифы ВБ'!$B$14*'Тарифы ВБ'!$B$16*'Тарифы ВБ'!$B$15+(K15-1)*'Тарифы ВБ'!$B$14,'Тарифы ВБ'!$B$14*'Тарифы ВБ'!B$16*'Тарифы ВБ'!$B$15) -> 32 | AC15: =+X15+AB15+Y15 -> 137.69 | AD15: =AC15/S15*100% -> 0.18358667 | AE15: 0.295 | AF15: =S15*AE15 -> 221.25 | AG15: =1.1*S15*$AG$3 -> 0 | AH15: =S15*$AH$3 -> 22.5 | AI15: =F15+V15 -> 566.44 | AJ15: =IFERROR(AL15/S15,0) -> 0.17474667 | AK15: =S15-AI15 -> 183.56 | AL15: =AK15-S15*7% -> 131.06 | AM15: =AL15/H15 -> 0.92295775 | AN15: 759 | AO15: =$AN15-$AI15 -> 192.56 | AP15: =$AO15-$AN15*7% -> 139.43 | AQ15: =$AP15/$H15*100% -> 0.98190141 | AR15: =$AP15/$AN15 -> 0.18370224 | AS15: =IFERROR(_xlfn.XLOOKUP(A15,'[2]Рассчет акции'!$A:$A,'[2]Рассчет акции'!$BH:$BH),0) -> * | AT15: =IFERROR(_xlfn.XLOOKUP($A15,'[2]Рассчет акции'!$A:$A,'[2]Рассчет акции'!$BC:$BC),0) -> 750 | AU15: =IFERROR($AW15/$AT15,0) -> 0.17474667 | AV15: =$AT15-$AI15 -> 183.56 | AW15: =$AV15-$AT15*7% -> 131.06 | AX15: =$AW15/$H15*100% -> 0.92295775 | AY15: =IFERROR(_xlfn.XLOOKUP(E15,'[2]Рассчет акции'!$D:$D,'[2]Рассчет акции'!$BM:$BM),0) -> 18 | AZ15: =IFERROR(_xlfn.XLOOKUP(E15,'[2]Рассчет акции'!$D:$D,'[2]Рассчет акции'!$BN:$BN),0) -> 152 | BA15: =S15/H15 -> 5.2816901 | BC15: =_xlfn.XLOOKUP(B15,#REF!,#REF!,0) -> #REF! | BD15: =BC15/(100%-BE15) -> #REF! | BE15: =_xlfn.XLOOKUP($B15,'[1]Рассчет акции'!$A:$A,'[1]Рассчет акции'!$J:$J) -> 0 | BF15: =BS15+BI15+BJ15+BU15+BK15 -> #REF! | BG15: =IFERROR(BF15/BC15,0) -> 0 | BH15: 0.4 | BI15: =BC15*BH15 -> #REF! | BJ15: =BC15*$BJ$3 -> #REF! | BK15: =K15*$BK$3*30 -> 0 | BL15: =(IF(K15>$BL$3,('Тарифы ОЗОН'!$G$3+ROUNDUP(K15-$BL$3,0)*'Тарифы ОЗОН'!$G$4),'Тарифы ОЗОН'!$G$3)) -> 46.77 | BM15: =$BN$3 -> 35 | BN15: =_xlfn.XLOOKUP(BM15,'Тарифы ОЗОН'!$A:$A,'Тарифы ОЗОН'!$B:$B) -> 1.32 | BO15: =_xlfn.XLOOKUP(BM15,'Тарифы ОЗОН'!$A:$A,'Тарифы ОЗОН'!C:C) -> 0.016 | BP15: =$BP$3 -> 25 | BQ15: =BL15*BN15+BC15*BO15+BP15 -> #REF! | BR15: =$BR$3 -> 0.85 | BS15: =(100%/BR15)*BQ15+(100%/BR15-1)*BL15 -> #REF! | BT15: =IFERROR(BS15/BC15*100%,0) -> 0 | BU15: =BC15*$BU$3 -> #REF! | BV15: =BF15+F15 -> #REF! | BW15: =IFERROR(BY15/BC15,0) -> 0 | BX15: =IFERROR(BC15-BV15,0) -> 0 | BY15: =BX15-BC15*7% -> #REF! | BZ15: =IFERROR(BY15/H15*100%,0) -> 0 | CA15: 0 | CB15: =IF(BC15=0,0,CA15-BV15) -> #REF! | CC15: =IF(CB15=0,0,CB15-CA15*7%) -> #REF! | CD15: =CC15/H15*100% -> #REF! | CE15: =IFERROR(CC15/CA15,0) -> 0 | CF15: =_xlfn.XLOOKUP(B15,'[1]Рассчет акции'!$A:$A,'[1]Рассчет акции'!$R:$R,0) -> 0 | CG15: =_xlfn.XLOOKUP(B15,'[1]Рассчет акции'!$A:$A,'[1]Рассчет акции'!$M:$M,0) -> 0 | CH15: =IFERROR($CJ15/$CG15,0) -> 0 | CI15: =IF(BC15>0,CG15-BV15,0) -> #REF! | CJ15: =IF(CI15>0,$CI15-$CG15*7%,0) -> #REF! | CK15: =$CJ15/$H15*100% -> #REF! | CL15: =_xlfn.XLOOKUP(B15,'[1]Рассчет акции'!$A:$A,'[1]Рассчет акции'!$W:$W,0) -> 0 | CM15: =_xlfn.XLOOKUP(B15,'[1]Рассчет акции'!$A:$A,'[1]Рассчет акции'!$X:$X,0) -> 0 | CN15: =BC15/H15 -> #REF! | CO15: =CA15-10%*CA15 -> 0 | CP15: =_xlfn.XLOOKUP(B15,'[1]Рассчет акции'!$A:$A,'[1]Рассчет акции'!$Z:$Z,0) -> 0
A16: 236929187 | B16: 2419349360 | C16: AHMA1BW112WH | D16: Мешок 60*80 крупн | E16: 2040335626849 | F16: =SUM(H16:J16) -> 107.34113 | G16: =IFERROR(F16/S16*100%,0) -> 0.16045011 | H16: =IF(_xlfn.XLOOKUP($C16,'Юнит Карго'!$A:$A,'Юнит Карго'!$G:$G)=0,_xlfn.XLOOKUP(E16,'Себес 1С текущ'!G:G,'Себес 1С текущ'!H:H),_xlfn.XLOOKUP($C16,'Юнит Карго'!$A:$A,'Юнит Карго'!$P:$P,0,0)) -> 85.341127 | I16: =_xlfn.XLOOKUP(E16,[3]ТЗ_ФФ!$D:$D,[3]ТЗ_ФФ!$BG:$BG,0) -> 14 | J16: =$J$3 -> 8 | K16: =(L16*M16*N16)/1000 -> 0.616 | L16: 28 | M16: 22 | N16: 1 | O16: =_xlfn.XLOOKUP($C16,'Юнит Карго'!$A:$A,'Юнит Карго'!$T:$T,0,0) -> 0.1 | P16: своя | S16: =T16-(T16*U16) -> 669 | T16: =_xlfn.XLOOKUP(E16,'[2]Рассчет акции'!$D:$D,'[2]Рассчет акции'!$G:$G,0) -> 1115 | U16: =_xlfn.XLOOKUP(E16,'[2]Рассчет акции'!$D:$D,'[2]Рассчет акции'!$F:$F,0) -> 0.4 | V16: =AC16+AF16+AH16+AG16 -> 354.4832 | W16: =IFERROR(V16/S16,0) -> 0.52987025 | X16: =IF(K16>1,('Тарифы ВБ'!$B$9+(K16-1)*'Тарифы ВБ'!$B$10)*'Тарифы ВБ'!$B$15*'Тарифы ВБ'!$B$12+S16*'Тарифы ВБ'!$B$13,'Тарифы ВБ'!$B$8*'Тарифы ВБ'!$B$15*'Тарифы ВБ'!$B$12+S16*'Тарифы ВБ'!$B$13) -> 73.0582 | Y16: =IF(K16>1,'Тарифы ВБ'!$B$9+(K16-1)*'Тарифы ВБ'!$B$10,'Тарифы ВБ'!$B$8) -> 32 | Z16: =SUM(X16:Y16) -> 105.0582 | AA16: =IFERROR(Z16/S16,0) -> 0.15703767 | AB16: =IF(K16>1,'Тарифы ВБ'!$B$14*'Тарифы ВБ'!$B$16*'Тарифы ВБ'!$B$15+(K16-1)*'Тарифы ВБ'!$B$14,'Тарифы ВБ'!$B$14*'Тарифы ВБ'!B$16*'Тарифы ВБ'!$B$15) -> 32 | AC16: =+X16+AB16+Y16 -> 137.0582 | AD16: =AC16/S16*100% -> 0.20487025 | AE16: 0.295 | AF16: =S16*AE16 -> 197.355 | AG16: =1.1*S16*$AG$3 -> 0 | AH16: =S16*$AH$3 -> 20.07 | AI16: =F16+V16 -> 461.82433 | AJ16: =IFERROR(AL16/S16,0) -> 0.23967963 | AK16: =S16-AI16 -> 207.17567 | AL16: =AK16-S16*7% -> 160.34567 | AM16: =AL16/H16 -> 1.8788793 | AN16: 669 | AO16: =$AN16-$AI16 -> 207.17567 | AP16: =$AO16-$AN16*7% -> 160.34567 | AQ16: =$AP16/$H16*100% -> 1.8788793 | AR16: =$AP16/$AN16 -> 0.23967963 | AS16: =IFERROR(_xlfn.XLOOKUP(A16,'[2]Рассчет акции'!$A:$A,'[2]Рассчет акции'!$BH:$BH),0) -> 0 | AT16: =IFERROR(_xlfn.XLOOKUP($A16,'[2]Рассчет акции'!$A:$A,'[2]Рассчет акции'!$BC:$BC),0) -> 669 | AU16: =IFERROR($AW16/$AT16,0) -> 0.23967963 | AV16: =$AT16-$AI16 -> 207.17567 | AW16: =$AV16-$AT16*7% -> 160.34567 | AX16: =$AW16/$H16*100% -> 1.8788793 | AY16: =IFERROR(_xlfn.XLOOKUP(E16,'[2]Рассчет акции'!$D:$D,'[2]Рассчет акции'!$BM:$BM),0) -> 94 | AZ16: =IFERROR(_xlfn.XLOOKUP(E16,'[2]Рассчет акции'!$D:$D,'[2]Рассчет акции'!$BN:$BN),0) -> 72 | BA16: =S16/H16 -> 7.8391278 | BC16: =_xlfn.XLOOKUP(B16,#REF!,#REF!,0) -> #REF! | BD16: =BC16/(100%-BE16) -> #REF! | BE16: =_xlfn.XLOOKUP($B16,'[1]Рассчет акции'!$A:$A,'[1]Рассчет акции'!$J:$J) -> 0.3500887 | BF16: =BS16+BI16+BJ16+BU16+BK16 -> #REF! | BG16: =IFERROR(BF16/BC16,0) -> 0 | BH16: 0.4 | BI16: =BC16*BH16 -> #REF! | BJ16: =BC16*$BJ$3 -> #REF! | BK16: =K16*$BK$3*30 -> 0 | BL16: =(IF(K16>$BL$3,('Тарифы ОЗОН'!$G$3+ROUNDUP(K16-$BL$3,0)*'Тарифы ОЗОН'!$G$4),'Тарифы ОЗОН'!$G$3)) -> 46.77 | BM16: =$BN$3 -> 35 | BN16: =_xlfn.XLOOKUP(BM16,'Тарифы ОЗОН'!$A:$A,'Тарифы ОЗОН'!$B:$B) -> 1.32 | BO16: =_xlfn.XLOOKUP(BM16,'Тарифы ОЗОН'!$A:$A,'Тарифы ОЗОН'!C:C) -> 0.016 | BP16: =$BP$3 -> 25 | BQ16: =BL16*BN16+BC16*BO16+BP16 -> #REF! | BR16: =$BR$3 -> 0.85 | BS16: =(100%/BR16)*BQ16+(100%/BR16-1)*BL16 -> #REF! | BT16: =IFERROR(BS16/BC16*100%,0) -> 0 | BU16: =BC16*$BU$3 -> #REF! | BV16: =BF16+F16 -> #REF! | BW16: =IFERROR(BY16/BC16,0) -> 0 | BX16: =IFERROR(BC16-BV16,0) -> 0 | BY16: =BX16-BC16*7% -> #REF! | BZ16: =IFERROR(BY16/H16*100%,0) -> 0 | CA16: 859 | CB16: =IF(BC16=0,0,CA16-BV16) -> #REF! | CC16: =IF(CB16=0,0,CB16-CA16*7%) -> #REF! | CD16: =CC16/H16*100% -> #REF! | CE16: =IFERROR(CC16/CA16,0) -> 0 | CF16: =_xlfn.XLOOKUP(B16,'[1]Рассчет акции'!$A:$A,'[1]Рассчет акции'!$R:$R,0) -> 0 | CG16: =_xlfn.XLOOKUP(B16,'[1]Рассчет акции'!$A:$A,'[1]Рассчет акции'!$M:$M,0) -> 670 | CH16: =IFERROR($CJ16/$CG16,0) -> 0 | CI16: =IF(BC16>0,CG16-BV16,0) -> #REF! | CJ16: =IF(CI16>0,$CI16-$CG16*7%,0) -> #REF! | CK16: =$CJ16/$H16*100% -> #REF! | CL16: =_xlfn.XLOOKUP(B16,'[1]Рассчет акции'!$A:$A,'[1]Рассчет акции'!$W:$W,0) -> 1 | CM16: =_xlfn.XLOOKUP(B16,'[1]Рассчет акции'!$A:$A,'[1]Рассчет акции'!$X:$X,0) -> 7 | CN16: =BC16/H16 -> #REF! | CO16: =CA16-10%*CA16 -> 773.1 | CP16: =_xlfn.XLOOKUP(B16,'[1]Рассчет акции'!$A:$A,'[1]Рассчет акции'!$Z:$Z,0) -> 0
